Workbook
Name fck: Input!$C$8
Name alpha_source: Input!$C$9
Name gamma_c: Input!$C$10
Name alpha: Input!$C$11
Name fcd: Input!$C$12
Name eco: Input!$C$13
Name ecu: Input!$C$14
Name n: Input!$C$15
Name Es: Input!$C$20
Name fy_char: Input!$C$21
Name gamma_s: Input!$C$22
Name fy: Input!$C$23
Name beta: Input!$C$28
Name etu: Input!$C$29
Name xc: Input!$C$30
Name yc: Input!$C$31
Name Pu: Input!$C$36
Name Mux: Input!$C$37
Name Muy: Input!$C$38
Name theta_L: Input!$C$40
Name Mu: Input!$C$41
Name Geom_Area: Geometry!$D$62
Name u_max: Geometry!$D$63
Name u_min: Geometry!$D$64
Name u_bar: Geometry!$D$65
Name u_C1: Geometry!$D$66
Name As_tot: Geometry!$D$68
Name Mesh_X: Mesh!$B$5:$B$1261
Name Mesh_Y: Mesh!$C$5:$C$1261
Name Mesh_A: Mesh!$D$5:$D$1261
Name St_e0: 'PM_Angle'!$J$7:$J$33
Name St_kx: 'PM_Angle'!$K$7:$K$33
Name St_ky: 'PM_Angle'!$L$7:$L$33
Name Det: Concrete!$C$4
Name St_P: 'PM_Angle'!$S$7:$S$33
Name St_Mx: 'PM_Angle'!$T$7:$T$33
Name St_My: 'PM_Angle'!$U$7:$U$33
Name Mb: 'MxMy_FixedP'!$E$53
Name Mtol: 'PM_Theta'!$C$7
Name Eq_e0: Equilibrium!$C$7
Name Eq_kx: Equilibrium!$C$8
Name Eq_ky: Equilibrium!$C$9

Sheet Input
B1: P–M–M SECTION CALCULATION — DESIGN RESISTANCE
B2: Project | C2: PM-advanced (7) 2D reference case | E2: Every value on a shaded input cell drives live formulas on the other sheets. Only the Mesh, Geometry and bar tables hold engine-computed constants.
B3: Section | C3: PM-advanced (7) 2D — 1500x1200 chamfered section, two voids
B4: Generated | C4: 2026-08-11 08:16:25
B6: Concrete
B7: standard | C7: KDS | E7: KDS C30 (workbook Input)
B8: fck | C8: 30 | D8: MPa | E8: characteristic/input strength
B9: α source | C9: 0.85 | D9: - | E9: α_cc for EN 1992, α₁/block factor for other families
B10: γc | C10: 1 | D10: - | E10: not applied by this material family
B11: α_eff | C11: =alpha_source -> 0.85 | D11: - | E11: stress multiplier used by formulas
B12: fcd = α_eff·fck | C12: =alpha*fck -> 25.5 | D12: MPa
B13: εco | C13: 0.002 | D13: -
B14: εcu | C14: 0.0033 | D14: -
B15: n | C15: 2 | D15: -
B16: law | C16: KDS parabola-rectangle: fc = α·fck·(1−(1−ε/εco)^n) up to εco, then α·fck
B18: Reinforcement
B19: standard | C19: KDS | E19: SD400 (workbook Input)
B20: Es | C20: 200000 | D20: MPa
B21: fy (characteristic) | C21: 400 | D21: MPa
B22: γs | C22: 1 | D22: - | E22: not applied by this material family
B23: fy (model) / fyd | C23: =fy_char -> 400 | D23: MPa | E23: yield stress used by formulas
B24: εy = fyd/Es | C24: =fy/Es -> 0.002 | D24: - | E24: used by the fₛ/fyd stations
B25: law | C25: Elastic – perfectly plastic: fs = clamp(Es·ε, −fy, +fy)
B27: Analysis
B28: β (strain direction) | C28: 15 | D28: deg | E28: strain-gradient direction of the audited states; not the N.A. line angle; drives Geometry, PM_Angle, Concrete, Steel
B29: εtu | C29: -0.05 | D29: - | E29: uniform strain used for station P18
B30: xc | C30: 0 | D30: mm | E30: analysis origin = net concrete centroid
B31: yc | C31: 0 | D31: mm | E31: all X, Y below are measured from it
B32: mesh cell size | C32: 87.242926 | D32: mm | E32: clipped-cell grid, docs/02 §5
B33: mesh points | C33: 1257 | D33: - | E33: 3-point degree-2 rule per clipped triangle
B35: Demand
B36: Pu | C36: 24942.922 | D36: kN | E36: ULS-1 workbook Newton demand (on the 15 deg surface)
B37: Mux | C37: 3714.1659 | D37: kN·m
B38: Muy | C38: 1431.7807 | D38: kN·m
B40: θ_L (demand direction) | C40: =IF(AND(Mux=0,Muy=0),0,DEGREES(ATAN2(Mux,Muy))) | D40: deg | E40: atan2 of the demand moment vector. Used only to query the finished surface (MxMy_FixedP, PM_Theta). It is not the strain-plane angle β above.
B41: Mu resultant | C41: =SQRT(Mux^2+Muy^2) | D41: kN·m
B42: αNA (N.A. axis in section x-y) | C42: =MOD(180-beta,180) | D42: deg | E42: Undirected ε = 0 line angle, CCW from section +x. This is the line angle corresponding to β.
B43: α⊥ (axis perpendicular to Rₘ) | C43: =IF(AND(Mux=0,Muy=0),0,MOD(DEGREES(ATAN2(-Mux,Muy)),180)) | D43: deg | E43: Reference line perpendicular to the in-section bending direction Rₘ = (Muy,Mux).
B44: Δα = angle(N.A., ⊥Rₘ) | C44: =MIN(ABS(C42-C43),180-ABS(C42-C43)) | D44: deg | E44: Smallest angle between two undirected section lines. This is the valid N.A. comparison.
B46: Net concrete area (from mesh) | C46: =SUM(Mesh_A) | D46: mm² | E46: =IF(ABS(C46-Geom_Area)<=0.000001*Geom_Area,"OK - matches the exact polygon area","CHECK - mesh and polygon areas differ")
...

Sheet Design_Check
B1: GOVERNING DESIGN-RESISTANCE CHECK
B2: The design surface is authoritative for acceptance. Nominal/reference results remain available for audit and are never compared directly with factored ULS demand.
B5: Profile identity
B6: Organization | C6: MOLIT/KDS | E6: Profile publisher
B7: Document | C7: KDS 2024 current set · resistance: KDS 14 20 10:2021 + KDS 14 20 20:2022 | E7: Exact code document selected in the project
B8: Edition | C8: 2024 partial-revision framework (effective 2025-01-05) | E8: MOLIT Notice 2024-879, 2024-12-30
B9: Method ID | C9: kds-2024-current-set-global-strength-reduction | E9: Profile 1.0.0
B10: Resistance format | C10: globalResultantFactor | E10: Determines whether factors act on resultants or material strengths
B11: Profile status | C11: draft | E11: Unmodified profile snapshot
B12: Concrete model basis | C12: Code-default | E12: Resolved by the calculation profile
B13: Override reason | C13: None
B15: Resistance factors
B16: φ compression · ties/other | C16: 0.65 | D16: - | E16: Global factor on Pn, Mnx and Mny
B17: φ compression · spiral | C17: 0.7 | D17: - | E17: Used only for qualifying spiral classification
B18: φ tension-controlled | C18: 0.85 | D18: - | E18: Global factor on the complete resultant ledger
B19: Transition fixed strain limit | C19: 0.005 | D19: - | E19: Fixed through fy = 400 MPa; above: 2.5 eps_y
B20: Maximum axial ratio · ties/other | C20: 0.8 | D20: - | E20: Applied after φ
B21: Maximum axial ratio · spiral | C21: 0.85 | D21: - | E21: Applied after φ
B22: Transverse reinforcement | C22: other | E22: Project classification
B23: Axial cap | C23: Enabled | E23: Project setting
B25: Factored ULS demand versus design surface
B26: Action basis | C26: factoredULS | E26: Pipeline: factored ULS demand → 3D demand ray → design-resistance surface → UR = 1/λ.
B27: Loadcase | C27: ULS-1 workbook Newton demand (on the 15 deg surface)
B28: 3D proportional UR | C28: 1.539385 | D28: - | E28: Governing reported section utilization
B29: Fixed-P UR | C29: n/a | D29: - | E29: Secondary diagnostic at Pu
B30: Verdict | C30: INADEQUATE | E30: Fixed-grid checks use ADEQUATE / INDETERMINATE / INADEQUATE screening; indeterminate requires Adaptive sampling
B31: UR screening interval | C31: 1.5092 – 1.5708 | E31: fixed-grid-screening-margin
B32: Capacity P | C32: 16203.173 | D32: kN | E32: Demand-ray intersection
B33: Capacity Mx | C33: 2412.7596 | D33: kN·m | E33: Demand-ray intersection
B34: Capacity My | C34: 930.09918 | D34: kN·m | E34: Demand-ray intersection
B35: Controlling factor | C35: 0.65 | D35: - | E35: compression-controlled
B36: εt,control | C36: 0 | D36: - | E36: Recorded when a global factor is state-dependent

Sheet Geometry
B1: GEOMETRY ABOUT THE ANALYSIS ORIGIN
B2: Coordinates are engine constants, already translated by (xc, yc). Everything else on this sheet is a formula.
B4: Solid 1 outer
B5: No. | C5: Ring | D5: X (mm) | E5: Y (mm) | F5: D_i | G5: u = Y·cosθ + X·sinθ
B6: 1 | C6: Solid 1 outer | D6: -550 | E6: 600 | F6: =D6*E7-D7*E6 | G6: =E6*COS(RADIANS(beta))+D6*SIN(RADIANS(beta))
B7: 2 | C7: Solid 1 outer | D7: 550 | E7: 600 | F7: =D7*E8-D8*E7 | G7: =E7*COS(RADIANS(beta))+D7*SIN(RADIANS(beta))
B8: 3 | C8: Solid 1 outer | D8: 750 | E8: 400 | F8: =D8*E9-D9*E8 | G8: =E8*COS(RADIANS(beta))+D8*SIN(RADIANS(beta))
B9: 4 | C9: Solid 1 outer | D9: 750 | E9: -400 | F9: =D9*E10-D10*E9 | G9: =E9*COS(RADIANS(beta))+D9*SIN(RADIANS(beta))
B10: 5 | C10: Solid 1 outer | D10: 550 | E10: -600 | F10: =D10*E11-D11*E10 | G10: =E10*COS(RADIANS(beta))+D10*SIN(RADIANS(beta))
B11: 6 | C11: Solid 1 outer | D11: -550 | E11: -600 | F11: =D11*E12-D12*E11 | G11: =E11*COS(RADIANS(beta))+D11*SIN(RADIANS(beta))
B12: 7 | C12: Solid 1 outer | D12: -750 | E12: -400 | F12: =D12*E13-D13*E12 | G12: =E12*COS(RADIANS(beta))+D12*SIN(RADIANS(beta))
B13: 8 | C13: Solid 1 outer | D13: -750 | E13: 400 | F13: =D13*E6-D6*E13 | G13: =E13*COS(RADIANS(beta))+D13*SIN(RADIANS(beta))
C14: Area = ½·Σ D_i | F14: =SUM(F6:F13)/2
B16: Solid 1 hole 1
B17: No. | C17: Ring | D17: X (mm) | E17: Y (mm) | F17: D_i | G17: u = Y·cosθ + X·sinθ
B18: 1 | C18: Solid 1 hole 1 | D18: -450 | E18: 400 | F18: =D18*E19-D19*E18 | G18: =E18*COS(RADIANS(beta))+D18*SIN(RADIANS(beta))
B19: 2 | C19: Solid 1 hole 1 | D19: -250 | E19: 400 | F19: =D19*E20-D20*E19 | G19: =E19*COS(RADIANS(beta))+D19*SIN(RADIANS(beta))
B20: 3 | C20: Solid 1 hole 1 | D20: -150 | E20: 300 | F20: =D20*E21-D21*E20 | G20: =E20*COS(RADIANS(beta))+D20*SIN(RADIANS(beta))
B21: 4 | C21: Solid 1 hole 1 | D21: -150 | E21: -300 | F21: =D21*E22-D22*E21 | G21: =E21*COS(RADIANS(beta))+D21*SIN(RADIANS(beta))
B22: 5 | C22: Solid 1 hole 1 | D22: -250 | E22: -400 | F22: =D22*E23-D23*E22 | G22: =E22*COS(RADIANS(beta))+D22*SIN(RADIANS(beta))
B23: 6 | C23: Solid 1 hole 1 | D23: -450 | E23: -400 | F23: =D23*E24-D24*E23 | G23: =E23*COS(RADIANS(beta))+D23*SIN(RADIANS(beta))
B24: 7 | C24: Solid 1 hole 1 | D24: -550 | E24: -300 | F24: =D24*E25-D25*E24 | G24: =E24*COS(RADIANS(beta))+D24*SIN(RADIANS(beta))
B25: 8 | C25: Solid 1 hole 1 | D25: -550 | E25: 300 | F25: =D25*E18-D18*E25 | G25: =E25*COS(RADIANS(beta))+D25*SIN(RADIANS(beta))
C26: Area = ½·Σ D_i | F26: =SUM(F18:F25)/2
B28: Solid 1 hole 2
B29: No. | C29: Ring | D29: X (mm) | E29: Y (mm) | F29: D_i | G29: u = Y·cosθ + X·sinθ
B30: 1 | C30: Solid 1 hole 2 | D30: 250 | E30: 400 | F30: =D30*E31-D31*E30 | G30: =E30*COS(RADIANS(beta))+D30*SIN(RADIANS(beta))
B31: 2 | C31: Solid 1 hole 2 | D31: 450 | E31: 400 | F31: =D31*E32-D32*E31 | G31: =E31*COS(RADIANS(beta))+D31*SIN(RADIANS(beta))
B32: 3 | C32: Solid 1 hole 2 | D32: 550 | E32: 300 | F32: =D32*E33-D33*E32 | G32: =E32*COS(RADIANS(beta))+D32*SIN(RADIANS(beta))
B33: 4 | C33: Solid 1 hole 2 | D33: 550 | E33: -300 | F33: =D33*E34-D34*E33 | G33: =E33*COS(RADIANS(beta))+D33*SIN(RADIANS(beta))
B34: 5 | C34: Solid 1 hole 2 | D34: 450 | E34: -400 | F34: =D34*E35-D35*E34 | G34: =E34*COS(RADIANS(beta))+D34*SIN(RADIANS(beta))
B35: 6 | C35: Solid 1 hole 2 | D35: 250 | E35: -400 | F35: =D35*E36-D36*E35 | G35: =E35*COS(RADIANS(beta))+D35*SIN(RADIANS(beta))
B36: 7 | C36: Solid 1 hole 2 | D36: 150 | E36: -300 | F36: =D36*E37-D37*E36 | G36: =E36*COS(RADIANS(beta))+D36*SIN(RADIANS(beta))
B37: 8 | C37: Solid 1 hole 2 | D37: 150 | E37: 300 | F37: =D37*E30-D30*E37 | G37: =E37*COS(RADIANS(beta))+D37*SIN(RADIANS(beta))
C38: Area = ½·Σ D_i | F38: =SUM(F30:F37)/2
B40: Reinforcement
B41: No. | C41: Dia (mm) | D41: X (mm) | E41: Y (mm) | F41: As (mm²) | G41: u = Y·cosθ + X·sinθ
B42: 1 | C42: 32 | D42: -400 | E42: 530 | F42: =PI()*C42^2/4 | G42: =E42*COS(RADIANS(beta))+D42*SIN(RADIANS(beta))
B43: 2 | C43: 32 | D43: -200 | E43: 530 | F43: =PI()*C43^2/4 | G43: =E43*COS(RADIANS(beta))+D43*SIN(RADIANS(beta))
B44: 3 | C44: 32 | D44: 0 | E44: 530 | F44: =PI()*C44^2/4 | G44: =E44*COS(RADIANS(beta))+D44*SIN(RADIANS(beta))
...

Sheet Mesh
A1: CONCRETE INTEGRATION MESH — ENGINE CONSTANTS
A2: Quadrature points of the clipped-cell mesh (docs/02 §5). X, Y are measured from the analysis origin; A is the tributary area. These four columns are the only geometric constants the workbook needs.
A4: No. | B4: X (mm) | C4: Y (mm) | D4: A (mm²)
A5: 1 | B5: -703.90959 | C5: -435.80228 | D5: 635.07367
A6: 2 | B6: -673.0452 | C6: -466.66667 | D6: 635.07367
A7: 3 | B7: -673.0452 | C7: -435.80228 | D7: 635.07367
A8: 4 | B8: -745.74764 | C8: -363.09984 | D8: 262.49286
A9: 5 | B9: -745.74764 | C9: -393.96423 | D9: 262.49286
A10: 6 | B10: -732.99057 | C10: -406.7213 | D10: 262.49286
A11: 7 | B11: -731.20715 | C11: -367.3522 | D11: 897.56653
A12: 8 | B12: -718.45008 | C12: -410.97366 | D12: 897.56653
A13: 9 | B13: -687.58569 | C13: -410.97366 | D13: 897.56653
A14: 10 | B14: -677.29756 | C14: -396.43317 | D14: 1268.5547
A15: 11 | B15: -677.29756 | C15: -352.81171 | D15: 1268.5547
A16: 12 | B16: -720.91902 | C16: -352.81171 | D16: 1268.5547
... A1261: 1257 | B1261: 738.75316 | C1261: 404.52554 | D1261: 113.39011

Sheet PM_Angle
B1: P–M ENVELOPE AT β (STRAIN DIRECTION) — 27 STATIONS, NOMINAL
B2: Strain-plane sampling angle β = 15.00 deg. This is a resistance sampling row, not the demand-direction diagram — see PM_Theta for that. Shaded cells are the station schedule.
B4: Station definition | F4: Strain plane (formula) | M4: Concrete | P4: Steel | S4: Total (nominal) | W4: Engine check
B5: Point | C5: c/D or c/c₁ | D5: εₛ/εy or fₛ/fyd | E5: εs | F5: u_ctrl (mm) | G5: ε_ctrl | H5: c (mm) | I5: κ (1/mm) | J5: ε₀ | K5: κx (1/mm) | L5: κy (1/mm) | M5: P (kN) | N5: Mx (kN·m) | O5: My (kN·m) | P5: P (kN) | Q5: Mx (kN·m) | R5: My (kN·m) | S5: P (kN) | T5: Mx (kN·m) | U5: My (kN·m) | V5: |M| (kN·m) | W5: P engine (kN) | X5: Δ P (%)
B7: P0 | F7: — | G7: =ecu | H7: n/a | I7: 0 | J7: =ecu | K7: =I7*COS(RADIANS(beta)) | L7: =I7*SIN(RADIANS(beta)) | M7: =SUMPRODUCT(alpha*fck*(1-(1-(((PM_Angle!$J$7+PM_Angle!$K$7*Mesh_Y+PM_Angle!$L$7*Mesh_X))*((PM_Angle!$J$7+PM_Angle!$K$7*Mesh_Y+PM_Angle!$L$7*Mesh_X)>0)*((PM_Angle!$J$7+PM_Angle!$K$7*Mesh_Y+PM_Angle!$L$7*Mesh_X)<eco)+eco*((PM_Angle!$J$7+PM_Angle!$K$7*Mesh_Y+PM_Angle!$L$7*Mesh_X)>=eco))/eco)^n)*(((PM_Angle!$J$7+PM_Angle!$K$7*Mesh_Y+PM_Angle!$L$7*Mesh_X))>0),Mesh_A)/1000 | N7: =SUMPRODUCT(alpha*fck*(1-(1-(((PM_Angle!$J$7+PM_Angle!$K$7*Mesh_Y+PM_Angle!$L$7*Mesh_X))*((PM_Angle!$J$7+PM_Angle!$K$7*Mesh_Y+PM_Angle!$L$7*Mesh_X)>0)*((PM_Angle!$J$7+PM_Angle!$K$7*Mesh_Y+PM_Angle!$L$7*Mesh_X)<eco)+eco*((PM_Angle!$J$7+PM_Angle!$K$7*Mesh_Y+PM_Angle!$L$7*Mesh_X)>=eco))/eco)^n)*(((PM_Angle!$J$7+PM_Angle!$K$7*Mesh_Y+PM_Angle!$L$7*Mesh_X))>0),Mesh_A,Mesh_Y)/1000000 | O7: =SUMPRODUCT(alpha*fck*(1-(1-(((PM_Angle!$J$7+PM_Angle!$K$7*Mesh_Y+PM_Angle!$L$7*Mesh_X))*((PM_Angle!$J$7+PM_Angle!$K$7*Mesh_Y+PM_Angle!$L$7*Mesh_X)>0)*((PM_Angle!$J$7+PM_Angle!$K$7*Mesh_Y+PM_Angle!$L$7*Mesh_X)<eco)+eco*((PM_Angle!$J$7+PM_Angle!$K$7*Mesh_Y+PM_Angle!$L$7*Mesh_X)>=eco))/eco)^n)*(((PM_Angle!$J$7+PM_Angle!$K$7*Mesh_Y+PM_Angle!$L$7*Mesh_X))>0),Mesh_A,Mesh_X)/1000000 | P7: =Steel!J6/1000 | Q7: =Steel!K6/1000000 | R7: =Steel!L6/1000000 | S7: =M7+P7 | T7: =N7+Q7 | U7: =O7+R7 | V7: =SQRT(T7^2+U7^2) | W7: 33981.434 | X7: =IF(ABS(W7)<0.000000001,0,(S7-W7)/W7*100)
B8: P1 | C8: 3 | F8: =u_max-C8*(u_max-u_min) | G8: =ROUND(0,0) | H8: =ecu/I8 | I8: =(ecu-G8)/(u_max-F8) | J8: =ecu-I8*u_max | K8: =I8*COS(RADIANS(beta)) | L8: =I8*SIN(RADIANS(beta)) | M8: =SUMPRODUCT(alpha*fck*(1-(1-(((PM_Angle!$J$8+PM_Angle!$K$8*Mesh_Y+PM_Angle!$L$8*Mesh_X))*((PM_Angle!$J$8+PM_Angle!$K$8*Mesh_Y+PM_Angle!$L$8*Mesh_X)>0)*((PM_Angle!$J$8+PM_Angle!$K$8*Mesh_Y+PM_Angle!$L$8*Mesh_X)<eco)+eco*((PM_Angle!$J$8+PM_Angle!$K$8*Mesh_Y+PM_Angle!$L$8*Mesh_X)>=eco))/eco)^n)*(((PM_Angle!$J$8+PM_Angle!$K$8*Mesh_Y+PM_Angle!$L$8*Mesh_X))>0),Mesh_A)/1000 | N8: =SUMPRODUCT(alpha*fck*(1-(1-(((PM_Angle!$J$8+PM_Angle!$K$8*Mesh_Y+PM_Angle!$L$8*Mesh_X))*((PM_Angle!$J$8+PM_Angle!$K$8*Mesh_Y+PM_Angle!$L$8*Mesh_X)>0)*((PM_Angle!$J$8+PM_Angle!$K$8*Mesh_Y+PM_Angle!$L$8*Mesh_X)<eco)+eco*((PM_Angle!$J$8+PM_Angle!$K$8*Mesh_Y+PM_Angle!$L$8*Mesh_X)>=eco))/eco)^n)*(((PM_Angle!$J$8+PM_Angle!$K$8*Mesh_Y+PM_Angle!$L$8*Mesh_X))>0),Mesh_A,Mesh_Y)/1000000 | O8: =SUMPRODUCT(alpha*fck*(1-(1-(((PM_Angle!$J$8+PM_Angle!$K$8*Mesh_Y+PM_Angle!$L$8*Mesh_X))*((PM_Angle!$J$8+PM_Angle!$K$8*Mesh_Y+PM_Angle!$L$8*Mesh_X)>0)*((PM_Angle!$J$8+PM_Angle!$K$8*Mesh_Y+PM_Angle!$L$8*Mesh_X)<eco)+eco*((PM_Angle!$J$8+PM_Angle!$K$8*Mesh_Y+PM_Angle!$L$8*Mesh_X)>=eco))/eco)^n)*(((PM_Angle!$J$8+PM_Angle!$K$8*Mesh_Y+PM_Angle!$L$8*Mesh_X))>0),Mesh_A,Mesh_X)/1000000 | P8: =Steel!Q6/1000 | Q8: =Steel!R6/1000000 | R8: =Steel!S6/1000000 | S8: =M8+P8 | T8: =N8+Q8 | U8: =O8+R8 | V8: =SQRT(T8^2+U8^2) | W8: 33981.434 | X8: =IF(ABS(W8)<0.000000001,0,(S8-W8)/W8*100)
B9: P2 | C9: 2 | F9: =u_max-C9*(u_max-u_min) | G9: =ROUND(0,0) | H9: =ecu/I9 | I9: =(ecu-G9)/(u_max-F9) | J9: =ecu-I9*u_max | K9: =I9*COS(RADIANS(beta)) | L9: =I9*SIN(RADIANS(beta)) | M9: =SUMPRODUCT(alpha*fck*(1-(1-(((PM_Angle!$J$9+PM_Angle!$K$9*Mesh_Y+PM_Angle!$L$9*Mesh_X))*((PM_Angle!$J$9+PM_Angle!$K$9*Mesh_Y+PM_Angle!$L$9*Mesh_X)>0)*((PM_Angle!$J$9+PM_Angle!$K$9*Mesh_Y+PM_Angle!$L$9*Mesh_X)<eco)+eco*((PM_Angle!$J$9+PM_Angle!$K$9*Mesh_Y+PM_Angle!$L$9*Mesh_X)>=eco))/eco)^n)*(((PM_Angle!$J$9+PM_Angle!$K$9*Mesh_Y+PM_Angle!$L$9*Mesh_X))>0),Mesh_A)/1000 | N9: =SUMPRODUCT(alpha*fck*(1-(1-(((PM_Angle!$J$9+PM_Angle!$K$9*Mesh_Y+PM_Angle!$L$9*Mesh_X))*((PM_Angle!$J$9+PM_Angle!$K$9*Mesh_Y+PM_Angle!$L$9*Mesh_X)>0)*((PM_Angle!$J$9+PM_Angle!$K$9*Mesh_Y+PM_Angle!$L$9*Mesh_X)<eco)+eco*((PM_Angle!$J$9+PM_Angle!$K$9*Mesh_Y+PM_Angle!$L$9*Mesh_X)>=eco))/eco)^n)*(((PM_Angle!$J$9+PM_Angle!$K$9*Mesh_Y+PM_Angle!$L$9*Mesh_X))>0),Mesh_A,Mesh_Y)/1000000 | O9: =SUMPRODUCT(alpha*fck*(1-(1-(((PM_Angle!$J$9+PM_Angle!$K$9*Mesh_Y+PM_Angle!$L$9*Mesh_X))*((PM_Angle!$J$9+PM_Angle!$K$9*Mesh_Y+PM_Angle!$L$9*Mesh_X)>0)*((PM_Angle!$J$9+PM_Angle!$K$9*Mesh_Y+PM_Angle!$L$9*Mesh_X)<eco)+eco*((PM_Angle!$J$9+PM_Angle!$K$9*Mesh_Y+PM_Angle!$L$9*Mesh_X)>=eco))/eco)^n)*(((PM_Angle!$J$9+PM_Angle!$K$9*Mesh_Y+PM_Angle!$L$9*Mesh_X))>0),Mesh_A,Mesh_X)/1000000 | P9: =Steel!X6/1000 | Q9: =Steel!Y6/1000000 | R9: =Steel!Z6/1000000 | S9: =M9+P9 | T9: =N9+Q9 | U9: =O9+R9 | V9: =SQRT(T9^2+U9^2) | W9: 33850.502 | X9: =IF(ABS(W9)<0.000000001,0,(S9-W9)/W9*100)
B10: P3 | C10: 1.5 | F10: =u_max-C10*(u_max-u_min) | G10: =ROUND(0,0) | H10: =ecu/I10 | I10: =(ecu-G10)/(u_max-F10) | J10: =ecu-I10*u_max | K10: =I10*COS(RADIANS(beta)) | L10: =I10*SIN(RADIANS(beta)) | M10: =SUMPRODUCT(alpha*fck*(1-(1-(((PM_Angle!$J$10+PM_Angle!$K$10*Mesh_Y+PM_Angle!$L$10*Mesh_X))*((PM_Angle!$J$10+PM_Angle!$K$10*Mesh_Y+PM_Angle!$L$10*Mesh_X)>0)*((PM_Angle!$J$10+PM_Angle!$K$10*Mesh_Y+PM_Angle!$L$10*Mesh_X)<eco)+eco*((PM_Angle!$J$10+PM_Angle!$K$10*Mesh_Y+PM_Angle!$L$10*Mesh_X)>=eco))/eco)^n)*(((PM_Angle!$J$10+PM_Angle!$K$10*Mesh_Y+PM_Angle!$L$10*Mesh_X))>0),Mesh_A)/1000 | N10: =SUMPRODUCT(alpha*fck*(1-(1-(((PM_Angle!$J$10+PM_Angle!$K$10*Mesh_Y+PM_Angle!$L$10*Mesh_X))*((PM_Angle!$J$10+PM_Angle!$K$10*Mesh_Y+PM_Angle!$L$10*Mesh_X)>0)*((PM_Angle!$J$10+PM_Angle!$K$10*Mesh_Y+PM_Angle!$L$10*Mesh_X)<eco)+eco*((PM_Angle!$J$10+PM_Angle!$K$10*Mesh_Y+PM_Angle!$L$10*Mesh_X)>=eco))/eco)^n)*(((PM_Angle!$J$10+PM_Angle!$K$10*Mesh_Y+PM_Angle!$L$10*Mesh_X))>0),Mesh_A,Mesh_Y)/1000000 | O10: =SUMPRODUCT(alpha*fck*(1-(1-(((PM_Angle!$J$10+PM_Angle!$K$10*Mesh_Y+PM_Angle!$L$10*Mesh_X))*((PM_Angle!$J$10+PM_Angle!$K$10*Mesh_Y+PM_Angle!$L$10*Mesh_X)>0)*((PM_Angle!$J$10+PM_Angle!$K$10*Mesh_Y+PM_Angle!$L$10*Mesh_X)<eco)+eco*((PM_Angle!$J$10+PM_Angle!$K$10*Mesh_Y+PM_Angle!$L$10*Mesh_X)>=eco))/eco)^n)*(((PM_Angle!$J$10+PM_Angle!$K$10*Mesh_Y+PM_Angle!$L$10*Mesh_X))>0),Mesh_A,Mesh_X)/1000000 | P10: =Steel!AE6/1000 | Q10: =Steel!AF6/1000000 | R10: =Steel!AG6/1000000 | S10: =M10+P10 | T10: =N10+Q10 | U10: =O10+R10 | V10: =SQRT(T10^2+U10^2) | W10: 32774.628 | X10: =IF(ABS(W10)<0.000000001,0,(S10-W10)/W10*100)
B11: P4 | C11: 1.2 | F11: =u_max-C11*(u_max-u_min) | G11: =ROUND(0,0) | H11: =ecu/I11 | I11: =(ecu-G11)/(u_max-F11) | J11: =ecu-I11*u_max | K11: =I11*COS(RADIANS(beta)) | L11: =I11*SIN(RADIANS(beta)) | M11: =SUMPRODUCT(alpha*fck*(1-(1-(((PM_Angle!$J$11+PM_Angle!$K$11*Mesh_Y+PM_Angle!$L$11*Mesh_X))*((PM_Angle!$J$11+PM_Angle!$K$11*Mesh_Y+PM_Angle!$L$11*Mesh_X)>0)*((PM_Angle!$J$11+PM_Angle!$K$11*Mesh_Y+PM_Angle!$L$11*Mesh_X)<eco)+eco*((PM_Angle!$J$11+PM_Angle!$K$11*Mesh_Y+PM_Angle!$L$11*Mesh_X)>=eco))/eco)^n)*(((PM_Angle!$J$11+PM_Angle!$K$11*Mesh_Y+PM_Angle!$L$11*Mesh_X))>0),Mesh_A)/1000 | N11: =SUMPRODUCT(alpha*fck*(1-(1-(((PM_Angle!$J$11+PM_Angle!$K$11*Mesh_Y+PM_Angle!$L$11*Mesh_X))*((PM_Angle!$J$11+PM_Angle!$K$11*Mesh_Y+PM_Angle!$L$11*Mesh_X)>0)*((PM_Angle!$J$11+PM_Angle!$K$11*Mesh_Y+PM_Angle!$L$11*Mesh_X)<eco)+eco*((PM_Angle!$J$11+PM_Angle!$K$11*Mesh_Y+PM_Angle!$L$11*Mesh_X)>=eco))/eco)^n)*(((PM_Angle!$J$11+PM_Angle!$K$11*Mesh_Y+PM_Angle!$L$11*Mesh_X))>0),Mesh_A,Mesh_Y)/1000000 | O11: =SUMPRODUCT(alpha*fck*(1-(1-(((PM_Angle!$J$11+PM_Angle!$K$11*Mesh_Y+PM_Angle!$L$11*Mesh_X))*((PM_Angle!$J$11+PM_Angle!$K$11*Mesh_Y+PM_Angle!$L$11*Mesh_X)>0)*((PM_Angle!$J$11+PM_Angle!$K$11*Mesh_Y+PM_Angle!$L$11*Mesh_X)<eco)+eco*((PM_Angle!$J$11+PM_Angle!$K$11*Mesh_Y+PM_Angle!$L$11*Mesh_X)>=eco))/eco)^n)*(((PM_Angle!$J$11+PM_Angle!$K$11*Mesh_Y+PM_Angle!$L$11*Mesh_X))>0),Mesh_A,Mesh_X)/1000000 | P11: =Steel!AL6/1000 | Q11: =Steel!AM6/1000000 | R11: =Steel!AN6/1000000 | S11: =M11+P11 | T11: =N11+Q11 | U11: =O11+R11 | V11: =SQRT(T11^2+U11^2) | W11: 30527.488 | X11: =IF(ABS(W11)<0.000000001,0,(S11-W11)/W11*100)
B12: P5 | C12: 1.1 | F12: =u_max-C12*(u_max-u_min) | G12: =ROUND(0,0) | H12: =ecu/I12 | I12: =(ecu-G12)/(u_max-F12) | J12: =ecu-I12*u_max | K12: =I12*COS(RADIANS(beta)) | L12: =I12*SIN(RADIANS(beta)) | M12: =SUMPRODUCT(alpha*fck*(1-(1-(((PM_Angle!$J$12+PM_Angle!$K$12*Mesh_Y+PM_Angle!$L$12*Mesh_X))*((PM_Angle!$J$12+PM_Angle!$K$12*Mesh_Y+PM_Angle!$L$12*Mesh_X)>0)*((PM_Angle!$J$12+PM_Angle!$K$12*Mesh_Y+PM_Angle!$L$12*Mesh_X)<eco)+eco*((PM_Angle!$J$12+PM_Angle!$K$12*Mesh_Y+PM_Angle!$L$12*Mesh_X)>=eco))/eco)^n)*(((PM_Angle!$J$12+PM_Angle!$K$12*Mesh_Y+PM_Angle!$L$12*Mesh_X))>0),Mesh_A)/1000 | N12: =SUMPRODUCT(alpha*fck*(1-(1-(((PM_Angle!$J$12+PM_Angle!$K$12*Mesh_Y+PM_Angle!$L$12*Mesh_X))*((PM_Angle!$J$12+PM_Angle!$K$12*Mesh_Y+PM_Angle!$L$12*Mesh_X)>0)*((PM_Angle!$J$12+PM_Angle!$K$12*Mesh_Y+PM_Angle!$L$12*Mesh_X)<eco)+eco*((PM_Angle!$J$12+PM_Angle!$K$12*Mesh_Y+PM_Angle!$L$12*Mesh_X)>=eco))/eco)^n)*(((PM_Angle!$J$12+PM_Angle!$K$12*Mesh_Y+PM_Angle!$L$12*Mesh_X))>0),Mesh_A,Mesh_Y)/1000000 | O12: =SUMPRODUCT(alpha*fck*(1-(1-(((PM_Angle!$J$12+PM_Angle!$K$12*Mesh_Y+PM_Angle!$L$12*Mesh_X))*((PM_Angle!$J$12+PM_Angle!$K$12*Mesh_Y+PM_Angle!$L$12*Mesh_X)>0)*((PM_Angle!$J$12+PM_Angle!$K$12*Mesh_Y+PM_Angle!$L$12*Mesh_X)<eco)+eco*((PM_Angle!$J$12+PM_Angle!$K$12*Mesh_Y+PM_Angle!$L$12*Mesh_X)>=eco))/eco)^n)*(((PM_Angle!$J$12+PM_Angle!$K$12*Mesh_Y+PM_Angle!$L$12*Mesh_X))>0),Mesh_A,Mesh_X)/1000000 | P12: =Steel!AS6/1000 | Q12: =Steel!AT6/1000000 | R12: =Steel!AU6/1000000 | S12: =M12+P12 | T12: =N12+Q12 | U12: =O12+R12 | V12: =SQRT(T12^2+U12^2) | W12: 29097.594 | X12: =IF(ABS(W12)<0.000000001,0,(S12-W12)/W12*100)
B13: P6 | C13: 1 | F13: =u_max-C13*(u_max-u_min) | G13: =ROUND(0,0) | H13: =ecu/I13 | I13: =(ecu-G13)/(u_max-F13) | J13: =ecu-I13*u_max | K13: =I13*COS(RADIANS(beta)) | L13: =I13*SIN(RADIANS(beta)) | M13: =SUMPRODUCT(alpha*fck*(1-(1-(((PM_Angle!$J$13+PM_Angle!$K$13*Mesh_Y+PM_Angle!$L$13*Mesh_X))*((PM_Angle!$J$13+PM_Angle!$K$13*Mesh_Y+PM_Angle!$L$13*Mesh_X)>0)*((PM_Angle!$J$13+PM_Angle!$K$13*Mesh_Y+PM_Angle!$L$13*Mesh_X)<eco)+eco*((PM_Angle!$J$13+PM_Angle!$K$13*Mesh_Y+PM_Angle!$L$13*Mesh_X)>=eco))/eco)^n)*(((PM_Angle!$J$13+PM_Angle!$K$13*Mesh_Y+PM_Angle!$L$13*Mesh_X))>0),Mesh_A)/1000 | N13: =SUMPRODUCT(alpha*fck*(1-(1-(((PM_Angle!$J$13+PM_Angle!$K$13*Mesh_Y+PM_Angle!$L$13*Mesh_X))*((PM_Angle!$J$13+PM_Angle!$K$13*Mesh_Y+PM_Angle!$L$13*Mesh_X)>0)*((PM_Angle!$J$13+PM_Angle!$K$13*Mesh_Y+PM_Angle!$L$13*Mesh_X)<eco)+eco*((PM_Angle!$J$13+PM_Angle!$K$13*Mesh_Y+PM_Angle!$L$13*Mesh_X)>=eco))/eco)^n)*(((PM_Angle!$J$13+PM_Angle!$K$13*Mesh_Y+PM_Angle!$L$13*Mesh_X))>0),Mesh_A,Mesh_Y)/1000000 | O13: =SUMPRODUCT(alpha*fck*(1-(1-(((PM_Angle!$J$13+PM_Angle!$K$13*Mesh_Y+PM_Angle!$L$13*Mesh_X))*((PM_Angle!$J$13+PM_Angle!$K$13*Mesh_Y+PM_Angle!$L$13*Mesh_X)>0)*((PM_Angle!$J$13+PM_Angle!$K$13*Mesh_Y+PM_Angle!$L$13*Mesh_X)<eco)+eco*((PM_Angle!$J$13+PM_Angle!$K$13*Mesh_Y+PM_Angle!$L$13*Mesh_X)>=eco))/eco)^n)*(((PM_Angle!$J$13+PM_Angle!$K$13*Mesh_Y+PM_Angle!$L$13*Mesh_X))>0),Mesh_A,Mesh_X)/1000000 | P13: =Steel!AZ6/1000 | Q13: =Steel!BA6/1000000 | R13: =Steel!BB6/1000000 | S13: =M13+P13 | T13: =N13+Q13 | U13: =O13+R13 | V13: =SQRT(T13^2+U13^2) | W13: 27011.957 | X13: =IF(ABS(W13)<0.000000001,0,(S13-W13)/W13*100)
B14: P7 | D14: 0 | F14: =u_bar | G14: 2.1684043e-19 | H14: =ecu/I14 | I14: =(ecu-G14)/(u_max-F14) | J14: =ecu-I14*u_max | K14: =I14*COS(RADIANS(beta)) | L14: =I14*SIN(RADIANS(beta)) | M14: =SUMPRODUCT(alpha*fck*(1-(1-(((PM_Angle!$J$14+PM_Angle!$K$14*Mesh_Y+PM_Angle!$L$14*Mesh_X))*((PM_Angle!$J$14+PM_Angle!$K$14*Mesh_Y+PM_Angle!$L$14*Mesh_X)>0)*((PM_Angle!$J$14+PM_Angle!$K$14*Mesh_Y+PM_Angle!$L$14*Mesh_X)<eco)+eco*((PM_Angle!$J$14+PM_Angle!$K$14*Mesh_Y+PM_Angle!$L$14*Mesh_X)>=eco))/eco)^n)*(((PM_Angle!$J$14+PM_Angle!$K$14*Mesh_Y+PM_Angle!$L$14*Mesh_X))>0),Mesh_A)/1000 | N14: =SUMPRODUCT(alpha*fck*(1-(1-(((PM_Angle!$J$14+PM_Angle!$K$14*Mesh_Y+PM_Angle!$L$14*Mesh_X))*((PM_Angle!$J$14+PM_Angle!$K$14*Mesh_Y+PM_Angle!$L$14*Mesh_X)>0)*((PM_Angle!$J$14+PM_Angle!$K$14*Mesh_Y+PM_Angle!$L$14*Mesh_X)<eco)+eco*((PM_Angle!$J$14+PM_Angle!$K$14*Mesh_Y+PM_Angle!$L$14*Mesh_X)>=eco))/eco)^n)*(((PM_Angle!$J$14+PM_Angle!$K$14*Mesh_Y+PM_Angle!$L$14*Mesh_X))>0),Mesh_A,Mesh_Y)/1000000 | O14: =SUMPRODUCT(alpha*fck*(1-(1-(((PM_Angle!$J$14+PM_Angle!$K$14*Mesh_Y+PM_Angle!$L$14*Mesh_X))*((PM_Angle!$J$14+PM_Angle!$K$14*Mesh_Y+PM_Angle!$L$14*Mesh_X)>0)*((PM_Angle!$J$14+PM_Angle!$K$14*Mesh_Y+PM_Angle!$L$14*Mesh_X)<eco)+eco*((PM_Angle!$J$14+PM_Angle!$K$14*Mesh_Y+PM_Angle!$L$14*Mesh_X)>=eco))/eco)^n)*(((PM_Angle!$J$14+PM_Angle!$K$14*Mesh_Y+PM_Angle!$L$14*Mesh_X))>0),Mesh_A,Mesh_X)/1000000 | P14: =Steel!BG6/1000 | Q14: =Steel!BH6/1000000 | R14: =Steel!BI6/1000000 | S14: =M14+P14 | T14: =N14+Q14 | U14: =O14+R14 | V14: =SQRT(T14^2+U14^2) | W14: 24941.454 | X14: =IF(ABS(W14)<0.000000001,0,(S14-W14)/W14*100)
B15: P8 | D15: 0.25 | F15: =u_bar | G15: -0.0005 | H15: =ecu/I15 | I15: =(ecu-G15)/(u_max-F15) | J15: =ecu-I15*u_max | K15: =I15*COS(RADIANS(beta)) | L15: =I15*SIN(RADIANS(beta)) | M15: =SUMPRODUCT(alpha*fck*(1-(1-(((PM_Angle!$J$15+PM_Angle!$K$15*Mesh_Y+PM_Angle!$L$15*Mesh_X))*((PM_Angle!$J$15+PM_Angle!$K$15*Mesh_Y+PM_Angle!$L$15*Mesh_X)>0)*((PM_Angle!$J$15+PM_Angle!$K$15*Mesh_Y+PM_Angle!$L$15*Mesh_X)<eco)+eco*((PM_Angle!$J$15+PM_Angle!$K$15*Mesh_Y+PM_Angle!$L$15*Mesh_X)>=eco))/eco)^n)*(((PM_Angle!$J$15+PM_Angle!$K$15*Mesh_Y+PM_Angle!$L$15*Mesh_X))>0),Mesh_A)/1000 | N15: =SUMPRODUCT(alpha*fck*(1-(1-(((PM_Angle!$J$15+PM_Angle!$K$15*Mesh_Y+PM_Angle!$L$15*Mesh_X))*((PM_Angle!$J$15+PM_Angle!$K$15*Mesh_Y+PM_Angle!$L$15*Mesh_X)>0)*((PM_Angle!$J$15+PM_Angle!$K$15*Mesh_Y+PM_Angle!$L$15*Mesh_X)<eco)+eco*((PM_Angle!$J$15+PM_Angle!$K$15*Mesh_Y+PM_Angle!$L$15*Mesh_X)>=eco))/eco)^n)*(((PM_Angle!$J$15+PM_Angle!$K$15*Mesh_Y+PM_Angle!$L$15*Mesh_X))>0),Mesh_A,Mesh_Y)/1000000 | O15: =SUMPRODUCT(alpha*fck*(1-(1-(((PM_Angle!$J$15+PM_Angle!$K$15*Mesh_Y+PM_Angle!$L$15*Mesh_X))*((PM_Angle!$J$15+PM_Angle!$K$15*Mesh_Y+PM_Angle!$L$15*Mesh_X)>0)*((PM_Angle!$J$15+PM_Angle!$K$15*Mesh_Y+PM_Angle!$L$15*Mesh_X)<eco)+eco*((PM_Angle!$J$15+PM_Angle!$K$15*Mesh_Y+PM_Angle!$L$15*Mesh_X)>=eco))/eco)^n)*(((PM_Angle!$J$15+PM_Angle!$K$15*Mesh_Y+PM_Angle!$L$15*Mesh_X))>0),Mesh_A,Mesh_X)/1000000 | P15: =Steel!BN6/1000 | Q15: =Steel!BO6/1000000 | R15: =Steel!BP6/1000000 | S15: =M15+P15 | T15: =N15+Q15 | U15: =O15+R15 | V15: =SQRT(T15^2+U15^2) | W15: 21079.019 | X15: =IF(ABS(W15)<0.000000001,0,(S15-W15)/W15*100)
B16: P9 | D16: 0.375 | F16: =u_bar | G16: -0.00075 | H16: =ecu/I16 | I16: =(ecu-G16)/(u_max-F16) | J16: =ecu-I16*u_max | K16: =I16*COS(RADIANS(beta)) | L16: =I16*SIN(RADIANS(beta)) | M16: =SUMPRODUCT(alpha*fck*(1-(1-(((PM_Angle!$J$16+PM_Angle!$K$16*Mesh_Y+PM_Angle!$L$16*Mesh_X))*((PM_Angle!$J$16+PM_Angle!$K$16*Mesh_Y+PM_Angle!$L$16*Mesh_X)>0)*((PM_Angle!$J$16+PM_Angle!$K$16*Mesh_Y+PM_Angle!$L$16*Mesh_X)<eco)+eco*((PM_Angle!$J$16+PM_Angle!$K$16*Mesh_Y+PM_Angle!$L$16*Mesh_X)>=eco))/eco)^n)*(((PM_Angle!$J$16+PM_Angle!$K$16*Mesh_Y+PM_Angle!$L$16*Mesh_X))>0),Mesh_A)/1000 | N16: =SUMPRODUCT(alpha*fck*(1-(1-(((PM_Angle!$J$16+PM_Angle!$K$16*Mesh_Y+PM_Angle!$L$16*Mesh_X))*((PM_Angle!$J$16+PM_Angle!$K$16*Mesh_Y+PM_Angle!$L$16*Mesh_X)>0)*((PM_Angle!$J$16+PM_Angle!$K$16*Mesh_Y+PM_Angle!$L$16*Mesh_X)<eco)+eco*((PM_Angle!$J$16+PM_Angle!$K$16*Mesh_Y+PM_Angle!$L$16*Mesh_X)>=eco))/eco)^n)*(((PM_Angle!$J$16+PM_Angle!$K$16*Mesh_Y+PM_Angle!$L$16*Mesh_X))>0),Mesh_A,Mesh_Y)/1000000 | O16: =SUMPRODUCT(alpha*fck*(1-(1-(((PM_Angle!$J$16+PM_Angle!$K$16*Mesh_Y+PM_Angle!$L$16*Mesh_X))*((PM_Angle!$J$16+PM_Angle!$K$16*Mesh_Y+PM_Angle!$L$16*Mesh_X)>0)*((PM_Angle!$J$16+PM_Angle!$K$16*Mesh_Y+PM_Angle!$L$16*Mesh_X)<eco)+eco*((PM_Angle!$J$16+PM_Angle!$K$16*Mesh_Y+PM_Angle!$L$16*Mesh_X)>=eco))/eco)^n)*(((PM_Angle!$J$16+PM_Angle!$K$16*Mesh_Y+PM_Angle!$L$16*Mesh_X))>0),Mesh_A,Mesh_X)/1000000 | P16: =Steel!BU6/1000 | Q16: =Steel!BV6/1000000 | R16: =Steel!BW6/1000000 | S16: =M16+P16 | T16: =N16+Q16 | U16: =O16+R16 | V16: =SQRT(T16^2+U16^2) | W16: 19511.951 | X16: =IF(ABS(W16)<0.000000001,0,(S16-W16)/W16*100)
B17: P10 | D17: 0.5 | F17: =u_bar | G17: -0.001 | H17: =ecu/I17 | I17: =(ecu-G17)/(u_max-F17) | J17: =ecu-I17*u_max | K17: =I17*COS(RADIANS(beta)) | L17: =I17*SIN(RADIANS(beta)) | M17: =SUMPRODUCT(alpha*fck*(1-(1-(((PM_Angle!$J$17+PM_Angle!$K$17*Mesh_Y+PM_Angle!$L$17*Mesh_X))*((PM_Angle!$J$17+PM_Angle!$K$17*Mesh_Y+PM_Angle!$L$17*Mesh_X)>0)*((PM_Angle!$J$17+PM_Angle!$K$17*Mesh_Y+PM_Angle!$L$17*Mesh_X)<eco)+eco*((PM_Angle!$J$17+PM_Angle!$K$17*Mesh_Y+PM_Angle!$L$17*Mesh_X)>=eco))/eco)^n)*(((PM_Angle!$J$17+PM_Angle!$K$17*Mesh_Y+PM_Angle!$L$17*Mesh_X))>0),Mesh_A)/1000 | N17: =SUMPRODUCT(alpha*fck*(1-(1-(((PM_Angle!$J$17+PM_Angle!$K$17*Mesh_Y+PM_Angle!$L$17*Mesh_X))*((PM_Angle!$J$17+PM_Angle!$K$17*Mesh_Y+PM_Angle!$L$17*Mesh_X)>0)*((PM_Angle!$J$17+PM_Angle!$K$17*Mesh_Y+PM_Angle!$L$17*Mesh_X)<eco)+eco*((PM_Angle!$J$17+PM_Angle!$K$17*Mesh_Y+PM_Angle!$L$17*Mesh_X)>=eco))/eco)^n)*(((PM_Angle!$J$17+PM_Angle!$K$17*Mesh_Y+PM_Angle!$L$17*Mesh_X))>0),Mesh_A,Mesh_Y)/1000000 | O17: =SUMPRODUCT(alpha*fck*(1-(1-(((PM_Angle!$J$17+PM_Angle!$K$17*Mesh_Y+PM_Angle!$L$17*Mesh_X))*((PM_Angle!$J$17+PM_Angle!$K$17*Mesh_Y+PM_Angle!$L$17*Mesh_X)>0)*((PM_Angle!$J$17+PM_Angle!$K$17*Mesh_Y+PM_Angle!$L$17*Mesh_X)<eco)+eco*((PM_Angle!$J$17+PM_Angle!$K$17*Mesh_Y+PM_Angle!$L$17*Mesh_X)>=eco))/eco)^n)*(((PM_Angle!$J$17+PM_Angle!$K$17*Mesh_Y+PM_Angle!$L$17*Mesh_X))>0),Mesh_A,Mesh_X)/1000000 | P17: =Steel!CB6/1000 | Q17: =Steel!CC6/1000000 | R17: =Steel!CD6/1000000 | S17: =M17+P17 | T17: =N17+Q17 | U17: =O17+R17 | V17: =SQRT(T17^2+U17^2) | W17: 18153.31 | X17: =IF(ABS(W17)<0.000000001,0,(S17-W17)/W17*100)
B18: P11 | D18: 0.625 | F18: =u_bar | G18: -0.00125 | H18: =ecu/I18 | I18: =(ecu-G18)/(u_max-F18) | J18: =ecu-I18*u_max | K18: =I18*COS(RADIANS(beta)) | L18: =I18*SIN(RADIANS(beta)) | M18: =SUMPRODUCT(alpha*fck*(1-(1-(((PM_Angle!$J$18+PM_Angle!$K$18*Mesh_Y+PM_Angle!$L$18*Mesh_X))*((PM_Angle!$J$18+PM_Angle!$K$18*Mesh_Y+PM_Angle!$L$18*Mesh_X)>0)*((PM_Angle!$J$18+PM_Angle!$K$18*Mesh_Y+PM_Angle!$L$18*Mesh_X)<eco)+eco*((PM_Angle!$J$18+PM_Angle!$K$18*Mesh_Y+PM_Angle!$L$18*Mesh_X)>=eco))/eco)^n)*(((PM_Angle!$J$18+PM_Angle!$K$18*Mesh_Y+PM_Angle!$L$18*Mesh_X))>0),Mesh_A)/1000 | N18: =SUMPRODUCT(alpha*fck*(1-(1-(((PM_Angle!$J$18+PM_Angle!$K$18*Mesh_Y+PM_Angle!$L$18*Mesh_X))*((PM_Angle!$J$18+PM_Angle!$K$18*Mesh_Y+PM_Angle!$L$18*Mesh_X)>0)*((PM_Angle!$J$18+PM_Angle!$K$18*Mesh_Y+PM_Angle!$L$18*Mesh_X)<eco)+eco*((PM_Angle!$J$18+PM_Angle!$K$18*Mesh_Y+PM_Angle!$L$18*Mesh_X)>=eco))/eco)^n)*(((PM_Angle!$J$18+PM_Angle!$K$18*Mesh_Y+PM_Angle!$L$18*Mesh_X))>0),Mesh_A,Mesh_Y)/1000000 | O18: =SUMPRODUCT(alpha*fck*(1-(1-(((PM_Angle!$J$18+PM_Angle!$K$18*Mesh_Y+PM_Angle!$L$18*Mesh_X))*((PM_Angle!$J$18+PM_Angle!$K$18*Mesh_Y+PM_Angle!$L$18*Mesh_X)>0)*((PM_Angle!$J$18+PM_Angle!$K$18*Mesh_Y+PM_Angle!$L$18*Mesh_X)<eco)+eco*((PM_Angle!$J$18+PM_Angle!$K$18*Mesh_Y+PM_Angle!$L$18*Mesh_X)>=eco))/eco)^n)*(((PM_Angle!$J$18+PM_Angle!$K$18*Mesh_Y+PM_Angle!$L$18*Mesh_X))>0),Mesh_A,Mesh_X)/1000000 | P18: =Steel!CI6/1000 | Q18: =Steel!CJ6/1000000 | R18: =Steel!CK6/1000000 | S18: =M18+P18 | T18: =N18+Q18 | U18: =O18+R18 | V18: =SQRT(T18^2+U18^2) | W18: 16953.847 | X18: =IF(ABS(W18)<0.000000001,0,(S18-W18)/W18*100)
B19: P12 | D19: 0.75 | F19: =u_bar | G19: -0.0015 | H19: =ecu/I19 | I19: =(ecu-G19)/(u_max-F19) | J19: =ecu-I19*u_max | K19: =I19*COS(RADIANS(beta)) | L19: =I19*SIN(RADIANS(beta)) | M19: =SUMPRODUCT(alpha*fck*(1-(1-(((PM_Angle!$J$19+PM_Angle!$K$19*Mesh_Y+PM_Angle!$L$19*Mesh_X))*((PM_Angle!$J$19+PM_Angle!$K$19*Mesh_Y+PM_Angle!$L$19*Mesh_X)>0)*((PM_Angle!$J$19+PM_Angle!$K$19*Mesh_Y+PM_Angle!$L$19*Mesh_X)<eco)+eco*((PM_Angle!$J$19+PM_Angle!$K$19*Mesh_Y+PM_Angle!$L$19*Mesh_X)>=eco))/eco)^n)*(((PM_Angle!$J$19+PM_Angle!$K$19*Mesh_Y+PM_Angle!$L$19*Mesh_X))>0),Mesh_A)/1000 | N19: =SUMPRODUCT(alpha*fck*(1-(1-(((PM_Angle!$J$19+PM_Angle!$K$19*Mesh_Y+PM_Angle!$L$19*Mesh_X))*((PM_Angle!$J$19+PM_Angle!$K$19*Mesh_Y+PM_Angle!$L$19*Mesh_X)>0)*((PM_Angle!$J$19+PM_Angle!$K$19*Mesh_Y+PM_Angle!$L$19*Mesh_X)<eco)+eco*((PM_Angle!$J$19+PM_Angle!$K$19*Mesh_Y+PM_Angle!$L$19*Mesh_X)>=eco))/eco)^n)*(((PM_Angle!$J$19+PM_Angle!$K$19*Mesh_Y+PM_Angle!$L$19*Mesh_X))>0),Mesh_A,Mesh_Y)/1000000 | O19: =SUMPRODUCT(alpha*fck*(1-(1-(((PM_Angle!$J$19+PM_Angle!$K$19*Mesh_Y+PM_Angle!$L$19*Mesh_X))*((PM_Angle!$J$19+PM_Angle!$K$19*Mesh_Y+PM_Angle!$L$19*Mesh_X)>0)*((PM_Angle!$J$19+PM_Angle!$K$19*Mesh_Y+PM_Angle!$L$19*Mesh_X)<eco)+eco*((PM_Angle!$J$19+PM_Angle!$K$19*Mesh_Y+PM_Angle!$L$19*Mesh_X)>=eco))/eco)^n)*(((PM_Angle!$J$19+PM_Angle!$K$19*Mesh_Y+PM_Angle!$L$19*Mesh_X))>0),Mesh_A,Mesh_X)/1000000 | P19: =Steel!CP6/1000 | Q19: =Steel!CQ6/1000000 | R19: =Steel!CR6/1000000 | S19: =M19+P19 | T19: =N19+Q19 | U19: =O19+R19 | V19: =SQRT(T19^2+U19^2) | W19: 15853.978 | X19: =IF(ABS(W19)<0.000000001,0,(S19-W19)/W19*100)
B20: P13 | D20: 0.875 | F20: =u_bar | G20: -0.00175 | H20: =ecu/I20 | I20: =(ecu-G20)/(u_max-F20) | J20: =ecu-I20*u_max | K20: =I20*COS(RADIANS(beta)) | L20: =I20*SIN(RADIANS(beta)) | M20: =SUMPRODUCT(alpha*fck*(1-(1-(((PM_Angle!$J$20+PM_Angle!$K$20*Mesh_Y+PM_Angle!$L$20*Mesh_X))*((PM_Angle!$J$20+PM_Angle!$K$20*Mesh_Y+PM_Angle!$L$20*Mesh_X)>0)*((PM_Angle!$J$20+PM_Angle!$K$20*Mesh_Y+PM_Angle!$L$20*Mesh_X)<eco)+eco*((PM_Angle!$J$20+PM_Angle!$K$20*Mesh_Y+PM_Angle!$L$20*Mesh_X)>=eco))/eco)^n)*(((PM_Angle!$J$20+PM_Angle!$K$20*Mesh_Y+PM_Angle!$L$20*Mesh_X))>0),Mesh_A)/1000 | N20: =SUMPRODUCT(alpha*fck*(1-(1-(((PM_Angle!$J$20+PM_Angle!$K$20*Mesh_Y+PM_Angle!$L$20*Mesh_X))*((PM_Angle!$J$20+PM_Angle!$K$20*Mesh_Y+PM_Angle!$L$20*Mesh_X)>0)*((PM_Angle!$J$20+PM_Angle!$K$20*Mesh_Y+PM_Angle!$L$20*Mesh_X)<eco)+eco*((PM_Angle!$J$20+PM_Angle!$K$20*Mesh_Y+PM_Angle!$L$20*Mesh_X)>=eco))/eco)^n)*(((PM_Angle!$J$20+PM_Angle!$K$20*Mesh_Y+PM_Angle!$L$20*Mesh_X))>0),Mesh_A,Mesh_Y)/1000000 | O20: =SUMPRODUCT(alpha*fck*(1-(1-(((PM_Angle!$J$20+PM_Angle!$K$20*Mesh_Y+PM_Angle!$L$20*Mesh_X))*((PM_Angle!$J$20+PM_Angle!$K$20*Mesh_Y+PM_Angle!$L$20*Mesh_X)>0)*((PM_Angle!$J$20+PM_Angle!$K$20*Mesh_Y+PM_Angle!$L$20*Mesh_X)<eco)+eco*((PM_Angle!$J$20+PM_Angle!$K$20*Mesh_Y+PM_Angle!$L$20*Mesh_X)>=eco))/eco)^n)*(((PM_Angle!$J$20+PM_Angle!$K$20*Mesh_Y+PM_Angle!$L$20*Mesh_X))>0),Mesh_A,Mesh_X)/1000000 | P20: =Steel!CW6/1000 | Q20: =Steel!CX6/1000000 | R20: =Steel!CY6/1000000 | S20: =M20+P20 | T20: =N20+Q20 | U20: =O20+R20 | V20: =SQRT(T20^2+U20^2) | W20: 14830.262 | X20: =IF(ABS(W20)<0.000000001,0,(S20-W20)/W20*100)
B21: P14 | D21: 1 | F21: =u_bar | G21: -0.002 | H21: =ecu/I21 | I21: =(ecu-G21)/(u_max-F21) | J21: =ecu-I21*u_max | K21: =I21*COS(RADIANS(beta)) | L21: =I21*SIN(RADIANS(beta)) | M21: =SUMPRODUCT(alpha*fck*(1-(1-(((PM_Angle!$J$21+PM_Angle!$K$21*Mesh_Y+PM_Angle!$L$21*Mesh_X))*((PM_Angle!$J$21+PM_Angle!$K$21*Mesh_Y+PM_Angle!$L$21*Mesh_X)>0)*((PM_Angle!$J$21+PM_Angle!$K$21*Mesh_Y+PM_Angle!$L$21*Mesh_X)<eco)+eco*((PM_Angle!$J$21+PM_Angle!$K$21*Mesh_Y+PM_Angle!$L$21*Mesh_X)>=eco))/eco)^n)*(((PM_Angle!$J$21+PM_Angle!$K$21*Mesh_Y+PM_Angle!$L$21*Mesh_X))>0),Mesh_A)/1000 | N21: =SUMPRODUCT(alpha*fck*(1-(1-(((PM_Angle!$J$21+PM_Angle!$K$21*Mesh_Y+PM_Angle!$L$21*Mesh_X))*((PM_Angle!$J$21+PM_Angle!$K$21*Mesh_Y+PM_Angle!$L$21*Mesh_X)>0)*((PM_Angle!$J$21+PM_Angle!$K$21*Mesh_Y+PM_Angle!$L$21*Mesh_X)<eco)+eco*((PM_Angle!$J$21+PM_Angle!$K$21*Mesh_Y+PM_Angle!$L$21*Mesh_X)>=eco))/eco)^n)*(((PM_Angle!$J$21+PM_Angle!$K$21*Mesh_Y+PM_Angle!$L$21*Mesh_X))>0),Mesh_A,Mesh_Y)/1000000 | O21: =SUMPRODUCT(alpha*fck*(1-(1-(((PM_Angle!$J$21+PM_Angle!$K$21*Mesh_Y+PM_Angle!$L$21*Mesh_X))*((PM_Angle!$J$21+PM_Angle!$K$21*Mesh_Y+PM_Angle!$L$21*Mesh_X)>0)*((PM_Angle!$J$21+PM_Angle!$K$21*Mesh_Y+PM_Angle!$L$21*Mesh_X)<eco)+eco*((PM_Angle!$J$21+PM_Angle!$K$21*Mesh_Y+PM_Angle!$L$21*Mesh_X)>=eco))/eco)^n)*(((PM_Angle!$J$21+PM_Angle!$K$21*Mesh_Y+PM_Angle!$L$21*Mesh_X))>0),Mesh_A,Mesh_X)/1000000 | P21: =Steel!DD6/1000 | Q21: =Steel!DE6/1000000 | R21: =Steel!DF6/1000000 | S21: =M21+P21 | T21: =N21+Q21 | U21: =O21+R21 | V21: =SQRT(T21^2+U21^2) | W21: 13872.543 | X21: =IF(ABS(W21)<0.000000001,0,(S21-W21)/W21*100)
B22: P15 | D22: 1.25 | F22: =u_bar | G22: -0.0025 | H22: =ecu/I22 | I22: =(ecu-G22)/(u_max-F22) | J22: =ecu-I22*u_max | K22: =I22*COS(RADIANS(beta)) | L22: =I22*SIN(RADIANS(beta)) | M22: =SUMPRODUCT(alpha*fck*(1-(1-(((PM_Angle!$J$22+PM_Angle!$K$22*Mesh_Y+PM_Angle!$L$22*Mesh_X))*((PM_Angle!$J$22+PM_Angle!$K$22*Mesh_Y+PM_Angle!$L$22*Mesh_X)>0)*((PM_Angle!$J$22+PM_Angle!$K$22*Mesh_Y+PM_Angle!$L$22*Mesh_X)<eco)+eco*((PM_Angle!$J$22+PM_Angle!$K$22*Mesh_Y+PM_Angle!$L$22*Mesh_X)>=eco))/eco)^n)*(((PM_Angle!$J$22+PM_Angle!$K$22*Mesh_Y+PM_Angle!$L$22*Mesh_X))>0),Mesh_A)/1000 | N22: =SUMPRODUCT(alpha*fck*(1-(1-(((PM_Angle!$J$22+PM_Angle!$K$22*Mesh_Y+PM_Angle!$L$22*Mesh_X))*((PM_Angle!$J$22+PM_Angle!$K$22*Mesh_Y+PM_Angle!$L$22*Mesh_X)>0)*((PM_Angle!$J$22+PM_Angle!$K$22*Mesh_Y+PM_Angle!$L$22*Mesh_X)<eco)+eco*((PM_Angle!$J$22+PM_Angle!$K$22*Mesh_Y+PM_Angle!$L$22*Mesh_X)>=eco))/eco)^n)*(((PM_Angle!$J$22+PM_Angle!$K$22*Mesh_Y+PM_Angle!$L$22*Mesh_X))>0),Mesh_A,Mesh_Y)/1000000 | O22: =SUMPRODUCT(alpha*fck*(1-(1-(((PM_Angle!$J$22+PM_Angle!$K$22*Mesh_Y+PM_Angle!$L$22*Mesh_X))*((PM_Angle!$J$22+PM_Angle!$K$22*Mesh_Y+PM_Angle!$L$22*Mesh_X)>0)*((PM_Angle!$J$22+PM_Angle!$K$22*Mesh_Y+PM_Angle!$L$22*Mesh_X)<eco)+eco*((PM_Angle!$J$22+PM_Angle!$K$22*Mesh_Y+PM_Angle!$L$22*Mesh_X)>=eco))/eco)^n)*(((PM_Angle!$J$22+PM_Angle!$K$22*Mesh_Y+PM_Angle!$L$22*Mesh_X))>0),Mesh_A,Mesh_X)/1000000 | P22: =Steel!DK6/1000 | Q22: =Steel!DL6/1000000 | R22: =Steel!DM6/1000000 | S22: =M22+P22 | T22: =N22+Q22 | U22: =O22+R22 | V22: =SQRT(T22^2+U22^2) | W22: 12219.383 | X22: =IF(ABS(W22)<0.000000001,0,(S22-W22)/W22*100)
B23: P16 | D23: 1.5 | F23: =u_bar | G23: -0.003 | H23: =ecu/I23 | I23: =(ecu-G23)/(u_max-F23) | J23: =ecu-I23*u_max | K23: =I23*COS(RADIANS(beta)) | L23: =I23*SIN(RADIANS(beta)) | M23: =SUMPRODUCT(alpha*fck*(1-(1-(((PM_Angle!$J$23+PM_Angle!$K$23*Mesh_Y+PM_Angle!$L$23*Mesh_X))*((PM_Angle!$J$23+PM_Angle!$K$23*Mesh_Y+PM_Angle!$L$23*Mesh_X)>0)*((PM_Angle!$J$23+PM_Angle!$K$23*Mesh_Y+PM_Angle!$L$23*Mesh_X)<eco)+eco*((PM_Angle!$J$23+PM_Angle!$K$23*Mesh_Y+PM_Angle!$L$23*Mesh_X)>=eco))/eco)^n)*(((PM_Angle!$J$23+PM_Angle!$K$23*Mesh_Y+PM_Angle!$L$23*Mesh_X))>0),Mesh_A)/1000 | N23: =SUMPRODUCT(alpha*fck*(1-(1-(((PM_Angle!$J$23+PM_Angle!$K$23*Mesh_Y+PM_Angle!$L$23*Mesh_X))*((PM_Angle!$J$23+PM_Angle!$K$23*Mesh_Y+PM_Angle!$L$23*Mesh_X)>0)*((PM_Angle!$J$23+PM_Angle!$K$23*Mesh_Y+PM_Angle!$L$23*Mesh_X)<eco)+eco*((PM_Angle!$J$23+PM_Angle!$K$23*Mesh_Y+PM_Angle!$L$23*Mesh_X)>=eco))/eco)^n)*(((PM_Angle!$J$23+PM_Angle!$K$23*Mesh_Y+PM_Angle!$L$23*Mesh_X))>0),Mesh_A,Mesh_Y)/1000000 | O23: =SUMPRODUCT(alpha*fck*(1-(1-(((PM_Angle!$J$23+PM_Angle!$K$23*Mesh_Y+PM_Angle!$L$23*Mesh_X))*((PM_Angle!$J$23+PM_Angle!$K$23*Mesh_Y+PM_Angle!$L$23*Mesh_X)>0)*((PM_Angle!$J$23+PM_Angle!$K$23*Mesh_Y+PM_Angle!$L$23*Mesh_X)<eco)+eco*((PM_Angle!$J$23+PM_Angle!$K$23*Mesh_Y+PM_Angle!$L$23*Mesh_X)>=eco))/eco)^n)*(((PM_Angle!$J$23+PM_Angle!$K$23*Mesh_Y+PM_Angle!$L$23*Mesh_X))>0),Mesh_A,Mesh_X)/1000000 | P23: =Steel!DR6/1000 | Q23: =Steel!DS6/1000000 | R23: =Steel!DT6/1000000 | S23: =M23+P23 | T23: =N23+Q23 | U23: =O23+R23 | V23: =SQRT(T23^2+U23^2) | W23: 10905.321 | X23: =IF(ABS(W23)<0.000000001,0,(S23-W23)/W23*100)
B24: P17 | D24: 1.75 | F24: =u_bar | G24: -0.0035 | H24: =ecu/I24 | I24: =(ecu-G24)/(u_max-F24) | J24: =ecu-I24*u_max | K24: =I24*COS(RADIANS(beta)) | L24: =I24*SIN(RADIANS(beta)) | M24: =SUMPRODUCT(alpha*fck*(1-(1-(((PM_Angle!$J$24+PM_Angle!$K$24*Mesh_Y+PM_Angle!$L$24*Mesh_X))*((PM_Angle!$J$24+PM_Angle!$K$24*Mesh_Y+PM_Angle!$L$24*Mesh_X)>0)*((PM_Angle!$J$24+PM_Angle!$K$24*Mesh_Y+PM_Angle!$L$24*Mesh_X)<eco)+eco*((PM_Angle!$J$24+PM_Angle!$K$24*Mesh_Y+PM_Angle!$L$24*Mesh_X)>=eco))/eco)^n)*(((PM_Angle!$J$24+PM_Angle!$K$24*Mesh_Y+PM_Angle!$L$24*Mesh_X))>0),Mesh_A)/1000 | N24: =SUMPRODUCT(alpha*fck*(1-(1-(((PM_Angle!$J$24+PM_Angle!$K$24*Mesh_Y+PM_Angle!$L$24*Mesh_X))*((PM_Angle!$J$24+PM_Angle!$K$24*Mesh_Y+PM_Angle!$L$24*Mesh_X)>0)*((PM_Angle!$J$24+PM_Angle!$K$24*Mesh_Y+PM_Angle!$L$24*Mesh_X)<eco)+eco*((PM_Angle!$J$24+PM_Angle!$K$24*Mesh_Y+PM_Angle!$L$24*Mesh_X)>=eco))/eco)^n)*(((PM_Angle!$J$24+PM_Angle!$K$24*Mesh_Y+PM_Angle!$L$24*Mesh_X))>0),Mesh_A,Mesh_Y)/1000000 | O24: =SUMPRODUCT(alpha*fck*(1-(1-(((PM_Angle!$J$24+PM_Angle!$K$24*Mesh_Y+PM_Angle!$L$24*Mesh_X))*((PM_Angle!$J$24+PM_Angle!$K$24*Mesh_Y+PM_Angle!$L$24*Mesh_X)>0)*((PM_Angle!$J$24+PM_Angle!$K$24*Mesh_Y+PM_Angle!$L$24*Mesh_X)<eco)+eco*((PM_Angle!$J$24+PM_Angle!$K$24*Mesh_Y+PM_Angle!$L$24*Mesh_X)>=eco))/eco)^n)*(((PM_Angle!$J$24+PM_Angle!$K$24*Mesh_Y+PM_Angle!$L$24*Mesh_X))>0),Mesh_A,Mesh_X)/1000000 | P24: =Steel!DY6/1000 | Q24: =Steel!DZ6/1000000 | R24: =Steel!EA6/1000000 | S24: =M24+P24 | T24: =N24+Q24 | U24: =O24+R24 | V24: =SQRT(T24^2+U24^2) | W24: 9823.793 | X24: =IF(ABS(W24)<0.000000001,0,(S24-W24)/W24*100)
B25: P18 | D25: 2 | F25: =u_bar | G25: -0.004 | H25: =ecu/I25 | I25: =(ecu-G25)/(u_max-F25) | J25: =ecu-I25*u_max | K25: =I25*COS(RADIANS(beta)) | L25: =I25*SIN(RADIANS(beta)) | M25: =SUMPRODUCT(alpha*fck*(1-(1-(((PM_Angle!$J$25+PM_Angle!$K$25*Mesh_Y+PM_Angle!$L$25*Mesh_X))*((PM_Angle!$J$25+PM_Angle!$K$25*Mesh_Y+PM_Angle!$L$25*Mesh_X)>0)*((PM_Angle!$J$25+PM_Angle!$K$25*Mesh_Y+PM_Angle!$L$25*Mesh_X)<eco)+eco*((PM_Angle!$J$25+PM_Angle!$K$25*Mesh_Y+PM_Angle!$L$25*Mesh_X)>=eco))/eco)^n)*(((PM_Angle!$J$25+PM_Angle!$K$25*Mesh_Y+PM_Angle!$L$25*Mesh_X))>0),Mesh_A)/1000 | N25: =SUMPRODUCT(alpha*fck*(1-(1-(((PM_Angle!$J$25+PM_Angle!$K$25*Mesh_Y+PM_Angle!$L$25*Mesh_X))*((PM_Angle!$J$25+PM_Angle!$K$25*Mesh_Y+PM_Angle!$L$25*Mesh_X)>0)*((PM_Angle!$J$25+PM_Angle!$K$25*Mesh_Y+PM_Angle!$L$25*Mesh_X)<eco)+eco*((PM_Angle!$J$25+PM_Angle!$K$25*Mesh_Y+PM_Angle!$L$25*Mesh_X)>=eco))/eco)^n)*(((PM_Angle!$J$25+PM_Angle!$K$25*Mesh_Y+PM_Angle!$L$25*Mesh_X))>0),Mesh_A,Mesh_Y)/1000000 | O25: =SUMPRODUCT(alpha*fck*(1-(1-(((PM_Angle!$J$25+PM_Angle!$K$25*Mesh_Y+PM_Angle!$L$25*Mesh_X))*((PM_Angle!$J$25+PM_Angle!$K$25*Mesh_Y+PM_Angle!$L$25*Mesh_X)>0)*((PM_Angle!$J$25+PM_Angle!$K$25*Mesh_Y+PM_Angle!$L$25*Mesh_X)<eco)+eco*((PM_Angle!$J$25+PM_Angle!$K$25*Mesh_Y+PM_Angle!$L$25*Mesh_X)>=eco))/eco)^n)*(((PM_Angle!$J$25+PM_Angle!$K$25*Mesh_Y+PM_Angle!$L$25*Mesh_X))>0),Mesh_A,Mesh_X)/1000000 | P25: =Steel!EF6/1000 | Q25: =Steel!EG6/1000000 | R25: =Steel!EH6/1000000 | S25: =M25+P25 | T25: =N25+Q25 | U25: =O25+R25 | V25: =SQRT(T25^2+U25^2) | W25: 8823.4175 | X25: =IF(ABS(W25)<0.000000001,0,(S25-W25)/W25*100)
B26: P19 | D26: 2.5 | F26: =u_bar | G26: -0.005 | H26: =ecu/I26 | I26: =(ecu-G26)/(u_max-F26) | J26: =ecu-I26*u_max | K26: =I26*COS(RADIANS(beta)) | L26: =I26*SIN(RADIANS(beta)) | M26: =SUMPRODUCT(alpha*fck*(1-(1-(((PM_Angle!$J$26+PM_Angle!$K$26*Mesh_Y+PM_Angle!$L$26*Mesh_X))*((PM_Angle!$J$26+PM_Angle!$K$26*Mesh_Y+PM_Angle!$L$26*Mesh_X)>0)*((PM_Angle!$J$26+PM_Angle!$K$26*Mesh_Y+PM_Angle!$L$26*Mesh_X)<eco)+eco*((PM_Angle!$J$26+PM_Angle!$K$26*Mesh_Y+PM_Angle!$L$26*Mesh_X)>=eco))/eco)^n)*(((PM_Angle!$J$26+PM_Angle!$K$26*Mesh_Y+PM_Angle!$L$26*Mesh_X))>0),Mesh_A)/1000 | N26: =SUMPRODUCT(alpha*fck*(1-(1-(((PM_Angle!$J$26+PM_Angle!$K$26*Mesh_Y+PM_Angle!$L$26*Mesh_X))*((PM_Angle!$J$26+PM_Angle!$K$26*Mesh_Y+PM_Angle!$L$26*Mesh_X)>0)*((PM_Angle!$J$26+PM_Angle!$K$26*Mesh_Y+PM_Angle!$L$26*Mesh_X)<eco)+eco*((PM_Angle!$J$26+PM_Angle!$K$26*Mesh_Y+PM_Angle!$L$26*Mesh_X)>=eco))/eco)^n)*(((PM_Angle!$J$26+PM_Angle!$K$26*Mesh_Y+PM_Angle!$L$26*Mesh_X))>0),Mesh_A,Mesh_Y)/1000000 | O26: =SUMPRODUCT(alpha*fck*(1-(1-(((PM_Angle!$J$26+PM_Angle!$K$26*Mesh_Y+PM_Angle!$L$26*Mesh_X))*((PM_Angle!$J$26+PM_Angle!$K$26*Mesh_Y+PM_Angle!$L$26*Mesh_X)>0)*((PM_Angle!$J$26+PM_Angle!$K$26*Mesh_Y+PM_Angle!$L$26*Mesh_X)<eco)+eco*((PM_Angle!$J$26+PM_Angle!$K$26*Mesh_Y+PM_Angle!$L$26*Mesh_X)>=eco))/eco)^n)*(((PM_Angle!$J$26+PM_Angle!$K$26*Mesh_Y+PM_Angle!$L$26*Mesh_X))>0),Mesh_A,Mesh_X)/1000000 | P26: =Steel!EM6/1000 | Q26: =Steel!EN6/1000000 | R26: =Steel!EO6/1000000 | S26: =M26+P26 | T26: =N26+Q26 | U26: =O26+R26 | V26: =SQRT(T26^2+U26^2) | W26: 7089.75 | X26: =IF(ABS(W26)<0.000000001,0,(S26-W26)/W26*100)
B27: P20 | D27: 3 | F27: =u_bar | G27: -0.006 | H27: =ecu/I27 | I27: =(ecu-G27)/(u_max-F27) | J27: =ecu-I27*u_max | K27: =I27*COS(RADIANS(beta)) | L27: =I27*SIN(RADIANS(beta)) | M27: =SUMPRODUCT(alpha*fck*(1-(1-(((PM_Angle!$J$27+PM_Angle!$K$27*Mesh_Y+PM_Angle!$L$27*Mesh_X))*((PM_Angle!$J$27+PM_Angle!$K$27*Mesh_Y+PM_Angle!$L$27*Mesh_X)>0)*((PM_Angle!$J$27+PM_Angle!$K$27*Mesh_Y+PM_Angle!$L$27*Mesh_X)<eco)+eco*((PM_Angle!$J$27+PM_Angle!$K$27*Mesh_Y+PM_Angle!$L$27*Mesh_X)>=eco))/eco)^n)*(((PM_Angle!$J$27+PM_Angle!$K$27*Mesh_Y+PM_Angle!$L$27*Mesh_X))>0),Mesh_A)/1000 | N27: =SUMPRODUCT(alpha*fck*(1-(1-(((PM_Angle!$J$27+PM_Angle!$K$27*Mesh_Y+PM_Angle!$L$27*Mesh_X))*((PM_Angle!$J$27+PM_Angle!$K$27*Mesh_Y+PM_Angle!$L$27*Mesh_X)>0)*((PM_Angle!$J$27+PM_Angle!$K$27*Mesh_Y+PM_Angle!$L$27*Mesh_X)<eco)+eco*((PM_Angle!$J$27+PM_Angle!$K$27*Mesh_Y+PM_Angle!$L$27*Mesh_X)>=eco))/eco)^n)*(((PM_Angle!$J$27+PM_Angle!$K$27*Mesh_Y+PM_Angle!$L$27*Mesh_X))>0),Mesh_A,Mesh_Y)/1000000 | O27: =SUMPRODUCT(alpha*fck*(1-(1-(((PM_Angle!$J$27+PM_Angle!$K$27*Mesh_Y+PM_Angle!$L$27*Mesh_X))*((PM_Angle!$J$27+PM_Angle!$K$27*Mesh_Y+PM_Angle!$L$27*Mesh_X)>0)*((PM_Angle!$J$27+PM_Angle!$K$27*Mesh_Y+PM_Angle!$L$27*Mesh_X)<eco)+eco*((PM_Angle!$J$27+PM_Angle!$K$27*Mesh_Y+PM_Angle!$L$27*Mesh_X)>=eco))/eco)^n)*(((PM_Angle!$J$27+PM_Angle!$K$27*Mesh_Y+PM_Angle!$L$27*Mesh_X))>0),Mesh_A,Mesh_X)/1000000 | P27: =Steel!ET6/1000 | Q27: =Steel!EU6/1000000 | R27: =Steel!EV6/1000000 | S27: =M27+P27 | T27: =N27+Q27 | U27: =O27+R27 | V27: =SQRT(T27^2+U27^2) | W27: 5653.3272 | X27: =IF(ABS(W27)<0.000000001,0,(S27-W27)/W27*100)
B28: P21 | D28: 4 | F28: =u_bar | G28: -0.008 | H28: =ecu/I28 | I28: =(ecu-G28)/(u_max-F28) | J28: =ecu-I28*u_max | K28: =I28*COS(RADIANS(beta)) | L28: =I28*SIN(RADIANS(beta)) | M28: =SUMPRODUCT(alpha*fck*(1-(1-(((PM_Angle!$J$28+PM_Angle!$K$28*Mesh_Y+PM_Angle!$L$28*Mesh_X))*((PM_Angle!$J$28+PM_Angle!$K$28*Mesh_Y+PM_Angle!$L$28*Mesh_X)>0)*((PM_Angle!$J$28+PM_Angle!$K$28*Mesh_Y+PM_Angle!$L$28*Mesh_X)<eco)+eco*((PM_Angle!$J$28+PM_Angle!$K$28*Mesh_Y+PM_Angle!$L$28*Mesh_X)>=eco))/eco)^n)*(((PM_Angle!$J$28+PM_Angle!$K$28*Mesh_Y+PM_Angle!$L$28*Mesh_X))>0),Mesh_A)/1000 | N28: =SUMPRODUCT(alpha*fck*(1-(1-(((PM_Angle!$J$28+PM_Angle!$K$28*Mesh_Y+PM_Angle!$L$28*Mesh_X))*((PM_Angle!$J$28+PM_Angle!$K$28*Mesh_Y+PM_Angle!$L$28*Mesh_X)>0)*((PM_Angle!$J$28+PM_Angle!$K$28*Mesh_Y+PM_Angle!$L$28*Mesh_X)<eco)+eco*((PM_Angle!$J$28+PM_Angle!$K$28*Mesh_Y+PM_Angle!$L$28*Mesh_X)>=eco))/eco)^n)*(((PM_Angle!$J$28+PM_Angle!$K$28*Mesh_Y+PM_Angle!$L$28*Mesh_X))>0),Mesh_A,Mesh_Y)/1000000 | O28: =SUMPRODUCT(alpha*fck*(1-(1-(((PM_Angle!$J$28+PM_Angle!$K$28*Mesh_Y+PM_Angle!$L$28*Mesh_X))*((PM_Angle!$J$28+PM_Angle!$K$28*Mesh_Y+PM_Angle!$L$28*Mesh_X)>0)*((PM_Angle!$J$28+PM_Angle!$K$28*Mesh_Y+PM_Angle!$L$28*Mesh_X)<eco)+eco*((PM_Angle!$J$28+PM_Angle!$K$28*Mesh_Y+PM_Angle!$L$28*Mesh_X)>=eco))/eco)^n)*(((PM_Angle!$J$28+PM_Angle!$K$28*Mesh_Y+PM_Angle!$L$28*Mesh_X))>0),Mesh_A,Mesh_X)/1000000 | P28: =Steel!FA6/1000 | Q28: =Steel!FB6/1000000 | R28: =Steel!FC6/1000000 | S28: =M28+P28 | T28: =N28+Q28 | U28: =O28+R28 | V28: =SQRT(T28^2+U28^2) | W28: 3322.7572 | X28: =IF(ABS(W28)<0.000000001,0,(S28-W28)/W28*100)
B29: P22 | D29: 5 | F29: =u_bar | G29: -0.01 | H29: =ecu/I29 | I29: =(ecu-G29)/(u_max-F29) | J29: =ecu-I29*u_max | K29: =I29*COS(RADIANS(beta)) | L29: =I29*SIN(RADIANS(beta)) | M29: =SUMPRODUCT(alpha*fck*(1-(1-(((PM_Angle!$J$29+PM_Angle!$K$29*Mesh_Y+PM_Angle!$L$29*Mesh_X))*((PM_Angle!$J$29+PM_Angle!$K$29*Mesh_Y+PM_Angle!$L$29*Mesh_X)>0)*((PM_Angle!$J$29+PM_Angle!$K$29*Mesh_Y+PM_Angle!$L$29*Mesh_X)<eco)+eco*((PM_Angle!$J$29+PM_Angle!$K$29*Mesh_Y+PM_Angle!$L$29*Mesh_X)>=eco))/eco)^n)*(((PM_Angle!$J$29+PM_Angle!$K$29*Mesh_Y+PM_Angle!$L$29*Mesh_X))>0),Mesh_A)/1000 | N29: =SUMPRODUCT(alpha*fck*(1-(1-(((PM_Angle!$J$29+PM_Angle!$K$29*Mesh_Y+PM_Angle!$L$29*Mesh_X))*((PM_Angle!$J$29+PM_Angle!$K$29*Mesh_Y+PM_Angle!$L$29*Mesh_X)>0)*((PM_Angle!$J$29+PM_Angle!$K$29*Mesh_Y+PM_Angle!$L$29*Mesh_X)<eco)+eco*((PM_Angle!$J$29+PM_Angle!$K$29*Mesh_Y+PM_Angle!$L$29*Mesh_X)>=eco))/eco)^n)*(((PM_Angle!$J$29+PM_Angle!$K$29*Mesh_Y+PM_Angle!$L$29*Mesh_X))>0),Mesh_A,Mesh_Y)/1000000 | O29: =SUMPRODUCT(alpha*fck*(1-(1-(((PM_Angle!$J$29+PM_Angle!$K$29*Mesh_Y+PM_Angle!$L$29*Mesh_X))*((PM_Angle!$J$29+PM_Angle!$K$29*Mesh_Y+PM_Angle!$L$29*Mesh_X)>0)*((PM_Angle!$J$29+PM_Angle!$K$29*Mesh_Y+PM_Angle!$L$29*Mesh_X)<eco)+eco*((PM_Angle!$J$29+PM_Angle!$K$29*Mesh_Y+PM_Angle!$L$29*Mesh_X)>=eco))/eco)^n)*(((PM_Angle!$J$29+PM_Angle!$K$29*Mesh_Y+PM_Angle!$L$29*Mesh_X))>0),Mesh_A,Mesh_X)/1000000 | P29: =Steel!FH6/1000 | Q29: =Steel!FI6/1000000 | R29: =Steel!FJ6/1000000 | S29: =M29+P29 | T29: =N29+Q29 | U29: =O29+R29 | V29: =SQRT(T29^2+U29^2) | W29: 1694.8502 | X29: =IF(ABS(W29)<0.000000001,0,(S29-W29)/W29*100)
B30: P23 | D30: 7.5 | F30: =u_bar | G30: -0.015 | H30: =ecu/I30 | I30: =(ecu-G30)/(u_max-F30) | J30: =ecu-I30*u_max | K30: =I30*COS(RADIANS(beta)) | L30: =I30*SIN(RADIANS(beta)) | M30: =SUMPRODUCT(alpha*fck*(1-(1-(((PM_Angle!$J$30+PM_Angle!$K$30*Mesh_Y+PM_Angle!$L$30*Mesh_X))*((PM_Angle!$J$30+PM_Angle!$K$30*Mesh_Y+PM_Angle!$L$30*Mesh_X)>0)*((PM_Angle!$J$30+PM_Angle!$K$30*Mesh_Y+PM_Angle!$L$30*Mesh_X)<eco)+eco*((PM_Angle!$J$30+PM_Angle!$K$30*Mesh_Y+PM_Angle!$L$30*Mesh_X)>=eco))/eco)^n)*(((PM_Angle!$J$30+PM_Angle!$K$30*Mesh_Y+PM_Angle!$L$30*Mesh_X))>0),Mesh_A)/1000 | N30: =SUMPRODUCT(alpha*fck*(1-(1-(((PM_Angle!$J$30+PM_Angle!$K$30*Mesh_Y+PM_Angle!$L$30*Mesh_X))*((PM_Angle!$J$30+PM_Angle!$K$30*Mesh_Y+PM_Angle!$L$30*Mesh_X)>0)*((PM_Angle!$J$30+PM_Angle!$K$30*Mesh_Y+PM_Angle!$L$30*Mesh_X)<eco)+eco*((PM_Angle!$J$30+PM_Angle!$K$30*Mesh_Y+PM_Angle!$L$30*Mesh_X)>=eco))/eco)^n)*(((PM_Angle!$J$30+PM_Angle!$K$30*Mesh_Y+PM_Angle!$L$30*Mesh_X))>0),Mesh_A,Mesh_Y)/1000000 | O30: =SUMPRODUCT(alpha*fck*(1-(1-(((PM_Angle!$J$30+PM_Angle!$K$30*Mesh_Y+PM_Angle!$L$30*Mesh_X))*((PM_Angle!$J$30+PM_Angle!$K$30*Mesh_Y+PM_Angle!$L$30*Mesh_X)>0)*((PM_Angle!$J$30+PM_Angle!$K$30*Mesh_Y+PM_Angle!$L$30*Mesh_X)<eco)+eco*((PM_Angle!$J$30+PM_Angle!$K$30*Mesh_Y+PM_Angle!$L$30*Mesh_X)>=eco))/eco)^n)*(((PM_Angle!$J$30+PM_Angle!$K$30*Mesh_Y+PM_Angle!$L$30*Mesh_X))>0),Mesh_A,Mesh_X)/1000000 | P30: =Steel!FO6/1000 | Q30: =Steel!FP6/1000000 | R30: =Steel!FQ6/1000000 | S30: =M30+P30 | T30: =N30+Q30 | U30: =O30+R30 | V30: =SQRT(T30^2+U30^2) | W30: -1005.049 | X30: =IF(ABS(W30)<0.000000001,0,(S30-W30)/W30*100)
B31: P24 | D31: 10 | F31: =u_bar | G31: -0.02 | H31: =ecu/I31 | I31: =(ecu-G31)/(u_max-F31) | J31: =ecu-I31*u_max | K31: =I31*COS(RADIANS(beta)) | L31: =I31*SIN(RADIANS(beta)) | M31: =SUMPRODUCT(alpha*fck*(1-(1-(((PM_Angle!$J$31+PM_Angle!$K$31*Mesh_Y+PM_Angle!$L$31*Mesh_X))*((PM_Angle!$J$31+PM_Angle!$K$31*Mesh_Y+PM_Angle!$L$31*Mesh_X)>0)*((PM_Angle!$J$31+PM_Angle!$K$31*Mesh_Y+PM_Angle!$L$31*Mesh_X)<eco)+eco*((PM_Angle!$J$31+PM_Angle!$K$31*Mesh_Y+PM_Angle!$L$31*Mesh_X)>=eco))/eco)^n)*(((PM_Angle!$J$31+PM_Angle!$K$31*Mesh_Y+PM_Angle!$L$31*Mesh_X))>0),Mesh_A)/1000 | N31: =SUMPRODUCT(alpha*fck*(1-(1-(((PM_Angle!$J$31+PM_Angle!$K$31*Mesh_Y+PM_Angle!$L$31*Mesh_X))*((PM_Angle!$J$31+PM_Angle!$K$31*Mesh_Y+PM_Angle!$L$31*Mesh_X)>0)*((PM_Angle!$J$31+PM_Angle!$K$31*Mesh_Y+PM_Angle!$L$31*Mesh_X)<eco)+eco*((PM_Angle!$J$31+PM_Angle!$K$31*Mesh_Y+PM_Angle!$L$31*Mesh_X)>=eco))/eco)^n)*(((PM_Angle!$J$31+PM_Angle!$K$31*Mesh_Y+PM_Angle!$L$31*Mesh_X))>0),Mesh_A,Mesh_Y)/1000000 | O31: =SUMPRODUCT(alpha*fck*(1-(1-(((PM_Angle!$J$31+PM_Angle!$K$31*Mesh_Y+PM_Angle!$L$31*Mesh_X))*((PM_Angle!$J$31+PM_Angle!$K$31*Mesh_Y+PM_Angle!$L$31*Mesh_X)>0)*((PM_Angle!$J$31+PM_Angle!$K$31*Mesh_Y+PM_Angle!$L$31*Mesh_X)<eco)+eco*((PM_Angle!$J$31+PM_Angle!$K$31*Mesh_Y+PM_Angle!$L$31*Mesh_X)>=eco))/eco)^n)*(((PM_Angle!$J$31+PM_Angle!$K$31*Mesh_Y+PM_Angle!$L$31*Mesh_X))>0),Mesh_A,Mesh_X)/1000000 | P31: =Steel!FV6/1000 | Q31: =Steel!FW6/1000000 | R31: =Steel!FX6/1000000 | S31: =M31+P31 | T31: =N31+Q31 | U31: =O31+R31 | V31: =SQRT(T31^2+U31^2) | W31: -2705.1851 | X31: =IF(ABS(W31)<0.000000001,0,(S31-W31)/W31*100)
B32: P25 | D32: 20 | F32: =u_bar | G32: -0.04 | H32: =ecu/I32 | I32: =(ecu-G32)/(u_max-F32) | J32: =ecu-I32*u_max | K32: =I32*COS(RADIANS(beta)) | L32: =I32*SIN(RADIANS(beta)) | M32: =SUMPRODUCT(alpha*fck*(1-(1-(((PM_Angle!$J$32+PM_Angle!$K$32*Mesh_Y+PM_Angle!$L$32*Mesh_X))*((PM_Angle!$J$32+PM_Angle!$K$32*Mesh_Y+PM_Angle!$L$32*Mesh_X)>0)*((PM_Angle!$J$32+PM_Angle!$K$32*Mesh_Y+PM_Angle!$L$32*Mesh_X)<eco)+eco*((PM_Angle!$J$32+PM_Angle!$K$32*Mesh_Y+PM_Angle!$L$32*Mesh_X)>=eco))/eco)^n)*(((PM_Angle!$J$32+PM_Angle!$K$32*Mesh_Y+PM_Angle!$L$32*Mesh_X))>0),Mesh_A)/1000 | N32: =SUMPRODUCT(alpha*fck*(1-(1-(((PM_Angle!$J$32+PM_Angle!$K$32*Mesh_Y+PM_Angle!$L$32*Mesh_X))*((PM_Angle!$J$32+PM_Angle!$K$32*Mesh_Y+PM_Angle!$L$32*Mesh_X)>0)*((PM_Angle!$J$32+PM_Angle!$K$32*Mesh_Y+PM_Angle!$L$32*Mesh_X)<eco)+eco*((PM_Angle!$J$32+PM_Angle!$K$32*Mesh_Y+PM_Angle!$L$32*Mesh_X)>=eco))/eco)^n)*(((PM_Angle!$J$32+PM_Angle!$K$32*Mesh_Y+PM_Angle!$L$32*Mesh_X))>0),Mesh_A,Mesh_Y)/1000000 | O32: =SUMPRODUCT(alpha*fck*(1-(1-(((PM_Angle!$J$32+PM_Angle!$K$32*Mesh_Y+PM_Angle!$L$32*Mesh_X))*((PM_Angle!$J$32+PM_Angle!$K$32*Mesh_Y+PM_Angle!$L$32*Mesh_X)>0)*((PM_Angle!$J$32+PM_Angle!$K$32*Mesh_Y+PM_Angle!$L$32*Mesh_X)<eco)+eco*((PM_Angle!$J$32+PM_Angle!$K$32*Mesh_Y+PM_Angle!$L$32*Mesh_X)>=eco))/eco)^n)*(((PM_Angle!$J$32+PM_Angle!$K$32*Mesh_Y+PM_Angle!$L$32*Mesh_X))>0),Mesh_A,Mesh_X)/1000000 | P32: =Steel!GC6/1000 | Q32: =Steel!GD6/1000000 | R32: =Steel!GE6/1000000 | S32: =M32+P32 | T32: =N32+Q32 | U32: =O32+R32 | V32: =SQRT(T32^2+U32^2) | W32: -4986.1898 | X32: =IF(ABS(W32)<0.000000001,0,(S32-W32)/W32*100)
B33: P26 | F33: — | G33: =etu | H33: n/a | I33: 0 | J33: =etu | K33: =I33*COS(RADIANS(beta)) | L33: =I33*SIN(RADIANS(beta)) | M33: =SUMPRODUCT(alpha*fck*(1-(1-(((PM_Angle!$J$33+PM_Angle!$K$33*Mesh_Y+PM_Angle!$L$33*Mesh_X))*((PM_Angle!$J$33+PM_Angle!$K$33*Mesh_Y+PM_Angle!$L$33*Mesh_X)>0)*((PM_Angle!$J$33+PM_Angle!$K$33*Mesh_Y+PM_Angle!$L$33*Mesh_X)<eco)+eco*((PM_Angle!$J$33+PM_Angle!$K$33*Mesh_Y+PM_Angle!$L$33*Mesh_X)>=eco))/eco)^n)*(((PM_Angle!$J$33+PM_Angle!$K$33*Mesh_Y+PM_Angle!$L$33*Mesh_X))>0),Mesh_A)/1000 | N33: =SUMPRODUCT(alpha*fck*(1-(1-(((PM_Angle!$J$33+PM_Angle!$K$33*Mesh_Y+PM_Angle!$L$33*Mesh_X))*((PM_Angle!$J$33+PM_Angle!$K$33*Mesh_Y+PM_Angle!$L$33*Mesh_X)>0)*((PM_Angle!$J$33+PM_Angle!$K$33*Mesh_Y+PM_Angle!$L$33*Mesh_X)<eco)+eco*((PM_Angle!$J$33+PM_Angle!$K$33*Mesh_Y+PM_Angle!$L$33*Mesh_X)>=eco))/eco)^n)*(((PM_Angle!$J$33+PM_Angle!$K$33*Mesh_Y+PM_Angle!$L$33*Mesh_X))>0),Mesh_A,Mesh_Y)/1000000 | O33: =SUMPRODUCT(alpha*fck*(1-(1-(((PM_Angle!$J$33+PM_Angle!$K$33*Mesh_Y+PM_Angle!$L$33*Mesh_X))*((PM_Angle!$J$33+PM_Angle!$K$33*Mesh_Y+PM_Angle!$L$33*Mesh_X)>0)*((PM_Angle!$J$33+PM_Angle!$K$33*Mesh_Y+PM_Angle!$L$33*Mesh_X)<eco)+eco*((PM_Angle!$J$33+PM_Angle!$K$33*Mesh_Y+PM_Angle!$L$33*Mesh_X)>=eco))/eco)^n)*(((PM_Angle!$J$33+PM_Angle!$K$33*Mesh_Y+PM_Angle!$L$33*Mesh_X))>0),Mesh_A,Mesh_X)/1000000 | P33: =Steel!GJ6/1000 | Q33: =Steel!GK6/1000000 | R33: =Steel!GL6/1000000 | S33: =M33+P33 | T33: =N33+Q33 | U33: =O33+R33 | V33: =SQRT(T33^2+U33^2) | W33: -5790.5836 | X33: =IF(ABS(W33)<0.000000001,0,(S33-W33)/W33*100)
B35: Where the demand check lives
C36: This table is the resistance sampled at β. The moment direction of each row is atan2(My, Mx) of that row, which is generally not β.
C37: Capacity against the demand: MxMy_FixedP intersects the P = Pu contour with the ray at θ_L; PM_Theta cuts the surface with the plane Mx·sin(θ_L) − My·cos(θ_L) = 0.
B38: =beta | C38: β of this sheet vs θ_L of the demand (deg) | D38: =theta_L

Sheet Concrete
A1: CONCRETE — FIBRE STRAIN AND STRESS PER STATION
A2: ε = ε₀ + κx·Y + κy·X | fc = KDS parabola-rectangle: fc = α·fck·(1−(1−ε/εco)^n) up to εco, then α·fck
A3: Columns A-D mirror the Mesh sheet. Columns E-I expand the full force/moment ledger for the station chosen in cell C4. The 27 station totals on PM_Angle integrate the same law over the same mesh without materialising 27 more column blocks.
A4: Detail station (0…26) | C4: 5 | D4: ="detail shown for station P"&C4
K5: At the converged equilibrium state
A6: No. | B6: X (mm) | C6: Y (mm) | D6: A (mm²) | E6: ε | F6: fc (MPa) | G6: Fc (N) | H6: Mcx (N·mm) | I6: Mcy (N·mm) | K6: ε | L6: fc (MPa)
A7: SUM | D7: =SUM(D8:D1264) | G7: =SUM(G8:G1264) | H7: =SUM(H8:H1264) | I7: =SUM(I8:I1264)
A8: =Mesh!A5 | B8: =Mesh!B5 | C8: =Mesh!C5 | D8: =Mesh!D5 | E8: =INDEX(St_e0,Det+1)+INDEX(St_kx,Det+1)*C8+INDEX(St_ky,Det+1)*B8 | F8: =IF(E8>0,IF(E8<=eco,alpha*fck*(1-(1-E8/eco)^n),alpha*fck),0) | G8: =F8*D8 | H8: =G8*C8 | I8: =G8*B8 | K8: =Eq_e0+Eq_kx*$C8+Eq_ky*$B8 | L8: =IF(K8>0,IF(K8<=eco,alpha*fck*(1-(1-K8/eco)^n),alpha*fck),0)
A9: =Mesh!A6 | B9: =Mesh!B6 | C9: =Mesh!C6 | D9: =Mesh!D6 | E9: =INDEX(St_e0,Det+1)+INDEX(St_kx,Det+1)*C9+INDEX(St_ky,Det+1)*B9 | F9: =IF(E9>0,IF(E9<=eco,alpha*fck*(1-(1-E9/eco)^n),alpha*fck),0) | G9: =F9*D9 | H9: =G9*C9 | I9: =G9*B9 | K9: =Eq_e0+Eq_kx*$C9+Eq_ky*$B9 | L9: =IF(K9>0,IF(K9<=eco,alpha*fck*(1-(1-K9/eco)^n),alpha*fck),0)
A10: =Mesh!A7 | B10: =Mesh!B7 | C10: =Mesh!C7 | D10: =Mesh!D7 | E10: =INDEX(St_e0,Det+1)+INDEX(St_kx,Det+1)*C10+INDEX(St_ky,Det+1)*B10 | F10: =IF(E10>0,IF(E10<=eco,alpha*fck*(1-(1-E10/eco)^n),alpha*fck),0) | G10: =F10*D10 | H10: =G10*C10 | I10: =G10*B10 | K10: =Eq_e0+Eq_kx*$C10+Eq_ky*$B10 | L10: =IF(K10>0,IF(K10<=eco,alpha*fck*(1-(1-K10/eco)^n),alpha*fck),0)
A11: =Mesh!A8 | B11: =Mesh!B8 | C11: =Mesh!C8 | D11: =Mesh!D8 | E11: =INDEX(St_e0,Det+1)+INDEX(St_kx,Det+1)*C11+INDEX(St_ky,Det+1)*B11 | F11: =IF(E11>0,IF(E11<=eco,alpha*fck*(1-(1-E11/eco)^n),alpha*fck),0) | G11: =F11*D11 | H11: =G11*C11 | I11: =G11*B11 | K11: =Eq_e0+Eq_kx*$C11+Eq_ky*$B11 | L11: =IF(K11>0,IF(K11<=eco,alpha*fck*(1-(1-K11/eco)^n),alpha*fck),0)
A12: =Mesh!A9 | B12: =Mesh!B9 | C12: =Mesh!C9 | D12: =Mesh!D9 | E12: =INDEX(St_e0,Det+1)+INDEX(St_kx,Det+1)*C12+INDEX(St_ky,Det+1)*B12 | F12: =IF(E12>0,IF(E12<=eco,alpha*fck*(1-(1-E12/eco)^n),alpha*fck),0) | G12: =F12*D12 | H12: =G12*C12 | I12: =G12*B12 | K12: =Eq_e0+Eq_kx*$C12+Eq_ky*$B12 | L12: =IF(K12>0,IF(K12<=eco,alpha*fck*(1-(1-K12/eco)^n),alpha*fck),0)
A13: =Mesh!A10 | B13: =Mesh!B10 | C13: =Mesh!C10 | D13: =Mesh!D10 | E13: =INDEX(St_e0,Det+1)+INDEX(St_kx,Det+1)*C13+INDEX(St_ky,Det+1)*B13 | F13: =IF(E13>0,IF(E13<=eco,alpha*fck*(1-(1-E13/eco)^n),alpha*fck),0) | G13: =F13*D13 | H13: =G13*C13 | I13: =G13*B13 | K13: =Eq_e0+Eq_kx*$C13+Eq_ky*$B13 | L13: =IF(K13>0,IF(K13<=eco,alpha*fck*(1-(1-K13/eco)^n),alpha*fck),0)
A14: =Mesh!A11 | B14: =Mesh!B11 | C14: =Mesh!C11 | D14: =Mesh!D11 | E14: =INDEX(St_e0,Det+1)+INDEX(St_kx,Det+1)*C14+INDEX(St_ky,Det+1)*B14 | F14: =IF(E14>0,IF(E14<=eco,alpha*fck*(1-(1-E14/eco)^n),alpha*fck),0) | G14: =F14*D14 | H14: =G14*C14 | I14: =G14*B14 | K14: =Eq_e0+Eq_kx*$C14+Eq_ky*$B14 | L14: =IF(K14>0,IF(K14<=eco,alpha*fck*(1-(1-K14/eco)^n),alpha*fck),0)
A15: =Mesh!A12 | B15: =Mesh!B12 | C15: =Mesh!C12 | D15: =Mesh!D12 | E15: =INDEX(St_e0,Det+1)+INDEX(St_kx,Det+1)*C15+INDEX(St_ky,Det+1)*B15 | F15: =IF(E15>0,IF(E15<=eco,alpha*fck*(1-(1-E15/eco)^n),alpha*fck),0) | G15: =F15*D15 | H15: =G15*C15 | I15: =G15*B15 | K15: =Eq_e0+Eq_kx*$C15+Eq_ky*$B15 | L15: =IF(K15>0,IF(K15<=eco,alpha*fck*(1-(1-K15/eco)^n),alpha*fck),0)
