Workbook
Name Origin_X: Geometry!$C$6
Name Origin_Y: Geometry!$C$7
Name Boundary_X: Geometry!$F$13:$F$36
Name Boundary_Y: Geometry!$G$13:$G$36
Name C_fck: Materials!$C$10
Name C_alpha: Materials!$C$12
Name C_eco: Materials!$C$13
Name C_n: Materials!$C$14
Name C_ecu: Materials!$C$15
Name S_1_fy: Materials!$D$20
Name S_1_Es: Materials!$E$20
Name Mesh_X: Mesh!$B$6:$B$425
Name Mesh_Y: Mesh!$C$6:$C$425
Name Mesh_A: Mesh!$D$6:$D$425

Sheet Geometry
A1: PROJECT GEOMETRY AND LOAD INPUTS
A2: Legend | B2: Editable calculation input | C2: Formula | D2: Generated / check | E2: Requires re-export / remesh
B3: Project | C3: PM-advanced (7) 2D reference case | F3: Client | G3: Engineering review client
B4: Section | C4: PM-advanced (7) 2D — 1500x1200 chamfered section, two voids | F4: Company | G4: Audit engineering
B5: Calculation profile | C5: strain-domain-surface-v1 | F5: Designed by | G5: Engineering example
B6: Analysis origin X | C6: 0 | D6: mm | F6: Checked by | G6: Independent review
B7: Analysis origin Y | C7: 0 | D7: mm | F7: Address | G7: Seoul, Korea
F8: Date | G8: 2026-07-23
A12: Ring ID | B12: Boundary | C12: Point order | D12: X input (mm) | E12: Y input (mm) | F12: x local (mm) | G12: y local (mm)
A13: R1-OUTER | B13: Outer | C13: 1 | D13: -550 | E13: 600 | F13: =D13-Origin_X -> -550 | G13: =E13-Origin_Y -> 600
A14: R1-OUTER | B14: Outer | C14: 2 | D14: 550 | E14: 600 | F14: =D14-Origin_X -> 550 | G14: =E14-Origin_Y -> 600
A15: R1-OUTER | B15: Outer | C15: 3 | D15: 750 | E15: 400 | F15: =D15-Origin_X -> 750 | G15: =E15-Origin_Y -> 400
A16: R1-OUTER | B16: Outer | C16: 4 | D16: 750 | E16: -400 | F16: =D16-Origin_X -> 750 | G16: =E16-Origin_Y -> -400
A17: R1-OUTER | B17: Outer | C17: 5 | D17: 550 | E17: -600 | F17: =D17-Origin_X -> 550 | G17: =E17-Origin_Y -> -600
A18: R1-OUTER | B18: Outer | C18: 6 | D18: -550 | E18: -600 | F18: =D18-Origin_X -> -550 | G18: =E18-Origin_Y -> -600
A19: R1-OUTER | B19: Outer | C19: 7 | D19: -750 | E19: -400 | F19: =D19-Origin_X -> -750 | G19: =E19-Origin_Y -> -400
A20: R1-OUTER | B20: Outer | C20: 8 | D20: -750 | E20: 400 | F20: =D20-Origin_X -> -750 | G20: =E20-Origin_Y -> 400
A21: R1-H1 | B21: Hole | C21: 1 | D21: -450 | E21: 400 | F21: =D21-Origin_X -> -450 | G21: =E21-Origin_Y -> 400
A22: R1-H1 | B22: Hole | C22: 2 | D22: -250 | E22: 400 | F22: =D22-Origin_X -> -250 | G22: =E22-Origin_Y -> 400
A23: R1-H1 | B23: Hole | C23: 3 | D23: -150 | E23: 300 | F23: =D23-Origin_X -> -150 | G23: =E23-Origin_Y -> 300
A24: R1-H1 | B24: Hole | C24: 4 | D24: -150 | E24: -300 | F24: =D24-Origin_X -> -150 | G24: =E24-Origin_Y -> -300
... A36: R1-H2 | B36: Hole | C36: 8 | D36: 150 | E36: 300 | F36: =D36-Origin_X -> 150 | G36: =E36-Origin_Y -> 300
B38: Reinforcement
A39: No. | B39: Rebar ID | C39: Diameter (mm) | D39: X world (mm) | E39: Y world (mm) | F39: X local (mm) | G39: Y local (mm) | H39: Area (mm²) | I39: Steel material ID
A40: 1 | B40: 1 | C40: 32 | D40: -400 | E40: 530 | F40: =D40-Origin_X -> -400 | G40: =E40-Origin_Y -> 530 | H40: =PI()*C40^2/4 -> 804.24772 | I40: 1
A41: 2 | B41: 2 | C41: 32 | D41: -200 | E41: 530 | F41: =D41-Origin_X -> -200 | G41: =E41-Origin_Y -> 530 | H41: =PI()*C41^2/4 -> 804.24772 | I41: 1
A42: 3 | B42: 3 | C42: 32 | D42: 0 | E42: 530 | F42: =D42-Origin_X -> 0 | G42: =E42-Origin_Y -> 530 | H42: =PI()*C42^2/4 -> 804.24772 | I42: 1
A43: 4 | B43: 4 | C43: 32 | D43: 200 | E43: 530 | F43: =D43-Origin_X -> 200 | G43: =E43-Origin_Y -> 530 | H43: =PI()*C43^2/4 -> 804.24772 | I43: 1
A44: 5 | B44: 5 | C44: 32 | D44: 400 | E44: 530 | F44: =D44-Origin_X -> 400 | G44: =E44-Origin_Y -> 530 | H44: =PI()*C44^2/4 -> 804.24772 | I44: 1
A45: 6 | B45: 6 | C45: 32 | D45: -400 | E45: -530 | F45: =D45-Origin_X -> -400 | G45: =E45-Origin_Y -> -530 | H45: =PI()*C45^2/4 -> 804.24772 | I45: 1
A46: 7 | B46: 7 | C46: 32 | D46: -200 | E46: -530 | F46: =D46-Origin_X -> -200 | G46: =E46-Origin_Y -> -530 | H46: =PI()*C46^2/4 -> 804.24772 | I46: 1
A47: 8 | B47: 8 | C47: 32 | D47: 0 | E47: -530 | F47: =D47-Origin_X -> 0 | G47: =E47-Origin_Y -> -530 | H47: =PI()*C47^2/4 -> 804.24772 | I47: 1
A48: 9 | B48: 9 | C48: 32 | D48: 200 | E48: -530 | F48: =D48-Origin_X -> 200 | G48: =E48-Origin_Y -> -530 | H48: =PI()*C48^2/4 -> 804.24772 | I48: 1
A49: 10 | B49: 10 | C49: 32 | D49: 400 | E49: -530 | F49: =D49-Origin_X -> 400 | G49: =E49-Origin_Y -> -530 | H49: =PI()*C49^2/4 -> 804.24772 | I49: 1
A50: 11 | B50: 11 | C50: 32 | D50: -680 | E50: 300 | F50: =D50-Origin_X -> -680 | G50: =E50-Origin_Y -> 300 | H50: =PI()*C50^2/4 -> 804.24772 | I50: 1
A51: 12 | B51: 12 | C51: 32 | D51: -680 | E51: 100 | F51: =D51-Origin_X -> -680 | G51: =E51-Origin_Y -> 100 | H51: =PI()*C51^2/4 -> 804.24772 | I51: 1
... A57: 18 | B57: 18 | C57: 32 | D57: 680 | E57: -300 | F57: =D57-Origin_X -> 680 | G57: =E57-Origin_Y -> -300 | H57: =PI()*C57^2/4 -> 804.24772 | I57: 1
B61: Project load cases
A62: ID | B62: Name | C62: P (kN) | D62: Mx (kN·m) | E62: My (kN·m) | F62: Action basis
A63: 1 | B63: ULS-1 workbook Newton demand (on the 15 deg surface) | C63: 24942.922 | D63: 3714.1659 | E63: 1431.7807 | F63: factoredULS
...

Sheet Materials
A1: MATERIALS AND RESISTANCE BASIS
A2: Legend | B2: Editable calculation input | C2: Formula | D2: Generated / check | E2: Requires re-export / remesh
A3: Active result stage | B3: Design resistance | D3: Calculation profile | E3: KDS 2024 current set · resistance: KDS 14 20 10:2021 + KDS 14 20 20:2022
B5: Concrete
A6: Symbol | B6: Parameter | C6: Value | D6: Unit | E6: Basis / use in calculation
B7: Material | C7: KDS C30 (workbook Input)
B8: Standard | C8: KDS
B9: Stress–strain law | C9: kds-parabolic
A10: f′c / fck | B10: Specified concrete compressive strength | C10: 30 | D10: MPa | E10: Strength used by the active material law
A11: Eᴄ | B11: Elastic modulus | C11: 28417.475 | D11: MPa | E11: Concrete elastic modulus reported by the selected standard
A12: α | B12: Concrete stress coefficient | C12: 0.85 | D12: – | E12: Multiplier applied to the concrete compression stress
A13: εc0 | B13: Peak / plateau strain | C13: 0.002 | D13: – | E13: End of the parabolic branch
A14: n | B14: Parabola exponent | C14: 2 | D14: – | E14: Exponent of the concrete stress–strain curve
A15: εcu | B15: Ultimate compression strain | C15: 0.0033 | D15: – | E15: Compression strain used at the neutral-axis boundary state
B16: Calculation law | C16: KDS parabola-rectangle: fc = α·fck·(1−(1−ε/εco)^n) up to εco, then α·fck
B18: Reinforcing steel
A19: ID | B19: Material | C19: Standard | D19: fy (MPa) | E19: Eₛ (MPa) | F19: εy | G19: εu | H19: Stress–strain law
A20: 1 | B20: SD400 (workbook Input) | C20: KDS | D20: 400 | E20: 200000 | F20: =D20/E20 -> 0.002 | H20: elastic-perfectly-plastic
B24: Resistance basis
A25: Symbol / setting | B25: Parameter | C25: Value | D25: Unit | E25: Code basis / note
B26: Resistance format | C26: globalResultantFactor | D26: –
B27: Active result stage | C27: design | D27: –
B28: Profile | C28: kds-2024-current-set | D28: – | E28: KDS 2024 current set · resistance: KDS 14 20 10:2021 + KDS 14 20 20:2022
B29: Transverse reinforcement | C29: other | D29: –
A30: φc | B30: Compression-controlled strength factor | C30: 0.65 | D30: –
A31: φt | B31: Tension-controlled strength factor | C31: 0.85 | D31: –
A32: Pmax | B32: Axial compression limit enabled | C32: Yes | D32: –
A33: Pmax/P0 | B33: Axial compression limit ratio | C33: 0.8 | D33: –
A34: εt | B34: Tension-controlled transition rule | C34: fixed 0.005; high-strength 2.5·εy | D34: –
A36: Blue text marks editable values that drive formulas. Orange text marks settings that require re-export because they change the generated surface or mesh.

Sheet Mesh
A1: CONCRETE INTEGRATION MESH
B2: X and Y are measured from the analysis origin. Area is the quadrature weight used directly by Result SUMPRODUCT formulas.
B3: Cell size (mm) | C3: 150 | D3: Points | E3: 420 | F3: Area error | G3: 4.6566129e-10
A4: Legend | B4: Editable calculation input | C4: Formula | D4: Generated / check | E4: Requires re-export / remesh
A5: No. | B5: X local (mm) | C5: Y local (mm) | D5: Area (mm²) | E5: Component | F5: X world (mm) | G5: Y world (mm)
A6: 1 | B6: -666.66667 | C6: -466.66667 | D6: 1666.6667 | E6: 0 | F6: =B6+Origin_X -> -666.66667 | G6: =C6+Origin_Y -> -466.66667
A7: 2 | B7: -616.66667 | C7: -516.66667 | D7: 1666.6667 | E7: 0 | F7: =B7+Origin_X -> -616.66667 | G7: =C7+Origin_Y -> -516.66667
A8: 3 | B8: -616.66667 | C8: -466.66667 | D8: 1666.6667 | E8: 0 | F8: =B8+Origin_X -> -616.66667 | G8: =C8+Origin_Y -> -466.66667
A9: 4 | B9: -741.66667 | C9: -341.66667 | D9: 833.33333 | E9: 1 | F9: =B9+Origin_X -> -741.66667 | G9: =C9+Origin_Y -> -341.66667
A10: 5 | B10: -741.66667 | C10: -391.66667 | D10: 833.33333 | E10: 1 | F10: =B10+Origin_X -> -741.66667 | G10: =C10+Origin_Y -> -391.66667
A11: 6 | B11: -716.66667 | C11: -416.66667 | D11: 833.33333 | E11: 1 | F11: =B11+Origin_X -> -716.66667 | G11: =C11+Origin_Y -> -416.66667
A12: 7 | B12: -716.66667 | C12: -350 | D12: 2500 | E12: 1 | F12: =B12+Origin_X -> -716.66667 | G12: =C12+Origin_Y -> -350
A13: 8 | B13: -691.66667 | C13: -425 | D13: 2500 | E13: 1 | F13: =B13+Origin_X -> -691.66667 | G13: =C13+Origin_Y -> -425
A14: 9 | B14: -641.66667 | C14: -425 | D14: 2500 | E14: 1 | F14: =B14+Origin_X -> -641.66667 | G14: =C14+Origin_Y -> -425
A15: 10 | B15: -625 | C15: -400 | D15: 3750 | E15: 1 | F15: =B15+Origin_X -> -625 | G15: =C15+Origin_Y -> -400
A16: 11 | B16: -625 | C16: -325 | D16: 3750 | E16: 1 | F16: =B16+Origin_X -> -625 | G16: =C16+Origin_Y -> -325
A17: 12 | B17: -700 | C17: -325 | D17: 3750 | E17: 1 | F17: =B17+Origin_X -> -700 | G17: =C17+Origin_Y -> -325
... A425: 420 | B425: 616.66667 | C425: 516.66667 | D425: 1666.6667 | E425: 63 | F425: =B425+Origin_X -> 616.66667 | G425: =C425+Origin_Y -> 516.66667

Sheet Result
A1: FORMULA-DRIVEN CHART AUDIT
B2: Displayed values are formulas. Each resolved station criterion determines ε₀, κx and κy; the section result is then integrated from Materials and Mesh.
B3: Chart source | C3: Vertical
B4: Resistance stage | C4: design
B5: Selected beta (deg) | C5: 15
A6: Legend | B6: Editable calculation input | C6: Formula | D6: Generated / check | E6: Requires re-export / remesh
A7: # | B7: Resolved criterion | C7: P (kN) | D7: M (kN·m) | G7: Source key | H7: Station / role | I7: β (deg) | J7: Criterion basis | K7: Criterion value | L7: zc (mm) | M7: z control (mm) | N7: D (mm) | O7: εc | P7: ε control | Q7: κ (1/mm) | R7: ε₀ | S7: κx (1/mm) | T7: κy (1/mm) | U7: Concrete P | V7: Concrete Mx | W7: Concrete My | X7: Steel P | Y7: Steel Mx | Z7: Steel My | AA7: Base P | AB7: Base Mx | AC7: Base My | AD7: P scale | AE7: M scale | AF7: Final P | AG7: Final Mx | AH7: Final My | AI7: Engine P | AJ7: Engine Mx | AK7: Engine My | AL7: ΔP | AM7: ΔM | AN7: Calculation mode | AO7: Base engine P | AP7: Base engine Mx | AQ7: Base engine My | AR7: Concrete engine P | AS7: Concrete engine Mx | AT7: Concrete engine My | AU7: Steel engine P | AV7: Steel engine Mx | AW7: Steel engine My
A8: 1 | B8: Pure compression | C8: =$AF$8 -> 17670.346 | D8: =$AG$8*COS(RADIANS($C$5))+$AH$8*SIN(RADIANS($C$5)) -> 0 | G8: 10-pure-compression|0.17453292519943295|0 | H8: Pure compression | I8: 15 | J8: ε = constant | K8: 0.0033 | L8: =MAX(('Geometry'!$G$13*COS(RADIANS(I8))+'Geometry'!$F$13*SIN(RADIANS(I8))),('Geometry'!$G$14*COS(RADIANS(I8))+'Geometry'!$F$14*SIN(RADIANS(I8))),('Geometry'!$G$15*COS(RADIANS(I8))+'Geometry'!$F$15*SIN(RADIANS(I8))),('Geometry'!$G$16*COS(RADIANS(I8))+'Geometry'!$F$16*SIN(RADIANS(I8))),('Geometry'!$G$17*COS(RADIANS(I8))+'Geometry'!$F$17*SIN(RADIANS(I8))),('Geometry'!$G$18*COS(RADIANS(I8))+'Geometry'!$F$18*SIN(RADIANS(I8))),('Geometry'!$G$19*COS(RADIANS(I8))+'Geometry'!$F$19*SIN(RADIANS(I8))),('Geometry'!$G$20*COS(RADIANS(I8))+'Geometry'!$F$20*SIN(RADIANS(I8)))) -> 721.90597 | M8: =L8 -> -615.46831 | N8: =L8-MIN(('Geometry'!$G$13*COS(RADIANS(I8))+'Geometry'!$F$13*SIN(RADIANS(I8))),('Geometry'!$G$14*COS(RADIANS(I8))+'Geometry'!$F$14*SIN(RADIANS(I8))),('Geometry'!$G$15*COS(RADIANS(I8))+'Geometry'!$F$15*SIN(RADIANS(I8))),('Geometry'!$G$16*COS(RADIANS(I8))+'Geometry'!$F$16*SIN(RADIANS(I8))),('Geometry'!$G$17*COS(RADIANS(I8))+'Geometry'!$F$17*SIN(RADIANS(I8))),('Geometry'!$G$18*COS(RADIANS(I8))+'Geometry'!$F$18*SIN(RADIANS(I8))),('Geometry'!$G$19*COS(RADIANS(I8))+'Geometry'!$F$19*SIN(RADIANS(I8))),('Geometry'!$G$20*COS(RADIANS(I8))+'Geometry'!$F$20*SIN(RADIANS(I8)))) -> 1443.8119 | O8: =K8 -> 0.0033 | P8: =K8 -> 0.0033 | Q8: =0 -> 0 | R8: =K8 -> 0.0033 | S8: =Q8*COS(RADIANS(I8)) -> 0 | T8: =Q8*SIN(RADIANS(I8)) -> 0 | U8: =SUMPRODUCT(C_alpha*C_fck*(1-(1-((($R8+$S8*Mesh_Y+$T8*Mesh_X))*(($R8+$S8*Mesh_Y+$T8*Mesh_X)>0)*(($R8+$S8*Mesh_Y+$T8*Mesh_X)<C_eco)+C_eco*(($R8+$S8*Mesh_Y+$T8*Mesh_X)>=C_eco))/C_eco)^C_n)*((($R8+$S8*Mesh_Y+$T8*Mesh_X))>0),Mesh_A)/1000 -> 28560 | V8: =SUMPRODUCT(C_alpha*C_fck*(1-(1-((($R8+$S8*Mesh_Y+$T8*Mesh_X))*(($R8+$S8*Mesh_Y+$T8*Mesh_X)>0)*(($R8+$S8*Mesh_Y+$T8*Mesh_X)<C_eco)+C_eco*(($R8+$S8*Mesh_Y+$T8*Mesh_X)>=C_eco))/C_eco)^C_n)*((($R8+$S8*Mesh_Y+$T8*Mesh_X))>0),Mesh_A,Mesh_Y)/1000000 -> 7.4505806e-15 | W8: =SUMPRODUCT(C_alpha*C_fck*(1-(1-((($R8+$S8*Mesh_Y+$T8*Mesh_X))*(($R8+$S8*Mesh_Y+$T8*Mesh_X)>0)*(($R8+$S8*Mesh_Y+$T8*Mesh_X)<C_eco)+C_eco*(($R8+$S8*Mesh_Y+$T8*Mesh_X)>=C_eco))/C_eco)^C_n)*((($R8+$S8*Mesh_Y+$T8*Mesh_X))>0),Mesh_A,Mesh_X)/1000000 -> 2.4586916e-13 | X8: =(((MAX(MIN(S_1_Es*($R8+$S8*'Geometry'!$G$40+$T8*'Geometry'!$F$40),S_1_fy),-S_1_fy))-(IF(($R8+$S8*'Geometry'!$G$40+$T8*'Geometry'!$F$40)>0,IF(($R8+$S8*'Geometry'!$G$40+$T8*'Geometry'!$F$40)<=C_eco,C_alpha*C_fck*(1-(1-($R8+$S8*'Geometry'!$G$40+$T8*'Geometry'!$F$40)/C_eco)^C_n),C_alpha*C_fck),0)))*'Geometry'!$H$40+((MAX(MIN(S_1_Es*($R8+$S8*'Geometry'!$G$41+$T8*'Geometry'!$F$41),S_1_fy),-S_1_fy))-(IF(($R8+$S8*'Geometry'!$G$41+$T8*'Geometry'!$F$41)>0,IF(($R8+$S8*'Geometry'!$G$41+$T8*'Geometry'!$F$41)<=C_eco,C_alpha*C_fck*(1-(1-($R8+$S8*'Geometry'!$G$41+$T8*'Geometry'!$F$41)/C_eco)^C_n),C_alpha*C_fck),0)))*'Geometry'!$H$41+((MAX(MIN(S_1_Es*($R8+$S8*'Geometry'!$G$42+$T8*'Geometry'!$F$42),S_1_fy),-S_1_fy))-(IF(($R8+$S8*'Geometry'!$G$42+$T8*'Geometry'!$F$42)>0,IF(($R8+$S8*'Geometry'!$G$42+$T8*'Geometry'!$F$42)<=C_eco,C_alpha*C_fck*(1-(1-($R8+$S8*'Geometry'!$G$42+$T8*'Geometry'!$F$42)/C_eco)^C_n),C_alpha*C_fck),0)))*'Geometry'!$H$42+((MAX(MIN(S_1_Es*($R8+$S8*'Geometry'!$G$43+$T8*'Geometry'!$F$43),S_1_fy),-S_1_fy))-(IF(($R8+$S8*'Geometry'!$G$43+$T8*'Geometry'!$F$43)>0,IF(($R8+$S8*'Geometry'!$G$43+$T8*'Geometry'!$F$43)<=C_eco,C_alpha*C_fck*(1-(1-($R8+$S8*'Geometry'!$G$43+$T8*'Geometry'!$F$43)/C_eco)^C_n),C_alpha*C_fck),0)))*'Geometry'!$H$43+((MAX(MIN(S_1_Es*($R8+$S8*'Geometry'!$G$44+$T8*'Geometry'!$F$44),S_1_fy),-S_1_fy))-(IF(($R8+$S8*'Geometry'!$G$44+$T8*'Geometry'!$F$44)>0,IF(($R8+$S8*'Geometry'!$G$44+$T8*'Geometry'!$F$44)<=C_eco,C_alpha*C_fck*(1-(1-($R8+$S8*'Geometry'!$G$44+$T8*'Geometry'!$F$44)/C_eco)^C_n),C_alpha*C_fck),0)))*'Geometry'!$H$44+((MAX(MIN(S_1_Es*($R8+$S8*'Geometry'!$G$45+$T8*'Geometry'!$F$45),S_1_fy),-S_1_fy))-(IF(($R8+$S8*'Geometry'!$G$45+$T8*'Geometry'!$F$45)>0,IF(($R8+$S8*'Geometry'!$G$45+$T8*'Geometry'!$F$45)<=C_eco,C_alpha*C_fck*(1-(1-($R8+$S8*'Geometry'!$G$45+$T8*'Geometry'!$F$45)/C_eco)^C_n),C_alpha*C_fck),0)))*'Geometry'!$H$45+((MAX(MIN(S_1_Es*($R8+$S8*'Geometry'!$G$46+$T8*'Geometry'!$F$46),S_1_fy),-S_1_fy))-(IF(($R8+$S8*'Geometry'!$G$46+$T8*'Geometry'!$F$46)>0,IF(($R8+$S8*'Geometry'!$G$46+$T8*'Geometry'!$F$46)<=C_eco,C_alpha*C_fck*(1-(1-($R8+$S8*'Geometry'!$G$46+$T8*'Geometry'!$F$46)/C_eco)^C_n),C_alpha*C_fck),0)))*'Geometry'!$H$46+((MAX(MIN(S_1_Es*($R8+$S8*'Geometry'!$G$47+$T8*'Geometry'!$F$47),S_1_fy),-S_1_fy))-(IF(($R8+$S8*'Geometry'!$G$47+$T8*'Geometry'!$F$47)>0,IF(($R8+$S8*'Geometry'!$G$47+$T8*'Geometry'!$F$47)<=C_eco,C_alpha*C_fck*(1-(1-($R8+$S8*'Geometry'!$G$47+$T8*'Geometry'!$F$47)/C_eco)^C_n),C_alpha*C_fck),0)))*'Geometry'!$H$47+((MAX(MIN(S_1_Es*($R8+$S8*'Geometry'!$G$48+$T8*'Geometry'!$F$48),S_1_fy),-S_1_fy))-(IF(($R8+$S8*'Geometry'!$G$48+$T8*'Geometry'!$F$48)>0,IF(($R8+$S8*'Geometry'!$G$48+$T8*'Geometry'!$F$48)<=C_eco,C_alpha*C_fck*(1-(1-($R8+$S8*'Geometry'!$G$48+$T8*'Geometry'!$F$48)/C_eco)^C_n),C_alpha*C_fck),0)))*'Geometry'!$H$48+((MAX(MIN(S_1_Es*($R8+$S8*'Geometry'!$G$49+$T8*'Geometry'!$F$49),S_1_fy),-S_1_fy))-(IF(($R8+$S8*'Geometry'!$G$49+$T8*'Geometry'!$F$49)>0,IF(($R8+$S8*'Geometry'!$G$49+$T8*'Geometry'!$F$49)<=C_eco,C_alpha*C_fck*(1-(1-($R8+$S8*'Geometry'!$G$49+$T8*'Geometry'!$F$49)/C_eco)^C_n),C_alpha*C_fck),0)))*'Geometry'!$H$49+((MAX(MIN(S_1_Es*($R8+$S8*'Geometry'!$G$50+$T8*'Geometry'!$F$50),S_1_fy),-S_1_fy))-(IF(($R8+$S8*'Geometry'!$G$50+$T8*'Geometry'!$F$50)>0,IF(($R8+$S8*'Geometry'!$G$50+$T8*'Geometry'!$F$50)<=C_eco,C_alpha*C_fck*(1-(1-($R8+$S8*'Geometry'!$G$50+$T8*'Geometry'!$F$50)/C_eco)^C_n),C_alpha*C_fck),0)))*'Geometry'!$H$50+((MAX(MIN(S_1_Es*($R8+$S8*'Geometry'!$G$51+$T8*'Geometry'!$F$51),S_1_fy),-S_1_fy))-(IF(($R8+$S8*'Geometry'!$G$51+$T8*'Geometry'!$F$51)>0,IF(($R8+$S8*'Geometry'!$G$51+$T8*'Geometry'!$F$51)<=C_eco,C_alpha*C_fck*(1-(1-($R8+$S8*'Geometry'!$G$51+$T8*'Geometry'!$F$51)/C_eco)^C_n),C_alpha*C_fck),0)))*'Geometry'!$H$51+((MAX(MIN(S_1_Es*($R8+$S8*'Geometry'!$G$52+$T8*'Geometry'!$F$52),S_1_fy),-S_1_fy))-(IF(($R8+$S8*'Geometry'!$G$52+$T8*'Geometry'!$F$52)>0,IF(($R8+$S8*'Geometry'!$G$52+$T8*'Geometry'!$F$52)<=C_eco,C_alpha*C_fck*(1-(1-($R8+$S8*'Geometry'!$G$52+$T8*'Geometry'!$F$52)/C_eco)^C_n),C_alpha*C_fck),0)))*'Geometry'!$H$52+((MAX(MIN(S_1_Es*($R8+$S8*'Geometry'!$G$53+$T8*'Geometry'!$F$53),S_1_fy),-S_1_fy))-(IF(($R8+$S8*'Geometry'!$G$53+$T8*'Geometry'!$F$53)>0,IF(($R8+$S8*'Geometry'!$G$53+$T8*'Geometry'!$F$53)<=C_eco,C_alpha*C_fck*(1-(1-($R8+$S8*'Geometry'!$G$53+$T8*'Geometry'!$F$53)/C_eco)^C_n),C_alpha*C_fck),0)))*'Geometry'!$H$53+((MAX(MIN(S_1_Es*($R8+$S8*'Geometry'!$G$54+$T8*'Geometry'!$F$54),S_1_fy),-S_1_fy))-(IF(($R8+$S8*'Geometry'!$G$54+$T8*'Geometry'!$F$54)>0,IF(($R8+$S8*'Geometry'!$G$54+$T8*'Geometry'!$F$54)<=C_eco,C_alpha*C_fck*(1-(1-($R8+$S8*'Geometry'!$G$54+$T8*'Geometry'!$F$54)/C_eco)^C_n),C_alpha*C_fck),0)))*'Geometry'!$H$54+((MAX(MIN(S_1_Es*($R8+$S8*'Geometry'!$G$55+$T8*'Geometry'!$F$55),S_1_fy),-S_1_fy))-(IF(($R8+$S8*'Geometry'!$G$55+$T8*'Geometry'!$F$55)>0,IF(($R8+$S8*'Geometry'!$G$55+$T8*'Geometry'!$F$55)<=C_eco,C_alpha*C_fck*(1-(1-($R8+$S8*'Geometry'!$G$55+$T8*'Geometry'!$F$55)/C_eco)^C_n),C_alpha*C_fck),0)))*'Geometry'!$H$55+((MAX(MIN(S_1_Es*($R8+$S8*'Geometry'!$G$56+$T8*'Geometry'!$F$56),S_1_fy),-S_1_fy))-(IF(($R8+$S8*'Geometry'!$G$56+$T8*'Geometry'!$F$56)>0,IF(($R8+$S8*'Geometry'!$G$56+$T8*'Geometry'!$F$56)<=C_eco,C_alpha*C_fck*(1-(1-($R8+$S8*'Geometry'!$G$56+$T8*'Geometry'!$F$56)/C_eco)^C_n),C_alpha*C_fck),0)))*'Geometry'!$H$56+((MAX(MIN(S_1_Es*($R8+$S8*'Geometry'!$G$57+$T8*'Geometry'!$F$57),S_1_fy),-S_1_fy))-(IF(($R8+$S8*'Geometry'!$G$57+$T8*'Geometry'!$F$57)>0,IF(($R8+$S8*'Geometry'!$G$57+$T8*'Geometry'!$F$57)<=C_eco,C_alpha*C_fck*(1-(1-($R8+$S8*'Geometry'!$G$57+$T8*'Geometry'!$F$57)/C_eco)^C_n),C_alpha*C_fck),0)))*'Geometry'!$H$57)/1000 -> 5421.4339 | Y8: =(((MAX(MIN(S_1_Es*($R8+$S8*'Geometry'!$G$40+$T8*'Geometry'!$F$40),S_1_fy),-S_1_fy))-(IF(($R8+$S8*'Geometry'!$G$40+$T8*'Geometry'!$F$40)>0,IF(($R8+$S8*'Geometry'!$G$40+$T8*'Geometry'!$F$40)<=C_eco,C_alpha*C_fck*(1-(1-($R8+$S8*'Geometry'!$G$40+$T8*'Geometry'!$F$40)/C_eco)^C_n),C_alpha*C_fck),0)))*'Geometry'!$H$40*'Geometry'!$G$40+((MAX(MIN(S_1_Es*($R8+$S8*'Geometry'!$G$41+$T8*'Geometry'!$F$41),S_1_fy),-S_1_fy))-(IF(($R8+$S8*'Geometry'!$G$41+$T8*'Geometry'!$F$41)>0,IF(($R8+$S8*'Geometry'!$G$41+$T8*'Geometry'!$F$41)<=C_eco,C_alpha*C_fck*(1-(1-($R8+$S8*'Geometry'!$G$41+$T8*'Geometry'!$F$41)/C_eco)^C_n),C_alpha*C_fck),0)))*'Geometry'!$H$41*'Geometry'!$G$41+((MAX(MIN(S_1_Es*($R8+$S8*'Geometry'!$G$42+$T8*'Geometry'!$F$42),S_1_fy),-S_1_fy))-(IF(($R8+$S8*'Geometry'!$G$42+$T8*'Geometry'!$F$42)>0,IF(($R8+$S8*'Geometry'!$G$42+$T8*'Geometry'!$F$42)<=C_eco,C_alpha*C_fck*(1-(1-($R8+$S8*'Geometry'!$G$42+$T8*'Geometry'!$F$42)/C_eco)^C_n),C_alpha*C_fck),0)))*'Geometry'!$H$42*'Geometry'!$G$42+((MAX(MIN(S_1_Es*($R8+$S8*'Geometry'!$G$43+$T8*'Geometry'!$F$43),S_1_fy),-S_1_fy))-(IF(($R8+$S8*'Geometry'!$G$43+$T8*'Geometry'!$F$43)>0,IF(($R8+$S8*'Geometry'!$G$43+$T8*'Geometry'!$F$43)<=C_eco,C_alpha*C_fck*(1-(1-($R8+$S8*'Geometry'!$G$43+$T8*'Geometry'!$F$43)/C_eco)^C_n),C_alpha*C_fck),0)))*'Geometry'!$H$43*'Geometry'!$G$43+((MAX(MIN(S_1_Es*($R8+$S8*'Geometry'!$G$44+$T8*'Geometry'!$F$44),S_1_fy),-S_1_fy))-(IF(($R8+$S8*'Geometry'!$G$44+$T8*'Geometry'!$F$44)>0,IF(($R8+$S8*'Geometry'!$G$44+$T8*'Geometry'!$F$44)<=C_eco,C_alpha*C_fck*(1-(1-($R8+$S8*'Geometry'!$G$44+$T8*'Geometry'!$F$44)/C_eco)^C_n),C_alpha*C_fck),0)))*'Geometry'!$H$44*'Geometry'!$G$44+((MAX(MIN(S_1_Es*($R8+$S8*'Geometry'!$G$45+$T8*'Geometry'!$F$45),S_1_fy),-S_1_fy))-(IF(($R8+$S8*'Geometry'!$G$45+$T8*'Geometry'!$F$45)>0,IF(($R8+$S8*'Geometry'!$G$45+$T8*'Geometry'!$F$45)<=C_eco,C_alpha*C_fck*(1-(1-($R8+$S8*'Geometry'!$G$45+$T8*'Geometry'!$F$45)/C_eco)^C_n),C_alpha*C_fck),0)))*'Geometry'!$H$45*'Geometry'!$G$45+((MAX(MIN(S_1_Es*($R8+$S8*'Geometry'!$G$46+$T8*'Geometry'!$F$46),S_1_fy),-S_1_fy))-(IF(($R8+$S8*'Geometry'!$G$46+$T8*'Geometry'!$F$46)>0,IF(($R8+$S8*'Geometry'!$G$46+$T8*'Geometry'!$F$46)<=C_eco,C_alpha*C_fck*(1-(1-($R8+$S8*'Geometry'!$G$46+$T8*'Geometry'!$F$46)/C_eco)^C_n),C_alpha*C_fck),0)))*'Geometry'!$H$46*'Geometry'!$G$46+((MAX(MIN(S_1_Es*($R8+$S8*'Geometry'!$G$47+$T8*'Geometry'!$F$47),S_1_fy),-S_1_fy))-(IF(($R8+$S8*'Geometry'!$G$47+$T8*'Geometry'!$F$47)>0,IF(($R8+$S8*'Geometry'!$G$47+$T8*'Geometry'!$F$47)<=C_eco,C_alpha*C_fck*(1-(1-($R8+$S8*'Geometry'!$G$47+$T8*'Geometry'!$F$47)/C_eco)^C_n),C_alpha*C_fck),0)))*'Geometry'!$H$47*'Geometry'!$G$47+((MAX(MIN(S_1_Es*($R8+$S8*'Geometry'!$G$48+$T8*'Geometry'!$F$48),S_1_fy),-S_1_fy))-(IF(($R8+$S8*'Geometry'!$G$48+$T8*'Geometry'!$F$48)>0,IF(($R8+$S8*'Geometry'!$G$48+$T8*'Geometry'!$F$48)<=C_eco,C_alpha*C_fck*(1-(1-($R8+$S8*'Geometry'!$G$48+$T8*'Geometry'!$F$48)/C_eco)^C_n),C_alpha*C_fck),0)))*'Geometry'!$H$48*'Geometry'!$G$48+((MAX(MIN(S_1_Es*($R8+$S8*'Geometry'!$G$49+$T8*'Geometry'!$F$49),S_1_fy),-S_1_fy))-(IF(($R8+$S8*'Geometry'!$G$49+$T8*'Geometry'!$F$49)>0,IF(($R8+$S8*'Geometry'!$G$49+$T8*'Geometry'!$F$49)<=C_eco,C_alpha*C_fck*(1-(1-($R8+$S8*'Geometry'!$G$49+$T8*'Geometry'!$F$49)/C_eco)^C_n),C_alpha*C_fck),0)))*'Geometry'!$H$49*'Geometry'!$G$49+((MAX(MIN(S_1_Es*($R8+$S8*'Geometry'!$G$50+$T8*'Geometry'!$F$50),S_1_fy),-S_1_fy))-(IF(($R8+$S8*'Geometry'!$G$50+$T8*'Geometry'!$F$50)>0,IF(($R8+$S8*'Geometry'!$G$50+$T8*'Geometry'!$F$50)<=C_eco,C_alpha*C_fck*(1-(1-($R8+$S8*'Geometry'!$G$50+$T8*'Geometry'!$F$50)/C_eco)^C_n),C_alpha*C_fck),0)))*'Geometry'!$H$50*'Geometry'!$G$50+((MAX(MIN(S_1_Es*($R8+$S8*'Geometry'!$G$51+$T8*'Geometry'!$F$51),S_1_fy),-S_1_fy))-(IF(($R8+$S8*'Geometry'!$G$51+$T8*'Geometry'!$F$51)>0,IF(($R8+$S8*'Geometry'!$G$51+$T8*'Geometry'!$F$51)<=C_eco,C_alpha*C_fck*(1-(1-($R8+$S8*'Geometry'!$G$51+$T8*'Geometry'!$F$51)/C_eco)^C_n),C_alpha*C_fck),0)))*'Geometry'!$H$51*'Geometry'!$G$51+((MAX(MIN(S_1_Es*($R8+$S8*'Geometry'!$G$52+$T8*'Geometry'!$F$52),S_1_fy),-S_1_fy))-(IF(($R8+$S8*'Geometry'!$G$52+$T8*'Geometry'!$F$52)>0,IF(($R8+$S8*'Geometry'!$G$52+$T8*'Geometry'!$F$52)<=C_eco,C_alpha*C_fck*(1-(1-($R8+$S8*'Geometry'!$G$52+$T8*'Geometry'!$F$52)/C_eco)^C_n),C_alpha*C_fck),0)))*'Geometry'!$H$52*'Geometry'!$G$52+((MAX(MIN(S_1_Es*($R8+$S8*'Geometry'!$G$53+$T8*'Geometry'!$F$53),S_1_fy),-S_1_fy))-(IF(($R8+$S8*'Geometry'!$G$53+$T8*'Geometry'!$F$53)>0,IF(($R8+$S8*'Geometry'!$G$53+$T8*'Geometry'!$F$53)<=C_eco,C_alpha*C_fck*(1-(1-($R8+$S8*'Geometry'!$G$53+$T8*'Geometry'!$F$53)/C_eco)^C_n),C_alpha*C_fck),0)))*'Geometry'!$H$53*'Geometry'!$G$53+((MAX(MIN(S_1_Es*($R8+$S8*'Geometry'!$G$54+$T8*'Geometry'!$F$54),S_1_fy),-S_1_fy))-(IF(($R8+$S8*'Geometry'!$G$54+$T8*'Geometry'!$F$54)>0,IF(($R8+$S8*'Geometry'!$G$54+$T8*'Geometry'!$F$54)<=C_eco,C_alpha*C_fck*(1-(1-($R8+$S8*'Geometry'!$G$54+$T8*'Geometry'!$F$54)/C_eco)^C_n),C_alpha*C_fck),0)))*'Geometry'!$H$54*'Geometry'!$G$54+((MAX(MIN(S_1_Es*($R8+$S8*'Geometry'!$G$55+$T8*'Geometry'!$F$55),S_1_fy),-S_1_fy))-(IF(($R8+$S8*'Geometry'!$G$55+$T8*'Geometry'!$F$55)>0,IF(($R8+$S8*'Geometry'!$G$55+$T8*'Geometry'!$F$55)<=C_eco,C_alpha*C_fck*(1-(1-($R8+$S8*'Geometry'!$G$55+$T8*'Geometry'!$F$55)/C_eco)^C_n),C_alpha*C_fck),0)))*'Geometry'!$H$55*'Geometry'!$G$55+((MAX(MIN(S_1_Es*($R8+$S8*'Geometry'!$G$56+$T8*'Geometry'!$F$56),S_1_fy),-S_1_fy))-(IF(($R8+$S8*'Geometry'!$G$56+$T8*'Geometry'!$F$56)>0,IF(($R8+$S8*'Geometry'!$G$56+$T8*'Geometry'!$F$56)<=C_eco,C_alpha*C_fck*(1-(1-($R8+$S8*'Geometry'!$G$56+$T8*'Geometry'!$F$56)/C_eco)^C_n),C_alpha*C_fck),0)))*'Geometry'!$H$56*'Geometry'!$G$56+((MAX(MIN(S_1_Es*($R8+$S8*'Geometry'!$G$57+$T8*'Geometry'!$F$57),S_1_fy),-S_1_fy))-(IF(($R8+$S8*'Geometry'!$G$57+$T8*'Geometry'!$F$57)>0,IF(($R8+$S8*'Geometry'!$G$57+$T8*'Geometry'!$F$57)<=C_eco,C_alpha*C_fck*(1-(1-($R8+$S8*'Geometry'!$G$57+$T8*'Geometry'!$F$57)/C_eco)^C_n),C_alpha*C_fck),0)))*'Geometry'!$H$57*'Geometry'!$G$57)/1000000 -> 0 | Z8: =(((MAX(MIN(S_1_Es*($R8+$S8*'Geometry'!$G$40+$T8*'Geometry'!$F$40),S_1_fy),-S_1_fy))-(IF(($R8+$S8*'Geometry'!$G$40+$T8*'Geometry'!$F$40)>0,IF(($R8+$S8*'Geometry'!$G$40+$T8*'Geometry'!$F$40)<=C_eco,C_alpha*C_fck*(1-(1-($R8+$S8*'Geometry'!$G$40+$T8*'Geometry'!$F$40)/C_eco)^C_n),C_alpha*C_fck),0)))*'Geometry'!$H$40*'Geometry'!$F$40+((MAX(MIN(S_1_Es*($R8+$S8*'Geometry'!$G$41+$T8*'Geometry'!$F$41),S_1_fy),-S_1_fy))-(IF(($R8+$S8*'Geometry'!$G$41+$T8*'Geometry'!$F$41)>0,IF(($R8+$S8*'Geometry'!$G$41+$T8*'Geometry'!$F$41)<=C_eco,C_alpha*C_fck*(1-(1-($R8+$S8*'Geometry'!$G$41+$T8*'Geometry'!$F$41)/C_eco)^C_n),C_alpha*C_fck),0)))*'Geometry'!$H$41*'Geometry'!$F$41+((MAX(MIN(S_1_Es*($R8+$S8*'Geometry'!$G$42+$T8*'Geometry'!$F$42),S_1_fy),-S_1_fy))-(IF(($R8+$S8*'Geometry'!$G$42+$T8*'Geometry'!$F$42)>0,IF(($R8+$S8*'Geometry'!$G$42+$T8*'Geometry'!$F$42)<=C_eco,C_alpha*C_fck*(1-(1-($R8+$S8*'Geometry'!$G$42+$T8*'Geometry'!$F$42)/C_eco)^C_n),C_alpha*C_fck),0)))*'Geometry'!$H$42*'Geometry'!$F$42+((MAX(MIN(S_1_Es*($R8+$S8*'Geometry'!$G$43+$T8*'Geometry'!$F$43),S_1_fy),-S_1_fy))-(IF(($R8+$S8*'Geometry'!$G$43+$T8*'Geometry'!$F$43)>0,IF(($R8+$S8*'Geometry'!$G$43+$T8*'Geometry'!$F$43)<=C_eco,C_alpha*C_fck*(1-(1-($R8+$S8*'Geometry'!$G$43+$T8*'Geometry'!$F$43)/C_eco)^C_n),C_alpha*C_fck),0)))*'Geometry'!$H$43*'Geometry'!$F$43+((MAX(MIN(S_1_Es*($R8+$S8*'Geometry'!$G$44+$T8*'Geometry'!$F$44),S_1_fy),-S_1_fy))-(IF(($R8+$S8*'Geometry'!$G$44+$T8*'Geometry'!$F$44)>0,IF(($R8+$S8*'Geometry'!$G$44+$T8*'Geometry'!$F$44)<=C_eco,C_alpha*C_fck*(1-(1-($R8+$S8*'Geometry'!$G$44+$T8*'Geometry'!$F$44)/C_eco)^C_n),C_alpha*C_fck),0)))*'Geometry'!$H$44*'Geometry'!$F$44+((MAX(MIN(S_1_Es*($R8+$S8*'Geometry'!$G$45+$T8*'Geometry'!$F$45),S_1_fy),-S_1_fy))-(IF(($R8+$S8*'Geometry'!$G$45+$T8*'Geometry'!$F$45)>0,IF(($R8+$S8*'Geometry'!$G$45+$T8*'Geometry'!$F$45)<=C_eco,C_alpha*C_fck*(1-(1-($R8+$S8*'Geometry'!$G$45+$T8*'Geometry'!$F$45)/C_eco)^C_n),C_alpha*C_fck),0)))*'Geometry'!$H$45*'Geometry'!$F$45+((MAX(MIN(S_1_Es*($R8+$S8*'Geometry'!$G$46+$T8*'Geometry'!$F$46),S_1_fy),-S_1_fy))-(IF(($R8+$S8*'Geometry'!$G$46+$T8*'Geometry'!$F$46)>0,IF(($R8+$S8*'Geometry'!$G$46+$T8*'Geometry'!$F$46)<=C_eco,C_alpha*C_fck*(1-(1-($R8+$S8*'Geometry'!$G$46+$T8*'Geometry'!$F$46)/C_eco)^C_n),C_alpha*C_fck),0)))*'Geometry'!$H$46*'Geometry'!$F$46+((MAX(MIN(S_1_Es*($R8+$S8*'Geometry'!$G$47+$T8*'Geometry'!$F$47),S_1_fy),-S_1_fy))-(IF(($R8+$S8*'Geometry'!$G$47+$T8*'Geometry'!$F$47)>0,IF(($R8+$S8*'Geometry'!$G$47+$T8*'Geometry'!$F$47)<=C_eco,C_alpha*C_fck*(1-(1-($R8+$S8*'Geometry'!$G$47+$T8*'Geometry'!$F$47)/C_eco)^C_n),C_alpha*C_fck),0)))*'Geometry'!$H$47*'Geometry'!$F$47+((MAX(MIN(S_1_Es*($R8+$S8*'Geometry'!$G$48+$T8*'Geometry'!$F$48),S_1_fy),-S_1_fy))-(IF(($R8+$S8*'Geometry'!$G$48+$T8*'Geometry'!$F$48)>0,IF(($R8+$S8*'Geometry'!$G$48+$T8*'Geometry'!$F$48)<=C_eco,C_alpha*C_fck*(1-(1-($R8+$S8*'Geometry'!$G$48+$T8*'Geometry'!$F$48)/C_eco)^C_n),C_alpha*C_fck),0)))*'Geometry'!$H$48*'Geometry'!$F$48+((MAX(MIN(S_1_Es*($R8+$S8*'Geometry'!$G$49+$T8*'Geometry'!$F$49),S_1_fy),-S_1_fy))-(IF(($R8+$S8*'Geometry'!$G$49+$T8*'Geometry'!$F$49)>0,IF(($R8+$S8*'Geometry'!$G$49+$T8*'Geometry'!$F$49)<=C_eco,C_alpha*C_fck*(1-(1-($R8+$S8*'Geometry'!$G$49+$T8*'Geometry'!$F$49)/C_eco)^C_n),C_alpha*C_fck),0)))*'Geometry'!$H$49*'Geometry'!$F$49+((MAX(MIN(S_1_Es*($R8+$S8*'Geometry'!$G$50+$T8*'Geometry'!$F$50),S_1_fy),-S_1_fy))-(IF(($R8+$S8*'Geometry'!$G$50+$T8*'Geometry'!$F$50)>0,IF(($R8+$S8*'Geometry'!$G$50+$T8*'Geometry'!$F$50)<=C_eco,C_alpha*C_fck*(1-(1-($R8+$S8*'Geometry'!$G$50+$T8*'Geometry'!$F$50)/C_eco)^C_n),C_alpha*C_fck),0)))*'Geometry'!$H$50*'Geometry'!$F$50+((MAX(MIN(S_1_Es*($R8+$S8*'Geometry'!$G$51+$T8*'Geometry'!$F$51),S_1_fy),-S_1_fy))-(IF(($R8+$S8*'Geometry'!$G$51+$T8*'Geometry'!$F$51)>0,IF(($R8+$S8*'Geometry'!$G$51+$T8*'Geometry'!$F$51)<=C_eco,C_alpha*C_fck*(1-(1-($R8+$S8*'Geometry'!$G$51+$T8*'Geometry'!$F$51)/C_eco)^C_n),C_alpha*C_fck),0)))*'Geometry'!$H$51*'Geometry'!$F$51+((MAX(MIN(S_1_Es*($R8+$S8*'Geometry'!$G$52+$T8*'Geometry'!$F$52),S_1_fy),-S_1_fy))-(IF(($R8+$S8*'Geometry'!$G$52+$T8*'Geometry'!$F$52)>0,IF(($R8+$S8*'Geometry'!$G$52+$T8*'Geometry'!$F$52)<=C_eco,C_alpha*C_fck*(1-(1-($R8+$S8*'Geometry'!$G$52+$T8*'Geometry'!$F$52)/C_eco)^C_n),C_alpha*C_fck),0)))*'Geometry'!$H$52*'Geometry'!$F$52+((MAX(MIN(S_1_Es*($R8+$S8*'Geometry'!$G$53+$T8*'Geometry'!$F$53),S_1_fy),-S_1_fy))-(IF(($R8+$S8*'Geometry'!$G$53+$T8*'Geometry'!$F$53)>0,IF(($R8+$S8*'Geometry'!$G$53+$T8*'Geometry'!$F$53)<=C_eco,C_alpha*C_fck*(1-(1-($R8+$S8*'Geometry'!$G$53+$T8*'Geometry'!$F$53)/C_eco)^C_n),C_alpha*C_fck),0)))*'Geometry'!$H$53*'Geometry'!$F$53+((MAX(MIN(S_1_Es*($R8+$S8*'Geometry'!$G$54+$T8*'Geometry'!$F$54),S_1_fy),-S_1_fy))-(IF(($R8+$S8*'Geometry'!$G$54+$T8*'Geometry'!$F$54)>0,IF(($R8+$S8*'Geometry'!$G$54+$T8*'Geometry'!$F$54)<=C_eco,C_alpha*C_fck*(1-(1-($R8+$S8*'Geometry'!$G$54+$T8*'Geometry'!$F$54)/C_eco)^C_n),C_alpha*C_fck),0)))*'Geometry'!$H$54*'Geometry'!$F$54+((MAX(MIN(S_1_Es*($R8+$S8*'Geometry'!$G$55+$T8*'Geometry'!$F$55),S_1_fy),-S_1_fy))-(IF(($R8+$S8*'Geometry'!$G$55+$T8*'Geometry'!$F$55)>0,IF(($R8+$S8*'Geometry'!$G$55+$T8*'Geometry'!$F$55)<=C_eco,C_alpha*C_fck*(1-(1-($R8+$S8*'Geometry'!$G$55+$T8*'Geometry'!$F$55)/C_eco)^C_n),C_alpha*C_fck),0)))*'Geometry'!$H$55*'Geometry'!$F$55+((MAX(MIN(S_1_Es*($R8+$S8*'Geometry'!$G$56+$T8*'Geometry'!$F$56),S_1_fy),-S_1_fy))-(IF(($R8+$S8*'Geometry'!$G$56+$T8*'Geometry'!$F$56)>0,IF(($R8+$S8*'Geometry'!$G$56+$T8*'Geometry'!$F$56)<=C_eco,C_alpha*C_fck*(1-(1-($R8+$S8*'Geometry'!$G$56+$T8*'Geometry'!$F$56)/C_eco)^C_n),C_alpha*C_fck),0)))*'Geometry'!$H$56*'Geometry'!$F$56+((MAX(MIN(S_1_Es*($R8+$S8*'Geometry'!$G$57+$T8*'Geometry'!$F$57),S_1_fy),-S_1_fy))-(IF(($R8+$S8*'Geometry'!$G$57+$T8*'Geometry'!$F$57)>0,IF(($R8+$S8*'Geometry'!$G$57+$T8*'Geometry'!$F$57)<=C_eco,C_alpha*C_fck*(1-(1-($R8+$S8*'Geometry'!$G$57+$T8*'Geometry'!$F$57)/C_eco)^C_n),C_alpha*C_fck),0)))*'Geometry'!$H$57*'Geometry'!$F$57)/1000000 -> -5.5879354e-14 | AA8: =U8+X8 -> 33981.434 | AB8: =V8+Y8 -> 7.4505806e-15 | AC8: =W8+Z8 -> 1.8998981e-13 | AD8: 0.52 | AE8: 1 | AF8: =AA8*AD8 -> 17670.346 | AG8: =AB8*AE8 -> 0 | AH8: =AC8*AE8 -> 0 | AI8: 17670.346 | AJ8: 0 | AK8: 0 | AL8: =AF8-AI8 -> 0 | AM8: =SQRT((AG8-AJ8)^2+(AH8-AK8)^2) -> 0 | AN8: mesh formula | AO8: 33981.434 | AP8: 7.4505806e-15 | AQ8: 1.8998981e-13 | AR8: 28560 | AS8: 7.4505806e-15 | AT8: 2.4586916e-13 | AU8: 5421.4339 | AV8: 0 | AW8: -5.5879354e-14
A9: 2 | B9: c/D = 3 | C9: =$AF$9 -> 17670.346 | D9: =$AG$9*COS(RADIANS($C$5))+$AH$9*SIN(RADIANS($C$5)) -> 344.96662 | G9: 10-station-1|0.17453292519943295|1 | H9: c/D = 3 | I9: 10 | J9: c/D | K9: 3 | L9: =MAX(('Geometry'!$G$13*COS(RADIANS(I9))+'Geometry'!$F$13*SIN(RADIANS(I9))),('Geometry'!$G$14*COS(RADIANS(I9))+'Geometry'!$F$14*SIN(RADIANS(I9))),('Geometry'!$G$15*COS(RADIANS(I9))+'Geometry'!$F$15*SIN(RADIANS(I9))),('Geometry'!$G$16*COS(RADIANS(I9))+'Geometry'!$F$16*SIN(RADIANS(I9))),('Geometry'!$G$17*COS(RADIANS(I9))+'Geometry'!$F$17*SIN(RADIANS(I9))),('Geometry'!$G$18*COS(RADIANS(I9))+'Geometry'!$F$18*SIN(RADIANS(I9))),('Geometry'!$G$19*COS(RADIANS(I9))+'Geometry'!$F$19*SIN(RADIANS(I9))),('Geometry'!$G$20*COS(RADIANS(I9))+'Geometry'!$F$20*SIN(RADIANS(I9)))) -> 686.39115 | M9: =L9-K9*N9 -> -3431.9557 | N9: =L9-MIN(('Geometry'!$G$13*COS(RADIANS(I9))+'Geometry'!$F$13*SIN(RADIANS(I9))),('Geometry'!$G$14*COS(RADIANS(I9))+'Geometry'!$F$14*SIN(RADIANS(I9))),('Geometry'!$G$15*COS(RADIANS(I9))+'Geometry'!$F$15*SIN(RADIANS(I9))),('Geometry'!$G$16*COS(RADIANS(I9))+'Geometry'!$F$16*SIN(RADIANS(I9))),('Geometry'!$G$17*COS(RADIANS(I9))+'Geometry'!$F$17*SIN(RADIANS(I9))),('Geometry'!$G$18*COS(RADIANS(I9))+'Geometry'!$F$18*SIN(RADIANS(I9))),('Geometry'!$G$19*COS(RADIANS(I9))+'Geometry'!$F$19*SIN(RADIANS(I9))),('Geometry'!$G$20*COS(RADIANS(I9))+'Geometry'!$F$20*SIN(RADIANS(I9)))) -> 1372.7823 | O9: =C_ecu -> 0.0033 | P9: =0 -> 0 | Q9: =IF(ABS(L9-M9)<0.000000000001,0,(O9-P9)/(L9-M9)) -> 8.0129238e-07 | R9: =O9-Q9*L9 -> 0.00275 | S9: =Q9*COS(RADIANS(I9)) -> 7.8911895e-07 | T9: =Q9*SIN(RADIANS(I9)) -> 1.3914296e-07 | U9: =SUMPRODUCT(C_alpha*C_fck*(1-(1-((($R9+$S9*Mesh_Y+$T9*Mesh_X))*(($R9+$S9*Mesh_Y+$T9*Mesh_X)>0)*(($R9+$S9*Mesh_Y+$T9*Mesh_X)<C_eco)+C_eco*(($R9+$S9*Mesh_Y+$T9*Mesh_X)>=C_eco))/C_eco)^C_n)*((($R9+$S9*Mesh_Y+$T9*Mesh_X))>0),Mesh_A)/1000 -> 28560 | V9: =SUMPRODUCT(C_alpha*C_fck*(1-(1-((($R9+$S9*Mesh_Y+$T9*Mesh_X))*(($R9+$S9*Mesh_Y+$T9*Mesh_X)>0)*(($R9+$S9*Mesh_Y+$T9*Mesh_X)<C_eco)+C_eco*(($R9+$S9*Mesh_Y+$T9*Mesh_X)>=C_eco))/C_eco)^C_n)*((($R9+$S9*Mesh_Y+$T9*Mesh_X))>0),Mesh_A,Mesh_Y)/1000000 -> 7.4505806e-15 | W9: =SUMPRODUCT(C_alpha*C_fck*(1-(1-((($R9+$S9*Mesh_Y+$T9*Mesh_X))*(($R9+$S9*Mesh_Y+$T9*Mesh_X)>0)*(($R9+$S9*Mesh_Y+$T9*Mesh_X)<C_eco)+C_eco*(($R9+$S9*Mesh_Y+$T9*Mesh_X)>=C_eco))/C_eco)^C_n)*((($R9+$S9*Mesh_Y+$T9*Mesh_X))>0),Mesh_A,Mesh_X)/1000000 -> 2.4586916e-13 | X9: =(((MAX(MIN(S_1_Es*($R9+$S9*'Geometry'!$G$40+$T9*'Geometry'!$F$40),S_1_fy),-S_1_fy))-(IF(($R9+$S9*'Geometry'!$G$40+$T9*'Geometry'!$F$40)>0,IF(($R9+$S9*'Geometry'!$G$40+$T9*'Geometry'!$F$40)<=C_eco,C_alpha*C_fck*(1-(1-($R9+$S9*'Geometry'!$G$40+$T9*'Geometry'!$F$40)/C_eco)^C_n),C_alpha*C_fck),0)))*'Geometry'!$H$40+((MAX(MIN(S_1_Es*($R9+$S9*'Geometry'!$G$41+$T9*'Geometry'!$F$41),S_1_fy),-S_1_fy))-(IF(($R9+$S9*'Geometry'!$G$41+$T9*'Geometry'!$F$41)>0,IF(($R9+$S9*'Geometry'!$G$41+$T9*'Geometry'!$F$41)<=C_eco,C_alpha*C_fck*(1-(1-($R9+$S9*'Geometry'!$G$41+$T9*'Geometry'!$F$41)/C_eco)^C_n),C_alpha*C_fck),0)))*'Geometry'!$H$41+((MAX(MIN(S_1_Es*($R9+$S9*'Geometry'!$G$42+$T9*'Geometry'!$F$42),S_1_fy),-S_1_fy))-(IF(($R9+$S9*'Geometry'!$G$42+$T9*'Geometry'!$F$42)>0,IF(($R9+$S9*'Geometry'!$G$42+$T9*'Geometry'!$F$42)<=C_eco,C_alpha*C_fck*(1-(1-($R9+$S9*'Geometry'!$G$42+$T9*'Geometry'!$F$42)/C_eco)^C_n),C_alpha*C_fck),0)))*'Geometry'!$H$42+((MAX(MIN(S_1_Es*($R9+$S9*'Geometry'!$G$43+$T9*'Geometry'!$F$43),S_1_fy),-S_1_fy))-(IF(($R9+$S9*'Geometry'!$G$43+$T9*'Geometry'!$F$43)>0,IF(($R9+$S9*'Geometry'!$G$43+$T9*'Geometry'!$F$43)<=C_eco,C_alpha*C_fck*(1-(1-($R9+$S9*'Geometry'!$G$43+$T9*'Geometry'!$F$43)/C_eco)^C_n),C_alpha*C_fck),0)))*'Geometry'!$H$43+((MAX(MIN(S_1_Es*($R9+$S9*'Geometry'!$G$44+$T9*'Geometry'!$F$44),S_1_fy),-S_1_fy))-(IF(($R9+$S9*'Geometry'!$G$44+$T9*'Geometry'!$F$44)>0,IF(($R9+$S9*'Geometry'!$G$44+$T9*'Geometry'!$F$44)<=C_eco,C_alpha*C_fck*(1-(1-($R9+$S9*'Geometry'!$G$44+$T9*'Geometry'!$F$44)/C_eco)^C_n),C_alpha*C_fck),0)))*'Geometry'!$H$44+((MAX(MIN(S_1_Es*($R9+$S9*'Geometry'!$G$45+$T9*'Geometry'!$F$45),S_1_fy),-S_1_fy))-(IF(($R9+$S9*'Geometry'!$G$45+$T9*'Geometry'!$F$45)>0,IF(($R9+$S9*'Geometry'!$G$45+$T9*'Geometry'!$F$45)<=C_eco,C_alpha*C_fck*(1-(1-($R9+$S9*'Geometry'!$G$45+$T9*'Geometry'!$F$45)/C_eco)^C_n),C_alpha*C_fck),0)))*'Geometry'!$H$45+((MAX(MIN(S_1_Es*($R9+$S9*'Geometry'!$G$46+$T9*'Geometry'!$F$46),S_1_fy),-S_1_fy))-(IF(($R9+$S9*'Geometry'!$G$46+$T9*'Geometry'!$F$46)>0,IF(($R9+$S9*'Geometry'!$G$46+$T9*'Geometry'!$F$46)<=C_eco,C_alpha*C_fck*(1-(1-($R9+$S9*'Geometry'!$G$46+$T9*'Geometry'!$F$46)/C_eco)^C_n),C_alpha*C_fck),0)))*'Geometry'!$H$46+((MAX(MIN(S_1_Es*($R9+$S9*'Geometry'!$G$47+$T9*'Geometry'!$F$47),S_1_fy),-S_1_fy))-(IF(($R9+$S9*'Geometry'!$G$47+$T9*'Geometry'!$F$47)>0,IF(($R9+$S9*'Geometry'!$G$47+$T9*'Geometry'!$F$47)<=C_eco,C_alpha*C_fck*(1-(1-($R9+$S9*'Geometry'!$G$47+$T9*'Geometry'!$F$47)/C_eco)^C_n),C_alpha*C_fck),0)))*'Geometry'!$H$47+((MAX(MIN(S_1_Es*($R9+$S9*'Geometry'!$G$48+$T9*'Geometry'!$F$48),S_1_fy),-S_1_fy))-(IF(($R9+$S9*'Geometry'!$G$48+$T9*'Geometry'!$F$48)>0,IF(($R9+$S9*'Geometry'!$G$48+$T9*'Geometry'!$F$48)<=C_eco,C_alpha*C_fck*(1-(1-($R9+$S9*'Geometry'!$G$48+$T9*'Geometry'!$F$48)/C_eco)^C_n),C_alpha*C_fck),0)))*'Geometry'!$H$48+((MAX(MIN(S_1_Es*($R9+$S9*'Geometry'!$G$49+$T9*'Geometry'!$F$49),S_1_fy),-S_1_fy))-(IF(($R9+$S9*'Geometry'!$G$49+$T9*'Geometry'!$F$49)>0,IF(($R9+$S9*'Geometry'!$G$49+$T9*'Geometry'!$F$49)<=C_eco,C_alpha*C_fck*(1-(1-($R9+$S9*'Geometry'!$G$49+$T9*'Geometry'!$F$49)/C_eco)^C_n),C_alpha*C_fck),0)))*'Geometry'!$H$49+((MAX(MIN(S_1_Es*($R9+$S9*'Geometry'!$G$50+$T9*'Geometry'!$F$50),S_1_fy),-S_1_fy))-(IF(($R9+$S9*'Geometry'!$G$50+$T9*'Geometry'!$F$50)>0,IF(($R9+$S9*'Geometry'!$G$50+$T9*'Geometry'!$F$50)<=C_eco,C_alpha*C_fck*(1-(1-($R9+$S9*'Geometry'!$G$50+$T9*'Geometry'!$F$50)/C_eco)^C_n),C_alpha*C_fck),0)))*'Geometry'!$H$50+((MAX(MIN(S_1_Es*($R9+$S9*'Geometry'!$G$51+$T9*'Geometry'!$F$51),S_1_fy),-S_1_fy))-(IF(($R9+$S9*'Geometry'!$G$51+$T9*'Geometry'!$F$51)>0,IF(($R9+$S9*'Geometry'!$G$51+$T9*'Geometry'!$F$51)<=C_eco,C_alpha*C_fck*(1-(1-($R9+$S9*'Geometry'!$G$51+$T9*'Geometry'!$F$51)/C_eco)^C_n),C_alpha*C_fck),0)))*'Geometry'!$H$51+((MAX(MIN(S_1_Es*($R9+$S9*'Geometry'!$G$52+$T9*'Geometry'!$F$52),S_1_fy),-S_1_fy))-(IF(($R9+$S9*'Geometry'!$G$52+$T9*'Geometry'!$F$52)>0,IF(($R9+$S9*'Geometry'!$G$52+$T9*'Geometry'!$F$52)<=C_eco,C_alpha*C_fck*(1-(1-($R9+$S9*'Geometry'!$G$52+$T9*'Geometry'!$F$52)/C_eco)^C_n),C_alpha*C_fck),0)))*'Geometry'!$H$52+((MAX(MIN(S_1_Es*($R9+$S9*'Geometry'!$G$53+$T9*'Geometry'!$F$53),S_1_fy),-S_1_fy))-(IF(($R9+$S9*'Geometry'!$G$53+$T9*'Geometry'!$F$53)>0,IF(($R9+$S9*'Geometry'!$G$53+$T9*'Geometry'!$F$53)<=C_eco,C_alpha*C_fck*(1-(1-($R9+$S9*'Geometry'!$G$53+$T9*'Geometry'!$F$53)/C_eco)^C_n),C_alpha*C_fck),0)))*'Geometry'!$H$53+((MAX(MIN(S_1_Es*($R9+$S9*'Geometry'!$G$54+$T9*'Geometry'!$F$54),S_1_fy),-S_1_fy))-(IF(($R9+$S9*'Geometry'!$G$54+$T9*'Geometry'!$F$54)>0,IF(($R9+$S9*'Geometry'!$G$54+$T9*'Geometry'!$F$54)<=C_eco,C_alpha*C_fck*(1-(1-($R9+$S9*'Geometry'!$G$54+$T9*'Geometry'!$F$54)/C_eco)^C_n),C_alpha*C_fck),0)))*'Geometry'!$H$54+((MAX(MIN(S_1_Es*($R9+$S9*'Geometry'!$G$55+$T9*'Geometry'!$F$55),S_1_fy),-S_1_fy))-(IF(($R9+$S9*'Geometry'!$G$55+$T9*'Geometry'!$F$55)>0,IF(($R9+$S9*'Geometry'!$G$55+$T9*'Geometry'!$F$55)<=C_eco,C_alpha*C_fck*(1-(1-($R9+$S9*'Geometry'!$G$55+$T9*'Geometry'!$F$55)/C_eco)^C_n),C_alpha*C_fck),0)))*'Geometry'!$H$55+((MAX(MIN(S_1_Es*($R9+$S9*'Geometry'!$G$56+$T9*'Geometry'!$F$56),S_1_fy),-S_1_fy))-(IF(($R9+$S9*'Geometry'!$G$56+$T9*'Geometry'!$F$56)>0,IF(($R9+$S9*'Geometry'!$G$56+$T9*'Geometry'!$F$56)<=C_eco,C_alpha*C_fck*(1-(1-($R9+$S9*'Geometry'!$G$56+$T9*'Geometry'!$F$56)/C_eco)^C_n),C_alpha*C_fck),0)))*'Geometry'!$H$56+((MAX(MIN(S_1_Es*($R9+$S9*'Geometry'!$G$57+$T9*'Geometry'!$F$57),S_1_fy),-S_1_fy))-(IF(($R9+$S9*'Geometry'!$G$57+$T9*'Geometry'!$F$57)>0,IF(($R9+$S9*'Geometry'!$G$57+$T9*'Geometry'!$F$57)<=C_eco,C_alpha*C_fck*(1-(1-($R9+$S9*'Geometry'!$G$57+$T9*'Geometry'!$F$57)/C_eco)^C_n),C_alpha*C_fck),0)))*'Geometry'!$H$57)/1000 -> 5421.4339 | Y9: =(((MAX(MIN(S_1_Es*($R9+$S9*'Geometry'!$G$40+$T9*'Geometry'!$F$40),S_1_fy),-S_1_fy))-(IF(($R9+$S9*'Geometry'!$G$40+$T9*'Geometry'!$F$40)>0,IF(($R9+$S9*'Geometry'!$G$40+$T9*'Geometry'!$F$40)<=C_eco,C_alpha*C_fck*(1-(1-($R9+$S9*'Geometry'!$G$40+$T9*'Geometry'!$F$40)/C_eco)^C_n),C_alpha*C_fck),0)))*'Geometry'!$H$40*'Geometry'!$G$40+((MAX(MIN(S_1_Es*($R9+$S9*'Geometry'!$G$41+$T9*'Geometry'!$F$41),S_1_fy),-S_1_fy))-(IF(($R9+$S9*'Geometry'!$G$41+$T9*'Geometry'!$F$41)>0,IF(($R9+$S9*'Geometry'!$G$41+$T9*'Geometry'!$F$41)<=C_eco,C_alpha*C_fck*(1-(1-($R9+$S9*'Geometry'!$G$41+$T9*'Geometry'!$F$41)/C_eco)^C_n),C_alpha*C_fck),0)))*'Geometry'!$H$41*'Geometry'!$G$41+((MAX(MIN(S_1_Es*($R9+$S9*'Geometry'!$G$42+$T9*'Geometry'!$F$42),S_1_fy),-S_1_fy))-(IF(($R9+$S9*'Geometry'!$G$42+$T9*'Geometry'!$F$42)>0,IF(($R9+$S9*'Geometry'!$G$42+$T9*'Geometry'!$F$42)<=C_eco,C_alpha*C_fck*(1-(1-($R9+$S9*'Geometry'!$G$42+$T9*'Geometry'!$F$42)/C_eco)^C_n),C_alpha*C_fck),0)))*'Geometry'!$H$42*'Geometry'!$G$42+((MAX(MIN(S_1_Es*($R9+$S9*'Geometry'!$G$43+$T9*'Geometry'!$F$43),S_1_fy),-S_1_fy))-(IF(($R9+$S9*'Geometry'!$G$43+$T9*'Geometry'!$F$43)>0,IF(($R9+$S9*'Geometry'!$G$43+$T9*'Geometry'!$F$43)<=C_eco,C_alpha*C_fck*(1-(1-($R9+$S9*'Geometry'!$G$43+$T9*'Geometry'!$F$43)/C_eco)^C_n),C_alpha*C_fck),0)))*'Geometry'!$H$43*'Geometry'!$G$43+((MAX(MIN(S_1_Es*($R9+$S9*'Geometry'!$G$44+$T9*'Geometry'!$F$44),S_1_fy),-S_1_fy))-(IF(($R9+$S9*'Geometry'!$G$44+$T9*'Geometry'!$F$44)>0,IF(($R9+$S9*'Geometry'!$G$44+$T9*'Geometry'!$F$44)<=C_eco,C_alpha*C_fck*(1-(1-($R9+$S9*'Geometry'!$G$44+$T9*'Geometry'!$F$44)/C_eco)^C_n),C_alpha*C_fck),0)))*'Geometry'!$H$44*'Geometry'!$G$44+((MAX(MIN(S_1_Es*($R9+$S9*'Geometry'!$G$45+$T9*'Geometry'!$F$45),S_1_fy),-S_1_fy))-(IF(($R9+$S9*'Geometry'!$G$45+$T9*'Geometry'!$F$45)>0,IF(($R9+$S9*'Geometry'!$G$45+$T9*'Geometry'!$F$45)<=C_eco,C_alpha*C_fck*(1-(1-($R9+$S9*'Geometry'!$G$45+$T9*'Geometry'!$F$45)/C_eco)^C_n),C_alpha*C_fck),0)))*'Geometry'!$H$45*'Geometry'!$G$45+((MAX(MIN(S_1_Es*($R9+$S9*'Geometry'!$G$46+$T9*'Geometry'!$F$46),S_1_fy),-S_1_fy))-(IF(($R9+$S9*'Geometry'!$G$46+$T9*'Geometry'!$F$46)>0,IF(($R9+$S9*'Geometry'!$G$46+$T9*'Geometry'!$F$46)<=C_eco,C_alpha*C_fck*(1-(1-($R9+$S9*'Geometry'!$G$46+$T9*'Geometry'!$F$46)/C_eco)^C_n),C_alpha*C_fck),0)))*'Geometry'!$H$46*'Geometry'!$G$46+((MAX(MIN(S_1_Es*($R9+$S9*'Geometry'!$G$47+$T9*'Geometry'!$F$47),S_1_fy),-S_1_fy))-(IF(($R9+$S9*'Geometry'!$G$47+$T9*'Geometry'!$F$47)>0,IF(($R9+$S9*'Geometry'!$G$47+$T9*'Geometry'!$F$47)<=C_eco,C_alpha*C_fck*(1-(1-($R9+$S9*'Geometry'!$G$47+$T9*'Geometry'!$F$47)/C_eco)^C_n),C_alpha*C_fck),0)))*'Geometry'!$H$47*'Geometry'!$G$47+((MAX(MIN(S_1_Es*($R9+$S9*'Geometry'!$G$48+$T9*'Geometry'!$F$48),S_1_fy),-S_1_fy))-(IF(($R9+$S9*'Geometry'!$G$48+$T9*'Geometry'!$F$48)>0,IF(($R9+$S9*'Geometry'!$G$48+$T9*'Geometry'!$F$48)<=C_eco,C_alpha*C_fck*(1-(1-($R9+$S9*'Geometry'!$G$48+$T9*'Geometry'!$F$48)/C_eco)^C_n),C_alpha*C_fck),0)))*'Geometry'!$H$48*'Geometry'!$G$48+((MAX(MIN(S_1_Es*($R9+$S9*'Geometry'!$G$49+$T9*'Geometry'!$F$49),S_1_fy),-S_1_fy))-(IF(($R9+$S9*'Geometry'!$G$49+$T9*'Geometry'!$F$49)>0,IF(($R9+$S9*'Geometry'!$G$49+$T9*'Geometry'!$F$49)<=C_eco,C_alpha*C_fck*(1-(1-($R9+$S9*'Geometry'!$G$49+$T9*'Geometry'!$F$49)/C_eco)^C_n),C_alpha*C_fck),0)))*'Geometry'!$H$49*'Geometry'!$G$49+((MAX(MIN(S_1_Es*($R9+$S9*'Geometry'!$G$50+$T9*'Geometry'!$F$50),S_1_fy),-S_1_fy))-(IF(($R9+$S9*'Geometry'!$G$50+$T9*'Geometry'!$F$50)>0,IF(($R9+$S9*'Geometry'!$G$50+$T9*'Geometry'!$F$50)<=C_eco,C_alpha*C_fck*(1-(1-($R9+$S9*'Geometry'!$G$50+$T9*'Geometry'!$F$50)/C_eco)^C_n),C_alpha*C_fck),0)))*'Geometry'!$H$50*'Geometry'!$G$50+((MAX(MIN(S_1_Es*($R9+$S9*'Geometry'!$G$51+$T9*'Geometry'!$F$51),S_1_fy),-S_1_fy))-(IF(($R9+$S9*'Geometry'!$G$51+$T9*'Geometry'!$F$51)>0,IF(($R9+$S9*'Geometry'!$G$51+$T9*'Geometry'!$F$51)<=C_eco,C_alpha*C_fck*(1-(1-($R9+$S9*'Geometry'!$G$51+$T9*'Geometry'!$F$51)/C_eco)^C_n),C_alpha*C_fck),0)))*'Geometry'!$H$51*'Geometry'!$G$51+((MAX(MIN(S_1_Es*($R9+$S9*'Geometry'!$G$52+$T9*'Geometry'!$F$52),S_1_fy),-S_1_fy))-(IF(($R9+$S9*'Geometry'!$G$52+$T9*'Geometry'!$F$52)>0,IF(($R9+$S9*'Geometry'!$G$52+$T9*'Geometry'!$F$52)<=C_eco,C_alpha*C_fck*(1-(1-($R9+$S9*'Geometry'!$G$52+$T9*'Geometry'!$F$52)/C_eco)^C_n),C_alpha*C_fck),0)))*'Geometry'!$H$52*'Geometry'!$G$52+((MAX(MIN(S_1_Es*($R9+$S9*'Geometry'!$G$53+$T9*'Geometry'!$F$53),S_1_fy),-S_1_fy))-(IF(($R9+$S9*'Geometry'!$G$53+$T9*'Geometry'!$F$53)>0,IF(($R9+$S9*'Geometry'!$G$53+$T9*'Geometry'!$F$53)<=C_eco,C_alpha*C_fck*(1-(1-($R9+$S9*'Geometry'!$G$53+$T9*'Geometry'!$F$53)/C_eco)^C_n),C_alpha*C_fck),0)))*'Geometry'!$H$53*'Geometry'!$G$53+((MAX(MIN(S_1_Es*($R9+$S9*'Geometry'!$G$54+$T9*'Geometry'!$F$54),S_1_fy),-S_1_fy))-(IF(($R9+$S9*'Geometry'!$G$54+$T9*'Geometry'!$F$54)>0,IF(($R9+$S9*'Geometry'!$G$54+$T9*'Geometry'!$F$54)<=C_eco,C_alpha*C_fck*(1-(1-($R9+$S9*'Geometry'!$G$54+$T9*'Geometry'!$F$54)/C_eco)^C_n),C_alpha*C_fck),0)))*'Geometry'!$H$54*'Geometry'!$G$54+((MAX(MIN(S_1_Es*($R9+$S9*'Geometry'!$G$55+$T9*'Geometry'!$F$55),S_1_fy),-S_1_fy))-(IF(($R9+$S9*'Geometry'!$G$55+$T9*'Geometry'!$F$55)>0,IF(($R9+$S9*'Geometry'!$G$55+$T9*'Geometry'!$F$55)<=C_eco,C_alpha*C_fck*(1-(1-($R9+$S9*'Geometry'!$G$55+$T9*'Geometry'!$F$55)/C_eco)^C_n),C_alpha*C_fck),0)))*'Geometry'!$H$55*'Geometry'!$G$55+((MAX(MIN(S_1_Es*($R9+$S9*'Geometry'!$G$56+$T9*'Geometry'!$F$56),S_1_fy),-S_1_fy))-(IF(($R9+$S9*'Geometry'!$G$56+$T9*'Geometry'!$F$56)>0,IF(($R9+$S9*'Geometry'!$G$56+$T9*'Geometry'!$F$56)<=C_eco,C_alpha*C_fck*(1-(1-($R9+$S9*'Geometry'!$G$56+$T9*'Geometry'!$F$56)/C_eco)^C_n),C_alpha*C_fck),0)))*'Geometry'!$H$56*'Geometry'!$G$56+((MAX(MIN(S_1_Es*($R9+$S9*'Geometry'!$G$57+$T9*'Geometry'!$F$57),S_1_fy),-S_1_fy))-(IF(($R9+$S9*'Geometry'!$G$57+$T9*'Geometry'!$F$57)>0,IF(($R9+$S9*'Geometry'!$G$57+$T9*'Geometry'!$F$57)<=C_eco,C_alpha*C_fck*(1-(1-($R9+$S9*'Geometry'!$G$57+$T9*'Geometry'!$F$57)/C_eco)^C_n),C_alpha*C_fck),0)))*'Geometry'!$H$57*'Geometry'!$G$57)/1000000 -> 0 | Z9: =(((MAX(MIN(S_1_Es*($R9+$S9*'Geometry'!$G$40+$T9*'Geometry'!$F$40),S_1_fy),-S_1_fy))-(IF(($R9+$S9*'Geometry'!$G$40+$T9*'Geometry'!$F$40)>0,IF(($R9+$S9*'Geometry'!$G$40+$T9*'Geometry'!$F$40)<=C_eco,C_alpha*C_fck*(1-(1-($R9+$S9*'Geometry'!$G$40+$T9*'Geometry'!$F$40)/C_eco)^C_n),C_alpha*C_fck),0)))*'Geometry'!$H$40*'Geometry'!$F$40+((MAX(MIN(S_1_Es*($R9+$S9*'Geometry'!$G$41+$T9*'Geometry'!$F$41),S_1_fy),-S_1_fy))-(IF(($R9+$S9*'Geometry'!$G$41+$T9*'Geometry'!$F$41)>0,IF(($R9+$S9*'Geometry'!$G$41+$T9*'Geometry'!$F$41)<=C_eco,C_alpha*C_fck*(1-(1-($R9+$S9*'Geometry'!$G$41+$T9*'Geometry'!$F$41)/C_eco)^C_n),C_alpha*C_fck),0)))*'Geometry'!$H$41*'Geometry'!$F$41+((MAX(MIN(S_1_Es*($R9+$S9*'Geometry'!$G$42+$T9*'Geometry'!$F$42),S_1_fy),-S_1_fy))-(IF(($R9+$S9*'Geometry'!$G$42+$T9*'Geometry'!$F$42)>0,IF(($R9+$S9*'Geometry'!$G$42+$T9*'Geometry'!$F$42)<=C_eco,C_alpha*C_fck*(1-(1-($R9+$S9*'Geometry'!$G$42+$T9*'Geometry'!$F$42)/C_eco)^C_n),C_alpha*C_fck),0)))*'Geometry'!$H$42*'Geometry'!$F$42+((MAX(MIN(S_1_Es*($R9+$S9*'Geometry'!$G$43+$T9*'Geometry'!$F$43),S_1_fy),-S_1_fy))-(IF(($R9+$S9*'Geometry'!$G$43+$T9*'Geometry'!$F$43)>0,IF(($R9+$S9*'Geometry'!$G$43+$T9*'Geometry'!$F$43)<=C_eco,C_alpha*C_fck*(1-(1-($R9+$S9*'Geometry'!$G$43+$T9*'Geometry'!$F$43)/C_eco)^C_n),C_alpha*C_fck),0)))*'Geometry'!$H$43*'Geometry'!$F$43+((MAX(MIN(S_1_Es*($R9+$S9*'Geometry'!$G$44+$T9*'Geometry'!$F$44),S_1_fy),-S_1_fy))-(IF(($R9+$S9*'Geometry'!$G$44+$T9*'Geometry'!$F$44)>0,IF(($R9+$S9*'Geometry'!$G$44+$T9*'Geometry'!$F$44)<=C_eco,C_alpha*C_fck*(1-(1-($R9+$S9*'Geometry'!$G$44+$T9*'Geometry'!$F$44)/C_eco)^C_n),C_alpha*C_fck),0)))*'Geometry'!$H$44*'Geometry'!$F$44+((MAX(MIN(S_1_Es*($R9+$S9*'Geometry'!$G$45+$T9*'Geometry'!$F$45),S_1_fy),-S_1_fy))-(IF(($R9+$S9*'Geometry'!$G$45+$T9*'Geometry'!$F$45)>0,IF(($R9+$S9*'Geometry'!$G$45+$T9*'Geometry'!$F$45)<=C_eco,C_alpha*C_fck*(1-(1-($R9+$S9*'Geometry'!$G$45+$T9*'Geometry'!$F$45)/C_eco)^C_n),C_alpha*C_fck),0)))*'Geometry'!$H$45*'Geometry'!$F$45+((MAX(MIN(S_1_Es*($R9+$S9*'Geometry'!$G$46+$T9*'Geometry'!$F$46),S_1_fy),-S_1_fy))-(IF(($R9+$S9*'Geometry'!$G$46+$T9*'Geometry'!$F$46)>0,IF(($R9+$S9*'Geometry'!$G$46+$T9*'Geometry'!$F$46)<=C_eco,C_alpha*C_fck*(1-(1-($R9+$S9*'Geometry'!$G$46+$T9*'Geometry'!$F$46)/C_eco)^C_n),C_alpha*C_fck),0)))*'Geometry'!$H$46*'Geometry'!$F$46+((MAX(MIN(S_1_Es*($R9+$S9*'Geometry'!$G$47+$T9*'Geometry'!$F$47),S_1_fy),-S_1_fy))-(IF(($R9+$S9*'Geometry'!$G$47+$T9*'Geometry'!$F$47)>0,IF(($R9+$S9*'Geometry'!$G$47+$T9*'Geometry'!$F$47)<=C_eco,C_alpha*C_fck*(1-(1-($R9+$S9*'Geometry'!$G$47+$T9*'Geometry'!$F$47)/C_eco)^C_n),C_alpha*C_fck),0)))*'Geometry'!$H$47*'Geometry'!$F$47+((MAX(MIN(S_1_Es*($R9+$S9*'Geometry'!$G$48+$T9*'Geometry'!$F$48),S_1_fy),-S_1_fy))-(IF(($R9+$S9*'Geometry'!$G$48+$T9*'Geometry'!$F$48)>0,IF(($R9+$S9*'Geometry'!$G$48+$T9*'Geometry'!$F$48)<=C_eco,C_alpha*C_fck*(1-(1-($R9+$S9*'Geometry'!$G$48+$T9*'Geometry'!$F$48)/C_eco)^C_n),C_alpha*C_fck),0)))*'Geometry'!$H$48*'Geometry'!$F$48+((MAX(MIN(S_1_Es*($R9+$S9*'Geometry'!$G$49+$T9*'Geometry'!$F$49),S_1_fy),-S_1_fy))-(IF(($R9+$S9*'Geometry'!$G$49+$T9*'Geometry'!$F$49)>0,IF(($R9+$S9*'Geometry'!$G$49+$T9*'Geometry'!$F$49)<=C_eco,C_alpha*C_fck*(1-(1-($R9+$S9*'Geometry'!$G$49+$T9*'Geometry'!$F$49)/C_eco)^C_n),C_alpha*C_fck),0)))*'Geometry'!$H$49*'Geometry'!$F$49+((MAX(MIN(S_1_Es*($R9+$S9*'Geometry'!$G$50+$T9*'Geometry'!$F$50),S_1_fy),-S_1_fy))-(IF(($R9+$S9*'Geometry'!$G$50+$T9*'Geometry'!$F$50)>0,IF(($R9+$S9*'Geometry'!$G$50+$T9*'Geometry'!$F$50)<=C_eco,C_alpha*C_fck*(1-(1-($R9+$S9*'Geometry'!$G$50+$T9*'Geometry'!$F$50)/C_eco)^C_n),C_alpha*C_fck),0)))*'Geometry'!$H$50*'Geometry'!$F$50+((MAX(MIN(S_1_Es*($R9+$S9*'Geometry'!$G$51+$T9*'Geometry'!$F$51),S_1_fy),-S_1_fy))-(IF(($R9+$S9*'Geometry'!$G$51+$T9*'Geometry'!$F$51)>0,IF(($R9+$S9*'Geometry'!$G$51+$T9*'Geometry'!$F$51)<=C_eco,C_alpha*C_fck*(1-(1-($R9+$S9*'Geometry'!$G$51+$T9*'Geometry'!$F$51)/C_eco)^C_n),C_alpha*C_fck),0)))*'Geometry'!$H$51*'Geometry'!$F$51+((MAX(MIN(S_1_Es*($R9+$S9*'Geometry'!$G$52+$T9*'Geometry'!$F$52),S_1_fy),-S_1_fy))-(IF(($R9+$S9*'Geometry'!$G$52+$T9*'Geometry'!$F$52)>0,IF(($R9+$S9*'Geometry'!$G$52+$T9*'Geometry'!$F$52)<=C_eco,C_alpha*C_fck*(1-(1-($R9+$S9*'Geometry'!$G$52+$T9*'Geometry'!$F$52)/C_eco)^C_n),C_alpha*C_fck),0)))*'Geometry'!$H$52*'Geometry'!$F$52+((MAX(MIN(S_1_Es*($R9+$S9*'Geometry'!$G$53+$T9*'Geometry'!$F$53),S_1_fy),-S_1_fy))-(IF(($R9+$S9*'Geometry'!$G$53+$T9*'Geometry'!$F$53)>0,IF(($R9+$S9*'Geometry'!$G$53+$T9*'Geometry'!$F$53)<=C_eco,C_alpha*C_fck*(1-(1-($R9+$S9*'Geometry'!$G$53+$T9*'Geometry'!$F$53)/C_eco)^C_n),C_alpha*C_fck),0)))*'Geometry'!$H$53*'Geometry'!$F$53+((MAX(MIN(S_1_Es*($R9+$S9*'Geometry'!$G$54+$T9*'Geometry'!$F$54),S_1_fy),-S_1_fy))-(IF(($R9+$S9*'Geometry'!$G$54+$T9*'Geometry'!$F$54)>0,IF(($R9+$S9*'Geometry'!$G$54+$T9*'Geometry'!$F$54)<=C_eco,C_alpha*C_fck*(1-(1-($R9+$S9*'Geometry'!$G$54+$T9*'Geometry'!$F$54)/C_eco)^C_n),C_alpha*C_fck),0)))*'Geometry'!$H$54*'Geometry'!$F$54+((MAX(MIN(S_1_Es*($R9+$S9*'Geometry'!$G$55+$T9*'Geometry'!$F$55),S_1_fy),-S_1_fy))-(IF(($R9+$S9*'Geometry'!$G$55+$T9*'Geometry'!$F$55)>0,IF(($R9+$S9*'Geometry'!$G$55+$T9*'Geometry'!$F$55)<=C_eco,C_alpha*C_fck*(1-(1-($R9+$S9*'Geometry'!$G$55+$T9*'Geometry'!$F$55)/C_eco)^C_n),C_alpha*C_fck),0)))*'Geometry'!$H$55*'Geometry'!$F$55+((MAX(MIN(S_1_Es*($R9+$S9*'Geometry'!$G$56+$T9*'Geometry'!$F$56),S_1_fy),-S_1_fy))-(IF(($R9+$S9*'Geometry'!$G$56+$T9*'Geometry'!$F$56)>0,IF(($R9+$S9*'Geometry'!$G$56+$T9*'Geometry'!$F$56)<=C_eco,C_alpha*C_fck*(1-(1-($R9+$S9*'Geometry'!$G$56+$T9*'Geometry'!$F$56)/C_eco)^C_n),C_alpha*C_fck),0)))*'Geometry'!$H$56*'Geometry'!$F$56+((MAX(MIN(S_1_Es*($R9+$S9*'Geometry'!$G$57+$T9*'Geometry'!$F$57),S_1_fy),-S_1_fy))-(IF(($R9+$S9*'Geometry'!$G$57+$T9*'Geometry'!$F$57)>0,IF(($R9+$S9*'Geometry'!$G$57+$T9*'Geometry'!$F$57)<=C_eco,C_alpha*C_fck*(1-(1-($R9+$S9*'Geometry'!$G$57+$T9*'Geometry'!$F$57)/C_eco)^C_n),C_alpha*C_fck),0)))*'Geometry'!$H$57*'Geometry'!$F$57)/1000000 -> -5.5879354e-14 | AA9: =U9+X9 -> 33981.434 | AB9: =V9+Y9 -> 7.4505806e-15 | AC9: =W9+Z9 -> 1.8998981e-13 | AD9: 0.52 | AE9: 0 | AF9: =AA9*AD9 -> 17670.346 | AG9: =AB9*AE9 -> 333.53729 | AH9: =AC9*AE9 -> 88.070562 | AI9: 17670.346 | AJ9: 333.53729 | AK9: 88.070562 | AL9: =AF9-AI9 -> 0 | AM9: =SQRT((AG9-AJ9)^2+(AH9-AK9)^2) -> 0 | AN9: mesh formula | AO9: 33981.434 | AP9: 7.4505806e-15 | AQ9: 1.8998981e-13 | AR9: 28560 | AS9: 7.4505806e-15 | AT9: 2.4586916e-13 | AU9: 5421.4339 | AV9: 0 | AW9: -5.5879354e-14
