Workbook
Name Origin_X: Geometry!$C$6
Name Origin_Y: Geometry!$C$7
Name Boundary_X: Geometry!$F$13:$F$36
Name Boundary_Y: Geometry!$G$13:$G$36
Name C_fck: Materials!$C$10
Name C_alpha: Materials!$C$12
Name C_eco: Materials!$C$13
Name C_n: Materials!$C$14
Name C_ecu: Materials!$C$15
Name S_1_fy: Materials!$D$20
Name S_1_Es: Materials!$E$20
Name Mesh_X: Mesh!$B$6:$B$425
Name Mesh_Y: Mesh!$C$6:$C$425
Name Mesh_A: Mesh!$D$6:$D$425
Name Selected_P: Result!$C$5

Sheet Geometry
A1: PROJECT GEOMETRY AND LOAD INPUTS
A2: Legend | B2: Editable calculation input | C2: Formula | D2: Generated / check | E2: Requires re-export / remesh
B3: Project | C3: PM-advanced (7) 2D reference case | F3: Client | G3: Reference verification
B4: Section | C4: PM-advanced (7) 2D — 1500x1200 chamfered section, two voids | F4: Company | G4: P-M Column Designer
B5: Calculation profile | C5: strain-domain-surface-v1 | F5: Designed by | G5: Engineering example
B6: Analysis origin X | C6: 0 | D6: mm | F6: Checked by | G6: Independent review
B7: Analysis origin Y | C7: 0 | D7: mm | F7: Address | G7: Seoul, Korea
F8: Date | G8: 2026-07-23
A12: Ring ID | B12: Boundary | C12: Point order | D12: X input (mm) | E12: Y input (mm) | F12: x local (mm) | G12: y local (mm)
A13: R1-OUTER | B13: Outer | C13: 1 | D13: -550 | E13: 600 | F13: =D13-Origin_X -> -550 | G13: =E13-Origin_Y -> 600
A14: R1-OUTER | B14: Outer | C14: 2 | D14: 550 | E14: 600 | F14: =D14-Origin_X -> 550 | G14: =E14-Origin_Y -> 600
A15: R1-OUTER | B15: Outer | C15: 3 | D15: 750 | E15: 400 | F15: =D15-Origin_X -> 750 | G15: =E15-Origin_Y -> 400
A16: R1-OUTER | B16: Outer | C16: 4 | D16: 750 | E16: -400 | F16: =D16-Origin_X -> 750 | G16: =E16-Origin_Y -> -400
A17: R1-OUTER | B17: Outer | C17: 5 | D17: 550 | E17: -600 | F17: =D17-Origin_X -> 550 | G17: =E17-Origin_Y -> -600
A18: R1-OUTER | B18: Outer | C18: 6 | D18: -550 | E18: -600 | F18: =D18-Origin_X -> -550 | G18: =E18-Origin_Y -> -600
A19: R1-OUTER | B19: Outer | C19: 7 | D19: -750 | E19: -400 | F19: =D19-Origin_X -> -750 | G19: =E19-Origin_Y -> -400
A20: R1-OUTER | B20: Outer | C20: 8 | D20: -750 | E20: 400 | F20: =D20-Origin_X -> -750 | G20: =E20-Origin_Y -> 400
A21: R1-H1 | B21: Hole | C21: 1 | D21: -450 | E21: 400 | F21: =D21-Origin_X -> -450 | G21: =E21-Origin_Y -> 400
A22: R1-H1 | B22: Hole | C22: 2 | D22: -250 | E22: 400 | F22: =D22-Origin_X -> -250 | G22: =E22-Origin_Y -> 400
A23: R1-H1 | B23: Hole | C23: 3 | D23: -150 | E23: 300 | F23: =D23-Origin_X -> -150 | G23: =E23-Origin_Y -> 300
A24: R1-H1 | B24: Hole | C24: 4 | D24: -150 | E24: -300 | F24: =D24-Origin_X -> -150 | G24: =E24-Origin_Y -> -300
... A36: R1-H2 | B36: Hole | C36: 8 | D36: 150 | E36: 300 | F36: =D36-Origin_X -> 150 | G36: =E36-Origin_Y -> 300
B38: Reinforcement
A39: No. | B39: Rebar ID | C39: Diameter (mm) | D39: X world (mm) | E39: Y world (mm) | F39: X local (mm) | G39: Y local (mm) | H39: Area (mm²) | I39: Steel material ID
A40: 1 | B40: 1 | C40: 32 | D40: -400 | E40: 530 | F40: =D40-Origin_X -> -400 | G40: =E40-Origin_Y -> 530 | H40: =PI()*C40^2/4 -> 804.24772 | I40: 1
A41: 2 | B41: 2 | C41: 32 | D41: -200 | E41: 530 | F41: =D41-Origin_X -> -200 | G41: =E41-Origin_Y -> 530 | H41: =PI()*C41^2/4 -> 804.24772 | I41: 1
A42: 3 | B42: 3 | C42: 32 | D42: 0 | E42: 530 | F42: =D42-Origin_X -> 0 | G42: =E42-Origin_Y -> 530 | H42: =PI()*C42^2/4 -> 804.24772 | I42: 1
A43: 4 | B43: 4 | C43: 32 | D43: 200 | E43: 530 | F43: =D43-Origin_X -> 200 | G43: =E43-Origin_Y -> 530 | H43: =PI()*C43^2/4 -> 804.24772 | I43: 1
A44: 5 | B44: 5 | C44: 32 | D44: 400 | E44: 530 | F44: =D44-Origin_X -> 400 | G44: =E44-Origin_Y -> 530 | H44: =PI()*C44^2/4 -> 804.24772 | I44: 1
A45: 6 | B45: 6 | C45: 32 | D45: -400 | E45: -530 | F45: =D45-Origin_X -> -400 | G45: =E45-Origin_Y -> -530 | H45: =PI()*C45^2/4 -> 804.24772 | I45: 1
A46: 7 | B46: 7 | C46: 32 | D46: -200 | E46: -530 | F46: =D46-Origin_X -> -200 | G46: =E46-Origin_Y -> -530 | H46: =PI()*C46^2/4 -> 804.24772 | I46: 1
A47: 8 | B47: 8 | C47: 32 | D47: 0 | E47: -530 | F47: =D47-Origin_X -> 0 | G47: =E47-Origin_Y -> -530 | H47: =PI()*C47^2/4 -> 804.24772 | I47: 1
A48: 9 | B48: 9 | C48: 32 | D48: 200 | E48: -530 | F48: =D48-Origin_X -> 200 | G48: =E48-Origin_Y -> -530 | H48: =PI()*C48^2/4 -> 804.24772 | I48: 1
A49: 10 | B49: 10 | C49: 32 | D49: 400 | E49: -530 | F49: =D49-Origin_X -> 400 | G49: =E49-Origin_Y -> -530 | H49: =PI()*C49^2/4 -> 804.24772 | I49: 1
A50: 11 | B50: 11 | C50: 32 | D50: -680 | E50: 300 | F50: =D50-Origin_X -> -680 | G50: =E50-Origin_Y -> 300 | H50: =PI()*C50^2/4 -> 804.24772 | I50: 1
A51: 12 | B51: 12 | C51: 32 | D51: -680 | E51: 100 | F51: =D51-Origin_X -> -680 | G51: =E51-Origin_Y -> 100 | H51: =PI()*C51^2/4 -> 804.24772 | I51: 1
... A57: 18 | B57: 18 | C57: 32 | D57: 680 | E57: -300 | F57: =D57-Origin_X -> 680 | G57: =E57-Origin_Y -> -300 | H57: =PI()*C57^2/4 -> 804.24772 | I57: 1
B61: Project load cases
A62: ID | B62: Name | C62: P (kN) | D62: Mx (kN·m) | E62: My (kN·m) | F62: Action basis
A63: 1 | B63: ULS-1 workbook Newton demand (on the 15 deg surface) | C63: 24942.922 | D63: 3714.1659 | E63: 1431.7807 | F63: factoredULS
...

Sheet Materials
A1: MATERIALS AND RESISTANCE BASIS
A2: Legend | B2: Editable calculation input | C2: Formula | D2: Generated / check | E2: Requires re-export / remesh
A3: Active result stage | B3: Design resistance | D3: Calculation profile | E3: KDS 2024 current set · resistance: KDS 14 20 10:2021 + KDS 14 20 20:2022
B5: Concrete
A6: Symbol | B6: Parameter | C6: Value | D6: Unit | E6: Basis / use in calculation
B7: Material | C7: KDS C30 (workbook Input)
B8: Standard | C8: KDS
B9: Stress–strain law | C9: kds-parabolic
A10: f′c / fck | B10: Specified concrete compressive strength | C10: 30 | D10: MPa | E10: Strength used by the active material law
A11: Eᴄ | B11: Elastic modulus | C11: 28417.475 | D11: MPa | E11: Concrete elastic modulus reported by the selected standard
A12: α | B12: Concrete stress coefficient | C12: 0.85 | D12: – | E12: Multiplier applied to the concrete compression stress
A13: εc0 | B13: Peak / plateau strain | C13: 0.002 | D13: – | E13: End of the parabolic branch
A14: n | B14: Parabola exponent | C14: 2 | D14: – | E14: Exponent of the concrete stress–strain curve
A15: εcu | B15: Ultimate compression strain | C15: 0.0033 | D15: – | E15: Compression strain used at the neutral-axis boundary state
B16: Calculation law | C16: KDS parabola-rectangle: fc = α·fck·(1−(1−ε/εco)^n) up to εco, then α·fck
B18: Reinforcing steel
A19: ID | B19: Material | C19: Standard | D19: fy (MPa) | E19: Eₛ (MPa) | F19: εy | G19: εu | H19: Stress–strain law
A20: 1 | B20: SD400 (workbook Input) | C20: KDS | D20: 400 | E20: 200000 | F20: =D20/E20 -> 0.002 | H20: elastic-perfectly-plastic
B24: Resistance basis
A25: Symbol / setting | B25: Parameter | C25: Value | D25: Unit | E25: Code basis / note
B26: Resistance format | C26: globalResultantFactor | D26: –
B27: Active result stage | C27: design | D27: –
B28: Profile | C28: kds-2024-current-set | D28: – | E28: KDS 2024 current set · resistance: KDS 14 20 10:2021 + KDS 14 20 20:2022
B29: Transverse reinforcement | C29: other | D29: –
A30: φc | B30: Compression-controlled strength factor | C30: 0.65 | D30: –
A31: φt | B31: Tension-controlled strength factor | C31: 0.85 | D31: –
A32: Pmax | B32: Axial compression limit enabled | C32: Yes | D32: –
A33: Pmax/P0 | B33: Axial compression limit ratio | C33: 0.8 | D33: –
A34: εt | B34: Tension-controlled transition rule | C34: fixed 0.005; high-strength 2.5·εy | D34: –
A36: Blue text marks editable values that drive formulas. Orange text marks settings that require re-export because they change the generated surface or mesh.

Sheet Mesh
A1: CONCRETE INTEGRATION MESH
B2: X and Y are measured from the analysis origin. Area is the quadrature weight used directly by Result SUMPRODUCT formulas.
B3: Cell size (mm) | C3: 150 | D3: Points | E3: 420 | F3: Area error | G3: 4.6566129e-10
A4: Legend | B4: Editable calculation input | C4: Formula | D4: Generated / check | E4: Requires re-export / remesh
A5: No. | B5: X local (mm) | C5: Y local (mm) | D5: Area (mm²) | E5: Component | F5: X world (mm) | G5: Y world (mm)
A6: 1 | B6: -666.66667 | C6: -466.66667 | D6: 1666.6667 | E6: 0 | F6: =B6+Origin_X -> -666.66667 | G6: =C6+Origin_Y -> -466.66667
A7: 2 | B7: -616.66667 | C7: -516.66667 | D7: 1666.6667 | E7: 0 | F7: =B7+Origin_X -> -616.66667 | G7: =C7+Origin_Y -> -516.66667
A8: 3 | B8: -616.66667 | C8: -466.66667 | D8: 1666.6667 | E8: 0 | F8: =B8+Origin_X -> -616.66667 | G8: =C8+Origin_Y -> -466.66667
A9: 4 | B9: -741.66667 | C9: -341.66667 | D9: 833.33333 | E9: 1 | F9: =B9+Origin_X -> -741.66667 | G9: =C9+Origin_Y -> -341.66667
A10: 5 | B10: -741.66667 | C10: -391.66667 | D10: 833.33333 | E10: 1 | F10: =B10+Origin_X -> -741.66667 | G10: =C10+Origin_Y -> -391.66667
A11: 6 | B11: -716.66667 | C11: -416.66667 | D11: 833.33333 | E11: 1 | F11: =B11+Origin_X -> -716.66667 | G11: =C11+Origin_Y -> -416.66667
A12: 7 | B12: -716.66667 | C12: -350 | D12: 2500 | E12: 1 | F12: =B12+Origin_X -> -716.66667 | G12: =C12+Origin_Y -> -350
A13: 8 | B13: -691.66667 | C13: -425 | D13: 2500 | E13: 1 | F13: =B13+Origin_X -> -691.66667 | G13: =C13+Origin_Y -> -425
A14: 9 | B14: -641.66667 | C14: -425 | D14: 2500 | E14: 1 | F14: =B14+Origin_X -> -641.66667 | G14: =C14+Origin_Y -> -425
A15: 10 | B15: -625 | C15: -400 | D15: 3750 | E15: 1 | F15: =B15+Origin_X -> -625 | G15: =C15+Origin_Y -> -400
A16: 11 | B16: -625 | C16: -325 | D16: 3750 | E16: 1 | F16: =B16+Origin_X -> -625 | G16: =C16+Origin_Y -> -325
A17: 12 | B17: -700 | C17: -325 | D17: 3750 | E17: 1 | F17: =B17+Origin_X -> -700 | G17: =C17+Origin_Y -> -325
... A425: 420 | B425: 616.66667 | C425: 516.66667 | D425: 1666.6667 | E425: 63 | F425: =B425+Origin_X -> 616.66667 | G425: =C425+Origin_Y -> 516.66667

Sheet FixedP_Lower
A1: FIXED-P LOWER BRACKETING STATIONS
B2: Each row is one direction-specific bracket station. Physical stress-strain rows use Materials/Mesh formulas; geometric axial-cap and equivalent-block rows are explicitly labelled ledger anchors.
B3: Selected P (kN) | C3: =Selected_P -> 17670.346 | D3: Bracket role | E3: P below or exact
A6: Legend | B6: Editable calculation input | C6: Formula | D6: Generated / check | E6: Requires re-export / remesh
A7: Direction ID | B7: Branch | C7: Chart β (deg) | D7: Source key | E7: Station / role | F7: β strain (deg) | G7: Criterion basis | H7: Criterion value | I7: zc (mm) | J7: z control (mm) | K7: D (mm) | L7: εc | M7: ε control | N7: κ (1/mm) | O7: ε₀ | P7: κx (1/mm) | Q7: κy (1/mm) | R7: Concrete P | S7: Concrete Mx | T7: Concrete My | U7: Steel P | V7: Steel Mx | W7: Steel My | X7: Base P | Y7: Base Mx | Z7: Base My | AA7: P factor | AB7: Mx factor | AC7: My factor | AD7: Final P | AE7: Final Mx | AF7: Final My | AG7: Engine P | AH7: Engine Mx | AI7: Engine My | AJ7: ΔP | AK7: ΔM | AL7: Calculation mode | AM7: Base engine P | AN7: Base engine Mx | AO7: Base engine My | AP7: Concrete engine P | AQ7: Concrete engine Mx | AR7: Concrete engine My | AS7: Steel engine P | AT7: Steel engine Mx | AU7: Steel engine My
A8: fixedP-b0.000-branch1 | B8: 1 | C8: 0 | D8: 0-pure-compression|0|0 | E8: P below — pure-compression | F8: 0 | G8: retained ε = constant (not the cap rule) | H8: 0.0033 | I8: =MAX(('Geometry'!$G$13*COS(RADIANS(F8))+'Geometry'!$F$13*SIN(RADIANS(F8))),('Geometry'!$G$14*COS(RADIANS(F8))+'Geometry'!$F$14*SIN(RADIANS(F8))),('Geometry'!$G$15*COS(RADIANS(F8))+'Geometry'!$F$15*SIN(RADIANS(F8))),('Geometry'!$G$16*COS(RADIANS(F8))+'Geometry'!$F$16*SIN(RADIANS(F8))),('Geometry'!$G$17*COS(RADIANS(F8))+'Geometry'!$F$17*SIN(RADIANS(F8))),('Geometry'!$G$18*COS(RADIANS(F8))+'Geometry'!$F$18*SIN(RADIANS(F8))),('Geometry'!$G$19*COS(RADIANS(F8))+'Geometry'!$F$19*SIN(RADIANS(F8))),('Geometry'!$G$20*COS(RADIANS(F8))+'Geometry'!$F$20*SIN(RADIANS(F8)))) -> 600 | J8: =I8 -> -530 | K8: =I8-MIN(('Geometry'!$G$13*COS(RADIANS(F8))+'Geometry'!$F$13*SIN(RADIANS(F8))),('Geometry'!$G$14*COS(RADIANS(F8))+'Geometry'!$F$14*SIN(RADIANS(F8))),('Geometry'!$G$15*COS(RADIANS(F8))+'Geometry'!$F$15*SIN(RADIANS(F8))),('Geometry'!$G$16*COS(RADIANS(F8))+'Geometry'!$F$16*SIN(RADIANS(F8))),('Geometry'!$G$17*COS(RADIANS(F8))+'Geometry'!$F$17*SIN(RADIANS(F8))),('Geometry'!$G$18*COS(RADIANS(F8))+'Geometry'!$F$18*SIN(RADIANS(F8))),('Geometry'!$G$19*COS(RADIANS(F8))+'Geometry'!$F$19*SIN(RADIANS(F8))),('Geometry'!$G$20*COS(RADIANS(F8))+'Geometry'!$F$20*SIN(RADIANS(F8)))) -> 1200 | L8: =H8 -> 0.0033 | M8: =H8 -> 0.0033 | N8: =0 -> 0 | O8: =H8 -> 0.0033 | P8: =N8*COS(RADIANS(F8)) -> 0 | Q8: =N8*SIN(RADIANS(F8)) -> 0 | R8: =AP8 -> 15240.061 | S8: =AQ8 -> 0 | T8: =AR8 -> 0 | U8: =AS8 -> 2430.2851 | V8: =AT8 -> 0 | W8: =AU8 -> 0 | X8: =AM8 -> 17670.346 | Y8: =AN8 -> 0 | Z8: =AO8 -> 0 | AA8: 1 | AB8: 1 | AC8: 1 | AD8: =X8*AA8 -> 17670.346 | AE8: =Y8*AB8 -> 0 | AF8: =Z8*AC8 -> 0 | AG8: 17670.346 | AH8: 0 | AI8: 0 | AJ8: =AD8-AG8 -> 0 | AK8: =SQRT((AE8-AH8)^2+(AF8-AI8)^2) -> 0 | AL8: axial-cap projected-ledger anchor (geometric Pmax face) | AM8: 17670.346 | AN8: 0 | AO8: 0 | AP8: 15240.061 | AQ8: 0 | AR8: 0 | AS8: 2430.2851 | AT8: 0 | AU8: 0
A9: fixedP-b0.000-branch2 | B9: 2 | C9: 0 | D9: 0-station-1|0|1 | E9: P below — station-1 | F9: 0 | G9: retained c/D (not the cap rule) | H9: 3 | I9: =MAX(('Geometry'!$G$13*COS(RADIANS(F9))+'Geometry'!$F$13*SIN(RADIANS(F9))),('Geometry'!$G$14*COS(RADIANS(F9))+'Geometry'!$F$14*SIN(RADIANS(F9))),('Geometry'!$G$15*COS(RADIANS(F9))+'Geometry'!$F$15*SIN(RADIANS(F9))),('Geometry'!$G$16*COS(RADIANS(F9))+'Geometry'!$F$16*SIN(RADIANS(F9))),('Geometry'!$G$17*COS(RADIANS(F9))+'Geometry'!$F$17*SIN(RADIANS(F9))),('Geometry'!$G$18*COS(RADIANS(F9))+'Geometry'!$F$18*SIN(RADIANS(F9))),('Geometry'!$G$19*COS(RADIANS(F9))+'Geometry'!$F$19*SIN(RADIANS(F9))),('Geometry'!$G$20*COS(RADIANS(F9))+'Geometry'!$F$20*SIN(RADIANS(F9)))) -> 600 | J9: =I9-H9*K9 -> -3000 | K9: =I9-MIN(('Geometry'!$G$13*COS(RADIANS(F9))+'Geometry'!$F$13*SIN(RADIANS(F9))),('Geometry'!$G$14*COS(RADIANS(F9))+'Geometry'!$F$14*SIN(RADIANS(F9))),('Geometry'!$G$15*COS(RADIANS(F9))+'Geometry'!$F$15*SIN(RADIANS(F9))),('Geometry'!$G$16*COS(RADIANS(F9))+'Geometry'!$F$16*SIN(RADIANS(F9))),('Geometry'!$G$17*COS(RADIANS(F9))+'Geometry'!$F$17*SIN(RADIANS(F9))),('Geometry'!$G$18*COS(RADIANS(F9))+'Geometry'!$F$18*SIN(RADIANS(F9))),('Geometry'!$G$19*COS(RADIANS(F9))+'Geometry'!$F$19*SIN(RADIANS(F9))),('Geometry'!$G$20*COS(RADIANS(F9))+'Geometry'!$F$20*SIN(RADIANS(F9)))) -> 1200 | L9: =C_ecu -> 0.0033 | M9: =0 -> 0 | N9: =IF(ABS(I9-J9)<0.000000000001,0,(L9-M9)/(I9-J9)) -> 9.1666667e-07 | O9: =L9-N9*I9 -> 0.00275 | P9: =N9*COS(RADIANS(F9)) -> 9.1666667e-07 | Q9: =N9*SIN(RADIANS(F9)) -> 0 | R9: =AP9 -> 15240.061 | S9: =AQ9 -> 285.94652 | T9: =AR9 -> 0.0021480206 | U9: =AS9 -> 2430.2851 | V9: =AT9 -> 93.442542 | W9: =AU9 -> 5.8792249e-16 | X9: =AM9 -> 17670.346 | Y9: =AN9 -> 379.38907 | Z9: =AO9 -> 0.0021480206 | AA9: 1 | AB9: 1 | AC9: 1 | AD9: =X9*AA9 -> 17670.346 | AE9: =Y9*AB9 -> 379.38907 | AF9: =Z9*AC9 -> 0.0021480206 | AG9: 17670.346 | AH9: 379.38907 | AI9: 0.0021480206 | AJ9: =AD9-AG9 -> 0 | AK9: =SQRT((AE9-AH9)^2+(AF9-AI9)^2) -> 0 | AL9: axial-cap projected-ledger anchor (geometric Pmax face) | AM9: 17670.346 | AN9: 379.38907 | AO9: 0.0021480206 | AP9: 15240.061 | AQ9: 285.94652 | AR9: 0.0021480206 | AS9: 2430.2851 | AT9: 93.442542 | AU9: 5.8792249e-16
A10: fixedP-b0.000-branch3 | B10: 3 | C10: 0 | D10: 0-station-2|0|2 | E10: P below — station-2 | F10: 0 | G10: retained c/D (not the cap rule) | H10: 2 | I10: =MAX(('Geometry'!$G$13*COS(RADIANS(F10))+'Geometry'!$F$13*SIN(RADIANS(F10))),('Geometry'!$G$14*COS(RADIANS(F10))+'Geometry'!$F$14*SIN(RADIANS(F10))),('Geometry'!$G$15*COS(RADIANS(F10))+'Geometry'!$F$15*SIN(RADIANS(F10))),('Geometry'!$G$16*COS(RADIANS(F10))+'Geometry'!$F$16*SIN(RADIANS(F10))),('Geometry'!$G$17*COS(RADIANS(F10))+'Geometry'!$F$17*SIN(RADIANS(F10))),('Geometry'!$G$18*COS(RADIANS(F10))+'Geometry'!$F$18*SIN(RADIANS(F10))),('Geometry'!$G$19*COS(RADIANS(F10))+'Geometry'!$F$19*SIN(RADIANS(F10))),('Geometry'!$G$20*COS(RADIANS(F10))+'Geometry'!$F$20*SIN(RADIANS(F10)))) -> 600 | J10: =I10-H10*K10 -> -1800 | K10: =I10-MIN(('Geometry'!$G$13*COS(RADIANS(F10))+'Geometry'!$F$13*SIN(RADIANS(F10))),('Geometry'!$G$14*COS(RADIANS(F10))+'Geometry'!$F$14*SIN(RADIANS(F10))),('Geometry'!$G$15*COS(RADIANS(F10))+'Geometry'!$F$15*SIN(RADIANS(F10))),('Geometry'!$G$16*COS(RADIANS(F10))+'Geometry'!$F$16*SIN(RADIANS(F10))),('Geometry'!$G$17*COS(RADIANS(F10))+'Geometry'!$F$17*SIN(RADIANS(F10))),('Geometry'!$G$18*COS(RADIANS(F10))+'Geometry'!$F$18*SIN(RADIANS(F10))),('Geometry'!$G$19*COS(RADIANS(F10))+'Geometry'!$F$19*SIN(RADIANS(F10))),('Geometry'!$G$20*COS(RADIANS(F10))+'Geometry'!$F$20*SIN(RADIANS(F10)))) -> 1200 | L10: =C_ecu -> 0.0033 | M10: =0 -> 0 | N10: =IF(ABS(I10-J10)<0.000000000001,0,(L10-M10)/(I10-J10)) -> 1.375e-06 | O10: =L10-N10*I10 -> 0.002475 | P10: =N10*COS(RADIANS(F10)) -> 1.375e-06 | Q10: =N10*SIN(RADIANS(F10)) -> 0 | R10: =AP10 -> 15240.061 | S10: =AQ10 -> 571.89305 | T10: =AR10 -> 0.0042960413 | U10: =AS10 -> 2430.2851 | V10: =AT10 -> 186.88508 | W10: =AU10 -> 1.175845e-15 | X10: =AM10 -> 17670.346 | Y10: =AN10 -> 758.77813 | Z10: =AO10 -> 0.0042960413 | AA10: 1 | AB10: 1 | AC10: 1 | AD10: =X10*AA10 -> 17670.346 | AE10: =Y10*AB10 -> 758.77813 | AF10: =Z10*AC10 -> 0.0042960413 | AG10: 17670.346 | AH10: 758.77813 | AI10: 0.0042960413 | AJ10: =AD10-AG10 -> 0 | AK10: =SQRT((AE10-AH10)^2+(AF10-AI10)^2) -> 0 | AL10: axial-cap projected-ledger anchor (geometric Pmax face) | AM10: 17670.346 | AN10: 758.77813 | AO10: 0.0042960413 | AP10: 15240.061 | AQ10: 571.89305 | AR10: 0.0042960413 | AS10: 2430.2851 | AT10: 186.88508 | AU10: 1.175845e-15
A11: fixedP-b0.000-branch4 | B11: 4 | C11: 0 | D11: 0-station-3|0|3 | E11: P below — station-3 | F11: 0 | G11: retained c/D (not the cap rule) | H11: 1.5 | I11: =MAX(('Geometry'!$G$13*COS(RADIANS(F11))+'Geometry'!$F$13*SIN(RADIANS(F11))),('Geometry'!$G$14*COS(RADIANS(F11))+'Geometry'!$F$14*SIN(RADIANS(F11))),('Geometry'!$G$15*COS(RADIANS(F11))+'Geometry'!$F$15*SIN(RADIANS(F11))),('Geometry'!$G$16*COS(RADIANS(F11))+'Geometry'!$F$16*SIN(RADIANS(F11))),('Geometry'!$G$17*COS(RADIANS(F11))+'Geometry'!$F$17*SIN(RADIANS(F11))),('Geometry'!$G$18*COS(RADIANS(F11))+'Geometry'!$F$18*SIN(RADIANS(F11))),('Geometry'!$G$19*COS(RADIANS(F11))+'Geometry'!$F$19*SIN(RADIANS(F11))),('Geometry'!$G$20*COS(RADIANS(F11))+'Geometry'!$F$20*SIN(RADIANS(F11)))) -> 600 | J11: =I11-H11*K11 -> -1200 | K11: =I11-MIN(('Geometry'!$G$13*COS(RADIANS(F11))+'Geometry'!$F$13*SIN(RADIANS(F11))),('Geometry'!$G$14*COS(RADIANS(F11))+'Geometry'!$F$14*SIN(RADIANS(F11))),('Geometry'!$G$15*COS(RADIANS(F11))+'Geometry'!$F$15*SIN(RADIANS(F11))),('Geometry'!$G$16*COS(RADIANS(F11))+'Geometry'!$F$16*SIN(RADIANS(F11))),('Geometry'!$G$17*COS(RADIANS(F11))+'Geometry'!$F$17*SIN(RADIANS(F11))),('Geometry'!$G$18*COS(RADIANS(F11))+'Geometry'!$F$18*SIN(RADIANS(F11))),('Geometry'!$G$19*COS(RADIANS(F11))+'Geometry'!$F$19*SIN(RADIANS(F11))),('Geometry'!$G$20*COS(RADIANS(F11))+'Geometry'!$F$20*SIN(RADIANS(F11)))) -> 1200 | L11: =C_ecu -> 0.0033 | M11: =0 -> 0 | N11: =IF(ABS(I11-J11)<0.000000000001,0,(L11-M11)/(I11-J11)) -> 1.8333333e-06 | O11: =L11-N11*I11 -> 0.0022 | P11: =N11*COS(RADIANS(F11)) -> 1.8333333e-06 | Q11: =N11*SIN(RADIANS(F11)) -> 0 | R11: =AP11 -> 15240.061 | S11: =AQ11 -> 857.83957 | T11: =AR11 -> 0.0064440619 | U11: =AS11 -> 2430.2851 | V11: =AT11 -> 280.32763 | W11: =AU11 -> 1.7637675e-15 | X11: =AM11 -> 17670.346 | Y11: =AN11 -> 1138.1672 | Z11: =AO11 -> 0.0064440619 | AA11: 1 | AB11: 1 | AC11: 1 | AD11: =X11*AA11 -> 17670.346 | AE11: =Y11*AB11 -> 1138.1672 | AF11: =Z11*AC11 -> 0.0064440619 | AG11: 17670.346 | AH11: 1138.1672 | AI11: 0.0064440619 | AJ11: =AD11-AG11 -> 0 | AK11: =SQRT((AE11-AH11)^2+(AF11-AI11)^2) -> 0 | AL11: axial-cap projected-ledger anchor (geometric Pmax face) | AM11: 17670.346 | AN11: 1138.1672 | AO11: 0.0064440619 | AP11: 15240.061 | AQ11: 857.83957 | AR11: 0.0064440619 | AS11: 2430.2851 | AT11: 280.32763 | AU11: 1.7637675e-15
A12: fixedP-b0.000-branch5 | B12: 5 | C12: 0 | D12: 0-station-4|0|4 | E12: P below — station-4 | F12: 0 | G12: retained c/D (not the cap rule) | H12: 1.2 | I12: =MAX(('Geometry'!$G$13*COS(RADIANS(F12))+'Geometry'!$F$13*SIN(RADIANS(F12))),('Geometry'!$G$14*COS(RADIANS(F12))+'Geometry'!$F$14*SIN(RADIANS(F12))),('Geometry'!$G$15*COS(RADIANS(F12))+'Geometry'!$F$15*SIN(RADIANS(F12))),('Geometry'!$G$16*COS(RADIANS(F12))+'Geometry'!$F$16*SIN(RADIANS(F12))),('Geometry'!$G$17*COS(RADIANS(F12))+'Geometry'!$F$17*SIN(RADIANS(F12))),('Geometry'!$G$18*COS(RADIANS(F12))+'Geometry'!$F$18*SIN(RADIANS(F12))),('Geometry'!$G$19*COS(RADIANS(F12))+'Geometry'!$F$19*SIN(RADIANS(F12))),('Geometry'!$G$20*COS(RADIANS(F12))+'Geometry'!$F$20*SIN(RADIANS(F12)))) -> 600 | J12: =I12-H12*K12 -> -840 | K12: =I12-MIN(('Geometry'!$G$13*COS(RADIANS(F12))+'Geometry'!$F$13*SIN(RADIANS(F12))),('Geometry'!$G$14*COS(RADIANS(F12))+'Geometry'!$F$14*SIN(RADIANS(F12))),('Geometry'!$G$15*COS(RADIANS(F12))+'Geometry'!$F$15*SIN(RADIANS(F12))),('Geometry'!$G$16*COS(RADIANS(F12))+'Geometry'!$F$16*SIN(RADIANS(F12))),('Geometry'!$G$17*COS(RADIANS(F12))+'Geometry'!$F$17*SIN(RADIANS(F12))),('Geometry'!$G$18*COS(RADIANS(F12))+'Geometry'!$F$18*SIN(RADIANS(F12))),('Geometry'!$G$19*COS(RADIANS(F12))+'Geometry'!$F$19*SIN(RADIANS(F12))),('Geometry'!$G$20*COS(RADIANS(F12))+'Geometry'!$F$20*SIN(RADIANS(F12)))) -> 1200 | L12: =C_ecu -> 0.0033 | M12: =0 -> 0 | N12: =IF(ABS(I12-J12)<0.000000000001,0,(L12-M12)/(I12-J12)) -> 2.2916667e-06 | O12: =L12-N12*I12 -> 0.001925 | P12: =N12*COS(RADIANS(F12)) -> 2.2916667e-06 | Q12: =N12*SIN(RADIANS(F12)) -> 0 | R12: =AP12 -> 15240.061 | S12: =AQ12 -> 1143.7861 | T12: =AR12 -> 0.0085920826 | U12: =AS12 -> 2430.2851 | V12: =AT12 -> 373.77017 | W12: =AU12 -> 2.35169e-15 | X12: =AM12 -> 17670.346 | Y12: =AN12 -> 1517.5563 | Z12: =AO12 -> 0.0085920826 | AA12: 1 | AB12: 1 | AC12: 1 | AD12: =X12*AA12 -> 17670.346 | AE12: =Y12*AB12 -> 1517.5563 | AF12: =Z12*AC12 -> 0.0085920826 | AG12: 17670.346 | AH12: 1517.5563 | AI12: 0.0085920826 | AJ12: =AD12-AG12 -> 0 | AK12: =SQRT((AE12-AH12)^2+(AF12-AI12)^2) -> 0 | AL12: axial-cap projected-ledger anchor (geometric Pmax face) | AM12: 17670.346 | AN12: 1517.5563 | AO12: 0.0085920826 | AP12: 15240.061 | AQ12: 1143.7861 | AR12: 0.0085920826 | AS12: 2430.2851 | AT12: 373.77017 | AU12: 2.35169e-15
A13: fixedP-b0.000-branch6 | B13: 6 | C13: 0 | D13: 0-station-5|0|5 | E13: P below — station-5 | F13: 0 | G13: retained c/D (not the cap rule) | H13: 1.1 | I13: =MAX(('Geometry'!$G$13*COS(RADIANS(F13))+'Geometry'!$F$13*SIN(RADIANS(F13))),('Geometry'!$G$14*COS(RADIANS(F13))+'Geometry'!$F$14*SIN(RADIANS(F13))),('Geometry'!$G$15*COS(RADIANS(F13))+'Geometry'!$F$15*SIN(RADIANS(F13))),('Geometry'!$G$16*COS(RADIANS(F13))+'Geometry'!$F$16*SIN(RADIANS(F13))),('Geometry'!$G$17*COS(RADIANS(F13))+'Geometry'!$F$17*SIN(RADIANS(F13))),('Geometry'!$G$18*COS(RADIANS(F13))+'Geometry'!$F$18*SIN(RADIANS(F13))),('Geometry'!$G$19*COS(RADIANS(F13))+'Geometry'!$F$19*SIN(RADIANS(F13))),('Geometry'!$G$20*COS(RADIANS(F13))+'Geometry'!$F$20*SIN(RADIANS(F13)))) -> 600 | J13: =I13-H13*K13 -> -720 | K13: =I13-MIN(('Geometry'!$G$13*COS(RADIANS(F13))+'Geometry'!$F$13*SIN(RADIANS(F13))),('Geometry'!$G$14*COS(RADIANS(F13))+'Geometry'!$F$14*SIN(RADIANS(F13))),('Geometry'!$G$15*COS(RADIANS(F13))+'Geometry'!$F$15*SIN(RADIANS(F13))),('Geometry'!$G$16*COS(RADIANS(F13))+'Geometry'!$F$16*SIN(RADIANS(F13))),('Geometry'!$G$17*COS(RADIANS(F13))+'Geometry'!$F$17*SIN(RADIANS(F13))),('Geometry'!$G$18*COS(RADIANS(F13))+'Geometry'!$F$18*SIN(RADIANS(F13))),('Geometry'!$G$19*COS(RADIANS(F13))+'Geometry'!$F$19*SIN(RADIANS(F13))),('Geometry'!$G$20*COS(RADIANS(F13))+'Geometry'!$F$20*SIN(RADIANS(F13)))) -> 1200 | L13: =C_ecu -> 0.0033 | M13: =0 -> 0 | N13: =IF(ABS(I13-J13)<0.000000000001,0,(L13-M13)/(I13-J13)) -> 2.5e-06 | O13: =L13-N13*I13 -> 0.0018 | P13: =N13*COS(RADIANS(F13)) -> 2.5e-06 | Q13: =N13*SIN(RADIANS(F13)) -> 0 | R13: =AP13 -> 15240.061 | S13: =AQ13 -> 1429.7326 | T13: =AR13 -> 0.010740103 | U13: =AS13 -> 2430.2851 | V13: =AT13 -> 467.21271 | W13: =AU13 -> 2.9396125e-15 | X13: =AM13 -> 17670.346 | Y13: =AN13 -> 1896.9453 | Z13: =AO13 -> 0.010740103 | AA13: 1 | AB13: 1 | AC13: 1 | AD13: =X13*AA13 -> 17670.346 | AE13: =Y13*AB13 -> 1896.9453 | AF13: =Z13*AC13 -> 0.010740103 | AG13: 17670.346 | AH13: 1896.9453 | AI13: 0.010740103 | AJ13: =AD13-AG13 -> 0 | AK13: =SQRT((AE13-AH13)^2+(AF13-AI13)^2) -> 0 | AL13: axial-cap projected-ledger anchor (geometric Pmax face) | AM13: 17670.346 | AN13: 1896.9453 | AO13: 0.010740103 | AP13: 15240.061 | AQ13: 1429.7326 | AR13: 0.010740103 | AS13: 2430.2851 | AT13: 467.21271 | AU13: 2.9396125e-15
A14: fixedP-b10.000-branch1 | B14: 1 | C14: 10 | D14: 10-station-1|0.17453292519943295|1 | E14: P below — station-1 | F14: 10 | G14: retained c/D (not the cap rule) | H14: 3 | I14: =MAX(('Geometry'!$G$13*COS(RADIANS(F14))+'Geometry'!$F$13*SIN(RADIANS(F14))),('Geometry'!$G$14*COS(RADIANS(F14))+'Geometry'!$F$14*SIN(RADIANS(F14))),('Geometry'!$G$15*COS(RADIANS(F14))+'Geometry'!$F$15*SIN(RADIANS(F14))),('Geometry'!$G$16*COS(RADIANS(F14))+'Geometry'!$F$16*SIN(RADIANS(F14))),('Geometry'!$G$17*COS(RADIANS(F14))+'Geometry'!$F$17*SIN(RADIANS(F14))),('Geometry'!$G$18*COS(RADIANS(F14))+'Geometry'!$F$18*SIN(RADIANS(F14))),('Geometry'!$G$19*COS(RADIANS(F14))+'Geometry'!$F$19*SIN(RADIANS(F14))),('Geometry'!$G$20*COS(RADIANS(F14))+'Geometry'!$F$20*SIN(RADIANS(F14)))) -> 686.39115 | J14: =I14-H14*K14 -> -3431.9557 | K14: =I14-MIN(('Geometry'!$G$13*COS(RADIANS(F14))+'Geometry'!$F$13*SIN(RADIANS(F14))),('Geometry'!$G$14*COS(RADIANS(F14))+'Geometry'!$F$14*SIN(RADIANS(F14))),('Geometry'!$G$15*COS(RADIANS(F14))+'Geometry'!$F$15*SIN(RADIANS(F14))),('Geometry'!$G$16*COS(RADIANS(F14))+'Geometry'!$F$16*SIN(RADIANS(F14))),('Geometry'!$G$17*COS(RADIANS(F14))+'Geometry'!$F$17*SIN(RADIANS(F14))),('Geometry'!$G$18*COS(RADIANS(F14))+'Geometry'!$F$18*SIN(RADIANS(F14))),('Geometry'!$G$19*COS(RADIANS(F14))+'Geometry'!$F$19*SIN(RADIANS(F14))),('Geometry'!$G$20*COS(RADIANS(F14))+'Geometry'!$F$20*SIN(RADIANS(F14)))) -> 1372.7823 | L14: =C_ecu -> 0.0033 | M14: =0 -> 0 | N14: =IF(ABS(I14-J14)<0.000000000001,0,(L14-M14)/(I14-J14)) -> 8.0129238e-07 | O14: =L14-N14*I14 -> 0.00275 | P14: =N14*COS(RADIANS(F14)) -> 7.8911895e-07 | Q14: =N14*SIN(RADIANS(F14)) -> 1.3914296e-07 | R14: =AP14 -> 15258.271 | S14: =AQ14 -> 251.17873 | T14: =AR14 -> 67.969118 | U14: =AS14 -> 2412.0743 | V14: =AT14 -> 82.358562 | W14: =AU14 -> 20.101444 | X14: =AM14 -> 17670.346 | Y14: =AN14 -> 333.53729 | Z14: =AO14 -> 88.070562 | AA14: 1 | AB14: 1 | AC14: 1 | AD14: =X14*AA14 -> 17670.346 | AE14: =Y14*AB14 -> 333.53729 | AF14: =Z14*AC14 -> 88.070562 | AG14: 17670.346 | AH14: 333.53729 | AI14: 88.070562 | AJ14: =AD14-AG14 -> 0 | AK14: =SQRT((AE14-AH14)^2+(AF14-AI14)^2) -> 0 | AL14: axial-cap projected-ledger anchor (geometric Pmax face) | AM14: 17670.346 | AN14: 333.53729 | AO14: 88.070562 | AP14: 15258.271 | AQ14: 251.17873 | AR14: 67.969118 | AS14: 2412.0743 | AT14: 82.358562 | AU14: 20.101444
A15: fixedP-b10.000-branch2 | B15: 2 | C15: 10 | D15: 10-station-2|0.17453292519943295|2 | E15: P below — station-2 | F15: 10 | G15: retained c/D (not the cap rule) | H15: 2 | I15: =MAX(('Geometry'!$G$13*COS(RADIANS(F15))+'Geometry'!$F$13*SIN(RADIANS(F15))),('Geometry'!$G$14*COS(RADIANS(F15))+'Geometry'!$F$14*SIN(RADIANS(F15))),('Geometry'!$G$15*COS(RADIANS(F15))+'Geometry'!$F$15*SIN(RADIANS(F15))),('Geometry'!$G$16*COS(RADIANS(F15))+'Geometry'!$F$16*SIN(RADIANS(F15))),('Geometry'!$G$17*COS(RADIANS(F15))+'Geometry'!$F$17*SIN(RADIANS(F15))),('Geometry'!$G$18*COS(RADIANS(F15))+'Geometry'!$F$18*SIN(RADIANS(F15))),('Geometry'!$G$19*COS(RADIANS(F15))+'Geometry'!$F$19*SIN(RADIANS(F15))),('Geometry'!$G$20*COS(RADIANS(F15))+'Geometry'!$F$20*SIN(RADIANS(F15)))) -> 686.39115 | J15: =I15-H15*K15 -> -2059.1734 | K15: =I15-MIN(('Geometry'!$G$13*COS(RADIANS(F15))+'Geometry'!$F$13*SIN(RADIANS(F15))),('Geometry'!$G$14*COS(RADIANS(F15))+'Geometry'!$F$14*SIN(RADIANS(F15))),('Geometry'!$G$15*COS(RADIANS(F15))+'Geometry'!$F$15*SIN(RADIANS(F15))),('Geometry'!$G$16*COS(RADIANS(F15))+'Geometry'!$F$16*SIN(RADIANS(F15))),('Geometry'!$G$17*COS(RADIANS(F15))+'Geometry'!$F$17*SIN(RADIANS(F15))),('Geometry'!$G$18*COS(RADIANS(F15))+'Geometry'!$F$18*SIN(RADIANS(F15))),('Geometry'!$G$19*COS(RADIANS(F15))+'Geometry'!$F$19*SIN(RADIANS(F15))),('Geometry'!$G$20*COS(RADIANS(F15))+'Geometry'!$F$20*SIN(RADIANS(F15)))) -> 1372.7823 | L15: =C_ecu -> 0.0033 | M15: =0 -> 0 | N15: =IF(ABS(I15-J15)<0.000000000001,0,(L15-M15)/(I15-J15)) -> 1.2019386e-06 | O15: =L15-N15*I15 -> 0.002475 | P15: =N15*COS(RADIANS(F15)) -> 1.1836784e-06 | Q15: =N15*SIN(RADIANS(F15)) -> 2.0871444e-07 | R15: =AP15 -> 15258.271 | S15: =AQ15 -> 502.35746 | T15: =AR15 -> 135.93824 | U15: =AS15 -> 2412.0743 | V15: =AT15 -> 164.71712 | W15: =AU15 -> 40.202887 | X15: =AM15 -> 17670.346 | Y15: =AN15 -> 667.07459 | Z15: =AO15 -> 176.14112 | AA15: 1 | AB15: 1 | AC15: 1 | AD15: =X15*AA15 -> 17670.346 | AE15: =Y15*AB15 -> 667.07459 | AF15: =Z15*AC15 -> 176.14112 | AG15: 17670.346 | AH15: 667.07459 | AI15: 176.14112 | AJ15: =AD15-AG15 -> 0 | AK15: =SQRT((AE15-AH15)^2+(AF15-AI15)^2) -> 0 | AL15: axial-cap projected-ledger anchor (geometric Pmax face) | AM15: 17670.346 | AN15: 667.07459 | AO15: 176.14112 | AP15: 15258.271 | AQ15: 502.35746 | AR15: 135.93824 | AS15: 2412.0743 | AT15: 164.71712 | AU15: 40.202887
A16: fixedP-b10.000-branch3 | B16: 3 | C16: 10 | D16: 10-station-3|0.17453292519943295|3 | E16: P below — station-3 | F16: 10 | G16: retained c/D (not the cap rule) | H16: 1.5 | I16: =MAX(('Geometry'!$G$13*COS(RADIANS(F16))+'Geometry'!$F$13*SIN(RADIANS(F16))),('Geometry'!$G$14*COS(RADIANS(F16))+'Geometry'!$F$14*SIN(RADIANS(F16))),('Geometry'!$G$15*COS(RADIANS(F16))+'Geometry'!$F$15*SIN(RADIANS(F16))),('Geometry'!$G$16*COS(RADIANS(F16))+'Geometry'!$F$16*SIN(RADIANS(F16))),('Geometry'!$G$17*COS(RADIANS(F16))+'Geometry'!$F$17*SIN(RADIANS(F16))),('Geometry'!$G$18*COS(RADIANS(F16))+'Geometry'!$F$18*SIN(RADIANS(F16))),('Geometry'!$G$19*COS(RADIANS(F16))+'Geometry'!$F$19*SIN(RADIANS(F16))),('Geometry'!$G$20*COS(RADIANS(F16))+'Geometry'!$F$20*SIN(RADIANS(F16)))) -> 686.39115 | J16: =I16-H16*K16 -> -1372.7823 | K16: =I16-MIN(('Geometry'!$G$13*COS(RADIANS(F16))+'Geometry'!$F$13*SIN(RADIANS(F16))),('Geometry'!$G$14*COS(RADIANS(F16))+'Geometry'!$F$14*SIN(RADIANS(F16))),('Geometry'!$G$15*COS(RADIANS(F16))+'Geometry'!$F$15*SIN(RADIANS(F16))),('Geometry'!$G$16*COS(RADIANS(F16))+'Geometry'!$F$16*SIN(RADIANS(F16))),('Geometry'!$G$17*COS(RADIANS(F16))+'Geometry'!$F$17*SIN(RADIANS(F16))),('Geometry'!$G$18*COS(RADIANS(F16))+'Geometry'!$F$18*SIN(RADIANS(F16))),('Geometry'!$G$19*COS(RADIANS(F16))+'Geometry'!$F$19*SIN(RADIANS(F16))),('Geometry'!$G$20*COS(RADIANS(F16))+'Geometry'!$F$20*SIN(RADIANS(F16)))) -> 1372.7823 | L16: =C_ecu -> 0.0033 | M16: =0 -> 0 | N16: =IF(ABS(I16-J16)<0.000000000001,0,(L16-M16)/(I16-J16)) -> 1.6025848e-06 | O16: =L16-N16*I16 -> 0.0022 | P16: =N16*COS(RADIANS(F16)) -> 1.5782379e-06 | Q16: =N16*SIN(RADIANS(F16)) -> 2.7828592e-07 | R16: =AP16 -> 15258.271 | S16: =AQ16 -> 753.5362 | T16: =AR16 -> 203.90736 | U16: =AS16 -> 2412.0743 | V16: =AT16 -> 247.07569 | W16: =AU16 -> 60.304331 | X16: =AM16 -> 17670.346 | Y16: =AN16 -> 1000.6119 | Z16: =AO16 -> 264.21169 | AA16: 1 | AB16: 1 | AC16: 1 | AD16: =X16*AA16 -> 17670.346 | AE16: =Y16*AB16 -> 1000.6119 | AF16: =Z16*AC16 -> 264.21169 | AG16: 17670.346 | AH16: 1000.6119 | AI16: 264.21169 | AJ16: =AD16-AG16 -> 0 | AK16: =SQRT((AE16-AH16)^2+(AF16-AI16)^2) -> 0 | AL16: axial-cap projected-ledger anchor (geometric Pmax face) | AM16: 17670.346 | AN16: 1000.6119 | AO16: 264.21169 | AP16: 15258.271 | AQ16: 753.5362 | AR16: 203.90736 | AS16: 2412.0743 | AT16: 247.07569 | AU16: 60.304331
A17: fixedP-b10.000-branch4 | B17: 4 | C17: 10 | D17: 10-station-4|0.17453292519943295|4 | E17: P below — station-4 | F17: 10 | G17: retained c/D (not the cap rule) | H17: 1.2 | I17: =MAX(('Geometry'!$G$13*COS(RADIANS(F17))+'Geometry'!$F$13*SIN(RADIANS(F17))),('Geometry'!$G$14*COS(RADIANS(F17))+'Geometry'!$F$14*SIN(RADIANS(F17))),('Geometry'!$G$15*COS(RADIANS(F17))+'Geometry'!$F$15*SIN(RADIANS(F17))),('Geometry'!$G$16*COS(RADIANS(F17))+'Geometry'!$F$16*SIN(RADIANS(F17))),('Geometry'!$G$17*COS(RADIANS(F17))+'Geometry'!$F$17*SIN(RADIANS(F17))),('Geometry'!$G$18*COS(RADIANS(F17))+'Geometry'!$F$18*SIN(RADIANS(F17))),('Geometry'!$G$19*COS(RADIANS(F17))+'Geometry'!$F$19*SIN(RADIANS(F17))),('Geometry'!$G$20*COS(RADIANS(F17))+'Geometry'!$F$20*SIN(RADIANS(F17)))) -> 686.39115 | J17: =I17-H17*K17 -> -960.94761 | K17: =I17-MIN(('Geometry'!$G$13*COS(RADIANS(F17))+'Geometry'!$F$13*SIN(RADIANS(F17))),('Geometry'!$G$14*COS(RADIANS(F17))+'Geometry'!$F$14*SIN(RADIANS(F17))),('Geometry'!$G$15*COS(RADIANS(F17))+'Geometry'!$F$15*SIN(RADIANS(F17))),('Geometry'!$G$16*COS(RADIANS(F17))+'Geometry'!$F$16*SIN(RADIANS(F17))),('Geometry'!$G$17*COS(RADIANS(F17))+'Geometry'!$F$17*SIN(RADIANS(F17))),('Geometry'!$G$18*COS(RADIANS(F17))+'Geometry'!$F$18*SIN(RADIANS(F17))),('Geometry'!$G$19*COS(RADIANS(F17))+'Geometry'!$F$19*SIN(RADIANS(F17))),('Geometry'!$G$20*COS(RADIANS(F17))+'Geometry'!$F$20*SIN(RADIANS(F17)))) -> 1372.7823 | L17: =C_ecu -> 0.0033 | M17: =0 -> 0 | N17: =IF(ABS(I17-J17)<0.000000000001,0,(L17-M17)/(I17-J17)) -> 2.003231e-06 | O17: =L17-N17*I17 -> 0.001925 | P17: =N17*COS(RADIANS(F17)) -> 1.9727974e-06 | Q17: =N17*SIN(RADIANS(F17)) -> 3.4785741e-07 | R17: =AP17 -> 15258.271 | S17: =AQ17 -> 1004.7149 | T17: =AR17 -> 271.87647 | U17: =AS17 -> 2412.0743 | V17: =AT17 -> 329.43425 | W17: =AU17 -> 80.405775 | X17: =AM17 -> 17670.346 | Y17: =AN17 -> 1334.1492 | Z17: =AO17 -> 352.28225 | AA17: 1 | AB17: 1 | AC17: 1 | AD17: =X17*AA17 -> 17670.346 | AE17: =Y17*AB17 -> 1334.1492 | AF17: =Z17*AC17 -> 352.28225 | AG17: 17670.346 | AH17: 1334.1492 | AI17: 352.28225 | AJ17: =AD17-AG17 -> 0 | AK17: =SQRT((AE17-AH17)^2+(AF17-AI17)^2) -> 0 | AL17: axial-cap projected-ledger anchor (geometric Pmax face) | AM17: 17670.346 | AN17: 1334.1492 | AO17: 352.28225 | AP17: 15258.271 | AQ17: 1004.7149 | AR17: 271.87647 | AS17: 2412.0743 | AT17: 329.43425 | AU17: 80.405775
A18: fixedP-b10.000-branch5 | B18: 5 | C18: 10 | D18: 10-station-5|0.17453292519943295|5 | E18: P below — station-5 | F18: 10 | G18: retained c/D (not the cap rule) | H18: 1.1 | I18: =MAX(('Geometry'!$G$13*COS(RADIANS(F18))+'Geometry'!$F$13*SIN(RADIANS(F18))),('Geometry'!$G$14*COS(RADIANS(F18))+'Geometry'!$F$14*SIN(RADIANS(F18))),('Geometry'!$G$15*COS(RADIANS(F18))+'Geometry'!$F$15*SIN(RADIANS(F18))),('Geometry'!$G$16*COS(RADIANS(F18))+'Geometry'!$F$16*SIN(RADIANS(F18))),('Geometry'!$G$17*COS(RADIANS(F18))+'Geometry'!$F$17*SIN(RADIANS(F18))),('Geometry'!$G$18*COS(RADIANS(F18))+'Geometry'!$F$18*SIN(RADIANS(F18))),('Geometry'!$G$19*COS(RADIANS(F18))+'Geometry'!$F$19*SIN(RADIANS(F18))),('Geometry'!$G$20*COS(RADIANS(F18))+'Geometry'!$F$20*SIN(RADIANS(F18)))) -> 686.39115 | J18: =I18-H18*K18 -> -823.66938 | K18: =I18-MIN(('Geometry'!$G$13*COS(RADIANS(F18))+'Geometry'!$F$13*SIN(RADIANS(F18))),('Geometry'!$G$14*COS(RADIANS(F18))+'Geometry'!$F$14*SIN(RADIANS(F18))),('Geometry'!$G$15*COS(RADIANS(F18))+'Geometry'!$F$15*SIN(RADIANS(F18))),('Geometry'!$G$16*COS(RADIANS(F18))+'Geometry'!$F$16*SIN(RADIANS(F18))),('Geometry'!$G$17*COS(RADIANS(F18))+'Geometry'!$F$17*SIN(RADIANS(F18))),('Geometry'!$G$18*COS(RADIANS(F18))+'Geometry'!$F$18*SIN(RADIANS(F18))),('Geometry'!$G$19*COS(RADIANS(F18))+'Geometry'!$F$19*SIN(RADIANS(F18))),('Geometry'!$G$20*COS(RADIANS(F18))+'Geometry'!$F$20*SIN(RADIANS(F18)))) -> 1372.7823 | L18: =C_ecu -> 0.0033 | M18: =0 -> 0 | N18: =IF(ABS(I18-J18)<0.000000000001,0,(L18-M18)/(I18-J18)) -> 2.1853429e-06 | O18: =L18-N18*I18 -> 0.0018 | P18: =N18*COS(RADIANS(F18)) -> 2.1521426e-06 | Q18: =N18*SIN(RADIANS(F18)) -> 3.7948081e-07 | R18: =AP18 -> 15258.271 | S18: =AQ18 -> 1255.8937 | T18: =AR18 -> 339.84559 | U18: =AS18 -> 2412.0743 | V18: =AT18 -> 411.79281 | W18: =AU18 -> 100.50722 | X18: =AM18 -> 17670.346 | Y18: =AN18 -> 1667.6865 | Z18: =AO18 -> 440.35281 | AA18: 1 | AB18: 1 | AC18: 1 | AD18: =X18*AA18 -> 17670.346 | AE18: =Y18*AB18 -> 1667.6865 | AF18: =Z18*AC18 -> 440.35281 | AG18: 17670.346 | AH18: 1667.6865 | AI18: 440.35281 | AJ18: =AD18-AG18 -> 0 | AK18: =SQRT((AE18-AH18)^2+(AF18-AI18)^2) -> 0 | AL18: axial-cap projected-ledger anchor (geometric Pmax face) | AM18: 17670.346 | AN18: 1667.6865 | AO18: 440.35281 | AP18: 15258.271 | AQ18: 1255.8937 | AR18: 339.84559 | AS18: 2412.0743 | AT18: 411.79281 | AU18: 100.50722
A19: fixedP-b20.000-branch1 | B19: 1 | C19: 20 | D19: 20-station-1|0.3490658503988659|1 | E19: P below — station-1 | F19: 20 | G19: retained c/D (not the cap rule) | H19: 3 | I19: =MAX(('Geometry'!$G$13*COS(RADIANS(F19))+'Geometry'!$F$13*SIN(RADIANS(F19))),('Geometry'!$G$14*COS(RADIANS(F19))+'Geometry'!$F$14*SIN(RADIANS(F19))),('Geometry'!$G$15*COS(RADIANS(F19))+'Geometry'!$F$15*SIN(RADIANS(F19))),('Geometry'!$G$16*COS(RADIANS(F19))+'Geometry'!$F$16*SIN(RADIANS(F19))),('Geometry'!$G$17*COS(RADIANS(F19))+'Geometry'!$F$17*SIN(RADIANS(F19))),('Geometry'!$G$18*COS(RADIANS(F19))+'Geometry'!$F$18*SIN(RADIANS(F19))),('Geometry'!$G$19*COS(RADIANS(F19))+'Geometry'!$F$19*SIN(RADIANS(F19))),('Geometry'!$G$20*COS(RADIANS(F19))+'Geometry'!$F$20*SIN(RADIANS(F19)))) -> 751.92665 | J19: =I19-H19*K19 -> -3759.6333 | K19: =I19-MIN(('Geometry'!$G$13*COS(RADIANS(F19))+'Geometry'!$F$13*SIN(RADIANS(F19))),('Geometry'!$G$14*COS(RADIANS(F19))+'Geometry'!$F$14*SIN(RADIANS(F19))),('Geometry'!$G$15*COS(RADIANS(F19))+'Geometry'!$F$15*SIN(RADIANS(F19))),('Geometry'!$G$16*COS(RADIANS(F19))+'Geometry'!$F$16*SIN(RADIANS(F19))),('Geometry'!$G$17*COS(RADIANS(F19))+'Geometry'!$F$17*SIN(RADIANS(F19))),('Geometry'!$G$18*COS(RADIANS(F19))+'Geometry'!$F$18*SIN(RADIANS(F19))),('Geometry'!$G$19*COS(RADIANS(F19))+'Geometry'!$F$19*SIN(RADIANS(F19))),('Geometry'!$G$20*COS(RADIANS(F19))+'Geometry'!$F$20*SIN(RADIANS(F19)))) -> 1503.8533 | L19: =C_ecu -> 0.0033 | M19: =0 -> 0 | N19: =IF(ABS(I19-J19)<0.000000000001,0,(L19-M19)/(I19-J19)) -> 7.3145432e-07 | O19: =L19-N19*I19 -> 0.00275 | P19: =N19*COS(RADIANS(F19)) -> 6.8734223e-07 | Q19: =N19*SIN(RADIANS(F19)) -> 2.5017211e-07 | R19: =AP19 -> 15275.582 | S19: =AQ19 -> 223.94357 | T19: =AR19 -> 120.0837 | U19: =AS19 -> 2394.7632 | V19: =AT19 -> 72.672077 | W19: =AU19 -> 38.140464 | X19: =AM19 -> 17670.346 | Y19: =AN19 -> 296.61565 | Z19: =AO19 -> 158.22416 | AA19: 1 | AB19: 1 | AC19: 1 | AD19: =X19*AA19 -> 17670.346 | AE19: =Y19*AB19 -> 296.61565 | AF19: =Z19*AC19 -> 158.22416 | AG19: 17670.346 | AH19: 296.61565 | AI19: 158.22416 | AJ19: =AD19-AG19 -> 0 | AK19: =SQRT((AE19-AH19)^2+(AF19-AI19)^2) -> 0 | AL19: axial-cap projected-ledger anchor (geometric Pmax face) | AM19: 17670.346 | AN19: 296.61565 | AO19: 158.22416 | AP19: 15275.582 | AQ19: 223.94357 | AR19: 120.0837 | AS19: 2394.7632 | AT19: 72.672077 | AU19: 38.140464
A20: fixedP-b20.000-branch2 | B20: 2 | C20: 20 | D20: 20-station-2|0.3490658503988659|2 | E20: P below — station-2 | F20: 20 | G20: retained c/D (not the cap rule) | H20: 2 | I20: =MAX(('Geometry'!$G$13*COS(RADIANS(F20))+'Geometry'!$F$13*SIN(RADIANS(F20))),('Geometry'!$G$14*COS(RADIANS(F20))+'Geometry'!$F$14*SIN(RADIANS(F20))),('Geometry'!$G$15*COS(RADIANS(F20))+'Geometry'!$F$15*SIN(RADIANS(F20))),('Geometry'!$G$16*COS(RADIANS(F20))+'Geometry'!$F$16*SIN(RADIANS(F20))),('Geometry'!$G$17*COS(RADIANS(F20))+'Geometry'!$F$17*SIN(RADIANS(F20))),('Geometry'!$G$18*COS(RADIANS(F20))+'Geometry'!$F$18*SIN(RADIANS(F20))),('Geometry'!$G$19*COS(RADIANS(F20))+'Geometry'!$F$19*SIN(RADIANS(F20))),('Geometry'!$G$20*COS(RADIANS(F20))+'Geometry'!$F$20*SIN(RADIANS(F20)))) -> 751.92665 | J20: =I20-H20*K20 -> -2255.78 | K20: =I20-MIN(('Geometry'!$G$13*COS(RADIANS(F20))+'Geometry'!$F$13*SIN(RADIANS(F20))),('Geometry'!$G$14*COS(RADIANS(F20))+'Geometry'!$F$14*SIN(RADIANS(F20))),('Geometry'!$G$15*COS(RADIANS(F20))+'Geometry'!$F$15*SIN(RADIANS(F20))),('Geometry'!$G$16*COS(RADIANS(F20))+'Geometry'!$F$16*SIN(RADIANS(F20))),('Geometry'!$G$17*COS(RADIANS(F20))+'Geometry'!$F$17*SIN(RADIANS(F20))),('Geometry'!$G$18*COS(RADIANS(F20))+'Geometry'!$F$18*SIN(RADIANS(F20))),('Geometry'!$G$19*COS(RADIANS(F20))+'Geometry'!$F$19*SIN(RADIANS(F20))),('Geometry'!$G$20*COS(RADIANS(F20))+'Geometry'!$F$20*SIN(RADIANS(F20)))) -> 1503.8533 | L20: =C_ecu -> 0.0033 | M20: =0 -> 0 | N20: =IF(ABS(I20-J20)<0.000000000001,0,(L20-M20)/(I20-J20)) -> 1.0971815e-06 | O20: =L20-N20*I20 -> 0.002475 | P20: =N20*COS(RADIANS(F20)) -> 1.0310133e-06 | Q20: =N20*SIN(RADIANS(F20)) -> 3.7525817e-07 | R20: =AP20 -> 15275.582 | S20: =AQ20 -> 447.88714 | T20: =AR20 -> 240.16739 | U20: =AS20 -> 2394.7632 | V20: =AT20 -> 145.34415 | W20: =AU20 -> 76.280927 | X20: =AM20 -> 17670.346 | Y20: =AN20 -> 593.2313 | Z20: =AO20 -> 316.44832 | AA20: 1 | AB20: 1 | AC20: 1 | AD20: =X20*AA20 -> 17670.346 | AE20: =Y20*AB20 -> 593.2313 | AF20: =Z20*AC20 -> 316.44832 | AG20: 17670.346 | AH20: 593.2313 | AI20: 316.44832 | AJ20: =AD20-AG20 -> 0 | AK20: =SQRT((AE20-AH20)^2+(AF20-AI20)^2) -> 0 | AL20: axial-cap projected-ledger anchor (geometric Pmax face) | AM20: 17670.346 | AN20: 593.2313 | AO20: 316.44832 | AP20: 15275.582 | AQ20: 447.88714 | AR20: 240.16739 | AS20: 2394.7632 | AT20: 145.34415 | AU20: 76.280927
... A212: fixedP-b350.000-branch5 | B212: 5 | C212: 350 | D212: 350-station-4|6.1086523819801535|4 | E212: P below — station-4 | F212: 350 | G212: retained c/D (not the cap rule) | H212: 1.2 | I212: =MAX(('Geometry'!$G$13*COS(RADIANS(F212))+'Geometry'!$F$13*SIN(RADIANS(F212))),('Geometry'!$G$14*COS(RADIANS(F212))+'Geometry'!$F$14*SIN(RADIANS(F212))),('Geometry'!$G$15*COS(RADIANS(F212))+'Geometry'!$F$15*SIN(RADIANS(F212))),('Geometry'!$G$16*COS(RADIANS(F212))+'Geometry'!$F$16*SIN(RADIANS(F212))),('Geometry'!$G$17*COS(RADIANS(F212))+'Geometry'!$F$17*SIN(RADIANS(F212))),('Geometry'!$G$18*COS(RADIANS(F212))+'Geometry'!$F$18*SIN(RADIANS(F212))),('Geometry'!$G$19*COS(RADIANS(F212))+'Geometry'!$F$19*SIN(RADIANS(F212))),('Geometry'!$G$20*COS(RADIANS(F212))+'Geometry'!$F$20*SIN(RADIANS(F212)))) -> 686.39115 | J212: =I212-H212*K212 -> -960.94761 | K212: =I212-MIN(('Geometry'!$G$13*COS(RADIANS(F212))+'Geometry'!$F$13*SIN(RADIANS(F212))),('Geometry'!$G$14*COS(RADIANS(F212))+'Geometry'!$F$14*SIN(RADIANS(F212))),('Geometry'!$G$15*COS(RADIANS(F212))+'Geometry'!$F$15*SIN(RADIANS(F212))),('Geometry'!$G$16*COS(RADIANS(F212))+'Geometry'!$F$16*SIN(RADIANS(F212))),('Geometry'!$G$17*COS(RADIANS(F212))+'Geometry'!$F$17*SIN(RADIANS(F212))),('Geometry'!$G$18*COS(RADIANS(F212))+'Geometry'!$F$18*SIN(RADIANS(F212))),('Geometry'!$G$19*COS(RADIANS(F212))+'Geometry'!$F$19*SIN(RADIANS(F212))),('Geometry'!$G$20*COS(RADIANS(F212))+'Geometry'!$F$20*SIN(RADIANS(F212)))) -> 1372.7823 | L212: =C_ecu -> 0.0033 | M212: =0 -> 0 | N212: =IF(ABS(I212-J212)<0.000000000001,0,(L212-M212)/(I212-J212)) -> 2.003231e-06 | O212: =L212-N212*I212 -> 0.001925 | P212: =N212*COS(RADIANS(F212)) -> 1.9727974e-06 | Q212: =N212*SIN(RADIANS(F212)) -> -3.4785741e-07 | R212: =AP212 -> 15258.27 | S212: =AQ212 -> 1004.7109 | T212: =AR212 -> -271.87809 | U212: =AS212 -> 2412.0755 | V212: =AT212 -> 329.43425 | W212: =AU212 -> -80.405783 | X212: =AM212 -> 17670.346 | Y212: =AN212 -> 1334.1451 | Z212: =AO212 -> -352.28387 | AA212: 1 | AB212: 1 | AC212: 1 | AD212: =X212*AA212 -> 17670.346 | AE212: =Y212*AB212 -> 1334.1451 | AF212: =Z212*AC212 -> -352.28387 | AG212: 17670.346 | AH212: 1334.1451 | AI212: -352.28387 | AJ212: =AD212-AG212 -> 0 | AK212: =SQRT((AE212-AH212)^2+(AF212-AI212)^2) -> 0 | AL212: axial-cap projected-ledger anchor (geometric Pmax face) | AM212: 17670.346 | AN212: 1334.1451 | AO212: -352.28387 | AP212: 15258.27 | AQ212: 1004.7109 | AR212: -271.87809 | AS212: 2412.0755 | AT212: 329.43425 | AU212: -80.405783

Sheet FixedP_Upper
A1: FIXED-P UPPER BRACKETING STATIONS
B2: Each row is one direction-specific bracket station. Physical stress-strain rows use Materials/Mesh formulas; geometric axial-cap and equivalent-block rows are explicitly labelled ledger anchors.
B3: Selected P (kN) | C3: =Selected_P -> 17670.346 | D3: Bracket role | E3: P above or exact
A6: Legend | B6: Editable calculation input | C6: Formula | D6: Generated / check | E6: Requires re-export / remesh
A7: Direction ID | B7: Branch | C7: Chart β (deg) | D7: Source key | E7: Station / role | F7: β strain (deg) | G7: Criterion basis | H7: Criterion value | I7: zc (mm) | J7: z control (mm) | K7: D (mm) | L7: εc | M7: ε control | N7: κ (1/mm) | O7: ε₀ | P7: κx (1/mm) | Q7: κy (1/mm) | R7: Concrete P | S7: Concrete Mx | T7: Concrete My | U7: Steel P | V7: Steel Mx | W7: Steel My | X7: Base P | Y7: Base Mx | Z7: Base My | AA7: P factor | AB7: Mx factor | AC7: My factor | AD7: Final P | AE7: Final Mx | AF7: Final My | AG7: Engine P | AH7: Engine Mx | AI7: Engine My | AJ7: ΔP | AK7: ΔM | AL7: Calculation mode | AM7: Base engine P | AN7: Base engine Mx | AO7: Base engine My | AP7: Concrete engine P | AQ7: Concrete engine Mx | AR7: Concrete engine My | AS7: Steel engine P | AT7: Steel engine Mx | AU7: Steel engine My
A8: fixedP-b0.000-branch1 | B8: 1 | C8: 0 | D8: 0-pure-compression|0|0 | E8: P above — pure-compression | F8: 0 | G8: retained ε = constant (not the cap rule) | H8: 0.0033 | I8: =MAX(('Geometry'!$G$13*COS(RADIANS(F8))+'Geometry'!$F$13*SIN(RADIANS(F8))),('Geometry'!$G$14*COS(RADIANS(F8))+'Geometry'!$F$14*SIN(RADIANS(F8))),('Geometry'!$G$15*COS(RADIANS(F8))+'Geometry'!$F$15*SIN(RADIANS(F8))),('Geometry'!$G$16*COS(RADIANS(F8))+'Geometry'!$F$16*SIN(RADIANS(F8))),('Geometry'!$G$17*COS(RADIANS(F8))+'Geometry'!$F$17*SIN(RADIANS(F8))),('Geometry'!$G$18*COS(RADIANS(F8))+'Geometry'!$F$18*SIN(RADIANS(F8))),('Geometry'!$G$19*COS(RADIANS(F8))+'Geometry'!$F$19*SIN(RADIANS(F8))),('Geometry'!$G$20*COS(RADIANS(F8))+'Geometry'!$F$20*SIN(RADIANS(F8)))) -> 600 | J8: =I8 -> -530 | K8: =I8-MIN(('Geometry'!$G$13*COS(RADIANS(F8))+'Geometry'!$F$13*SIN(RADIANS(F8))),('Geometry'!$G$14*COS(RADIANS(F8))+'Geometry'!$F$14*SIN(RADIANS(F8))),('Geometry'!$G$15*COS(RADIANS(F8))+'Geometry'!$F$15*SIN(RADIANS(F8))),('Geometry'!$G$16*COS(RADIANS(F8))+'Geometry'!$F$16*SIN(RADIANS(F8))),('Geometry'!$G$17*COS(RADIANS(F8))+'Geometry'!$F$17*SIN(RADIANS(F8))),('Geometry'!$G$18*COS(RADIANS(F8))+'Geometry'!$F$18*SIN(RADIANS(F8))),('Geometry'!$G$19*COS(RADIANS(F8))+'Geometry'!$F$19*SIN(RADIANS(F8))),('Geometry'!$G$20*COS(RADIANS(F8))+'Geometry'!$F$20*SIN(RADIANS(F8)))) -> 1200 | L8: =H8 -> 0.0033 | M8: =H8 -> 0.0033 | N8: =0 -> 0 | O8: =H8 -> 0.0033 | P8: =N8*COS(RADIANS(F8)) -> 0 | Q8: =N8*SIN(RADIANS(F8)) -> 0 | R8: =AP8 -> 15240.061 | S8: =AQ8 -> 0 | T8: =AR8 -> 0 | U8: =AS8 -> 2430.2851 | V8: =AT8 -> 0 | W8: =AU8 -> 0 | X8: =AM8 -> 17670.346 | Y8: =AN8 -> 0 | Z8: =AO8 -> 0 | AA8: 1 | AB8: 1 | AC8: 1 | AD8: =X8*AA8 -> 17670.346 | AE8: =Y8*AB8 -> 0 | AF8: =Z8*AC8 -> 0 | AG8: 17670.346 | AH8: 0 | AI8: 0 | AJ8: =AD8-AG8 -> 0 | AK8: =SQRT((AE8-AH8)^2+(AF8-AI8)^2) -> 0 | AL8: axial-cap projected-ledger anchor (geometric Pmax face) | AM8: 17670.346 | AN8: 0 | AO8: 0 | AP8: 15240.061 | AQ8: 0 | AR8: 0 | AS8: 2430.2851 | AT8: 0 | AU8: 0
A9: fixedP-b0.000-branch2 | B9: 2 | C9: 0 | D9: 0-station-1|0|1 | E9: P above — station-1 | F9: 0 | G9: retained c/D (not the cap rule) | H9: 3 | I9: =MAX(('Geometry'!$G$13*COS(RADIANS(F9))+'Geometry'!$F$13*SIN(RADIANS(F9))),('Geometry'!$G$14*COS(RADIANS(F9))+'Geometry'!$F$14*SIN(RADIANS(F9))),('Geometry'!$G$15*COS(RADIANS(F9))+'Geometry'!$F$15*SIN(RADIANS(F9))),('Geometry'!$G$16*COS(RADIANS(F9))+'Geometry'!$F$16*SIN(RADIANS(F9))),('Geometry'!$G$17*COS(RADIANS(F9))+'Geometry'!$F$17*SIN(RADIANS(F9))),('Geometry'!$G$18*COS(RADIANS(F9))+'Geometry'!$F$18*SIN(RADIANS(F9))),('Geometry'!$G$19*COS(RADIANS(F9))+'Geometry'!$F$19*SIN(RADIANS(F9))),('Geometry'!$G$20*COS(RADIANS(F9))+'Geometry'!$F$20*SIN(RADIANS(F9)))) -> 600 | J9: =I9-H9*K9 -> -3000 | K9: =I9-MIN(('Geometry'!$G$13*COS(RADIANS(F9))+'Geometry'!$F$13*SIN(RADIANS(F9))),('Geometry'!$G$14*COS(RADIANS(F9))+'Geometry'!$F$14*SIN(RADIANS(F9))),('Geometry'!$G$15*COS(RADIANS(F9))+'Geometry'!$F$15*SIN(RADIANS(F9))),('Geometry'!$G$16*COS(RADIANS(F9))+'Geometry'!$F$16*SIN(RADIANS(F9))),('Geometry'!$G$17*COS(RADIANS(F9))+'Geometry'!$F$17*SIN(RADIANS(F9))),('Geometry'!$G$18*COS(RADIANS(F9))+'Geometry'!$F$18*SIN(RADIANS(F9))),('Geometry'!$G$19*COS(RADIANS(F9))+'Geometry'!$F$19*SIN(RADIANS(F9))),('Geometry'!$G$20*COS(RADIANS(F9))+'Geometry'!$F$20*SIN(RADIANS(F9)))) -> 1200 | L9: =C_ecu -> 0.0033 | M9: =0 -> 0 | N9: =IF(ABS(I9-J9)<0.000000000001,0,(L9-M9)/(I9-J9)) -> 9.1666667e-07 | O9: =L9-N9*I9 -> 0.00275 | P9: =N9*COS(RADIANS(F9)) -> 9.1666667e-07 | Q9: =N9*SIN(RADIANS(F9)) -> 0 | R9: =AP9 -> 15240.061 | S9: =AQ9 -> 285.94652 | T9: =AR9 -> 0.0021480206 | U9: =AS9 -> 2430.2851 | V9: =AT9 -> 93.442542 | W9: =AU9 -> 5.8792249e-16 | X9: =AM9 -> 17670.346 | Y9: =AN9 -> 379.38907 | Z9: =AO9 -> 0.0021480206 | AA9: 1 | AB9: 1 | AC9: 1 | AD9: =X9*AA9 -> 17670.346 | AE9: =Y9*AB9 -> 379.38907 | AF9: =Z9*AC9 -> 0.0021480206 | AG9: 17670.346 | AH9: 379.38907 | AI9: 0.0021480206 | AJ9: =AD9-AG9 -> 0 | AK9: =SQRT((AE9-AH9)^2+(AF9-AI9)^2) -> 0 | AL9: axial-cap projected-ledger anchor (geometric Pmax face) | AM9: 17670.346 | AN9: 379.38907 | AO9: 0.0021480206 | AP9: 15240.061 | AQ9: 285.94652 | AR9: 0.0021480206 | AS9: 2430.2851 | AT9: 93.442542 | AU9: 5.8792249e-16
A10: fixedP-b0.000-branch3 | B10: 3 | C10: 0 | D10: 0-station-2|0|2 | E10: P above — station-2 | F10: 0 | G10: retained c/D (not the cap rule) | H10: 2 | I10: =MAX(('Geometry'!$G$13*COS(RADIANS(F10))+'Geometry'!$F$13*SIN(RADIANS(F10))),('Geometry'!$G$14*COS(RADIANS(F10))+'Geometry'!$F$14*SIN(RADIANS(F10))),('Geometry'!$G$15*COS(RADIANS(F10))+'Geometry'!$F$15*SIN(RADIANS(F10))),('Geometry'!$G$16*COS(RADIANS(F10))+'Geometry'!$F$16*SIN(RADIANS(F10))),('Geometry'!$G$17*COS(RADIANS(F10))+'Geometry'!$F$17*SIN(RADIANS(F10))),('Geometry'!$G$18*COS(RADIANS(F10))+'Geometry'!$F$18*SIN(RADIANS(F10))),('Geometry'!$G$19*COS(RADIANS(F10))+'Geometry'!$F$19*SIN(RADIANS(F10))),('Geometry'!$G$20*COS(RADIANS(F10))+'Geometry'!$F$20*SIN(RADIANS(F10)))) -> 600 | J10: =I10-H10*K10 -> -1800 | K10: =I10-MIN(('Geometry'!$G$13*COS(RADIANS(F10))+'Geometry'!$F$13*SIN(RADIANS(F10))),('Geometry'!$G$14*COS(RADIANS(F10))+'Geometry'!$F$14*SIN(RADIANS(F10))),('Geometry'!$G$15*COS(RADIANS(F10))+'Geometry'!$F$15*SIN(RADIANS(F10))),('Geometry'!$G$16*COS(RADIANS(F10))+'Geometry'!$F$16*SIN(RADIANS(F10))),('Geometry'!$G$17*COS(RADIANS(F10))+'Geometry'!$F$17*SIN(RADIANS(F10))),('Geometry'!$G$18*COS(RADIANS(F10))+'Geometry'!$F$18*SIN(RADIANS(F10))),('Geometry'!$G$19*COS(RADIANS(F10))+'Geometry'!$F$19*SIN(RADIANS(F10))),('Geometry'!$G$20*COS(RADIANS(F10))+'Geometry'!$F$20*SIN(RADIANS(F10)))) -> 1200 | L10: =C_ecu -> 0.0033 | M10: =0 -> 0 | N10: =IF(ABS(I10-J10)<0.000000000001,0,(L10-M10)/(I10-J10)) -> 1.375e-06 | O10: =L10-N10*I10 -> 0.002475 | P10: =N10*COS(RADIANS(F10)) -> 1.375e-06 | Q10: =N10*SIN(RADIANS(F10)) -> 0 | R10: =AP10 -> 15240.061 | S10: =AQ10 -> 571.89305 | T10: =AR10 -> 0.0042960413 | U10: =AS10 -> 2430.2851 | V10: =AT10 -> 186.88508 | W10: =AU10 -> 1.175845e-15 | X10: =AM10 -> 17670.346 | Y10: =AN10 -> 758.77813 | Z10: =AO10 -> 0.0042960413 | AA10: 1 | AB10: 1 | AC10: 1 | AD10: =X10*AA10 -> 17670.346 | AE10: =Y10*AB10 -> 758.77813 | AF10: =Z10*AC10 -> 0.0042960413 | AG10: 17670.346 | AH10: 758.77813 | AI10: 0.0042960413 | AJ10: =AD10-AG10 -> 0 | AK10: =SQRT((AE10-AH10)^2+(AF10-AI10)^2) -> 0 | AL10: axial-cap projected-ledger anchor (geometric Pmax face) | AM10: 17670.346 | AN10: 758.77813 | AO10: 0.0042960413 | AP10: 15240.061 | AQ10: 571.89305 | AR10: 0.0042960413 | AS10: 2430.2851 | AT10: 186.88508 | AU10: 1.175845e-15
A11: fixedP-b0.000-branch4 | B11: 4 | C11: 0 | D11: 0-station-3|0|3 | E11: P above — station-3 | F11: 0 | G11: retained c/D (not the cap rule) | H11: 1.5 | I11: =MAX(('Geometry'!$G$13*COS(RADIANS(F11))+'Geometry'!$F$13*SIN(RADIANS(F11))),('Geometry'!$G$14*COS(RADIANS(F11))+'Geometry'!$F$14*SIN(RADIANS(F11))),('Geometry'!$G$15*COS(RADIANS(F11))+'Geometry'!$F$15*SIN(RADIANS(F11))),('Geometry'!$G$16*COS(RADIANS(F11))+'Geometry'!$F$16*SIN(RADIANS(F11))),('Geometry'!$G$17*COS(RADIANS(F11))+'Geometry'!$F$17*SIN(RADIANS(F11))),('Geometry'!$G$18*COS(RADIANS(F11))+'Geometry'!$F$18*SIN(RADIANS(F11))),('Geometry'!$G$19*COS(RADIANS(F11))+'Geometry'!$F$19*SIN(RADIANS(F11))),('Geometry'!$G$20*COS(RADIANS(F11))+'Geometry'!$F$20*SIN(RADIANS(F11)))) -> 600 | J11: =I11-H11*K11 -> -1200 | K11: =I11-MIN(('Geometry'!$G$13*COS(RADIANS(F11))+'Geometry'!$F$13*SIN(RADIANS(F11))),('Geometry'!$G$14*COS(RADIANS(F11))+'Geometry'!$F$14*SIN(RADIANS(F11))),('Geometry'!$G$15*COS(RADIANS(F11))+'Geometry'!$F$15*SIN(RADIANS(F11))),('Geometry'!$G$16*COS(RADIANS(F11))+'Geometry'!$F$16*SIN(RADIANS(F11))),('Geometry'!$G$17*COS(RADIANS(F11))+'Geometry'!$F$17*SIN(RADIANS(F11))),('Geometry'!$G$18*COS(RADIANS(F11))+'Geometry'!$F$18*SIN(RADIANS(F11))),('Geometry'!$G$19*COS(RADIANS(F11))+'Geometry'!$F$19*SIN(RADIANS(F11))),('Geometry'!$G$20*COS(RADIANS(F11))+'Geometry'!$F$20*SIN(RADIANS(F11)))) -> 1200 | L11: =C_ecu -> 0.0033 | M11: =0 -> 0 | N11: =IF(ABS(I11-J11)<0.000000000001,0,(L11-M11)/(I11-J11)) -> 1.8333333e-06 | O11: =L11-N11*I11 -> 0.0022 | P11: =N11*COS(RADIANS(F11)) -> 1.8333333e-06 | Q11: =N11*SIN(RADIANS(F11)) -> 0 | R11: =AP11 -> 15240.061 | S11: =AQ11 -> 857.83957 | T11: =AR11 -> 0.0064440619 | U11: =AS11 -> 2430.2851 | V11: =AT11 -> 280.32763 | W11: =AU11 -> 1.7637675e-15 | X11: =AM11 -> 17670.346 | Y11: =AN11 -> 1138.1672 | Z11: =AO11 -> 0.0064440619 | AA11: 1 | AB11: 1 | AC11: 1 | AD11: =X11*AA11 -> 17670.346 | AE11: =Y11*AB11 -> 1138.1672 | AF11: =Z11*AC11 -> 0.0064440619 | AG11: 17670.346 | AH11: 1138.1672 | AI11: 0.0064440619 | AJ11: =AD11-AG11 -> 0 | AK11: =SQRT((AE11-AH11)^2+(AF11-AI11)^2) -> 0 | AL11: axial-cap projected-ledger anchor (geometric Pmax face) | AM11: 17670.346 | AN11: 1138.1672 | AO11: 0.0064440619 | AP11: 15240.061 | AQ11: 857.83957 | AR11: 0.0064440619 | AS11: 2430.2851 | AT11: 280.32763 | AU11: 1.7637675e-15
A12: fixedP-b0.000-branch5 | B12: 5 | C12: 0 | D12: 0-station-4|0|4 | E12: P above — station-4 | F12: 0 | G12: retained c/D (not the cap rule) | H12: 1.2 | I12: =MAX(('Geometry'!$G$13*COS(RADIANS(F12))+'Geometry'!$F$13*SIN(RADIANS(F12))),('Geometry'!$G$14*COS(RADIANS(F12))+'Geometry'!$F$14*SIN(RADIANS(F12))),('Geometry'!$G$15*COS(RADIANS(F12))+'Geometry'!$F$15*SIN(RADIANS(F12))),('Geometry'!$G$16*COS(RADIANS(F12))+'Geometry'!$F$16*SIN(RADIANS(F12))),('Geometry'!$G$17*COS(RADIANS(F12))+'Geometry'!$F$17*SIN(RADIANS(F12))),('Geometry'!$G$18*COS(RADIANS(F12))+'Geometry'!$F$18*SIN(RADIANS(F12))),('Geometry'!$G$19*COS(RADIANS(F12))+'Geometry'!$F$19*SIN(RADIANS(F12))),('Geometry'!$G$20*COS(RADIANS(F12))+'Geometry'!$F$20*SIN(RADIANS(F12)))) -> 600 | J12: =I12-H12*K12 -> -840 | K12: =I12-MIN(('Geometry'!$G$13*COS(RADIANS(F12))+'Geometry'!$F$13*SIN(RADIANS(F12))),('Geometry'!$G$14*COS(RADIANS(F12))+'Geometry'!$F$14*SIN(RADIANS(F12))),('Geometry'!$G$15*COS(RADIANS(F12))+'Geometry'!$F$15*SIN(RADIANS(F12))),('Geometry'!$G$16*COS(RADIANS(F12))+'Geometry'!$F$16*SIN(RADIANS(F12))),('Geometry'!$G$17*COS(RADIANS(F12))+'Geometry'!$F$17*SIN(RADIANS(F12))),('Geometry'!$G$18*COS(RADIANS(F12))+'Geometry'!$F$18*SIN(RADIANS(F12))),('Geometry'!$G$19*COS(RADIANS(F12))+'Geometry'!$F$19*SIN(RADIANS(F12))),('Geometry'!$G$20*COS(RADIANS(F12))+'Geometry'!$F$20*SIN(RADIANS(F12)))) -> 1200 | L12: =C_ecu -> 0.0033 | M12: =0 -> 0 | N12: =IF(ABS(I12-J12)<0.000000000001,0,(L12-M12)/(I12-J12)) -> 2.2916667e-06 | O12: =L12-N12*I12 -> 0.001925 | P12: =N12*COS(RADIANS(F12)) -> 2.2916667e-06 | Q12: =N12*SIN(RADIANS(F12)) -> 0 | R12: =AP12 -> 15240.061 | S12: =AQ12 -> 1143.7861 | T12: =AR12 -> 0.0085920826 | U12: =AS12 -> 2430.2851 | V12: =AT12 -> 373.77017 | W12: =AU12 -> 2.35169e-15 | X12: =AM12 -> 17670.346 | Y12: =AN12 -> 1517.5563 | Z12: =AO12 -> 0.0085920826 | AA12: 1 | AB12: 1 | AC12: 1 | AD12: =X12*AA12 -> 17670.346 | AE12: =Y12*AB12 -> 1517.5563 | AF12: =Z12*AC12 -> 0.0085920826 | AG12: 17670.346 | AH12: 1517.5563 | AI12: 0.0085920826 | AJ12: =AD12-AG12 -> 0 | AK12: =SQRT((AE12-AH12)^2+(AF12-AI12)^2) -> 0 | AL12: axial-cap projected-ledger anchor (geometric Pmax face) | AM12: 17670.346 | AN12: 1517.5563 | AO12: 0.0085920826 | AP12: 15240.061 | AQ12: 1143.7861 | AR12: 0.0085920826 | AS12: 2430.2851 | AT12: 373.77017 | AU12: 2.35169e-15
A13: fixedP-b0.000-branch6 | B13: 6 | C13: 0 | D13: 0-station-5|0|5 | E13: P above — station-5 | F13: 0 | G13: retained c/D (not the cap rule) | H13: 1.1 | I13: =MAX(('Geometry'!$G$13*COS(RADIANS(F13))+'Geometry'!$F$13*SIN(RADIANS(F13))),('Geometry'!$G$14*COS(RADIANS(F13))+'Geometry'!$F$14*SIN(RADIANS(F13))),('Geometry'!$G$15*COS(RADIANS(F13))+'Geometry'!$F$15*SIN(RADIANS(F13))),('Geometry'!$G$16*COS(RADIANS(F13))+'Geometry'!$F$16*SIN(RADIANS(F13))),('Geometry'!$G$17*COS(RADIANS(F13))+'Geometry'!$F$17*SIN(RADIANS(F13))),('Geometry'!$G$18*COS(RADIANS(F13))+'Geometry'!$F$18*SIN(RADIANS(F13))),('Geometry'!$G$19*COS(RADIANS(F13))+'Geometry'!$F$19*SIN(RADIANS(F13))),('Geometry'!$G$20*COS(RADIANS(F13))+'Geometry'!$F$20*SIN(RADIANS(F13)))) -> 600 | J13: =I13-H13*K13 -> -720 | K13: =I13-MIN(('Geometry'!$G$13*COS(RADIANS(F13))+'Geometry'!$F$13*SIN(RADIANS(F13))),('Geometry'!$G$14*COS(RADIANS(F13))+'Geometry'!$F$14*SIN(RADIANS(F13))),('Geometry'!$G$15*COS(RADIANS(F13))+'Geometry'!$F$15*SIN(RADIANS(F13))),('Geometry'!$G$16*COS(RADIANS(F13))+'Geometry'!$F$16*SIN(RADIANS(F13))),('Geometry'!$G$17*COS(RADIANS(F13))+'Geometry'!$F$17*SIN(RADIANS(F13))),('Geometry'!$G$18*COS(RADIANS(F13))+'Geometry'!$F$18*SIN(RADIANS(F13))),('Geometry'!$G$19*COS(RADIANS(F13))+'Geometry'!$F$19*SIN(RADIANS(F13))),('Geometry'!$G$20*COS(RADIANS(F13))+'Geometry'!$F$20*SIN(RADIANS(F13)))) -> 1200 | L13: =C_ecu -> 0.0033 | M13: =0 -> 0 | N13: =IF(ABS(I13-J13)<0.000000000001,0,(L13-M13)/(I13-J13)) -> 2.5e-06 | O13: =L13-N13*I13 -> 0.0018 | P13: =N13*COS(RADIANS(F13)) -> 2.5e-06 | Q13: =N13*SIN(RADIANS(F13)) -> 0 | R13: =AP13 -> 15240.061 | S13: =AQ13 -> 1429.7326 | T13: =AR13 -> 0.010740103 | U13: =AS13 -> 2430.2851 | V13: =AT13 -> 467.21271 | W13: =AU13 -> 2.9396125e-15 | X13: =AM13 -> 17670.346 | Y13: =AN13 -> 1896.9453 | Z13: =AO13 -> 0.010740103 | AA13: 1 | AB13: 1 | AC13: 1 | AD13: =X13*AA13 -> 17670.346 | AE13: =Y13*AB13 -> 1896.9453 | AF13: =Z13*AC13 -> 0.010740103 | AG13: 17670.346 | AH13: 1896.9453 | AI13: 0.010740103 | AJ13: =AD13-AG13 -> 0 | AK13: =SQRT((AE13-AH13)^2+(AF13-AI13)^2) -> 0 | AL13: axial-cap projected-ledger anchor (geometric Pmax face) | AM13: 17670.346 | AN13: 1896.9453 | AO13: 0.010740103 | AP13: 15240.061 | AQ13: 1429.7326 | AR13: 0.010740103 | AS13: 2430.2851 | AT13: 467.21271 | AU13: 2.9396125e-15
