Workbook
Name As: '15-degree'!$E$70
Name As: '30-degree'!$E$70
Name As: '0-degree'!$E$70
Name dia: '15-degree'!$E$19
Name dia: '30-degree'!$E$19
Name dia: '0-degree'!$E$19
Name eco: Input!$E$13
Name ecu: Input!$G$5
Name Es: Input!$E$24
Name fck: Input!$G$4
Name fy: Input!$E$25
Name h: [1]Input!$F$6
Name n: Input!$E$12
Name p: '0-degree'!$F$52
Name p: '15-degree'!$F$52
Name p: '30-degree'!$F$52
Name p: Summary!$F$58
Name p: 'Test Mesh'!$F$24
Name pc: Input!$E$27
Name ps: Input!$E$26
Name xc: '15-degree'!$H$47
Name xc: '30-degree'!$H$47
Name xc: '0-degree'!$H$47
Name yc: '15-degree'!$H$48
Name yc: '30-degree'!$H$48
Name yc: '0-degree'!$H$48

Sheet Input
B3: Material
B4: ● | C4: Concrete | E4: fck | F4: = | G4: 30 | H4: Mpa
E5: εcu | F5: = | G5: =MIN(0.0033-(fck-40)/100000,0.0033) -> 0.0033
C7: Strain - Stress Relationship : Parabolic | M7: [KDS 24 14 21 3.1.2.5 (2)]
C9: 0 ≤ εc ≤ εco | E9: fc = (0.85fck) [ 1 - (1 - εc/εco)n] | P9: ε | Q9: fc
C10: else | E10: fc = 0.85fck | O10: 1 | P10: 0 | Q10: =+IF(P10>=0,IF(P10<=eco,1-(1-P10/eco)^$E$12,1),0)*0.85*fck -> 0
O11: 2 | P11: =+ecu/10*(O11-1) -> 0.00033 | Q11: =+IF(P11>=0,IF(P11<=eco,1-(1-P11/eco)^$E$12,1),0)*0.85*fck -> 7.7207625
C12: n | D12: = | E12: =MIN(1.2+1.5*((100-fck)/60)^4,2) -> 2 | O12: 3 | P12: =+ecu/10*(O12-1) -> 0.00066 | Q12: =+IF(P12>=0,IF(P12<=eco,1-(1-P12/eco)^$E$12,1),0)*0.85*fck -> 14.05305
C13: εco | D13: = | E13: =MAX(0.002+(fck-40)/100000,0.002) -> 0.002 | O13: 4 | P13: =+ecu/10*(O13-1) -> 0.00099 | Q13: =+IF(P13>=0,IF(P13<=eco,1-(1-P13/eco)^$E$12,1),0)*0.85*fck -> 18.996862
O14: 5 | P14: =+ecu/10*(O14-1) -> 0.00132 | Q14: =+IF(P14>=0,IF(P14<=eco,1-(1-P14/eco)^$E$12,1),0)*0.85*fck -> 22.5522
O15: 6 | P15: =+ecu/10*(O15-1) -> 0.00165 | Q15: =+IF(P15>=0,IF(P15<=eco,1-(1-P15/eco)^$E$12,1),0)*0.85*fck -> 24.719062
O16: 7 | P16: =+ecu/10*(O16-1) -> 0.00198 | Q16: =+IF(P16>=0,IF(P16<=eco,1-(1-P16/eco)^$E$12,1),0)*0.85*fck -> 25.49745
O17: 8 | P17: =+ecu/10*(O17-1) -> 0.00231 | Q17: =+IF(P17>=0,IF(P17<=eco,1-(1-P17/eco)^$E$12,1),0)*0.85*fck -> 25.5
O18: 9 | P18: =+ecu/10*(O18-1) -> 0.00264 | Q18: =+IF(P18>=0,IF(P18<=eco,1-(1-P18/eco)^$E$12,1),0)*0.85*fck -> 25.5
O19: 10 | P19: =+ecu/10*(O19-1) -> 0.00297 | Q19: =+IF(P19>=0,IF(P19<=eco,1-(1-P19/eco)^$E$12,1),0)*0.85*fck -> 25.5
B23: ● | C23: Steel
C24: Es | D24: = | E24: 200000 | F24: Mpa
C25: fy | D25: = | E25: 400 | F25: Mpa
C26: φs | D26: = | E26: 0.9
C27: φc | D27: = | E27: 0.65

Sheet Test Mesh
B3: ● | C3: Original Geometry
C4: Boundary
C5: No. | D5: 1 | E5: 2 | F5: 3 | G5: 4 | H5: 5 | I5: 6 | J5: 7 | K5: 8 | L5: 9 | M5: 10 | N5: 11 | O5: 12 | P5: 13 | Q5: 14 | R5: 15 | S5: 16 | T5: 17 | U5: 18
C6: X | D6: -550 | E6: 550 | F6: 750 | G6: 750 | H6: 550 | I6: -550 | J6: -750 | K6: -750 | L6: =+D6 -> -550
C7: Y | D7: 600 | E7: 600 | F7: 400 | G7: -400 | H7: -600 | I7: -600 | J7: -400 | K7: 400 | L7: =+D7 -> 600
C9: Hole1
C10: No. | D10: 1 | E10: 2 | F10: 3 | G10: 4 | H10: 5 | I10: 6 | J10: 7 | K10: 8 | L10: 9 | M10: 10 | N10: 11 | O10: 12 | P10: 13 | Q10: 14 | R10: 15 | S10: 16 | T10: 17 | U10: 18
C11: X | D11: -450 | E11: -250 | F11: -150 | G11: -150 | H11: -250 | I11: -450 | J11: -550 | K11: -550 | L11: =+D11 -> -450
C12: Y | D12: 400 | E12: 400 | F12: 300 | G12: -300 | H12: -400 | I12: -400 | J12: -300 | K12: 300 | L12: =+D12 -> 400
C14: Hole2
C15: No. | D15: 1 | E15: 2 | F15: 3 | G15: 4 | H15: 5 | I15: 6 | J15: 7 | K15: 8 | L15: 9 | M15: 10 | N15: 11 | O15: 12 | P15: 13 | Q15: 14 | R15: 15 | S15: 16 | T15: 17 | U15: 18
C16: X | D16: 250 | E16: 450 | F16: 550 | G16: 550 | H16: 450 | I16: 250 | J16: 150 | K16: 150 | L16: =+D16 -> 250
C17: Y | D17: 400 | E17: 400 | F17: 300 | G17: -300 | H17: -400 | I17: -400 | J17: -300 | K17: 300 | L17: =+D17 -> 400
C19: Rebar
C20: No. | D20: 1 | E20: 2 | F20: 3 | G20: 4 | H20: 5 | I20: 6 | J20: 7 | K20: 8 | L20: 9 | M20: 10 | N20: 11 | O20: 12 | P20: 13 | Q20: 14 | R20: 15 | S20: 16 | T20: 17 | U20: 18
C21: X | D21: -400 | E21: =+D21+200 -> -200 | F21: =+E21+200 -> 0 | G21: =+F21+200 -> 200 | H21: =+G21+200 -> 400 | I21: -400 | J21: -200 | K21: 0 | L21: 200 | M21: 400 | N21: -680 | O21: -680 | P21: -680 | Q21: -680 | R21: 680 | S21: 680 | T21: 680 | U21: 680
C22: Y | D22: 530 | E22: 530 | F22: 530 | G22: 530 | H22: 530 | I22: -530 | J22: -530 | K22: -530 | L22: -530 | M22: -530 | N22: 300 | O22: 100 | P22: -100 | Q22: -300 | R22: 300 | S22: 100 | T22: -100 | U22: -300
B24: ● | C24: After Rotation | F24: 20 | G24: degree | I24: x = x*cos(a) - y*sin(a)
I25: y = x*sin(a) + y*cos(a)
C26: Boundary
C27: No. | D27: 1 | E27: 2 | F27: 3 | G27: 4 | H27: 5 | I27: 6 | J27: 7 | K27: 8 | L27: 9 | M27: 10 | N27: 11 | O27: 12 | P27: 13 | Q27: 14 | R27: 15 | S27: 16 | T27: 17 | U27: 18
C28: X | D28: =D6*COS(RADIANS(p))-D7*SIN(RADIANS(p)) -> -722.04303 | E28: =E6*COS(RADIANS(p))-E7*SIN(RADIANS(p)) -> 311.61886 | F28: =F6*COS(RADIANS(p))-F7*SIN(RADIANS(p)) -> 567.96141 | G28: =G6*COS(RADIANS(p))-G7*SIN(RADIANS(p)) -> 841.57752 | H28: =H6*COS(RADIANS(p))-H7*SIN(RADIANS(p)) -> 722.04303 | I28: =I6*COS(RADIANS(p))-I7*SIN(RADIANS(p)) -> -311.61886 | J28: =J6*COS(RADIANS(p))-J7*SIN(RADIANS(p)) -> -567.96141 | K28: =K6*COS(RADIANS(p))-K7*SIN(RADIANS(p)) -> -841.57752 | L28: =L6*COS(RADIANS(p))-L7*SIN(RADIANS(p)) -> -722.04303
C29: Y | D29: =D6*SIN(RADIANS(p))+D7*COS(RADIANS(p)) -> 375.70449 | E29: =E6*SIN(RADIANS(p))+E7*COS(RADIANS(p)) -> 751.92665 | F29: =F6*SIN(RADIANS(p))+F7*COS(RADIANS(p)) -> 632.39216 | G29: =G6*SIN(RADIANS(p))+G7*COS(RADIANS(p)) -> -119.36194 | H29: =H6*SIN(RADIANS(p))+H7*COS(RADIANS(p)) -> -375.70449 | I29: =I6*SIN(RADIANS(p))+I7*COS(RADIANS(p)) -> -751.92665 | J29: =J6*SIN(RADIANS(p))+J7*COS(RADIANS(p)) -> -632.39216 | K29: =K6*SIN(RADIANS(p))+K7*COS(RADIANS(p)) -> 119.36194 | L29: =L6*SIN(RADIANS(p))+L7*COS(RADIANS(p)) -> 375.70449
C31: Hole1
C32: No. | D32: 1 | E32: 2 | F32: 3 | G32: 4 | H32: 5 | I32: 6 | J32: 7 | K32: 8 | L32: 9 | M32: 10 | N32: 11 | O32: 12 | P32: 13 | Q32: 14 | R32: 15 | S32: 16 | T32: 17 | U32: 18
C33: X | D33: =D11*COS(RADIANS(p))-D12*SIN(RADIANS(p)) -> -559.66974 | E33: =E11*COS(RADIANS(p))-E12*SIN(RADIANS(p)) -> -371.73121 | F33: =F11*COS(RADIANS(p))-F12*SIN(RADIANS(p)) -> -243.55994 | G33: =G11*COS(RADIANS(p))-G12*SIN(RADIANS(p)) -> -38.34785 | H33: =H11*COS(RADIANS(p))-H12*SIN(RADIANS(p)) -> -98.115098 | I33: =I11*COS(RADIANS(p))-I12*SIN(RADIANS(p)) -> -286.05362 | J33: =J11*COS(RADIANS(p))-J12*SIN(RADIANS(p)) -> -414.2249 | K33: =K11*COS(RADIANS(p))-K12*SIN(RADIANS(p)) -> -619.43698 | L33: =L11*COS(RADIANS(p))-L12*SIN(RADIANS(p)) -> -559.66974
C34: Y | D34: =D11*SIN(RADIANS(p))+D12*COS(RADIANS(p)) -> 221.96798 | E34: =E11*SIN(RADIANS(p))+E12*COS(RADIANS(p)) -> 290.37201 | F34: =F11*SIN(RADIANS(p))+F12*COS(RADIANS(p)) -> 230.60476 | G34: =G11*SIN(RADIANS(p))+G12*COS(RADIANS(p)) -> -333.21081 | H34: =H11*SIN(RADIANS(p))+H12*COS(RADIANS(p)) -> -461.38208 | I34: =I11*SIN(RADIANS(p))+I12*COS(RADIANS(p)) -> -529.78611 | J34: =J11*SIN(RADIANS(p))+J12*COS(RADIANS(p)) -> -470.01887 | K34: =K11*SIN(RADIANS(p))+K12*COS(RADIANS(p)) -> 93.796707 | L34: =L11*SIN(RADIANS(p))+L12*COS(RADIANS(p)) -> 221.96798
C36: Hole2
C37: No. | D37: 1 | E37: 2 | F37: 3 | G37: 4 | H37: 5 | I37: 6 | J37: 7 | K37: 8 | L37: 9 | M37: 10 | N37: 11 | O37: 12 | P37: 13 | Q37: 14 | R37: 15 | S37: 16 | T37: 17 | U37: 18
C38: X | D38: =D16*COS(RADIANS(p))-D17*SIN(RADIANS(p)) -> 98.115098 | E38: =E16*COS(RADIANS(p))-E17*SIN(RADIANS(p)) -> 286.05362 | F38: =F16*COS(RADIANS(p))-F17*SIN(RADIANS(p)) -> 414.2249 | G38: =G16*COS(RADIANS(p))-G17*SIN(RADIANS(p)) -> 619.43698 | H38: =H16*COS(RADIANS(p))-H17*SIN(RADIANS(p)) -> 559.66974 | I38: =I16*COS(RADIANS(p))-I17*SIN(RADIANS(p)) -> 371.73121 | J38: =J16*COS(RADIANS(p))-J17*SIN(RADIANS(p)) -> 243.55994 | K38: =K16*COS(RADIANS(p))-K17*SIN(RADIANS(p)) -> 38.34785 | L38: =L16*COS(RADIANS(p))-L17*SIN(RADIANS(p)) -> 98.115098
C39: Y | D39: =D16*SIN(RADIANS(p))+D17*COS(RADIANS(p)) -> 461.38208 | E39: =E16*SIN(RADIANS(p))+E17*COS(RADIANS(p)) -> 529.78611 | F39: =F16*SIN(RADIANS(p))+F17*COS(RADIANS(p)) -> 470.01887 | G39: =G16*SIN(RADIANS(p))+G17*COS(RADIANS(p)) -> -93.796707 | H39: =H16*SIN(RADIANS(p))+H17*COS(RADIANS(p)) -> -221.96798 | I39: =I16*SIN(RADIANS(p))+I17*COS(RADIANS(p)) -> -290.37201 | J39: =J16*SIN(RADIANS(p))+J17*COS(RADIANS(p)) -> -230.60476 | K39: =K16*SIN(RADIANS(p))+K17*COS(RADIANS(p)) -> 333.21081 | L39: =L16*SIN(RADIANS(p))+L17*COS(RADIANS(p)) -> 461.38208
C41: Rebar
C42: No. | D42: 1 | E42: 2 | F42: 3 | G42: 4 | H42: 5 | I42: 6 | J42: 7 | K42: 8 | L42: 9 | M42: 10 | N42: 11 | O42: 12 | P42: 13 | Q42: 14 | R42: 15 | S42: 16 | T42: 17 | U42: 18
C43: X | D43: =D21*COS(RADIANS(p))-D22*SIN(RADIANS(p)) -> -557.14772 | E43: =E21*COS(RADIANS(p))-E22*SIN(RADIANS(p)) -> -369.2092 | F43: =F21*COS(RADIANS(p))-F22*SIN(RADIANS(p)) -> -181.27068 | G43: =G21*COS(RADIANS(p))-G22*SIN(RADIANS(p)) -> 6.6678482 | H43: =H21*COS(RADIANS(p))-H22*SIN(RADIANS(p)) -> 194.60637 | I43: =I21*COS(RADIANS(p))-I22*SIN(RADIANS(p)) -> -194.60637 | J43: =J21*COS(RADIANS(p))-J22*SIN(RADIANS(p)) -> -6.6678482 | K43: =K21*COS(RADIANS(p))-K22*SIN(RADIANS(p)) -> 181.27068 | ... U43: =U21*COS(RADIANS(p))-U22*SIN(RADIANS(p)) -> 741.59703
C44: Y | D44: =D21*SIN(RADIANS(p))+D22*COS(RADIANS(p)) -> 361.22903 | E44: =E21*SIN(RADIANS(p))+E22*COS(RADIANS(p)) -> 429.63306 | F44: =F21*SIN(RADIANS(p))+F22*COS(RADIANS(p)) -> 498.03709 | G44: =G21*SIN(RADIANS(p))+G22*COS(RADIANS(p)) -> 566.44112 | H44: =H21*SIN(RADIANS(p))+H22*COS(RADIANS(p)) -> 634.84515 | I44: =I21*SIN(RADIANS(p))+I22*COS(RADIANS(p)) -> -634.84515 | J44: =J21*SIN(RADIANS(p))+J22*COS(RADIANS(p)) -> -566.44112 | K44: =K21*SIN(RADIANS(p))+K22*COS(RADIANS(p)) -> -498.03709 | ... U44: =U21*SIN(RADIANS(p))+U22*COS(RADIANS(p)) -> -49.334089
D46: Max | E46: Min | G46: Boundary | J46: Area
C47: X | D47: =MAX(D28:U28) -> 841.57752 | E47: =MIN(D28:U28) -> -841.57752 | G47: Depth | H47: Width | J47: Boundary | K47: Hole1 | L47: Hole2 | M47: SUM | O47: Number of Mesh | R47: 30
C48: Y | D48: =MAX(D29:U29) -> 751.92665 | E48: =MIN(D29:U29) -> -751.92665 | G48: =+D48-E48 -> 1503.8533 | H48: =+D47-E47 -> 1683.155 | J48: =0.5*ABS(SUMPRODUCT(D28:K28,E29:L29)-SUMPRODUCT(D29:K29,E28:L28)) -> 1720000 | K48: =0.5*ABS(SUMPRODUCT(D33:K33,E34:L34)-SUMPRODUCT(D34:K34,E33:L33)) -> 300000 | L48: =0.5*ABS(SUMPRODUCT(D38:K38,E39:L39)-SUMPRODUCT(D39:K39,E38:L38)) -> 300000 | M48: =+J48-K48-L48 -> 1120000 | O48: Thickness | R48: =G48/R47 -> 50.128443
BZ51: Compare Area
D52: Line Equation for line (x1 y1) to (x2 y2) | L52: Intersection with Line of y = d | AC52: Select Intersection in range (x1, x2) (y1, y2) | BB52: Sort by X, and get unique | BS52: Length of lines by intersection | BZ52: Original | CA52: =+M48 -> 1120000
...

Sheet 0-degree
B3: ● | C3: Original Geometry
C4: Boundary
C5: No. | D5: 1 | E5: 2 | F5: 3 | G5: 4 | H5: 5 | I5: 6 | J5: 7 | K5: 8 | L5: 9 | M5: 10 | N5: 11 | O5: 12 | P5: 13 | Q5: 14 | R5: 15 | S5: 16 | T5: 17 | U5: 18
C6: X | D6: -550 | E6: 550 | F6: 750 | G6: 750 | H6: 550 | I6: -550 | J6: -750 | K6: -750 | L6: =+D6 -> -550
C7: Y | D7: 600 | E7: 600 | F7: 400 | G7: -400 | H7: -600 | I7: -600 | J7: -400 | K7: 400 | L7: =+D7 -> 600
C9: Hole1
C10: No. | D10: 1 | E10: 2 | F10: 3 | G10: 4 | H10: 5 | I10: 6 | J10: 7 | K10: 8 | L10: 9 | M10: 10 | N10: 11 | O10: 12 | P10: 13 | Q10: 14 | R10: 15 | S10: 16 | T10: 17 | U10: 18
C11: X | D11: -450 | E11: -250 | F11: -150 | G11: -150 | H11: -250 | I11: -450 | J11: -550 | K11: -550 | L11: =+D11 -> -450
C12: Y | D12: 400 | E12: 400 | F12: 300 | G12: -300 | H12: -400 | I12: -400 | J12: -300 | K12: 300 | L12: =+D12 -> 400
C14: Hole2
C15: No. | D15: 1 | E15: 2 | F15: 3 | G15: 4 | H15: 5 | I15: 6 | J15: 7 | K15: 8 | L15: 9 | M15: 10 | N15: 11 | O15: 12 | P15: 13 | Q15: 14 | R15: 15 | S15: 16 | T15: 17 | U15: 18
C16: X | D16: 250 | E16: 450 | F16: 550 | G16: 550 | H16: 450 | I16: 250 | J16: 150 | K16: 150 | L16: =+D16 -> 250
C17: Y | D17: 400 | E17: 400 | F17: 300 | G17: -300 | H17: -400 | I17: -400 | J17: -300 | K17: 300 | L17: =+D17 -> 400
C19: Rebar
C20: No. | D20: 1 | E20: 2 | F20: 3 | G20: 4 | H20: 5 | I20: 6 | J20: 7 | K20: 8 | L20: 9 | M20: 10 | N20: 11 | O20: 12 | P20: 13 | Q20: 14 | R20: 15 | S20: 16 | T20: 17 | U20: 18
C21: X | D21: -400 | E21: -200 | F21: 0 | G21: 200 | H21: 400 | I21: -400 | J21: -200 | K21: 0 | L21: 200 | M21: 400 | N21: -680 | O21: -680 | P21: -680 | Q21: -680 | R21: 680 | S21: 680 | T21: 680 | U21: 680
C22: Y | D22: 530 | E22: 530 | F22: 530 | G22: 530 | H22: 530 | I22: -530 | J22: -530 | K22: -530 | L22: -530 | M22: -530 | N22: 300 | O22: 100 | P22: -100 | Q22: -300 | R22: 300 | S22: 100 | T22: -100 | U22: -300
C23: Dia | D23: 32 | E23: 32 | F23: 32 | G23: 32 | H23: 32 | I23: 32 | J23: 32 | K23: 32 | L23: 32 | M23: 32 | N23: 32 | O23: 32 | P23: 32 | Q23: 32 | R23: 32 | S23: 32 | T23: 32 | U23: 32
C26: Boundary
C27: No. | D27: 1 | E27: 2 | F27: 3 | G27: 4 | H27: 5 | I27: 6 | J27: 7 | K27: 8 | L27: 9 | M27: 10 | N27: 11 | O27: 12 | P27: 13 | Q27: 14 | R27: 15 | S27: 16 | T27: 17 | U27: 18
C28: X | D28: -550 | E28: 550 | F28: 750 | G28: 750 | H28: 550 | I28: -550 | J28: -750 | K28: -750 | L28: =+D28 -> -550
C29: Y | D29: 600 | E29: 600 | F29: 400 | G29: -400 | H29: -600 | I29: -600 | J29: -400 | K29: 400 | L29: =+D29 -> 600
C30: Hole1
C31: No. | D31: 1 | E31: 2 | F31: 3 | G31: 4 | H31: 5 | I31: 6 | J31: 7 | K31: 8 | L31: 9 | M31: 10 | N31: 11 | O31: 12 | P31: 13 | Q31: 14 | R31: 15 | S31: 16 | T31: 17 | U31: 18
C32: X | D32: -450 | E32: -250 | F32: -150 | G32: -150 | H32: -250 | I32: -450 | J32: -550 | K32: -550 | L32: =+D32 -> -450
C33: Y | D33: 400 | E33: 400 | F33: 300 | G33: -300 | H33: -400 | I33: -400 | J33: -300 | K33: 300 | L33: =+D33 -> 400
C34: Hole2
C35: No. | D35: 1 | E35: 2 | F35: 3 | G35: 4 | H35: 5 | I35: 6 | J35: 7 | K35: 8 | L35: 9 | M35: 10 | N35: 11 | O35: 12 | P35: 13 | Q35: 14 | R35: 15 | S35: 16 | T35: 17 | U35: 18
C36: X | D36: 250 | E36: 450 | F36: 550 | G36: 550 | H36: 450 | I36: 250 | J36: 150 | K36: 150 | L36: =+D36 -> 250
C37: Y | D37: 400 | E37: 400 | F37: 300 | G37: -300 | H37: -400 | I37: -400 | J37: -300 | K37: 300 | L37: =+D37 -> 400
C38: Rebar
C39: No. | D39: 1 | E39: 2 | F39: 3 | G39: 4 | H39: 5 | I39: 6 | J39: 7 | K39: 8 | L39: 9 | M39: 10 | N39: 11 | O39: 12 | P39: 13 | Q39: 14 | R39: 15 | S39: 16 | T39: 17 | U39: 18
C40: X | D40: -400 | E40: -200 | F40: 0 | G40: 200 | H40: 400 | I40: -400 | J40: -200 | K40: 0 | L40: 200 | M40: 400 | N40: -680 | O40: -680 | P40: -680 | Q40: -680 | R40: 680 | S40: 680 | T40: 680 | U40: 680
C41: Y | D41: 530 | E41: 530 | F41: 530 | G41: 530 | H41: 530 | I41: -530 | J41: -530 | K41: -530 | L41: -530 | M41: -530 | N41: 300 | O41: 100 | P41: -100 | Q41: -300 | R41: 300 | S41: 100 | T41: -100 | U41: -300
C42: Dia | D42: 32 | E42: 32 | F42: 32 | G42: 32 | H42: 32 | I42: 32 | J42: 32 | K42: 32 | L42: 32 | M42: 32 | N42: 32 | O42: 32 | P42: 32 | Q42: 32 | R42: 32 | S42: 32 | T42: 32 | U42: 32
D44: Area and Centroid
E45: Boundary | F45: Hole1 | G45: Hole2 | H45: SUM | J45: with i = 1 to n, and point n+1 = point 1
D46: Area | E46: =0.5*ABS(SUMPRODUCT(D6:K6,E7:L7)-SUMPRODUCT(D7:K7,E6:L6)) -> 1720000 | F46: =-0.5*ABS(SUMPRODUCT(D11:K11,E12:L12)-SUMPRODUCT(D12:K12,E11:L11)) -> -300000 | G46: =-0.5*ABS(SUMPRODUCT(D16:K16,E17:L17)-SUMPRODUCT(D17:K17,E16:L16)) -> -300000 | H46: =+E46+F46+G46 -> 1120000 | J46: D_i = x_i*y_(i+1) - x_(i+1)*y_i
D47: X | E47: {=SUMPRODUCT((D6:K6+E6:L6),(D6:K6*E7:L7-E6:L6*D7:K7))/(3*(SUMPRODUCT(D6:K6,E7:L7)-SUMPRODUCT(E6:L6,D7:K7)))} -> 0 | F47: {=SUMPRODUCT((D11:K11+E11:L11),(D11:K11*E12:L12-E11:L11*D12:K12))/(3*(SUMPRODUCT(D11:K11,E12:L12)-SUMPRODUCT(E11:L11,D12:K12)))} -> -350 | G47: {=SUMPRODUCT((D16:K16+E16:L16),(D16:K16*E17:L17-E16:L16*D17:K17))/(3*(SUMPRODUCT(D16:K16,E17:L17)-SUMPRODUCT(E16:L16,D17:K17)))} -> 350 | H47: =IFERROR(SUMPRODUCT(E46:G46,E47:G47)/H46,E47) -> 0 | J47: A = 1/2 * |Σ(D_i)|
D48: Y | E48: {=SUMPRODUCT((D7:K7+E7:L7),(D6:K6*E7:L7-E6:L6*D7:K7))/(3*(SUMPRODUCT(D6:K6,E7:L7)-SUMPRODUCT(E6:L6,D7:K7)))} -> 0 | F48: {=SUMPRODUCT((D12:K12+E12:L12),(D11:K11*E12:L12-E11:L11*D12:K12))/(3*(SUMPRODUCT(D11:K11,E12:L12)-SUMPRODUCT(E11:L11,D12:K12)))} -> 0 | G48: {=SUMPRODUCT((D17:K17+E17:L17),(D16:K16*E17:L17-E16:L16*D17:K17))/(3*(SUMPRODUCT(D16:K16,E17:L17)-SUMPRODUCT(E16:L16,D17:K17)))} -> 0 | H48: =IFERROR(SUMPRODUCT(E46:G46,E48:G48)/H46,E48) -> 0 | J48: Xc = Σ[(x_i + x_(i+1))*D_i] / [3*Σ(D_i)]
...

Sheet 15-degree
B3: ● | C3: Original Geometry
C4: Boundary
C5: No. | D5: 1 | E5: 2 | F5: 3 | G5: 4 | H5: 5 | I5: 6 | J5: 7 | K5: 8 | L5: 9 | M5: 10 | N5: 11 | O5: 12 | P5: 13 | Q5: 14 | R5: 15 | S5: 16 | T5: 17 | U5: 18
C6: X | D6: -550 | E6: 550 | F6: 750 | G6: 750 | H6: 550 | I6: -550 | J6: -750 | K6: -750 | L6: =+D6 -> -550
C7: Y | D7: 600 | E7: 600 | F7: 400 | G7: -400 | H7: -600 | I7: -600 | J7: -400 | K7: 400 | L7: =+D7 -> 600
C9: Hole1
C10: No. | D10: 1 | E10: 2 | F10: 3 | G10: 4 | H10: 5 | I10: 6 | J10: 7 | K10: 8 | L10: 9 | M10: 10 | N10: 11 | O10: 12 | P10: 13 | Q10: 14 | R10: 15 | S10: 16 | T10: 17 | U10: 18
C11: X | D11: -450 | E11: -250 | F11: -150 | G11: -150 | H11: -250 | I11: -450 | J11: -550 | K11: -550 | L11: =+D11 -> -450
C12: Y | D12: 400 | E12: 400 | F12: 300 | G12: -300 | H12: -400 | I12: -400 | J12: -300 | K12: 300 | L12: =+D12 -> 400
C14: Hole2
C15: No. | D15: 1 | E15: 2 | F15: 3 | G15: 4 | H15: 5 | I15: 6 | J15: 7 | K15: 8 | L15: 9 | M15: 10 | N15: 11 | O15: 12 | P15: 13 | Q15: 14 | R15: 15 | S15: 16 | T15: 17 | U15: 18
C16: X | D16: 250 | E16: 450 | F16: 550 | G16: 550 | H16: 450 | I16: 250 | J16: 150 | K16: 150 | L16: =+D16 -> 250
C17: Y | D17: 400 | E17: 400 | F17: 300 | G17: -300 | H17: -400 | I17: -400 | J17: -300 | K17: 300 | L17: =+D17 -> 400
C19: Rebar
C20: No. | D20: 1 | E20: 2 | F20: 3 | G20: 4 | H20: 5 | I20: 6 | J20: 7 | K20: 8 | L20: 9 | M20: 10 | N20: 11 | O20: 12 | P20: 13 | Q20: 14 | R20: 15 | S20: 16 | T20: 17 | U20: 18
C21: X | D21: -400 | E21: -200 | F21: 0 | G21: 200 | H21: 400 | I21: -400 | J21: -200 | K21: 0 | L21: 200 | M21: 400 | N21: -680 | O21: -680 | P21: -680 | Q21: -680 | R21: 680 | S21: 680 | T21: 680 | U21: 680
C22: Y | D22: 530 | E22: 530 | F22: 530 | G22: 530 | H22: 530 | I22: -530 | J22: -530 | K22: -530 | L22: -530 | M22: -530 | N22: 300 | O22: 100 | P22: -100 | Q22: -300 | R22: 300 | S22: 100 | T22: -100 | U22: -300
C23: Dia | D23: 32 | E23: 32 | F23: 32 | G23: 32 | H23: 32 | I23: 32 | J23: 32 | K23: 32 | L23: 32 | M23: 32 | N23: 32 | O23: 32 | P23: 32 | Q23: 32 | R23: 32 | S23: 32 | T23: 32 | U23: 32
C26: Boundary
C27: No. | D27: 1 | E27: 2 | F27: 3 | G27: 4 | H27: 5 | I27: 6 | J27: 7 | K27: 8 | L27: 9 | M27: 10 | N27: 11 | O27: 12 | P27: 13 | Q27: 14 | R27: 15 | S27: 16 | T27: 17 | U27: 18
C28: X | D28: -550 | E28: 550 | F28: 750 | G28: 750 | H28: 550 | I28: -550 | J28: -750 | K28: -750 | L28: =+D28 -> -550
C29: Y | D29: 600 | E29: 600 | F29: 400 | G29: -400 | H29: -600 | I29: -600 | J29: -400 | K29: 400 | L29: =+D29 -> 600
C30: Hole1
C31: No. | D31: 1 | E31: 2 | F31: 3 | G31: 4 | H31: 5 | I31: 6 | J31: 7 | K31: 8 | L31: 9 | M31: 10 | N31: 11 | O31: 12 | P31: 13 | Q31: 14 | R31: 15 | S31: 16 | T31: 17 | U31: 18
C32: X | D32: -450 | E32: -250 | F32: -150 | G32: -150 | H32: -250 | I32: -450 | J32: -550 | K32: -550 | L32: =+D32 -> -450
C33: Y | D33: 400 | E33: 400 | F33: 300 | G33: -300 | H33: -400 | I33: -400 | J33: -300 | K33: 300 | L33: =+D33 -> 400
C34: Hole2
C35: No. | D35: 1 | E35: 2 | F35: 3 | G35: 4 | H35: 5 | I35: 6 | J35: 7 | K35: 8 | L35: 9 | M35: 10 | N35: 11 | O35: 12 | P35: 13 | Q35: 14 | R35: 15 | S35: 16 | T35: 17 | U35: 18
C36: X | D36: 250 | E36: 450 | F36: 550 | G36: 550 | H36: 450 | I36: 250 | J36: 150 | K36: 150 | L36: =+D36 -> 250
C37: Y | D37: 400 | E37: 400 | F37: 300 | G37: -300 | H37: -400 | I37: -400 | J37: -300 | K37: 300 | L37: =+D37 -> 400
C38: Rebar
C39: No. | D39: 1 | E39: 2 | F39: 3 | G39: 4 | H39: 5 | I39: 6 | J39: 7 | K39: 8 | L39: 9 | M39: 10 | N39: 11 | O39: 12 | P39: 13 | Q39: 14 | R39: 15 | S39: 16 | T39: 17 | U39: 18
C40: X | D40: -400 | E40: -200 | F40: 0 | G40: 200 | H40: 400 | I40: -400 | J40: -200 | K40: 0 | L40: 200 | M40: 400 | N40: -680 | O40: -680 | P40: -680 | Q40: -680 | R40: 680 | S40: 680 | T40: 680 | U40: 680
C41: Y | D41: 530 | E41: 530 | F41: 530 | G41: 530 | H41: 530 | I41: -530 | J41: -530 | K41: -530 | L41: -530 | M41: -530 | N41: 300 | O41: 100 | P41: -100 | Q41: -300 | R41: 300 | S41: 100 | T41: -100 | U41: -300
C42: Dia | D42: 32 | E42: 32 | F42: 32 | G42: 32 | H42: 32 | I42: 32 | J42: 32 | K42: 32 | L42: 32 | M42: 32 | N42: 32 | O42: 32 | P42: 32 | Q42: 32 | R42: 32 | S42: 32 | T42: 32 | U42: 32
D44: Area and Centroid
E45: Boundary | F45: Hole1 | G45: Hole2 | H45: SUM | J45: with i = 1 to n, and point n+1 = point 1
D46: Area | E46: =0.5*ABS(SUMPRODUCT(D6:K6,E7:L7)-SUMPRODUCT(D7:K7,E6:L6)) -> 1720000 | F46: =-0.5*ABS(SUMPRODUCT(D11:K11,E12:L12)-SUMPRODUCT(D12:K12,E11:L11)) -> -300000 | G46: =-0.5*ABS(SUMPRODUCT(D16:K16,E17:L17)-SUMPRODUCT(D17:K17,E16:L16)) -> -300000 | H46: =+E46+F46+G46 -> 1120000 | J46: D_i = x_i*y_(i+1) - x_(i+1)*y_i
D47: X | E47: {=SUMPRODUCT((D6:K6+E6:L6),(D6:K6*E7:L7-E6:L6*D7:K7))/(3*(SUMPRODUCT(D6:K6,E7:L7)-SUMPRODUCT(E6:L6,D7:K7)))} -> 0 | F47: {=SUMPRODUCT((D11:K11+E11:L11),(D11:K11*E12:L12-E11:L11*D12:K12))/(3*(SUMPRODUCT(D11:K11,E12:L12)-SUMPRODUCT(E11:L11,D12:K12)))} -> -350 | G47: {=SUMPRODUCT((D16:K16+E16:L16),(D16:K16*E17:L17-E16:L16*D17:K17))/(3*(SUMPRODUCT(D16:K16,E17:L17)-SUMPRODUCT(E16:L16,D17:K17)))} -> 350 | H47: =IFERROR(SUMPRODUCT(E46:G46,E47:G47)/H46,E47) -> 0 | J47: A = 1/2 * |Σ(D_i)|
D48: Y | E48: {=SUMPRODUCT((D7:K7+E7:L7),(D6:K6*E7:L7-E6:L6*D7:K7))/(3*(SUMPRODUCT(D6:K6,E7:L7)-SUMPRODUCT(E6:L6,D7:K7)))} -> 0 | F48: {=SUMPRODUCT((D12:K12+E12:L12),(D11:K11*E12:L12-E11:L11*D12:K12))/(3*(SUMPRODUCT(D11:K11,E12:L12)-SUMPRODUCT(E11:L11,D12:K12)))} -> 0 | G48: {=SUMPRODUCT((D17:K17+E17:L17),(D16:K16*E17:L17-E16:L16*D17:K17))/(3*(SUMPRODUCT(D16:K16,E17:L17)-SUMPRODUCT(E16:L16,D17:K17)))} -> 0 | H48: =IFERROR(SUMPRODUCT(E46:G46,E48:G48)/H46,E48) -> 0 | J48: Xc = Σ[(x_i + x_(i+1))*D_i] / [3*Σ(D_i)]
...

Sheet 30-degree
B3: ● | C3: Original Geometry
C4: Boundary
C5: No. | D5: 1 | E5: 2 | F5: 3 | G5: 4 | H5: 5 | I5: 6 | J5: 7 | K5: 8 | L5: 9 | M5: 10 | N5: 11 | O5: 12 | P5: 13 | Q5: 14 | R5: 15 | S5: 16 | T5: 17 | U5: 18
C6: X | D6: -550 | E6: 550 | F6: 750 | G6: 750 | H6: 550 | I6: -550 | J6: -750 | K6: -750 | L6: =+D6 -> -550
C7: Y | D7: 600 | E7: 600 | F7: 400 | G7: -400 | H7: -600 | I7: -600 | J7: -400 | K7: 400 | L7: =+D7 -> 600
C9: Hole1
C10: No. | D10: 1 | E10: 2 | F10: 3 | G10: 4 | H10: 5 | I10: 6 | J10: 7 | K10: 8 | L10: 9 | M10: 10 | N10: 11 | O10: 12 | P10: 13 | Q10: 14 | R10: 15 | S10: 16 | T10: 17 | U10: 18
C11: X | D11: -450 | E11: -250 | F11: -150 | G11: -150 | H11: -250 | I11: -450 | J11: -550 | K11: -550 | L11: =+D11 -> -450
C12: Y | D12: 400 | E12: 400 | F12: 300 | G12: -300 | H12: -400 | I12: -400 | J12: -300 | K12: 300 | L12: =+D12 -> 400
C14: Hole2
C15: No. | D15: 1 | E15: 2 | F15: 3 | G15: 4 | H15: 5 | I15: 6 | J15: 7 | K15: 8 | L15: 9 | M15: 10 | N15: 11 | O15: 12 | P15: 13 | Q15: 14 | R15: 15 | S15: 16 | T15: 17 | U15: 18
C16: X | D16: 250 | E16: 450 | F16: 550 | G16: 550 | H16: 450 | I16: 250 | J16: 150 | K16: 150 | L16: =+D16 -> 250
C17: Y | D17: 400 | E17: 400 | F17: 300 | G17: -300 | H17: -400 | I17: -400 | J17: -300 | K17: 300 | L17: =+D17 -> 400
C19: Rebar
C20: No. | D20: 1 | E20: 2 | F20: 3 | G20: 4 | H20: 5 | I20: 6 | J20: 7 | K20: 8 | L20: 9 | M20: 10 | N20: 11 | O20: 12 | P20: 13 | Q20: 14 | R20: 15 | S20: 16 | T20: 17 | U20: 18
C21: X | D21: -400 | E21: -200 | F21: 0 | G21: 200 | H21: 400 | I21: -400 | J21: -200 | K21: 0 | L21: 200 | M21: 400 | N21: -680 | O21: -680 | P21: -680 | Q21: -680 | R21: 680 | S21: 680 | T21: 680 | U21: 680
C22: Y | D22: 530 | E22: 530 | F22: 530 | G22: 530 | H22: 530 | I22: -530 | J22: -530 | K22: -530 | L22: -530 | M22: -530 | N22: 300 | O22: 100 | P22: -100 | Q22: -300 | R22: 300 | S22: 100 | T22: -100 | U22: -300
C23: Dia | D23: 32 | E23: 32 | F23: 32 | G23: 32 | H23: 32 | I23: 32 | J23: 32 | K23: 32 | L23: 32 | M23: 32 | N23: 32 | O23: 32 | P23: 32 | Q23: 32 | R23: 32 | S23: 32 | T23: 32 | U23: 32
C26: Boundary
C27: No. | D27: 1 | E27: 2 | F27: 3 | G27: 4 | H27: 5 | I27: 6 | J27: 7 | K27: 8 | L27: 9 | M27: 10 | N27: 11 | O27: 12 | P27: 13 | Q27: 14 | R27: 15 | S27: 16 | T27: 17 | U27: 18
C28: X | D28: -550 | E28: 550 | F28: 750 | G28: 750 | H28: 550 | I28: -550 | J28: -750 | K28: -750 | L28: =+D28 -> -550
C29: Y | D29: 600 | E29: 600 | F29: 400 | G29: -400 | H29: -600 | I29: -600 | J29: -400 | K29: 400 | L29: =+D29 -> 600
C30: Hole1
C31: No. | D31: 1 | E31: 2 | F31: 3 | G31: 4 | H31: 5 | I31: 6 | J31: 7 | K31: 8 | L31: 9 | M31: 10 | N31: 11 | O31: 12 | P31: 13 | Q31: 14 | R31: 15 | S31: 16 | T31: 17 | U31: 18
C32: X | D32: -450 | E32: -250 | F32: -150 | G32: -150 | H32: -250 | I32: -450 | J32: -550 | K32: -550 | L32: =+D32 -> -450
C33: Y | D33: 400 | E33: 400 | F33: 300 | G33: -300 | H33: -400 | I33: -400 | J33: -300 | K33: 300 | L33: =+D33 -> 400
C34: Hole2
C35: No. | D35: 1 | E35: 2 | F35: 3 | G35: 4 | H35: 5 | I35: 6 | J35: 7 | K35: 8 | L35: 9 | M35: 10 | N35: 11 | O35: 12 | P35: 13 | Q35: 14 | R35: 15 | S35: 16 | T35: 17 | U35: 18
C36: X | D36: 250 | E36: 450 | F36: 550 | G36: 550 | H36: 450 | I36: 250 | J36: 150 | K36: 150 | L36: =+D36 -> 250
C37: Y | D37: 400 | E37: 400 | F37: 300 | G37: -300 | H37: -400 | I37: -400 | J37: -300 | K37: 300 | L37: =+D37 -> 400
C38: Rebar
C39: No. | D39: 1 | E39: 2 | F39: 3 | G39: 4 | H39: 5 | I39: 6 | J39: 7 | K39: 8 | L39: 9 | M39: 10 | N39: 11 | O39: 12 | P39: 13 | Q39: 14 | R39: 15 | S39: 16 | T39: 17 | U39: 18
C40: X | D40: -400 | E40: -200 | F40: 0 | G40: 200 | H40: 400 | I40: -400 | J40: -200 | K40: 0 | L40: 200 | M40: 400 | N40: -680 | O40: -680 | P40: -680 | Q40: -680 | R40: 680 | S40: 680 | T40: 680 | U40: 680
C41: Y | D41: 530 | E41: 530 | F41: 530 | G41: 530 | H41: 530 | I41: -530 | J41: -530 | K41: -530 | L41: -530 | M41: -530 | N41: 300 | O41: 100 | P41: -100 | Q41: -300 | R41: 300 | S41: 100 | T41: -100 | U41: -300
C42: Dia | D42: 32 | E42: 32 | F42: 32 | G42: 32 | H42: 32 | I42: 32 | J42: 32 | K42: 32 | L42: 32 | M42: 32 | N42: 32 | O42: 32 | P42: 32 | Q42: 32 | R42: 32 | S42: 32 | T42: 32 | U42: 32
D44: Area and Centroid
E45: Boundary | F45: Hole1 | G45: Hole2 | H45: SUM | J45: with i = 1 to n, and point n+1 = point 1
D46: Area | E46: =0.5*ABS(SUMPRODUCT(D6:K6,E7:L7)-SUMPRODUCT(D7:K7,E6:L6)) -> 1720000 | F46: =-0.5*ABS(SUMPRODUCT(D11:K11,E12:L12)-SUMPRODUCT(D12:K12,E11:L11)) -> -300000 | G46: =-0.5*ABS(SUMPRODUCT(D16:K16,E17:L17)-SUMPRODUCT(D17:K17,E16:L16)) -> -300000 | H46: =+E46+F46+G46 -> 1120000 | J46: D_i = x_i*y_(i+1) - x_(i+1)*y_i
D47: X | E47: {=SUMPRODUCT((D6:K6+E6:L6),(D6:K6*E7:L7-E6:L6*D7:K7))/(3*(SUMPRODUCT(D6:K6,E7:L7)-SUMPRODUCT(E6:L6,D7:K7)))} -> 0 | F47: {=SUMPRODUCT((D11:K11+E11:L11),(D11:K11*E12:L12-E11:L11*D12:K12))/(3*(SUMPRODUCT(D11:K11,E12:L12)-SUMPRODUCT(E11:L11,D12:K12)))} -> -350 | G47: {=SUMPRODUCT((D16:K16+E16:L16),(D16:K16*E17:L17-E16:L16*D17:K17))/(3*(SUMPRODUCT(D16:K16,E17:L17)-SUMPRODUCT(E16:L16,D17:K17)))} -> 350 | H47: =IFERROR(SUMPRODUCT(E46:G46,E47:G47)/H46,E47) -> 0 | J47: A = 1/2 * |Σ(D_i)|
D48: Y | E48: {=SUMPRODUCT((D7:K7+E7:L7),(D6:K6*E7:L7-E6:L6*D7:K7))/(3*(SUMPRODUCT(D6:K6,E7:L7)-SUMPRODUCT(E6:L6,D7:K7)))} -> 0 | F48: {=SUMPRODUCT((D12:K12+E12:L12),(D11:K11*E12:L12-E11:L11*D12:K12))/(3*(SUMPRODUCT(D11:K11,E12:L12)-SUMPRODUCT(E11:L11,D12:K12)))} -> 0 | G48: {=SUMPRODUCT((D17:K17+E17:L17),(D16:K16*E17:L17-E16:L16*D17:K17))/(3*(SUMPRODUCT(D16:K16,E17:L17)-SUMPRODUCT(E16:L16,D17:K17)))} -> 0 | H48: =IFERROR(SUMPRODUCT(E46:G46,E48:G48)/H46,E48) -> 0 | J48: Xc = Σ[(x_i + x_(i+1))*D_i] / [3*Σ(D_i)]
...

Sheet Summary
C6: Do for all from o degree to 360 degree, with step 15 degree
C8: Rotation | E8: =+'0-degree'!E83 -> 0 | F8: degree
C9: Point | D9: C/C1 | E9: fs/fy | F9: εs | G9: ε0 | H9: κ | I9: P | K9: Mx | M9: My | O9: Normial | R9: Factored
H10: 1/mm | I10: Concrete | J10: Steel | K10: Concrete | L10: Steel | M10: Concrete | N10: Steel | O10: SumP | P10: SumMx | Q10: SumMy | R10: SumP | S10: SumMx | T10: SumMy
C11: P0 | D11: Pure Compression | G11: =+'0-degree'!G86 -> 0.0033 | H11: =+'0-degree'!H86 -> 0 | I11: =+'0-degree'!I86 -> 28560 | J11: =+'0-degree'!J86 -> 5421.4339 | K11: =+'0-degree'!K86 -> 0 | L11: =+'0-degree'!L86 -> 0 | M11: =+'0-degree'!M86 -> 0 | N11: =+'0-degree'!N86 -> 0 | ... T11: =+'0-degree'!T86 -> 0
C12: P1 | D12: 1 | E12: 0 | G12: =+'0-degree'!G87 -> 0.0024238938 | H12: =+'0-degree'!H87 -> 2.920354e-06 | I12: =+'0-degree'!I87 -> 25301.206 | J12: =+'0-degree'!J87 -> 4406.5465 | K12: =+'0-degree'!K87 -> 1729.7589 | L12: =+'0-degree'!L87 -> 504.91306 | M12: =+'0-degree'!M87 -> 0 | N12: =+'0-degree'!N87 -> 0 | ... T12: =+'0-degree'!T87 -> 0
C13: P2 | E13: 0.5 | G13: =+'0-degree'!G88 -> 0.0021584071 | H13: =+'0-degree'!H88 -> 3.8053097e-06 | I13: =+'0-degree'!I88 -> 18889.428 | J13: =+'0-degree'!J88 -> 3638.0217 | K13: =+'0-degree'!K88 -> 4345.1975 | L13: =+'0-degree'!L88 -> 844.23258 | M13: =+'0-degree'!M88 -> 0 | N13: =+'0-degree'!N88 -> 0 | ... T13: =+'0-degree'!T88 -> 0
C14: P3 | E14: 1 | G14: =+'0-degree'!G89 -> 0.0018929204 | H14: =+'0-degree'!H89 -> 4.6902655e-06 | I14: =+'0-degree'!I89 -> 16032.184 | J14: =+'0-degree'!J89 -> 2793.1015 | K14: =+'0-degree'!K89 -> 4792.6541 | L14: =+'0-degree'!L89 -> 1208.1598 | M14: =+'0-degree'!M89 -> 0 | N14: =+'0-degree'!N89 -> 0 | ... T14: =+'0-degree'!T89 -> 0
C15: P4 | F15: 0.05 | G15: =+'0-degree'!G90 -> 0.0010964602 | H15: =+'0-degree'!H90 -> 7.3451327e-06 | I15: =+'0-degree'!I90 -> 11565.747 | J15: =+'0-degree'!J90 -> 794.92776 | K15: =+'0-degree'!K90 -> 4683.7408 | L15: =+'0-degree'!L90 -> 1982.7529 | M15: =+'0-degree'!M90 -> 0 | N15: =+'0-degree'!N90 -> 0 | ... T15: =+'0-degree'!T90 -> 0
C16: P5 | D16: Pure Tension | G16: =+'0-degree'!G91 -> -0.05 | H16: =+'0-degree'!H91 -> 0 | I16: =+'0-degree'!I91 -> 0 | J16: =+'0-degree'!J91 -> -5790.5836 | K16: =+'0-degree'!K91 -> 0 | L16: =+'0-degree'!L91 -> 0 | M16: =+'0-degree'!M91 -> 0 | N16: =+'0-degree'!N91 -> 0 | ... T16: =+'0-degree'!T91 -> 0
C18: Rotation | E18: =+'15-degree'!E83 -> 15 | F18: degree
C19: Point | D19: C/C1 | E19: fs/fy | F19: εs | G19: ε0 | H19: κ | I19: P | K19: Mx | M19: My | O19: Normial | R19: Factored
H20: 1/mm | I20: Concrete | J20: Steel | K20: Concrete | L20: Steel | M20: Concrete | N20: Steel | O20: SumP | P20: SumMx | Q20: SumMy | R20: SumP | S20: SumMx | T20: SumMy
C21: P0 | D21: Pure Compression | G21: =+'15-degree'!G86 -> 0.0033 | H21: =+'15-degree'!H86 -> 0 | I21: =+'15-degree'!I86 -> 28560 | J21: =+'15-degree'!J86 -> 5421.4339 | K21: =+'15-degree'!K86 -> 0 | L21: =+'15-degree'!L86 -> 0 | M21: =+'15-degree'!M86 -> 0 | N21: =+'15-degree'!N86 -> 0 | ... T21: =+'15-degree'!T86 -> 0
C22: P1 | D22: 1 | E22: 0 | G22: =+'15-degree'!G87 -> 0.0025597435 | H22: =+'15-degree'!H87 -> 2.4675217e-06 | I22: =+'15-degree'!I87 -> 27091.888 | J22: =+'15-degree'!J87 -> 4758.0436 | K22: =+'15-degree'!K87 -> 727.22808 | L22: =+'15-degree'!L87 -> 311.43036 | M22: =+'15-degree'!M87 -> 133.92189 | N22: =+'15-degree'!N87 -> 29.718283 | ... T22: =+'15-degree'!T87 -> 113.79568
C23: P2 | E23: 0.5 | G23: =+'15-degree'!G88 -> 0.0023354233 | H23: =+'15-degree'!H88 -> 3.2152555e-06 | I23: =+'15-degree'!I88 -> 20002.941 | J23: =+'15-degree'!J88 -> 4142.425 | K23: =+'15-degree'!K88 -> 3685.7402 | L23: =+'15-degree'!L88 -> 578.17825 | M23: =+'15-degree'!M88 -> 321.27676 | N23: =+'15-degree'!N88 -> 58.572315 | ... T23: =+'15-degree'!T88 -> 261.54498
C24: P3 | E24: 1 | G24: =+'15-degree'!G89 -> 0.0021111032 | H24: =+'15-degree'!H89 -> 3.9629893e-06 | I24: =+'15-degree'!I89 -> 16312.512 | J24: =+'15-degree'!J89 -> 3464.3997 | K24: =+'15-degree'!K89 -> 4464.2644 | L24: =+'15-degree'!L89 -> 848.76506 | M24: =+'15-degree'!M89 -> 305.63545 | N24: =+'15-degree'!N89 -> 85.072584 | ... T24: =+'15-degree'!T89 -> 275.22837
C25: P4 | F25: 0.05 | G25: =+'15-degree'!G90 -> 0.0014381427 | H25: =+'15-degree'!H90 -> 6.2061909e-06 | I25: =+'15-degree'!I90 -> 10746.221 | J25: =+'15-degree'!J90 -> 1340.3732 | K25: =+'15-degree'!K90 -> 4236.4903 | L25: =+'15-degree'!L90 -> 1680.5538 | M25: =+'15-degree'!M90 -> 308.16501 | N25: =+'15-degree'!N90 -> 166.66554 | ... T25: =+'15-degree'!T90 -> 350.30624
C26: P5 | D26: Pure Tension | G26: =+'15-degree'!G91 -> -0.05 | H26: =+'15-degree'!H91 -> 0 | I26: =+'15-degree'!I91 -> 0 | J26: =+'15-degree'!J91 -> -5790.5836 | K26: =+'15-degree'!K91 -> 0 | L26: =+'15-degree'!L91 -> 0 | M26: =+'15-degree'!M91 -> 0 | N26: =+'15-degree'!N91 -> 0 | ... T26: =+'15-degree'!T91 -> 0
C28: Rotation | E28: 30 | F28: degree
C29: Point | D29: C/C1 | E29: fs/fy | F29: εs | G29: ε0 | H29: κ | I29: P | K29: Mx | M29: My | O29: Normial | R29: Factored
H30: 1/mm | I30: Concrete | J30: Steel | K30: Concrete | L30: Steel | M30: Concrete | N30: Steel | O30: SumP | P30: SumMx | Q30: SumMy | R30: SumP | S30: SumMx | T30: SumMy
C31: P0 | D31: Pure Compression | G31: =+'30-degree'!G86 -> 0.0033 | H31: =+'30-degree'!H86 -> 0 | I31: =+'30-degree'!I86 -> 28560 | J31: =+'30-degree'!J86 -> 5421.4339 | K31: =+'30-degree'!K86 -> 0 | L31: =+'30-degree'!L86 -> 0 | M31: =+'30-degree'!M86 -> 0 | N31: =+'30-degree'!N86 -> 0 | ... T31: =+'30-degree'!T86 -> 0
C32: P1 | D32: 1 | E32: 0 | G32: =+'30-degree'!G87 -> 0.0026189364 | H32: =+'30-degree'!H87 -> 2.270212e-06 | I32: =+'30-degree'!I87 -> 27030.915 | J32: =+'30-degree'!J87 -> 4911.1807 | K32: =+'30-degree'!K87 -> 643.96443 | L32: =+'30-degree'!L87 -> 190.26532 | M32: =+'30-degree'!M87 -> 396.58072 | N32: =+'30-degree'!N87 -> 93.095928 | ... T32: =+'30-degree'!T87 -> 341.5638
C33: P2 | E33: 0.5 | G33: =+'30-degree'!G88 -> 0.0024125535 | H33: =+'30-degree'!H88 -> 2.9581551e-06 | I33: =+'30-degree'!I88 -> 21387.303 | J33: =+'30-degree'!J88 -> 4292.5438 | K33: =+'30-degree'!K88 -> 2490.1425 | L33: =+'30-degree'!L88 -> 397.65637 | M33: =+'30-degree'!M88 -> 1201.4836 | N33: =+'30-degree'!N88 -> 179.38487 | ... T33: =+'30-degree'!T88 -> 942.41072
C34: P3 | E34: 1 | G34: =+'30-degree'!G89 -> 0.0022061706 | H34: =+'30-degree'!H89 -> 3.6460981e-06 | I34: =+'30-degree'!I89 -> 16518.158 | J34: =+'30-degree'!J89 -> 3666.2681 | K34: =+'30-degree'!K89 -> 3513.0446 | L34: =+'30-degree'!L89 -> 597.32231 | M34: =+'30-degree'!M89 -> 1239.8739 | N34: =+'30-degree'!N89 -> 269.16743 | ... T34: =+'30-degree'!T89 -> 1048.1687
C35: P4 | F35: 0.05 | G35: =+'30-degree'!G90 -> 0.0015870218 | H35: =+'30-degree'!H90 -> 5.7099273e-06 | I35: =+'30-degree'!I90 -> 9674.867 | J35: =+'30-degree'!J90 -> 1658.02 | K35: =+'30-degree'!K90 -> 3135.4426 | L35: =+'30-degree'!L90 -> 1194.0643 | M35: =+'30-degree'!M90 -> 1223.971 | N35: =+'30-degree'!N90 -> 579.48712 | ... T35: =+'30-degree'!T90 -> 1317.1195
C36: P5 | D36: Pure Tension | G36: =+'30-degree'!G91 -> -0.05 | H36: =+'30-degree'!H91 -> 0 | I36: =+'30-degree'!I91 -> 0 | J36: =+'30-degree'!J91 -> -5790.5836 | K36: =+'30-degree'!K91 -> 0 | L36: =+'30-degree'!L91 -> 0 | M36: =+'30-degree'!M91 -> 0 | N36: =+'30-degree'!N91 -> 0 | ... T36: =+'30-degree'!T91 -> 0
C40: For each degree of rotation, do for all points (18 points)
C42: Point | D42: C/C1 | E42: fs/fy | F42: εs
C44: P0 | D44: Pure Compression
C45: P1 | D45: 3
C46: P2 | D46: 2
C47: P3 | D47: 1.5
C48: P4 | D48: 1.2
C49: P5 fs=0 | D49: 1 | E49: 0
C50: P6 | E50: 0.25
C51: P7 | E51: 0.5
C52: P8 | E52: 0.75
C53: P9 fs=fy | E53: 1 | F53: 0.002
...
