Workbook
Name As: Input!$K$6
Name b: Input!$F$5
Name dia: Input!$K$5
Name eco: Input!$E$41
Name ecu: Input!$G$30
Name Es: Input!$E$49
Name fck: Input!$G$29
Name fy: Input!$E$50
Name h: Input!$F$6
Name ipos: Input!$D$2
Name n: Input!$E$40
Name pc: Input!$N$53
Name ps: Input!$N$52

Sheet Input
B3: Geometry | R3: -130 | S3: -43.333333 | T3: 43.333333 | U3: -130 | V3: -43.333333 | W3: 43.333333 | X3: 130 | Y3: -130 | Z3: 130 | AA3: -130 | AB3: 130
B4: ● | C4: Section Dimension (only for Rectangle) | H4: ● | I4: Rebar | R4: 230 | S4: 230 | T4: 230 | U4: -230 | V4: -230 | W4: -230 | X4: -230 | Y4: 130 | Z4: 130 | AA4: -130 | AB4: -130
C5: Width (b) | E5: = | F5: 400 | G5: mm | I5: Dia. | J5: = | K5: 32 | L5: mm
C6: Height (h) | E6: = | F6: 600 | G6: mm | I6: As | J6: = | K6: =0.25*PI()*dia^2 -> 804.24772 | L6: mm2
C8: Coordinate (mm, Origin is centroid)
D9: X | E9: Y | I9: Cross Section
C10: 1 | D10: -130 | E10: 230
C11: 2 | D11: -43.333333 | E11: 230
C12: 3 | D12: 43.333333 | E12: 230
C13: 4 | P13: x | Q13: y
C14: 5 | D14: -130 | E14: -230 | O14: 1 | P14: =-b/2 -> -200 | Q14: =+h/2 -> 300
C15: 6 | D15: -43.333333 | E15: -230 | O15: 2 | P15: =+b/2 -> 200 | Q15: =+h/2 -> 300
C16: 7 | D16: 43.333333 | E16: -230 | O16: 3 | P16: =+b/2 -> 200 | Q16: =-h/2 -> -300
C17: 8 | D17: 130 | E17: -230 | O17: 4 | P17: =-b/2 -> -200 | Q17: =-h/2 -> -300
C18: 9 | D18: -130 | E18: 130 | O18: 5 | P18: =+P14 -> -200 | Q18: =+Q14 -> 300
C19: 10 | D19: 130 | E19: 130
C20: 11 | D20: -130 | E20: -130
C21: 12 | D21: 130 | E21: -130
C22: 13
C23: 14
B27: Material
B28: Korea Standard
B29: ● | C29: Concrete | E29: fck | F29: = | G29: 30 | H29: Mpa
E30: εcu | F30: = | G30: =MIN(0.0033-(fck-40)/100000,0.0033) -> 0.0033 | M30: [KDS 24 14 21 3.1.2.5 (2)]
C32: Strain - Stress Relationship : Parabolic | M32: [KDS 24 14 21 3.1.2.5 (2)]
C34: 0 ≤ εc ≤ εco | E34: fc = φc (0.85fck) [ 1 - (1 - εc/εco)n] | P34: ε | Q34: fc
C35: else | E35: fc = φc (0.85fck) | O35: 1 | P35: 0 | Q35: =+IF(P35>=0,IF(P35<=eco,1-(1-P35/eco)^$E$40,1),0)*pc*0.85*fck -> 0
O36: 2 | P36: =+ecu/10*(O36-1) -> 0.00033 | Q36: =+IF(P36>=0,IF(P36<=eco,1-(1-P36/eco)^$E$40,1),0)*0.85*fck -> 7.7207625
O37: 3 | P37: =+ecu/10*(O37-1) -> 0.00066 | Q37: =+IF(P37>=0,IF(P37<=eco,1-(1-P37/eco)^$E$40,1),0)*0.85*fck -> 14.05305
O38: 4 | P38: =+ecu/10*(O38-1) -> 0.00099 | Q38: =+IF(P38>=0,IF(P38<=eco,1-(1-P38/eco)^$E$40,1),0)*0.85*fck -> 18.996862
O39: 5 | P39: =+ecu/10*(O39-1) -> 0.00132 | Q39: =+IF(P39>=0,IF(P39<=eco,1-(1-P39/eco)^$E$40,1),0)*0.85*fck -> 22.5522
C40: n | D40: = | E40: =MIN(1.2+1.5*((100-fck)/60)^4,2) -> 2 | O40: 6 | P40: =+ecu/10*(O40-1) -> 0.00165 | Q40: =+IF(P40>=0,IF(P40<=eco,1-(1-P40/eco)^$E$40,1),0)*0.85*fck -> 24.719062
C41: εco | D41: = | E41: =MAX(0.002+(fck-40)/100000,0.002) -> 0.002 | O41: 7 | P41: =+ecu/10*(O41-1) -> 0.00198 | Q41: =+IF(P41>=0,IF(P41<=eco,1-(1-P41/eco)^$E$40,1),0)*0.85*fck -> 25.49745
O42: 8 | P42: =+ecu/10*(O42-1) -> 0.00231 | Q42: =+IF(P42>=0,IF(P42<=eco,1-(1-P42/eco)^$E$40,1),0)*0.85*fck -> 25.5
O43: 9 | P43: =+ecu/10*(O43-1) -> 0.00264 | Q43: =+IF(P43>=0,IF(P43<=eco,1-(1-P43/eco)^$E$40,1),0)*0.85*fck -> 25.5
O44: 10 | P44: =+ecu/10*(O44-1) -> 0.00297 | Q44: =+IF(P44>=0,IF(P44<=eco,1-(1-P44/eco)^$E$40,1),0)*0.85*fck -> 25.5
B48: ● | C48: Steel
C49: Es | D49: = | E49: 200000 | F49: Mpa
C50: fy | D50: = | E50: 400 | F50: Mpa

Sheet Mesh & Convergence
B2: Mesh and Convergence criteria (for concrete)
I4: Equation of Strain | K4: ε = ε0 + κy
I9: Mesh | J9: ny | K9: ∑C | L9: ∑M | M9: Diff.C % | N9: Diff.M % | O9: Converged
I10: 1 | J10: 100 | K10: =+E28 -> 813995.14 | L10: =+G28 -> 2.1067518e+08 | M10: =(K10-K11)/K10 -> 5.1210978e-05 | N10: =(L10-L11)/L10 -> 3.3411007e-05 | O10: =+MIN(M10,N10)<=F15 -> TRUE
I11: 2 | J11: 200 | K11: =+M28 -> 813953.45 | L11: =+O28 -> 2.1066814e+08
B15: Converged Criteria | D15: Diff % (F, M) <= | F15: 0.001
A18: Number of mesh: 50, 100, 200, 400, 600, 800 and Max 1000
A19: Minimum one mesh fiber thickness: 1mm
A21: NA Position and Number of Mesh | E21: One Mesh fiber | I21: NA Position and Number of Mesh | M21: One Mesh fiber
A22: c | B22: 100 | C22: mm | E22: h | F22: =B$22/B$23 -> 2 | G22: mm | I22: c | J22: 100 | K22: mm | M22: h | N22: =J$22/J$23 -> 1 | O22: mm
A23: ny | B23: 50 | C23: EA | E23: b | F23: =+b -> 400 | G23: mm | I23: ny | J23: 100 | K23: EA | M23: b | N23: =+b -> 400 | O23: mm
E24: Ac | F24: =+F22*F23 -> 800 | G24: mm2 | M24: Ac | N24: =+N22*N23 -> 400 | O24: mm2
A26: i | B26: di | C26: εci | D26: fci | E26: Fci | F26: y | G26: Mci | I26: i | J26: di | K26: εci | L26: fci | M26: Fci | N26: y | O26: Mci
A27: Unit | B27: mm | D27: Mpa | E27: N | F27: mm | G27: Nmm | I27: Unit | J27: mm | L27: Mpa | M27: N | N27: mm | O27: Nmm
A28: SUM | E28: =+SUM(E29:E128) -> 813995.14 | G28: =+SUM(G29:G128) -> 2.1067518e+08 | I28: SUM | M28: =+SUM(M29:M228) -> 813953.45 | O28: =+SUM(O29:O228) -> 2.1066814e+08
A29: 1 | B29: =B$22/B$23*(A29-1)+F$22/2 -> 1 | C29: =+(B$22-B29)/B$22*ecu -> 0.003267 | D29: =+IF(C29>=0,IF(C29<=eco,1-(1-C29/eco)^n,1),0)*0.85*fck -> 25.5 | E29: =+D29*F$24 -> 20400 | F29: =+h/2-B29 -> 299 | G29: =+E29*F29 -> 6099600 | I29: 1 | J29: =J$22/J$23*(I29-1)+N$22/2 -> 0.5 | K29: =+(J$22-J29)/J$22*ecu -> 0.0032835 | L29: =+IF(K29>=0,IF(K29<=eco,1-(1-K29/eco)^n,1),0)*0.85*fck -> 25.5 | M29: =+L29*N$24 -> 10200 | N29: =+h/2-J29 -> 299.5 | O29: =+M29*N29 -> 3054900
A30: 2 | B30: =B$22/B$23*(A30-1)+F$22/2 -> 3 | C30: =+(B$22-B30)/B$22*ecu -> 0.003201 | D30: =+IF(C30>=0,IF(C30<=eco,1-(1-C30/eco)^n,1),0)*0.85*fck -> 25.5 | E30: =+D30*F$24 -> 20400 | F30: =+h/2-B30 -> 297 | G30: =+E30*F30 -> 6058800 | I30: 2 | J30: =J$22/J$23*(I30-1)+N$22/2 -> 1.5 | K30: =+(J$22-J30)/J$22*ecu -> 0.0032505 | L30: =+IF(K30>=0,IF(K30<=eco,1-(1-K30/eco)^n,1),0)*0.85*fck -> 25.5 | M30: =+L30*N$24 -> 10200 | N30: =+h/2-J30 -> 298.5 | O30: =+M30*N30 -> 3044700
A31: 3 | B31: =B$22/B$23*(A31-1)+F$22/2 -> 5 | C31: =+(B$22-B31)/B$22*ecu -> 0.003135 | D31: =+IF(C31>=0,IF(C31<=eco,1-(1-C31/eco)^n,1),0)*0.85*fck -> 25.5 | E31: =+D31*F$24 -> 20400 | F31: =+h/2-B31 -> 295 | G31: =+E31*F31 -> 6018000 | I31: 3 | J31: =J$22/J$23*(I31-1)+N$22/2 -> 2.5 | K31: =+(J$22-J31)/J$22*ecu -> 0.0032175 | L31: =+IF(K31>=0,IF(K31<=eco,1-(1-K31/eco)^n,1),0)*0.85*fck -> 25.5 | M31: =+L31*N$24 -> 10200 | N31: =+h/2-J31 -> 297.5 | O31: =+M31*N31 -> 3034500
A32: 4 | B32: =B$22/B$23*(A32-1)+F$22/2 -> 7 | C32: =+(B$22-B32)/B$22*ecu -> 0.003069 | D32: =+IF(C32>=0,IF(C32<=eco,1-(1-C32/eco)^n,1),0)*0.85*fck -> 25.5 | E32: =+D32*F$24 -> 20400 | F32: =+h/2-B32 -> 293 | G32: =+E32*F32 -> 5977200 | I32: 4 | J32: =J$22/J$23*(I32-1)+N$22/2 -> 3.5 | K32: =+(J$22-J32)/J$22*ecu -> 0.0031845 | L32: =+IF(K32>=0,IF(K32<=eco,1-(1-K32/eco)^n,1),0)*0.85*fck -> 25.5 | M32: =+L32*N$24 -> 10200 | N32: =+h/2-J32 -> 296.5 | O32: =+M32*N32 -> 3024300
A33: 5 | B33: =B$22/B$23*(A33-1)+F$22/2 -> 9 | C33: =+(B$22-B33)/B$22*ecu -> 0.003003 | D33: =+IF(C33>=0,IF(C33<=eco,1-(1-C33/eco)^n,1),0)*0.85*fck -> 25.5 | E33: =+D33*F$24 -> 20400 | F33: =+h/2-B33 -> 291 | G33: =+E33*F33 -> 5936400 | I33: 5 | J33: =J$22/J$23*(I33-1)+N$22/2 -> 4.5 | K33: =+(J$22-J33)/J$22*ecu -> 0.0031515 | L33: =+IF(K33>=0,IF(K33<=eco,1-(1-K33/eco)^n,1),0)*0.85*fck -> 25.5 | M33: =+L33*N$24 -> 10200 | N33: =+h/2-J33 -> 295.5 | O33: =+M33*N33 -> 3014100
A34: 6 | B34: =B$22/B$23*(A34-1)+F$22/2 -> 11 | C34: =+(B$22-B34)/B$22*ecu -> 0.002937 | D34: =+IF(C34>=0,IF(C34<=eco,1-(1-C34/eco)^n,1),0)*0.85*fck -> 25.5 | E34: =+D34*F$24 -> 20400 | F34: =+h/2-B34 -> 289 | G34: =+E34*F34 -> 5895600 | I34: 6 | J34: =J$22/J$23*(I34-1)+N$22/2 -> 5.5 | K34: =+(J$22-J34)/J$22*ecu -> 0.0031185 | L34: =+IF(K34>=0,IF(K34<=eco,1-(1-K34/eco)^n,1),0)*0.85*fck -> 25.5 | M34: =+L34*N$24 -> 10200 | N34: =+h/2-J34 -> 294.5 | O34: =+M34*N34 -> 3003900
A35: 7 | B35: =B$22/B$23*(A35-1)+F$22/2 -> 13 | C35: =+(B$22-B35)/B$22*ecu -> 0.002871 | D35: =+IF(C35>=0,IF(C35<=eco,1-(1-C35/eco)^n,1),0)*0.85*fck -> 25.5 | E35: =+D35*F$24 -> 20400 | F35: =+h/2-B35 -> 287 | G35: =+E35*F35 -> 5854800 | I35: 7 | J35: =J$22/J$23*(I35-1)+N$22/2 -> 6.5 | K35: =+(J$22-J35)/J$22*ecu -> 0.0030855 | L35: =+IF(K35>=0,IF(K35<=eco,1-(1-K35/eco)^n,1),0)*0.85*fck -> 25.5 | M35: =+L35*N$24 -> 10200 | N35: =+h/2-J35 -> 293.5 | O35: =+M35*N35 -> 2993700
A36: 8 | B36: =B$22/B$23*(A36-1)+F$22/2 -> 15 | C36: =+(B$22-B36)/B$22*ecu -> 0.002805 | D36: =+IF(C36>=0,IF(C36<=eco,1-(1-C36/eco)^n,1),0)*0.85*fck -> 25.5 | E36: =+D36*F$24 -> 20400 | F36: =+h/2-B36 -> 285 | G36: =+E36*F36 -> 5814000 | I36: 8 | J36: =J$22/J$23*(I36-1)+N$22/2 -> 7.5 | K36: =+(J$22-J36)/J$22*ecu -> 0.0030525 | L36: =+IF(K36>=0,IF(K36<=eco,1-(1-K36/eco)^n,1),0)*0.85*fck -> 25.5 | M36: =+L36*N$24 -> 10200 | N36: =+h/2-J36 -> 292.5 | O36: =+M36*N36 -> 2983500
A37: 9 | B37: =B$22/B$23*(A37-1)+F$22/2 -> 17 | C37: =+(B$22-B37)/B$22*ecu -> 0.002739 | D37: =+IF(C37>=0,IF(C37<=eco,1-(1-C37/eco)^n,1),0)*0.85*fck -> 25.5 | E37: =+D37*F$24 -> 20400 | F37: =+h/2-B37 -> 283 | G37: =+E37*F37 -> 5773200 | I37: 9 | J37: =J$22/J$23*(I37-1)+N$22/2 -> 8.5 | K37: =+(J$22-J37)/J$22*ecu -> 0.0030195 | L37: =+IF(K37>=0,IF(K37<=eco,1-(1-K37/eco)^n,1),0)*0.85*fck -> 25.5 | M37: =+L37*N$24 -> 10200 | N37: =+h/2-J37 -> 291.5 | O37: =+M37*N37 -> 2973300
A38: 10 | B38: =B$22/B$23*(A38-1)+F$22/2 -> 19 | C38: =+(B$22-B38)/B$22*ecu -> 0.002673 | D38: =+IF(C38>=0,IF(C38<=eco,1-(1-C38/eco)^n,1),0)*0.85*fck -> 25.5 | E38: =+D38*F$24 -> 20400 | F38: =+h/2-B38 -> 281 | G38: =+E38*F38 -> 5732400 | I38: 10 | J38: =J$22/J$23*(I38-1)+N$22/2 -> 9.5 | K38: =+(J$22-J38)/J$22*ecu -> 0.0029865 | L38: =+IF(K38>=0,IF(K38<=eco,1-(1-K38/eco)^n,1),0)*0.85*fck -> 25.5 | M38: =+L38*N$24 -> 10200 | N38: =+h/2-J38 -> 290.5 | O38: =+M38*N38 -> 2963100
A39: 11 | B39: =B$22/B$23*(A39-1)+F$22/2 -> 21 | C39: =+(B$22-B39)/B$22*ecu -> 0.002607 | D39: =+IF(C39>=0,IF(C39<=eco,1-(1-C39/eco)^n,1),0)*0.85*fck -> 25.5 | E39: =+D39*F$24 -> 20400 | F39: =+h/2-B39 -> 279 | G39: =+E39*F39 -> 5691600 | I39: 11 | J39: =J$22/J$23*(I39-1)+N$22/2 -> 10.5 | K39: =+(J$22-J39)/J$22*ecu -> 0.0029535 | L39: =+IF(K39>=0,IF(K39<=eco,1-(1-K39/eco)^n,1),0)*0.85*fck -> 25.5 | M39: =+L39*N$24 -> 10200 | N39: =+h/2-J39 -> 289.5 | O39: =+M39*N39 -> 2952900
A40: 12 | B40: =B$22/B$23*(A40-1)+F$22/2 -> 23 | C40: =+(B$22-B40)/B$22*ecu -> 0.002541 | D40: =+IF(C40>=0,IF(C40<=eco,1-(1-C40/eco)^n,1),0)*0.85*fck -> 25.5 | E40: =+D40*F$24 -> 20400 | F40: =+h/2-B40 -> 277 | G40: =+E40*F40 -> 5650800 | I40: 12 | J40: =J$22/J$23*(I40-1)+N$22/2 -> 11.5 | K40: =+(J$22-J40)/J$22*ecu -> 0.0029205 | L40: =+IF(K40>=0,IF(K40<=eco,1-(1-K40/eco)^n,1),0)*0.85*fck -> 25.5 | M40: =+L40*N$24 -> 10200 | N40: =+h/2-J40 -> 288.5 | O40: =+M40*N40 -> 2942700
... A78: 50 | B78: =B$22/B$23*(A78-1)+F$22/2 -> 99 | C78: =+(B$22-B78)/B$22*ecu -> 3.3e-05 | D78: =+IF(C78>=0,IF(C78<=eco,1-(1-C78/eco)^n,1),0)*0.85*fck -> 0.83455762 | E78: =+D78*F$24 -> 667.6461 | F78: =+h/2-B78 -> 201 | G78: =+E78*F78 -> 134196.87 | I78: 50 | J78: =J$22/J$23*(I78-1)+N$22/2 -> 49.5 | K78: =+(J$22-J78)/J$22*ecu -> 0.0016665 | L78: =+IF(K78>=0,IF(K78<=eco,1-(1-K78/eco)^n,1),0)*0.85*fck -> 24.790958 | M78: =+L78*N$24 -> 9916.3833 | N78: =+h/2-J78 -> 250.5 | O78: =+M78*N78 -> 2484054
I79: 51 | J79: =J$22/J$23*(I79-1)+N$22/2 -> 50.5 | K79: =+(J$22-J79)/J$22*ecu -> 0.0016335 | L79: =+IF(K79>=0,IF(K79<=eco,1-(1-K79/eco)^n,1),0)*0.85*fck -> 24.643696 | M79: =+L79*N$24 -> 9857.4783 | N79: =+h/2-J79 -> 249.5 | O79: =+M79*N79 -> 2459440.8
I80: 52 | J80: =J$22/J$23*(I80-1)+N$22/2 -> 51.5 | K80: =+(J$22-J80)/J$22*ecu -> 0.0016005 | L80: =+IF(K80>=0,IF(K80<=eco,1-(1-K80/eco)^n,1),0)*0.85*fck -> 24.482548 | M80: =+L80*N$24 -> 9793.0194 | N80: =+h/2-J80 -> 248.5 | O80: =+M80*N80 -> 2433565.3
I81: 53 | J81: =J$22/J$23*(I81-1)+N$22/2 -> 52.5 | K81: =+(J$22-J81)/J$22*ecu -> 0.0015675 | L81: =+IF(K81>=0,IF(K81<=eco,1-(1-K81/eco)^n,1),0)*0.85*fck -> 24.307516 | M81: =+L81*N$24 -> 9723.0066 | N81: =+h/2-J81 -> 247.5 | O81: =+M81*N81 -> 2406444.1
I82: 54 | J82: =J$22/J$23*(I82-1)+N$22/2 -> 53.5 | K82: =+(J$22-J82)/J$22*ecu -> 0.0015345 | L82: =+IF(K82>=0,IF(K82<=eco,1-(1-K82/eco)^n,1),0)*0.85*fck -> 24.1186 | M82: =+L82*N$24 -> 9647.4399 | N82: =+h/2-J82 -> 246.5 | O82: =+M82*N82 -> 2378093.9
I83: 55 | J83: =J$22/J$23*(I83-1)+N$22/2 -> 54.5 | K83: =+(J$22-J83)/J$22*ecu -> 0.0015015 | L83: =+IF(K83>=0,IF(K83<=eco,1-(1-K83/eco)^n,1),0)*0.85*fck -> 23.915798 | M83: =+L83*N$24 -> 9566.3193 | N83: =+h/2-J83 -> 245.5 | O83: =+M83*N83 -> 2348531.4
I84: 56 | J84: =J$22/J$23*(I84-1)+N$22/2 -> 55.5 | K84: =+(J$22-J84)/J$22*ecu -> 0.0014685 | L84: =+IF(K84>=0,IF(K84<=eco,1-(1-K84/eco)^n,1),0)*0.85*fck -> 23.699112 | M84: =+L84*N$24 -> 9479.6448 | N84: =+h/2-J84 -> 244.5 | O84: =+M84*N84 -> 2317773.1
I85: 57 | J85: =J$22/J$23*(I85-1)+N$22/2 -> 56.5 | K85: =+(J$22-J85)/J$22*ecu -> 0.0014355 | L85: =+IF(K85>=0,IF(K85<=eco,1-(1-K85/eco)^n,1),0)*0.85*fck -> 23.468541 | M85: =+L85*N$24 -> 9387.4164 | N85: =+h/2-J85 -> 243.5 | O85: =+M85*N85 -> 2285835.9
I86: 58 | J86: =J$22/J$23*(I86-1)+N$22/2 -> 57.5 | K86: =+(J$22-J86)/J$22*ecu -> 0.0014025 | L86: =+IF(K86>=0,IF(K86<=eco,1-(1-K86/eco)^n,1),0)*0.85*fck -> 23.224085 | M86: =+L86*N$24 -> 9289.6341 | N86: =+h/2-J86 -> 242.5 | O86: =+M86*N86 -> 2252736.3
I87: 59 | J87: =J$22/J$23*(I87-1)+N$22/2 -> 58.5 | K87: =+(J$22-J87)/J$22*ecu -> 0.0013695 | L87: =+IF(K87>=0,IF(K87<=eco,1-(1-K87/eco)^n,1),0)*0.85*fck -> 22.965745 | M87: =+L87*N$24 -> 9186.2979 | N87: =+h/2-J87 -> 241.5 | O87: =+M87*N87 -> 2218490.9
I88: 60 | J88: =J$22/J$23*(I88-1)+N$22/2 -> 59.5 | K88: =+(J$22-J88)/J$22*ecu -> 0.0013365 | L88: =+IF(K88>=0,IF(K88<=eco,1-(1-K88/eco)^n,1),0)*0.85*fck -> 22.693519 | M88: =+L88*N$24 -> 9077.4078 | N88: =+h/2-J88 -> 240.5 | O88: =+M88*N88 -> 2183116.6
I89: 61 | J89: =J$22/J$23*(I89-1)+N$22/2 -> 60.5 | K89: =+(J$22-J89)/J$22*ecu -> 0.0013035 | L89: =+IF(K89>=0,IF(K89<=eco,1-(1-K89/eco)^n,1),0)*0.85*fck -> 22.407409 | M89: =+L89*N$24 -> 8962.9638 | N89: =+h/2-J89 -> 239.5 | O89: =+M89*N89 -> 2146629.8
I90: 62 | J90: =J$22/J$23*(I90-1)+N$22/2 -> 61.5 | K90: =+(J$22-J90)/J$22*ecu -> 0.0012705 | L90: =+IF(K90>=0,IF(K90<=eco,1-(1-K90/eco)^n,1),0)*0.85*fck -> 22.107415 | M90: =+L90*N$24 -> 8842.9659 | N90: =+h/2-J90 -> 238.5 | O90: =+M90*N90 -> 2109047.4
...

Sheet Strain Equation
B2: Equation of strain
I4: Equation of Strain
J5: ε(y) = ε0 + κ*y
I7: ε0 = | J7: strain at the reference axis
I8: κ = | J8: curvature
I9: y = | J9: coordinate from reference axis

Sheet Loadcase
O3: Equation
R4: Tension | T4: Compression
O5: Concrete | P5: Strain | Q5: εc | T5: εci
P6: Stress | Q6: fc | T6: fci = f(εci)
P7: Force | Q7: Fc | R7: 0 | T7: SUM (Aci * fci)
P8: Eccentricity | Q8: e | T8: yci
P9: Moment | Q9: M | R9: 0 | T9: SUM (Aci * fci * yci)
O11: Steel | P11: Strain | Q11: εs | R11: εs (-) | T11: εs = εc
P12: Stress | Q12: fs | R12: MAX( εs * Es, fy) | T12: MAX( fs * Es - fc ; fy) | X12: Criteria for selecting Point to calculate
P13: Force | Q13: Fs | R13: As * fs (-) | T13: As * fs | X13: P-M point 선택하는 기준
P14: Eccentricity | Q14: e | R14: ys.ten (-) | T14: ys.com
P15: Moment | Q15: M | R15: Fs * e (+) | T15: Fs * e
O16: P = Fc + Fs.com + Fs.ten = Fc + Fs.com - Fs.ten
O17: M = Mc + Ms.com + Ms.ten
O23: Point | P23: N/A Position | S23: Description
O25: P0 | P25: ¥ | S25: Pure Compression
O26: P1 | P26: N/A Position C = C1, fs = 0 | S26: Rebar Stress = 0
O27: P2 | P27: fs = fy | S27: Rebar Stress Max = fy
O28: P3 | P28: all fs = fy, but big strain | S28: Pure Tension

Sheet P0
A1: Pure Compression and Tension
A2: The entire concrete section and all reinforcing bars are in compression. The neutral axis is assumed to be at infinity.
J6: P0 - Pure Compression
F7: Fc = | G7: 0.85f'c (Ac - As) | K7: Concrete | L7: Steel | M7: Nominal
F8: Fs = | G8: fyAs | J8: P | K8: =0.85*fck*G11/1000 -> 6120 | L8: =H22/1000 -> 3313.0985 | M8: =+K8+L8 -> 9433.0985
J9: M | K9: 0 | L9: =+I22/10^6 -> -69.273877 | M9: =+K9+L9 -> -69.273877
F11: Ac = | G11: =+b*h -> 240000 | H11: mm2
F12: As = | G12: =+COUNT(Input!D10:D23)*As -> 8846.7249 | H12: mm2 | J12: P0 - Pure Tension
F13: f'c = | G13: =fck -> 30 | H13: Mpa | K13: Concrete | L13: Steel | M13: Nominal
F14: fy = | G14: =+fy -> 400 | H14: MPa | J14: P | K14: 0 | L14: =J22/1000 -> -3538.69 | M14: =+K14+L14 -> -3538.69
J15: M | K15: 0 | L15: =+K22/10^6 -> 73.99079 | M15: =+K15+L15 -> 73.99079
B19: Steel Force | H19: Compression | J19: Tension
B20: i | C20: di | D20: fsi | E20: fci | F20: fsi_eff | G20: yi | H20: Fsi | I20: Msi | J20: Fsi | K20: Msi
B21: Unit | C21: mm | D21: Mpa | E21: Mpa | F21: Mpa | G21: mm | H21: Nmm | I21: Nmm | J21: Nmm | K21: Nmm
B22: SUM | H22: =+SUM(H23:H34) -> 3313098.5 | I22: =+SUM(I23:I34) -> -69273877 | J22: =+SUM(J23:J34) -> -3538690 | K22: =+SUM(K23:K34) -> 73990790
B23: 1 | C23: =+h/2-Input!E10 -> 70 | D23: =IF(AND(ISNUMBER(Input!D10),ISNUMBER(Input!E10)),fy,0) -> 400 | E23: =IF(AND(ISNUMBER(Input!D10),ISNUMBER(Input!E10)),0.85*fck,0) -> 25.5 | F23: =MAX(MIN(D23,fy),-fy)-IF(D23>=0,E23,0) -> 374.5 | G23: =h/2-C23 -> 230 | H23: =+F23*As -> 301190.77 | I23: =H23*G23 -> 69273877 | J23: =-D23*As -> -321699.09 | K23: =J23*G23 -> -73990790
B24: 2 | C24: =+h/2-Input!E11 -> 70 | D24: =IF(AND(ISNUMBER(Input!D11),ISNUMBER(Input!E11)),fy,0) -> 400 | E24: =IF(AND(ISNUMBER(Input!D11),ISNUMBER(Input!E11)),0.85*fck,0) -> 25.5 | F24: =MAX(MIN(D24,fy),-fy)-IF(D24>=0,E24,0) -> 374.5 | G24: =h/2-C24 -> 230 | H24: =+F24*As -> 301190.77 | I24: =H24*G24 -> 69273877 | J24: =-D24*As -> -321699.09 | K24: =J24*G24 -> -73990790
B25: 3 | C25: =+h/2-Input!E12 -> 70 | D25: =IF(AND(ISNUMBER(Input!D12),ISNUMBER(Input!E12)),fy,0) -> 400 | E25: =IF(AND(ISNUMBER(Input!D12),ISNUMBER(Input!E12)),0.85*fck,0) -> 25.5 | F25: =MAX(MIN(D25,fy),-fy)-IF(D25>=0,E25,0) -> 374.5 | G25: =h/2-C25 -> 230 | H25: =+F25*As -> 301190.77 | I25: =H25*G25 -> 69273877 | J25: =-D25*As -> -321699.09 | K25: =J25*G25 -> -73990790
B26: 4 | C26: =+h/2-Input!E13 -> 300 | D26: =IF(AND(ISNUMBER(Input!D13),ISNUMBER(Input!E13)),fy,0) -> 0 | E26: =IF(AND(ISNUMBER(Input!D13),ISNUMBER(Input!E13)),0.85*fck,0) -> 0 | F26: =MAX(MIN(D26,fy),-fy)-IF(D26>=0,E26,0) -> 0 | G26: =h/2-C26 -> 0 | H26: =+F26*As -> 0 | I26: =H26*G26 -> 0 | J26: =-D26*As -> 0 | K26: =J26*G26 -> 0
B27: 5 | C27: =+h/2-Input!E14 -> 530 | D27: =IF(AND(ISNUMBER(Input!D14),ISNUMBER(Input!E14)),fy,0) -> 400 | E27: =IF(AND(ISNUMBER(Input!D14),ISNUMBER(Input!E14)),0.85*fck,0) -> 25.5 | F27: =MAX(MIN(D27,fy),-fy)-IF(D27>=0,E27,0) -> 374.5 | G27: =h/2-C27 -> -230 | H27: =+F27*As -> 301190.77 | I27: =H27*G27 -> -69273877 | J27: =-D27*As -> -321699.09 | K27: =J27*G27 -> 73990790
B28: 6 | C28: =+h/2-Input!E15 -> 530 | D28: =IF(AND(ISNUMBER(Input!D15),ISNUMBER(Input!E15)),fy,0) -> 400 | E28: =IF(AND(ISNUMBER(Input!D15),ISNUMBER(Input!E15)),0.85*fck,0) -> 25.5 | F28: =MAX(MIN(D28,fy),-fy)-IF(D28>=0,E28,0) -> 374.5 | G28: =h/2-C28 -> -230 | H28: =+F28*As -> 301190.77 | I28: =H28*G28 -> -69273877 | J28: =-D28*As -> -321699.09 | K28: =J28*G28 -> 73990790
B29: 7 | C29: =+h/2-Input!E16 -> 530 | D29: =IF(AND(ISNUMBER(Input!D16),ISNUMBER(Input!E16)),fy,0) -> 400 | E29: =IF(AND(ISNUMBER(Input!D16),ISNUMBER(Input!E16)),0.85*fck,0) -> 25.5 | F29: =MAX(MIN(D29,fy),-fy)-IF(D29>=0,E29,0) -> 374.5 | G29: =h/2-C29 -> -230 | H29: =+F29*As -> 301190.77 | I29: =H29*G29 -> -69273877 | J29: =-D29*As -> -321699.09 | K29: =J29*G29 -> 73990790
B30: 8 | C30: =+h/2-Input!E17 -> 530 | D30: =IF(AND(ISNUMBER(Input!D17),ISNUMBER(Input!E17)),fy,0) -> 400 | E30: =IF(AND(ISNUMBER(Input!D17),ISNUMBER(Input!E17)),0.85*fck,0) -> 25.5 | F30: =MAX(MIN(D30,fy),-fy)-IF(D30>=0,E30,0) -> 374.5 | G30: =h/2-C30 -> -230 | H30: =+F30*As -> 301190.77 | I30: =H30*G30 -> -69273877 | J30: =-D30*As -> -321699.09 | K30: =J30*G30 -> 73990790
B31: 9 | C31: =+h/2-Input!E18 -> 170 | D31: =IF(AND(ISNUMBER(Input!D18),ISNUMBER(Input!E18)),fy,0) -> 400 | E31: =IF(AND(ISNUMBER(Input!D18),ISNUMBER(Input!E18)),0.85*fck,0) -> 25.5 | F31: =MAX(MIN(D31,fy),-fy)-IF(D31>=0,E31,0) -> 374.5 | G31: =h/2-C31 -> 130 | H31: =+F31*As -> 301190.77 | I31: =H31*G31 -> 39154800 | J31: =-D31*As -> -321699.09 | K31: =J31*G31 -> -41820881
B32: 10 | C32: =+h/2-Input!E19 -> 170 | D32: =IF(AND(ISNUMBER(Input!D19),ISNUMBER(Input!E19)),fy,0) -> 400 | E32: =IF(AND(ISNUMBER(Input!D19),ISNUMBER(Input!E19)),0.85*fck,0) -> 25.5 | F32: =MAX(MIN(D32,fy),-fy)-IF(D32>=0,E32,0) -> 374.5 | G32: =h/2-C32 -> 130 | H32: =+F32*As -> 301190.77 | I32: =H32*G32 -> 39154800 | J32: =-D32*As -> -321699.09 | K32: =J32*G32 -> -41820881
B33: 11 | C33: =+h/2-Input!E20 -> 430 | D33: =IF(AND(ISNUMBER(Input!D20),ISNUMBER(Input!E20)),fy,0) -> 400 | E33: =IF(AND(ISNUMBER(Input!D20),ISNUMBER(Input!E20)),0.85*fck,0) -> 25.5 | F33: =MAX(MIN(D33,fy),-fy)-IF(D33>=0,E33,0) -> 374.5 | G33: =h/2-C33 -> -130 | H33: =+F33*As -> 301190.77 | I33: =H33*G33 -> -39154800 | J33: =-D33*As -> -321699.09 | K33: =J33*G33 -> 41820881
B34: 12 | C34: =+h/2-Input!E21 -> 430 | D34: =IF(AND(ISNUMBER(Input!D21),ISNUMBER(Input!E21)),fy,0) -> 400 | E34: =IF(AND(ISNUMBER(Input!D21),ISNUMBER(Input!E21)),0.85*fck,0) -> 25.5 | F34: =MAX(MIN(D34,fy),-fy)-IF(D34>=0,E34,0) -> 374.5 | G34: =h/2-C34 -> -130 | H34: =+F34*As -> 301190.77 | I34: =H34*G34 -> -39154800 | J34: =-D34*As -> -321699.09 | K34: =J34*G34 -> 41820881

Sheet P_c
A1: Select N/A position C by C1
A2: The stress in the control steel is zero. | H2: N.A Line
H3: 1 | I3: =-b/2 -> -200 | J3: =+h/2-R22 -> -760 | Q3: P (kN) | S3: M (kNm)
H4: 2 | I4: =+b/2 -> 200 | J4: =+J3 -> -760 | N4: C/C1 | O4: ε0 | P4: κ | Q4: Concrete | R4: Steel | S4: Concrete | T4: Steel
N5: =+'P-M chart'!C16 -> 3 | O5: =+D25 -> 0.0026773585 | P5: =+D26 -> 2.0754717e-06 | Q5: =+L23 -> 6120 | R5: =+M23 -> 3313.0985 | S5: =+L24 -> 0 | T5: =+M24 -> -69.273877
N6: =+'P-M chart'!C17 -> 2 | O6: =+T25 -> 0.0023660377 | P6: =+T26 -> 3.1132075e-06 | Q6: =+AB23 -> 6070.0405 | R6: =+AC23 -> 3077.9937 | S6: =+AB24 -> 12.701906 | T6: =+AC24 -> -16.44254
N7: =+'P-M chart'!C18 -> 1.5 | O7: =+AJ25 -> 0.002054717 | P7: =+AJ26 -> 4.1509434e-06 | Q7: =+AR23 -> 5774.5846 | R7: =+AS23 -> 2597.0692 | S7: =+AR24 -> 78.824373 | T7: =+AS24 -> 80.054585
N8: =+'P-M chart'!C19 -> 1.2 | O8: =+AZ25 -> 0.0017433962 | P8: =+AZ26 -> 5.1886792e-06 | Q8: =+BH23 -> 5143.7139 | R8: =+BI23 -> 2132.6359 | S8: =+BH24 -> 207.51818 | T8: =+BI24 -> 173.16711
N9: =+'P-M chart'!C20 -> 1 | O9: =+BP25 -> 0.0014320755 | P9: =+BP26 -> 6.2264151e-06 | Q9: =+BX23 -> 4314.1742 | R9: =+BY23 -> 1684.6938 | S9: =+BX24 -> 352.58094 | T9: =+BY24 -> 262.89504
A20: Point P1: NA Position C = 3C1 | Q20: Point P2: NA Position C = 2C1 | AG20: Point P3: NA Position C = 1.5C1 | AW20: Point P4: NA Position C = 1.2C1 | BM20: Point P5: NA Position C = 1C1
A21: C1 = | B21: =+h/2-MIN(Input!$E$10:$E$23) -> 530 | C21: mm | F21: Mesh fiber | K21: Summary | Q21: C1 = | R21: =+h/2-MIN(Input!$E$10:$E$23) -> 530 | S21: mm | V21: Mesh fiber | AA21: Summary | AG21: C1 = | AH21: =+h/2-MIN(Input!$E$10:$E$23) -> 530 | AI21: mm | AL21: Mesh fiber | AQ21: Summary | AW21: C1 = | AX21: =+h/2-MIN(Input!$E$10:$E$23) -> 530 | AY21: mm | BB21: Mesh fiber | BG21: Summary | BM21: C1 = | BN21: =+h/2-MIN(Input!$E$10:$E$23) -> 530 | BO21: mm | BR21: Mesh fiber | BW21: Summary
A22: c | B22: =N5*B21 -> 1590 | C22: mm | F22: Hmesh | G22: =+MIN(B22,h) -> 600 | H22: mm | L22: Concrete | M22: Steel | N22: Nominal | O22: Unit | Q22: c | R22: =N6*R21 -> 1060 | S22: mm | V22: Hmesh | W22: =+MIN(R22,h) -> 600 | X22: mm | AB22: Concrete | AC22: Steel | AD22: Nominal | AE22: Unit | AG22: c | AH22: =N7*AH21 -> 795 | AI22: mm | AL22: Hmesh | AM22: =+MIN(AH22,h) -> 600 | AN22: mm | AR22: Concrete | AS22: Steel | AT22: Nominal | AU22: Unit | AW22: c | AX22: =N8*AX21 -> 636 | AY22: mm | BB22: Hmesh | BC22: =+MIN(AX22,h) -> 600 | BD22: mm | BH22: Concrete | BI22: Steel | BJ22: Nominal | BK22: Unit | BM22: c | BN22: =N9*BN21 -> 530 | BO22: mm | BR22: Hmesh | BS22: =+MIN(BN22,h) -> 530 | BT22: mm | BX22: Concrete | BY22: Steel | BZ22: Nominal | CA22: Unit
A23: Equation of Strain | F23: ny | G23: 50 | H23: EA | K23: P | L23: =+E31/10^3 -> 6120 | M23: =+N31/10^3 -> 3313.0985 | N23: =+L23+M23 -> 9433.0985 | O23: kN | Q23: Equation of Strain | V23: ny | W23: 50 | X23: EA | AA23: P | AB23: =+U31/10^3 -> 6070.0405 | AC23: =+AD31/10^3 -> 3077.9937 | AD23: =+AB23+AC23 -> 9148.0342 | AE23: kN | AG23: Equation of Strain | AL23: ny | AM23: 50 | AN23: EA | AQ23: P | AR23: =+AK31/10^3 -> 5774.5846 | AS23: =+AT31/10^3 -> 2597.0692 | AT23: =+AR23+AS23 -> 8371.6538 | AU23: kN | AW23: Equation of Strain | BB23: ny | BC23: 50 | BD23: EA | BG23: P | BH23: =+BA31/10^3 -> 5143.7139 | BI23: =+BJ31/10^3 -> 2132.6359 | BJ23: =+BH23+BI23 -> 7276.3498 | BK23: kN | BM23: Equation of Strain | BR23: ny | BS23: 50 | BT23: EA | BW23: P | BX23: =+BQ31/10^3 -> 4314.1742 | BY23: =+BZ31/10^3 -> 1684.6938 | BZ23: =+BX23+BY23 -> 5998.868 | CA23: kN
A24: ε(y) = ε0 + κy | F24: h | G24: =G22/G$23 -> 12 | H24: mm | K24: M | L24: =+F31/10^6 -> 0 | M24: =+O31/10^6 -> -69.273877 | N24: =+L24+M24 -> -69.273877 | O24: kNm | Q24: ε(y) = ε0 + κy | V24: h | W24: =W22/W$23 -> 12 | X24: mm | AA24: M | AB24: =+V31/10^6 -> 12.701906 | AC24: =+AE31/10^6 -> -16.44254 | AD24: =+AB24+AC24 -> -3.7406339 | AE24: kNm | AG24: ε(y) = ε0 + κy | AL24: h | AM24: =AM22/AM$23 -> 12 | AN24: mm | AQ24: M | AR24: =+AL31/10^6 -> 78.824373 | AS24: =+AU31/10^6 -> 80.054585 | AT24: =+AR24+AS24 -> 158.87896 | AU24: kNm | AW24: ε(y) = ε0 + κy | BB24: h | BC24: =BC22/BC$23 -> 12 | BD24: mm | BG24: M | BH24: =+BB31/10^6 -> 207.51818 | BI24: =+BK31/10^6 -> 173.16711 | BJ24: =+BH24+BI24 -> 380.6853 | BK24: kNm | BM24: ε(y) = ε0 + κy | BR24: h | BS24: =BS22/BS$23 -> 10.6 | BT24: mm | BW24: M | BX24: =+BR31/10^6 -> 352.58094 | BY24: =+CA31/10^6 -> 262.89504 | BZ24: =+BX24+BY24 -> 615.47598 | CA24: kNm
A25: ε0 = εcu * (c - h/2)/c | C25: ε0 = | D25: =+ecu*(B22-h/2)/B22 -> 0.0026773585 | F25: b | G25: =+b -> 400 | H25: mm | Q25: ε0 = εcu * (c - h/2)/c | S25: ε0 = | T25: =+ecu*(R22-h/2)/R22 -> 0.0023660377 | V25: b | W25: =+b -> 400 | X25: mm | AG25: ε0 = εcu * (c - h/2)/c | AI25: ε0 = | AJ25: =+ecu*(AH22-h/2)/AH22 -> 0.002054717 | AL25: b | AM25: =+b -> 400 | AN25: mm | AW25: ε0 = εcu * (c - h/2)/c | AY25: ε0 = | AZ25: =+ecu*(AX22-h/2)/AX22 -> 0.0017433962 | BB25: b | BC25: =+b -> 400 | BD25: mm | BM25: ε0 = εcu * (c - h/2)/c | BO25: ε0 = | BP25: =+ecu*(BN22-h/2)/BN22 -> 0.0014320755 | BR25: b | BS25: =+b -> 400 | BT25: mm
A26: κ = εcu / c | C26: κ = | D26: =+ecu/B22 -> 2.0754717e-06 | F26: Ac | G26: =+G24*G25 -> 4800 | H26: mm2 | Q26: κ = εcu / c | S26: κ = | T26: =+ecu/R22 -> 3.1132075e-06 | V26: Ac | W26: =+W24*W25 -> 4800 | X26: mm2 | AG26: κ = εcu / c | AI26: κ = | AJ26: =+ecu/AH22 -> 4.1509434e-06 | AL26: Ac | AM26: =+AM24*AM25 -> 4800 | AN26: mm2 | AW26: κ = εcu / c | AY26: κ = | AZ26: =+ecu/AX22 -> 5.1886792e-06 | BB26: Ac | BC26: =+BC24*BC25 -> 4800 | BD26: mm2 | BM26: κ = εcu / c | BO26: κ = | BP26: =+ecu/BN22 -> 6.2264151e-06 | BR26: Ac | BS26: =+BS24*BS25 -> 4240 | BT26: mm2
A28: Concrete Force | I28: Steel Force | Q28: Concrete Force | Y28: Steel Force | AG28: Concrete Force | AO28: Steel Force | AW28: Concrete Force | BE28: Steel Force | BM28: Concrete Force | BU28: Steel Force
A29: i | B29: y | C29: εci | D29: fci | E29: Fci | F29: Mci | H29: i | I29: Y | J29: εsi | K29: fsi | L29: fci | M29: fsi_eff | N29: Fsi | O29: Msi | Q29: i | R29: y | S29: εci | T29: fci | U29: Fci | V29: Mci | X29: i | Y29: Y | Z29: εsi | AA29: fsi | AB29: fci | AC29: fsi_eff | AD29: Fsi | AE29: Msi | AG29: i | AH29: y | AI29: εci | AJ29: fci | AK29: Fci | AL29: Mci | AN29: i | AO29: Y | AP29: εsi | AQ29: fsi | AR29: fci | AS29: fsi_eff | AT29: Fsi | AU29: Msi | AW29: i | AX29: y | AY29: εci | AZ29: fci | BA29: Fci | BB29: Mci | BD29: i | BE29: Y | BF29: εsi | BG29: fsi | BH29: fci | BI29: fsi_eff | BJ29: Fsi | BK29: Msi | BM29: i | BN29: y | BO29: εci | BP29: fci | BQ29: Fci | BR29: Mci | BT29: i | BU29: Y | BV29: εsi | BW29: fsi | BX29: fci | BY29: fsi_eff | BZ29: Fsi | CA29: Msi
A30: Unit | B30: mm | D30: Mpa | E30: N | F30: Nmm | H30: Unit | I30: mm | K30: Mpa | L30: Mpa | M30: Mpa | N30: Nmm | O30: Nmm | Q30: Unit | R30: mm | T30: Mpa | U30: N | V30: Nmm | X30: Unit | Y30: mm | AA30: Mpa | AB30: Mpa | AC30: Mpa | AD30: Nmm | AE30: Nmm | AG30: Unit | AH30: mm | AJ30: Mpa | AK30: N | AL30: Nmm | AN30: Unit | AO30: mm | AQ30: Mpa | AR30: Mpa | AS30: Mpa | AT30: Nmm | AU30: Nmm | AW30: Unit | AX30: mm | AZ30: Mpa | BA30: N | BB30: Nmm | BD30: Unit | BE30: mm | BG30: Mpa | BH30: Mpa | BI30: Mpa | BJ30: Nmm | BK30: Nmm | BM30: Unit | BN30: mm | BP30: Mpa | BQ30: N | BR30: Nmm | BT30: Unit | BU30: mm | BW30: Mpa | BX30: Mpa | BY30: Mpa | BZ30: Nmm | CA30: Nmm
A31: SUM | E31: =+SUM(E32:E81) -> 6120000 | F31: =+SUM(F32:F81) -> 0 | H31: SUM | N31: =+SUM(N32:N43) -> 3313098.5 | O31: =+SUM(O32:O43) -> -69273877 | Q31: SUM | U31: =+SUM(U32:U81) -> 6070040.5 | V31: =+SUM(V32:V81) -> 12701906 | X31: SUM | AD31: =+SUM(AD32:AD43) -> 3077993.7 | AE31: =+SUM(AE32:AE43) -> -16442540 | AG31: SUM | AK31: =+SUM(AK32:AK81) -> 5774584.6 | AL31: =+SUM(AL32:AL81) -> 78824373 | AN31: SUM | AT31: =+SUM(AT32:AT43) -> 2597069.2 | AU31: =+SUM(AU32:AU43) -> 80054585 | AW31: SUM | BA31: =+SUM(BA32:BA81) -> 5143713.9 | BB31: =+SUM(BB32:BB81) -> 2.0751818e+08 | BD31: SUM | BJ31: =+SUM(BJ32:BJ43) -> 2132635.9 | BK31: =+SUM(BK32:BK43) -> 1.7316711e+08 | BM31: SUM | BQ31: =+SUM(BQ32:BQ81) -> 4314174.2 | BR31: =+SUM(BR32:BR81) -> 3.5258094e+08 | BT31: SUM | BZ31: =+SUM(BZ32:BZ43) -> 1684693.8 | CA31: =+SUM(CA32:CA43) -> 2.6289504e+08
A32: 1 | B32: =h/2-($A32-0.5)*G$24 -> 294 | C32: =D$25+D$26*B32 -> 0.0032875472 | D32: =+IF(C32>=0,IF(C32<=eco,1-(1-C32/eco)^n,1),0)*0.85*fck -> 25.5 | E32: =+D32*G$26 -> 122400 | F32: =+E32*B32 -> 35985600 | H32: 1 | I32: =Input!$E10 -> 230 | J32: =D$25+D$26*I32 -> 0.003154717 | K32: =J32*Es -> 630.9434 | L32: =+IF(K32>=0,IF(J32<=eco,1-(1-J32/eco)^n,1),0)*0.85*fck -> 25.5 | M32: =MAX(MIN(K32,fy),-fy)-IF(K32>=0,L32,0) -> 374.5 | N32: =IF(AND(ISNUMBER(Input!$D10),ISNUMBER(Input!$E10)),M32*As,0) -> 301190.77 | O32: =N32*I32 -> 69273877 | Q32: 1 | R32: =h/2-($Q32-0.5)*W$24 -> 294 | S32: =T$25+T$26*R32 -> 0.0032813208 | T32: =+IF(S32>=0,IF(S32<=eco,1-(1-S32/eco)^n,1),0)*0.85*fck -> 25.5 | U32: =+T32*W$26 -> 122400 | V32: =+U32*R32 -> 35985600 | X32: 1 | Y32: =Input!$E10 -> 230 | Z32: =T$25+T$26*Y32 -> 0.0030820755 | AA32: =Z32*Es -> 616.41509 | AB32: =+IF(AA32>=0,IF(Z32<=eco,1-(1-Z32/eco)^n,1),0)*0.85*fck -> 25.5 | AC32: =MAX(MIN(AA32,fy),-fy)-IF(AA32>=0,AB32,0) -> 374.5 | AD32: =IF(AND(ISNUMBER(Input!$D10),ISNUMBER(Input!$E10)),AC32*As,0) -> 301190.77 | AE32: =AD32*Y32 -> 69273877 | AG32: 1 | AH32: =h/2-($AG32-0.5)*AM$24 -> 294 | AI32: =AJ$25+AJ$26*AH32 -> 0.0032750943 | AJ32: =+IF(AI32>=0,IF(AI32<=eco,1-(1-AI32/eco)^n,1),0)*0.85*fck -> 25.5 | AK32: =+AJ32*AM$26 -> 122400 | AL32: =+AK32*AH32 -> 35985600 | AN32: 1 | AO32: =Input!$E10 -> 230 | AP32: =AJ$25+AJ$26*AO32 -> 0.003009434 | AQ32: =AP32*Es -> 601.88679 | AR32: =+IF(AQ32>=0,IF(AP32<=eco,1-(1-AP32/eco)^n,1),0)*0.85*fck -> 25.5 | AS32: =MAX(MIN(AQ32,fy),-fy)-IF(AQ32>=0,AR32,0) -> 374.5 | AT32: =IF(AND(ISNUMBER(Input!$D10),ISNUMBER(Input!$E10)),AS32*As,0) -> 301190.77 | AU32: =AT32*AO32 -> 69273877 | AW32: 1 | AX32: =h/2-($AW32-0.5)*BC$24 -> 294 | AY32: =AZ$25+AZ$26*AX32 -> 0.0032688679 | AZ32: =+IF(AY32>=0,IF(AY32<=eco,1-(1-AY32/eco)^n,1),0)*0.85*fck -> 25.5 | BA32: =+AZ32*BC$26 -> 122400 | BB32: =+BA32*AX32 -> 35985600 | BD32: 1 | BE32: =Input!$E10 -> 230 | BF32: =AZ$25+AZ$26*BE32 -> 0.0029367925 | BG32: =BF32*Es -> 587.35849 | BH32: =+IF(BG32>=0,IF(BF32<=eco,1-(1-BF32/eco)^n,1),0)*0.85*fck -> 25.5 | BI32: =MAX(MIN(BG32,fy),-fy)-IF(BG32>=0,BH32,0) -> 374.5 | BJ32: =IF(AND(ISNUMBER(Input!$D10),ISNUMBER(Input!$E10)),BI32*As,0) -> 301190.77 | BK32: =BJ32*BE32 -> 69273877 | BM32: 1 | BN32: =h/2-($BM32-0.5)*BS$24 -> 294.7 | BO32: =BP$25+BP$26*BN32 -> 0.003267 | BP32: =+IF(BO32>=0,IF(BO32<=eco,1-(1-BO32/eco)^n,1),0)*0.85*fck -> 25.5 | BQ32: =+BP32*BS$26 -> 108120 | BR32: =+BQ32*BN32 -> 31862964 | BT32: 1 | BU32: =Input!$E10 -> 230 | BV32: =BP$25+BP$26*BU32 -> 0.0028641509 | BW32: =BV32*Es -> 572.83019 | BX32: =+IF(BW32>=0,IF(BV32<=eco,1-(1-BV32/eco)^n,1),0)*0.85*fck -> 25.5 | BY32: =MAX(MIN(BW32,fy),-fy)-IF(BW32>=0,BX32,0) -> 374.5 | BZ32: =IF(AND(ISNUMBER(Input!$D10),ISNUMBER(Input!$E10)),BY32*As,0) -> 301190.77 | CA32: =BZ32*BU32 -> 69273877
A33: 2 | B33: =h/2-($A33-0.5)*G$24 -> 282 | C33: =D$25+D$26*B33 -> 0.0032626415 | D33: =+IF(C33>=0,IF(C33<=eco,1-(1-C33/eco)^n,1),0)*0.85*fck -> 25.5 | E33: =+D33*G$26 -> 122400 | F33: =+E33*B33 -> 34516800 | H33: 2 | I33: =Input!$E11 -> 230 | J33: =D$25+D$26*I33 -> 0.003154717 | K33: =J33*Es -> 630.9434 | L33: =+IF(K33>=0,IF(J33<=eco,1-(1-J33/eco)^n,1),0)*0.85*fck -> 25.5 | M33: =MAX(MIN(K33,fy),-fy)-IF(K33>=0,L33,0) -> 374.5 | N33: =IF(AND(ISNUMBER(Input!$D11),ISNUMBER(Input!$E11)),M33*As,0) -> 301190.77 | O33: =N33*I33 -> 69273877 | Q33: 2 | R33: =h/2-($Q33-0.5)*W$24 -> 282 | S33: =T$25+T$26*R33 -> 0.0032439623 | T33: =+IF(S33>=0,IF(S33<=eco,1-(1-S33/eco)^n,1),0)*0.85*fck -> 25.5 | U33: =+T33*W$26 -> 122400 | V33: =+U33*R33 -> 34516800 | X33: 2 | Y33: =Input!$E11 -> 230 | Z33: =T$25+T$26*Y33 -> 0.0030820755 | AA33: =Z33*Es -> 616.41509 | AB33: =+IF(AA33>=0,IF(Z33<=eco,1-(1-Z33/eco)^n,1),0)*0.85*fck -> 25.5 | AC33: =MAX(MIN(AA33,fy),-fy)-IF(AA33>=0,AB33,0) -> 374.5 | AD33: =IF(AND(ISNUMBER(Input!$D11),ISNUMBER(Input!$E11)),AC33*As,0) -> 301190.77 | AE33: =AD33*Y33 -> 69273877 | AG33: 2 | AH33: =h/2-($AG33-0.5)*AM$24 -> 282 | AI33: =AJ$25+AJ$26*AH33 -> 0.003225283 | AJ33: =+IF(AI33>=0,IF(AI33<=eco,1-(1-AI33/eco)^n,1),0)*0.85*fck -> 25.5 | AK33: =+AJ33*AM$26 -> 122400 | AL33: =+AK33*AH33 -> 34516800 | AN33: 2 | AO33: =Input!$E11 -> 230 | AP33: =AJ$25+AJ$26*AO33 -> 0.003009434 | AQ33: =AP33*Es -> 601.88679 | AR33: =+IF(AQ33>=0,IF(AP33<=eco,1-(1-AP33/eco)^n,1),0)*0.85*fck -> 25.5 | AS33: =MAX(MIN(AQ33,fy),-fy)-IF(AQ33>=0,AR33,0) -> 374.5 | AT33: =IF(AND(ISNUMBER(Input!$D11),ISNUMBER(Input!$E11)),AS33*As,0) -> 301190.77 | AU33: =AT33*AO33 -> 69273877 | AW33: 2 | AX33: =h/2-($AW33-0.5)*BC$24 -> 282 | AY33: =AZ$25+AZ$26*AX33 -> 0.0032066038 | AZ33: =+IF(AY33>=0,IF(AY33<=eco,1-(1-AY33/eco)^n,1),0)*0.85*fck -> 25.5 | BA33: =+AZ33*BC$26 -> 122400 | BB33: =+BA33*AX33 -> 34516800 | BD33: 2 | BE33: =Input!$E11 -> 230 | BF33: =AZ$25+AZ$26*BE33 -> 0.0029367925 | BG33: =BF33*Es -> 587.35849 | BH33: =+IF(BG33>=0,IF(BF33<=eco,1-(1-BF33/eco)^n,1),0)*0.85*fck -> 25.5 | BI33: =MAX(MIN(BG33,fy),-fy)-IF(BG33>=0,BH33,0) -> 374.5 | BJ33: =IF(AND(ISNUMBER(Input!$D11),ISNUMBER(Input!$E11)),BI33*As,0) -> 301190.77 | BK33: =BJ33*BE33 -> 69273877 | BM33: 2 | BN33: =h/2-($BM33-0.5)*BS$24 -> 284.1 | BO33: =BP$25+BP$26*BN33 -> 0.003201 | BP33: =+IF(BO33>=0,IF(BO33<=eco,1-(1-BO33/eco)^n,1),0)*0.85*fck -> 25.5 | BQ33: =+BP33*BS$26 -> 108120 | BR33: =+BQ33*BN33 -> 30716892 | BT33: 2 | BU33: =Input!$E11 -> 230 | BV33: =BP$25+BP$26*BU33 -> 0.0028641509 | BW33: =BV33*Es -> 572.83019 | BX33: =+IF(BW33>=0,IF(BV33<=eco,1-(1-BV33/eco)^n,1),0)*0.85*fck -> 25.5 | BY33: =MAX(MIN(BW33,fy),-fy)-IF(BW33>=0,BX33,0) -> 374.5 | BZ33: =IF(AND(ISNUMBER(Input!$D11),ISNUMBER(Input!$E11)),BY33*As,0) -> 301190.77 | CA33: =BZ33*BU33 -> 69273877
A34: 3 | B34: =h/2-($A34-0.5)*G$24 -> 270 | C34: =D$25+D$26*B34 -> 0.0032377358 | D34: =+IF(C34>=0,IF(C34<=eco,1-(1-C34/eco)^n,1),0)*0.85*fck -> 25.5 | E34: =+D34*G$26 -> 122400 | F34: =+E34*B34 -> 33048000 | H34: 3 | I34: =Input!$E12 -> 230 | J34: =D$25+D$26*I34 -> 0.003154717 | K34: =J34*Es -> 630.9434 | L34: =+IF(K34>=0,IF(J34<=eco,1-(1-J34/eco)^n,1),0)*0.85*fck -> 25.5 | M34: =MAX(MIN(K34,fy),-fy)-IF(K34>=0,L34,0) -> 374.5 | N34: =IF(AND(ISNUMBER(Input!$D12),ISNUMBER(Input!$E12)),M34*As,0) -> 301190.77 | O34: =N34*I34 -> 69273877 | Q34: 3 | R34: =h/2-($Q34-0.5)*W$24 -> 270 | S34: =T$25+T$26*R34 -> 0.0032066038 | T34: =+IF(S34>=0,IF(S34<=eco,1-(1-S34/eco)^n,1),0)*0.85*fck -> 25.5 | U34: =+T34*W$26 -> 122400 | V34: =+U34*R34 -> 33048000 | X34: 3 | Y34: =Input!$E12 -> 230 | Z34: =T$25+T$26*Y34 -> 0.0030820755 | AA34: =Z34*Es -> 616.41509 | AB34: =+IF(AA34>=0,IF(Z34<=eco,1-(1-Z34/eco)^n,1),0)*0.85*fck -> 25.5 | AC34: =MAX(MIN(AA34,fy),-fy)-IF(AA34>=0,AB34,0) -> 374.5 | AD34: =IF(AND(ISNUMBER(Input!$D12),ISNUMBER(Input!$E12)),AC34*As,0) -> 301190.77 | AE34: =AD34*Y34 -> 69273877 | AG34: 3 | AH34: =h/2-($AG34-0.5)*AM$24 -> 270 | AI34: =AJ$25+AJ$26*AH34 -> 0.0031754717 | AJ34: =+IF(AI34>=0,IF(AI34<=eco,1-(1-AI34/eco)^n,1),0)*0.85*fck -> 25.5 | AK34: =+AJ34*AM$26 -> 122400 | AL34: =+AK34*AH34 -> 33048000 | AN34: 3 | AO34: =Input!$E12 -> 230 | AP34: =AJ$25+AJ$26*AO34 -> 0.003009434 | AQ34: =AP34*Es -> 601.88679 | AR34: =+IF(AQ34>=0,IF(AP34<=eco,1-(1-AP34/eco)^n,1),0)*0.85*fck -> 25.5 | AS34: =MAX(MIN(AQ34,fy),-fy)-IF(AQ34>=0,AR34,0) -> 374.5 | AT34: =IF(AND(ISNUMBER(Input!$D12),ISNUMBER(Input!$E12)),AS34*As,0) -> 301190.77 | AU34: =AT34*AO34 -> 69273877 | AW34: 3 | AX34: =h/2-($AW34-0.5)*BC$24 -> 270 | AY34: =AZ$25+AZ$26*AX34 -> 0.0031443396 | AZ34: =+IF(AY34>=0,IF(AY34<=eco,1-(1-AY34/eco)^n,1),0)*0.85*fck -> 25.5 | BA34: =+AZ34*BC$26 -> 122400 | BB34: =+BA34*AX34 -> 33048000 | BD34: 3 | BE34: =Input!$E12 -> 230 | BF34: =AZ$25+AZ$26*BE34 -> 0.0029367925 | BG34: =BF34*Es -> 587.35849 | BH34: =+IF(BG34>=0,IF(BF34<=eco,1-(1-BF34/eco)^n,1),0)*0.85*fck -> 25.5 | BI34: =MAX(MIN(BG34,fy),-fy)-IF(BG34>=0,BH34,0) -> 374.5 | BJ34: =IF(AND(ISNUMBER(Input!$D12),ISNUMBER(Input!$E12)),BI34*As,0) -> 301190.77 | BK34: =BJ34*BE34 -> 69273877 | BM34: 3 | BN34: =h/2-($BM34-0.5)*BS$24 -> 273.5 | BO34: =BP$25+BP$26*BN34 -> 0.003135 | BP34: =+IF(BO34>=0,IF(BO34<=eco,1-(1-BO34/eco)^n,1),0)*0.85*fck -> 25.5 | BQ34: =+BP34*BS$26 -> 108120 | BR34: =+BQ34*BN34 -> 29570820 | BT34: 3 | BU34: =Input!$E12 -> 230 | BV34: =BP$25+BP$26*BU34 -> 0.0028641509 | BW34: =BV34*Es -> 572.83019 | BX34: =+IF(BW34>=0,IF(BV34<=eco,1-(1-BV34/eco)^n,1),0)*0.85*fck -> 25.5 | BY34: =MAX(MIN(BW34,fy),-fy)-IF(BW34>=0,BX34,0) -> 374.5 | BZ34: =IF(AND(ISNUMBER(Input!$D12),ISNUMBER(Input!$E12)),BY34*As,0) -> 301190.77 | CA34: =BZ34*BU34 -> 69273877
A35: 4 | B35: =h/2-($A35-0.5)*G$24 -> 258 | C35: =D$25+D$26*B35 -> 0.0032128302 | D35: =+IF(C35>=0,IF(C35<=eco,1-(1-C35/eco)^n,1),0)*0.85*fck -> 25.5 | E35: =+D35*G$26 -> 122400 | F35: =+E35*B35 -> 31579200 | H35: 4 | I35: =Input!$E13 -> 0 | J35: =D$25+D$26*I35 -> 0.0026773585 | K35: =J35*Es -> 535.4717 | L35: =+IF(K35>=0,IF(J35<=eco,1-(1-J35/eco)^n,1),0)*0.85*fck -> 25.5 | M35: =MAX(MIN(K35,fy),-fy)-IF(K35>=0,L35,0) -> 374.5 | N35: =IF(AND(ISNUMBER(Input!$D13),ISNUMBER(Input!$E13)),M35*As,0) -> 0 | O35: =N35*I35 -> 0 | Q35: 4 | R35: =h/2-($Q35-0.5)*W$24 -> 258 | S35: =T$25+T$26*R35 -> 0.0031692453 | T35: =+IF(S35>=0,IF(S35<=eco,1-(1-S35/eco)^n,1),0)*0.85*fck -> 25.5 | U35: =+T35*W$26 -> 122400 | V35: =+U35*R35 -> 31579200 | X35: 4 | Y35: =Input!$E13 -> 0 | Z35: =T$25+T$26*Y35 -> 0.0023660377 | AA35: =Z35*Es -> 473.20755 | AB35: =+IF(AA35>=0,IF(Z35<=eco,1-(1-Z35/eco)^n,1),0)*0.85*fck -> 25.5 | AC35: =MAX(MIN(AA35,fy),-fy)-IF(AA35>=0,AB35,0) -> 374.5 | AD35: =IF(AND(ISNUMBER(Input!$D13),ISNUMBER(Input!$E13)),AC35*As,0) -> 0 | AE35: =AD35*Y35 -> 0 | AG35: 4 | AH35: =h/2-($AG35-0.5)*AM$24 -> 258 | AI35: =AJ$25+AJ$26*AH35 -> 0.0031256604 | AJ35: =+IF(AI35>=0,IF(AI35<=eco,1-(1-AI35/eco)^n,1),0)*0.85*fck -> 25.5 | AK35: =+AJ35*AM$26 -> 122400 | AL35: =+AK35*AH35 -> 31579200 | AN35: 4 | AO35: =Input!$E13 -> 0 | AP35: =AJ$25+AJ$26*AO35 -> 0.002054717 | AQ35: =AP35*Es -> 410.9434 | AR35: =+IF(AQ35>=0,IF(AP35<=eco,1-(1-AP35/eco)^n,1),0)*0.85*fck -> 25.5 | AS35: =MAX(MIN(AQ35,fy),-fy)-IF(AQ35>=0,AR35,0) -> 374.5 | AT35: =IF(AND(ISNUMBER(Input!$D13),ISNUMBER(Input!$E13)),AS35*As,0) -> 0 | AU35: =AT35*AO35 -> 0 | AW35: 4 | AX35: =h/2-($AW35-0.5)*BC$24 -> 258 | AY35: =AZ$25+AZ$26*AX35 -> 0.0030820755 | AZ35: =+IF(AY35>=0,IF(AY35<=eco,1-(1-AY35/eco)^n,1),0)*0.85*fck -> 25.5 | BA35: =+AZ35*BC$26 -> 122400 | BB35: =+BA35*AX35 -> 31579200 | BD35: 4 | BE35: =Input!$E13 -> 0 | BF35: =AZ$25+AZ$26*BE35 -> 0.0017433962 | BG35: =BF35*Es -> 348.67925 | BH35: =+IF(BG35>=0,IF(BF35<=eco,1-(1-BF35/eco)^n,1),0)*0.85*fck -> 25.080235 | BI35: =MAX(MIN(BG35,fy),-fy)-IF(BG35>=0,BH35,0) -> 323.59901 | BJ35: =IF(AND(ISNUMBER(Input!$D13),ISNUMBER(Input!$E13)),BI35*As,0) -> 0 | BK35: =BJ35*BE35 -> 0 | BM35: 4 | BN35: =h/2-($BM35-0.5)*BS$24 -> 262.9 | BO35: =BP$25+BP$26*BN35 -> 0.003069 | BP35: =+IF(BO35>=0,IF(BO35<=eco,1-(1-BO35/eco)^n,1),0)*0.85*fck -> 25.5 | BQ35: =+BP35*BS$26 -> 108120 | BR35: =+BQ35*BN35 -> 28424748 | BT35: 4 | BU35: =Input!$E13 -> 0 | BV35: =BP$25+BP$26*BU35 -> 0.0014320755 | BW35: =BV35*Es -> 286.41509 | BX35: =+IF(BW35>=0,IF(BV35<=eco,1-(1-BV35/eco)^n,1),0)*0.85*fck -> 23.443819 | BY35: =MAX(MIN(BW35,fy),-fy)-IF(BW35>=0,BX35,0) -> 262.97128 | BZ35: =IF(AND(ISNUMBER(Input!$D13),ISNUMBER(Input!$E13)),BY35*As,0) -> 0 | CA35: =BZ35*BU35 -> 0
A36: 5 | B36: =h/2-($A36-0.5)*G$24 -> 246 | C36: =D$25+D$26*B36 -> 0.0031879245 | D36: =+IF(C36>=0,IF(C36<=eco,1-(1-C36/eco)^n,1),0)*0.85*fck -> 25.5 | E36: =+D36*G$26 -> 122400 | F36: =+E36*B36 -> 30110400 | H36: 5 | I36: =Input!$E14 -> -230 | J36: =D$25+D$26*I36 -> 0.0022 | K36: =J36*Es -> 440 | L36: =+IF(K36>=0,IF(J36<=eco,1-(1-J36/eco)^n,1),0)*0.85*fck -> 25.5 | M36: =MAX(MIN(K36,fy),-fy)-IF(K36>=0,L36,0) -> 374.5 | N36: =IF(AND(ISNUMBER(Input!$D14),ISNUMBER(Input!$E14)),M36*As,0) -> 301190.77 | O36: =N36*I36 -> -69273877 | Q36: 5 | R36: =h/2-($Q36-0.5)*W$24 -> 246 | S36: =T$25+T$26*R36 -> 0.0031318868 | T36: =+IF(S36>=0,IF(S36<=eco,1-(1-S36/eco)^n,1),0)*0.85*fck -> 25.5 | U36: =+T36*W$26 -> 122400 | V36: =+U36*R36 -> 30110400 | X36: 5 | Y36: =Input!$E14 -> -230 | Z36: =T$25+T$26*Y36 -> 0.00165 | AA36: =Z36*Es -> 330 | AB36: =+IF(AA36>=0,IF(Z36<=eco,1-(1-Z36/eco)^n,1),0)*0.85*fck -> 24.719062 | AC36: =MAX(MIN(AA36,fy),-fy)-IF(AA36>=0,AB36,0) -> 305.28094 | AD36: =IF(AND(ISNUMBER(Input!$D14),ISNUMBER(Input!$E14)),AC36*As,0) -> 245521.5 | AE36: =AD36*Y36 -> -56469944 | AG36: 5 | AH36: =h/2-($AG36-0.5)*AM$24 -> 246 | AI36: =AJ$25+AJ$26*AH36 -> 0.0030758491 | AJ36: =+IF(AI36>=0,IF(AI36<=eco,1-(1-AI36/eco)^n,1),0)*0.85*fck -> 25.5 | AK36: =+AJ36*AM$26 -> 122400 | AL36: =+AK36*AH36 -> 30110400 | AN36: 5 | AO36: =Input!$E14 -> -230 | AP36: =AJ$25+AJ$26*AO36 -> 0.0011 | AQ36: =AP36*Es -> 220 | AR36: =+IF(AQ36>=0,IF(AP36<=eco,1-(1-AP36/eco)^n,1),0)*0.85*fck -> 20.33625 | AS36: =MAX(MIN(AQ36,fy),-fy)-IF(AQ36>=0,AR36,0) -> 199.66375 | AT36: =IF(AND(ISNUMBER(Input!$D14),ISNUMBER(Input!$E14)),AS36*As,0) -> 160579.12 | AU36: =AT36*AO36 -> -36933197 | AW36: 5 | AX36: =h/2-($AW36-0.5)*BC$24 -> 246 | AY36: =AZ$25+AZ$26*AX36 -> 0.0030198113 | AZ36: =+IF(AY36>=0,IF(AY36<=eco,1-(1-AY36/eco)^n,1),0)*0.85*fck -> 25.5 | BA36: =+AZ36*BC$26 -> 122400 | BB36: =+BA36*AX36 -> 30110400 | BD36: 5 | BE36: =Input!$E14 -> -230 | BF36: =AZ$25+AZ$26*BE36 -> 0.00055 | BG36: =BF36*Es -> 110 | BH36: =+IF(BG36>=0,IF(BF36<=eco,1-(1-BF36/eco)^n,1),0)*0.85*fck -> 12.096562 | BI36: =MAX(MIN(BG36,fy),-fy)-IF(BG36>=0,BH36,0) -> 97.903437 | BJ36: =IF(AND(ISNUMBER(Input!$D14),ISNUMBER(Input!$E14)),BI36*As,0) -> 78738.616 | BK36: =BJ36*BE36 -> -18109882 | BM36: 5 | BN36: =h/2-($BM36-0.5)*BS$24 -> 252.3 | BO36: =BP$25+BP$26*BN36 -> 0.003003 | BP36: =+IF(BO36>=0,IF(BO36<=eco,1-(1-BO36/eco)^n,1),0)*0.85*fck -> 25.5 | BQ36: =+BP36*BS$26 -> 108120 | BR36: =+BQ36*BN36 -> 27278676 | BT36: 5 | BU36: =Input!$E14 -> -230 | BV36: =BP$25+BP$26*BU36 -> 0 | BW36: =BV36*Es -> 0 | BX36: =+IF(BW36>=0,IF(BV36<=eco,1-(1-BV36/eco)^n,1),0)*0.85*fck -> 0 | BY36: =MAX(MIN(BW36,fy),-fy)-IF(BW36>=0,BX36,0) -> 0 | BZ36: =IF(AND(ISNUMBER(Input!$D14),ISNUMBER(Input!$E14)),BY36*As,0) -> 0 | CA36: =BZ36*BU36 -> 0
A37: 6 | B37: =h/2-($A37-0.5)*G$24 -> 234 | C37: =D$25+D$26*B37 -> 0.0031630189 | D37: =+IF(C37>=0,IF(C37<=eco,1-(1-C37/eco)^n,1),0)*0.85*fck -> 25.5 | E37: =+D37*G$26 -> 122400 | F37: =+E37*B37 -> 28641600 | H37: 6 | I37: =Input!$E15 -> -230 | J37: =D$25+D$26*I37 -> 0.0022 | K37: =J37*Es -> 440 | L37: =+IF(K37>=0,IF(J37<=eco,1-(1-J37/eco)^n,1),0)*0.85*fck -> 25.5 | M37: =MAX(MIN(K37,fy),-fy)-IF(K37>=0,L37,0) -> 374.5 | N37: =IF(AND(ISNUMBER(Input!$D15),ISNUMBER(Input!$E15)),M37*As,0) -> 301190.77 | O37: =N37*I37 -> -69273877 | Q37: 6 | R37: =h/2-($Q37-0.5)*W$24 -> 234 | S37: =T$25+T$26*R37 -> 0.0030945283 | T37: =+IF(S37>=0,IF(S37<=eco,1-(1-S37/eco)^n,1),0)*0.85*fck -> 25.5 | U37: =+T37*W$26 -> 122400 | V37: =+U37*R37 -> 28641600 | X37: 6 | Y37: =Input!$E15 -> -230 | Z37: =T$25+T$26*Y37 -> 0.00165 | AA37: =Z37*Es -> 330 | AB37: =+IF(AA37>=0,IF(Z37<=eco,1-(1-Z37/eco)^n,1),0)*0.85*fck -> 24.719062 | AC37: =MAX(MIN(AA37,fy),-fy)-IF(AA37>=0,AB37,0) -> 305.28094 | AD37: =IF(AND(ISNUMBER(Input!$D15),ISNUMBER(Input!$E15)),AC37*As,0) -> 245521.5 | AE37: =AD37*Y37 -> -56469944 | AG37: 6 | AH37: =h/2-($AG37-0.5)*AM$24 -> 234 | AI37: =AJ$25+AJ$26*AH37 -> 0.0030260377 | AJ37: =+IF(AI37>=0,IF(AI37<=eco,1-(1-AI37/eco)^n,1),0)*0.85*fck -> 25.5 | AK37: =+AJ37*AM$26 -> 122400 | AL37: =+AK37*AH37 -> 28641600 | AN37: 6 | AO37: =Input!$E15 -> -230 | AP37: =AJ$25+AJ$26*AO37 -> 0.0011 | AQ37: =AP37*Es -> 220 | AR37: =+IF(AQ37>=0,IF(AP37<=eco,1-(1-AP37/eco)^n,1),0)*0.85*fck -> 20.33625 | AS37: =MAX(MIN(AQ37,fy),-fy)-IF(AQ37>=0,AR37,0) -> 199.66375 | AT37: =IF(AND(ISNUMBER(Input!$D15),ISNUMBER(Input!$E15)),AS37*As,0) -> 160579.12 | AU37: =AT37*AO37 -> -36933197 | AW37: 6 | AX37: =h/2-($AW37-0.5)*BC$24 -> 234 | AY37: =AZ$25+AZ$26*AX37 -> 0.0029575472 | AZ37: =+IF(AY37>=0,IF(AY37<=eco,1-(1-AY37/eco)^n,1),0)*0.85*fck -> 25.5 | BA37: =+AZ37*BC$26 -> 122400 | BB37: =+BA37*AX37 -> 28641600 | BD37: 6 | BE37: =Input!$E15 -> -230 | BF37: =AZ$25+AZ$26*BE37 -> 0.00055 | BG37: =BF37*Es -> 110 | BH37: =+IF(BG37>=0,IF(BF37<=eco,1-(1-BF37/eco)^n,1),0)*0.85*fck -> 12.096562 | BI37: =MAX(MIN(BG37,fy),-fy)-IF(BG37>=0,BH37,0) -> 97.903437 | BJ37: =IF(AND(ISNUMBER(Input!$D15),ISNUMBER(Input!$E15)),BI37*As,0) -> 78738.616 | BK37: =BJ37*BE37 -> -18109882 | BM37: 6 | BN37: =h/2-($BM37-0.5)*BS$24 -> 241.7 | BO37: =BP$25+BP$26*BN37 -> 0.002937 | BP37: =+IF(BO37>=0,IF(BO37<=eco,1-(1-BO37/eco)^n,1),0)*0.85*fck -> 25.5 | BQ37: =+BP37*BS$26 -> 108120 | BR37: =+BQ37*BN37 -> 26132604 | BT37: 6 | BU37: =Input!$E15 -> -230 | BV37: =BP$25+BP$26*BU37 -> 0 | BW37: =BV37*Es -> 0 | BX37: =+IF(BW37>=0,IF(BV37<=eco,1-(1-BV37/eco)^n,1),0)*0.85*fck -> 0 | BY37: =MAX(MIN(BW37,fy),-fy)-IF(BW37>=0,BX37,0) -> 0 | BZ37: =IF(AND(ISNUMBER(Input!$D15),ISNUMBER(Input!$E15)),BY37*As,0) -> 0 | CA37: =BZ37*BU37 -> 0
A38: 7 | B38: =h/2-($A38-0.5)*G$24 -> 222 | C38: =D$25+D$26*B38 -> 0.0031381132 | D38: =+IF(C38>=0,IF(C38<=eco,1-(1-C38/eco)^n,1),0)*0.85*fck -> 25.5 | E38: =+D38*G$26 -> 122400 | F38: =+E38*B38 -> 27172800 | H38: 7 | I38: =Input!$E16 -> -230 | J38: =D$25+D$26*I38 -> 0.0022 | K38: =J38*Es -> 440 | L38: =+IF(K38>=0,IF(J38<=eco,1-(1-J38/eco)^n,1),0)*0.85*fck -> 25.5 | M38: =MAX(MIN(K38,fy),-fy)-IF(K38>=0,L38,0) -> 374.5 | N38: =IF(AND(ISNUMBER(Input!$D16),ISNUMBER(Input!$E16)),M38*As,0) -> 301190.77 | O38: =N38*I38 -> -69273877 | Q38: 7 | R38: =h/2-($Q38-0.5)*W$24 -> 222 | S38: =T$25+T$26*R38 -> 0.0030571698 | T38: =+IF(S38>=0,IF(S38<=eco,1-(1-S38/eco)^n,1),0)*0.85*fck -> 25.5 | U38: =+T38*W$26 -> 122400 | V38: =+U38*R38 -> 27172800 | X38: 7 | Y38: =Input!$E16 -> -230 | Z38: =T$25+T$26*Y38 -> 0.00165 | AA38: =Z38*Es -> 330 | AB38: =+IF(AA38>=0,IF(Z38<=eco,1-(1-Z38/eco)^n,1),0)*0.85*fck -> 24.719062 | AC38: =MAX(MIN(AA38,fy),-fy)-IF(AA38>=0,AB38,0) -> 305.28094 | AD38: =IF(AND(ISNUMBER(Input!$D16),ISNUMBER(Input!$E16)),AC38*As,0) -> 245521.5 | AE38: =AD38*Y38 -> -56469944 | AG38: 7 | AH38: =h/2-($AG38-0.5)*AM$24 -> 222 | AI38: =AJ$25+AJ$26*AH38 -> 0.0029762264 | AJ38: =+IF(AI38>=0,IF(AI38<=eco,1-(1-AI38/eco)^n,1),0)*0.85*fck -> 25.5 | AK38: =+AJ38*AM$26 -> 122400 | AL38: =+AK38*AH38 -> 27172800 | AN38: 7 | AO38: =Input!$E16 -> -230 | AP38: =AJ$25+AJ$26*AO38 -> 0.0011 | AQ38: =AP38*Es -> 220 | AR38: =+IF(AQ38>=0,IF(AP38<=eco,1-(1-AP38/eco)^n,1),0)*0.85*fck -> 20.33625 | AS38: =MAX(MIN(AQ38,fy),-fy)-IF(AQ38>=0,AR38,0) -> 199.66375 | AT38: =IF(AND(ISNUMBER(Input!$D16),ISNUMBER(Input!$E16)),AS38*As,0) -> 160579.12 | AU38: =AT38*AO38 -> -36933197 | AW38: 7 | AX38: =h/2-($AW38-0.5)*BC$24 -> 222 | AY38: =AZ$25+AZ$26*AX38 -> 0.002895283 | AZ38: =+IF(AY38>=0,IF(AY38<=eco,1-(1-AY38/eco)^n,1),0)*0.85*fck -> 25.5 | BA38: =+AZ38*BC$26 -> 122400 | BB38: =+BA38*AX38 -> 27172800 | BD38: 7 | BE38: =Input!$E16 -> -230 | BF38: =AZ$25+AZ$26*BE38 -> 0.00055 | BG38: =BF38*Es -> 110 | BH38: =+IF(BG38>=0,IF(BF38<=eco,1-(1-BF38/eco)^n,1),0)*0.85*fck -> 12.096562 | BI38: =MAX(MIN(BG38,fy),-fy)-IF(BG38>=0,BH38,0) -> 97.903437 | BJ38: =IF(AND(ISNUMBER(Input!$D16),ISNUMBER(Input!$E16)),BI38*As,0) -> 78738.616 | BK38: =BJ38*BE38 -> -18109882 | BM38: 7 | BN38: =h/2-($BM38-0.5)*BS$24 -> 231.1 | BO38: =BP$25+BP$26*BN38 -> 0.002871 | BP38: =+IF(BO38>=0,IF(BO38<=eco,1-(1-BO38/eco)^n,1),0)*0.85*fck -> 25.5 | BQ38: =+BP38*BS$26 -> 108120 | BR38: =+BQ38*BN38 -> 24986532 | BT38: 7 | BU38: =Input!$E16 -> -230 | BV38: =BP$25+BP$26*BU38 -> 0 | BW38: =BV38*Es -> 0 | BX38: =+IF(BW38>=0,IF(BV38<=eco,1-(1-BV38/eco)^n,1),0)*0.85*fck -> 0 | BY38: =MAX(MIN(BW38,fy),-fy)-IF(BW38>=0,BX38,0) -> 0 | BZ38: =IF(AND(ISNUMBER(Input!$D16),ISNUMBER(Input!$E16)),BY38*As,0) -> 0 | CA38: =BZ38*BU38 -> 0
A39: 8 | B39: =h/2-($A39-0.5)*G$24 -> 210 | C39: =D$25+D$26*B39 -> 0.0031132075 | D39: =+IF(C39>=0,IF(C39<=eco,1-(1-C39/eco)^n,1),0)*0.85*fck -> 25.5 | E39: =+D39*G$26 -> 122400 | F39: =+E39*B39 -> 25704000 | H39: 8 | I39: =Input!$E17 -> -230 | J39: =D$25+D$26*I39 -> 0.0022 | K39: =J39*Es -> 440 | L39: =+IF(K39>=0,IF(J39<=eco,1-(1-J39/eco)^n,1),0)*0.85*fck -> 25.5 | M39: =MAX(MIN(K39,fy),-fy)-IF(K39>=0,L39,0) -> 374.5 | N39: =IF(AND(ISNUMBER(Input!$D17),ISNUMBER(Input!$E17)),M39*As,0) -> 301190.77 | O39: =N39*I39 -> -69273877 | Q39: 8 | R39: =h/2-($Q39-0.5)*W$24 -> 210 | S39: =T$25+T$26*R39 -> 0.0030198113 | T39: =+IF(S39>=0,IF(S39<=eco,1-(1-S39/eco)^n,1),0)*0.85*fck -> 25.5 | U39: =+T39*W$26 -> 122400 | V39: =+U39*R39 -> 25704000 | X39: 8 | Y39: =Input!$E17 -> -230 | Z39: =T$25+T$26*Y39 -> 0.00165 | AA39: =Z39*Es -> 330 | AB39: =+IF(AA39>=0,IF(Z39<=eco,1-(1-Z39/eco)^n,1),0)*0.85*fck -> 24.719062 | AC39: =MAX(MIN(AA39,fy),-fy)-IF(AA39>=0,AB39,0) -> 305.28094 | AD39: =IF(AND(ISNUMBER(Input!$D17),ISNUMBER(Input!$E17)),AC39*As,0) -> 245521.5 | AE39: =AD39*Y39 -> -56469944 | AG39: 8 | AH39: =h/2-($AG39-0.5)*AM$24 -> 210 | AI39: =AJ$25+AJ$26*AH39 -> 0.0029264151 | AJ39: =+IF(AI39>=0,IF(AI39<=eco,1-(1-AI39/eco)^n,1),0)*0.85*fck -> 25.5 | AK39: =+AJ39*AM$26 -> 122400 | AL39: =+AK39*AH39 -> 25704000 | AN39: 8 | AO39: =Input!$E17 -> -230 | AP39: =AJ$25+AJ$26*AO39 -> 0.0011 | AQ39: =AP39*Es -> 220 | AR39: =+IF(AQ39>=0,IF(AP39<=eco,1-(1-AP39/eco)^n,1),0)*0.85*fck -> 20.33625 | AS39: =MAX(MIN(AQ39,fy),-fy)-IF(AQ39>=0,AR39,0) -> 199.66375 | AT39: =IF(AND(ISNUMBER(Input!$D17),ISNUMBER(Input!$E17)),AS39*As,0) -> 160579.12 | AU39: =AT39*AO39 -> -36933197 | AW39: 8 | AX39: =h/2-($AW39-0.5)*BC$24 -> 210 | AY39: =AZ$25+AZ$26*AX39 -> 0.0028330189 | AZ39: =+IF(AY39>=0,IF(AY39<=eco,1-(1-AY39/eco)^n,1),0)*0.85*fck -> 25.5 | BA39: =+AZ39*BC$26 -> 122400 | BB39: =+BA39*AX39 -> 25704000 | BD39: 8 | BE39: =Input!$E17 -> -230 | BF39: =AZ$25+AZ$26*BE39 -> 0.00055 | BG39: =BF39*Es -> 110 | BH39: =+IF(BG39>=0,IF(BF39<=eco,1-(1-BF39/eco)^n,1),0)*0.85*fck -> 12.096562 | BI39: =MAX(MIN(BG39,fy),-fy)-IF(BG39>=0,BH39,0) -> 97.903437 | BJ39: =IF(AND(ISNUMBER(Input!$D17),ISNUMBER(Input!$E17)),BI39*As,0) -> 78738.616 | BK39: =BJ39*BE39 -> -18109882 | BM39: 8 | BN39: =h/2-($BM39-0.5)*BS$24 -> 220.5 | BO39: =BP$25+BP$26*BN39 -> 0.002805 | BP39: =+IF(BO39>=0,IF(BO39<=eco,1-(1-BO39/eco)^n,1),0)*0.85*fck -> 25.5 | BQ39: =+BP39*BS$26 -> 108120 | BR39: =+BQ39*BN39 -> 23840460 | BT39: 8 | BU39: =Input!$E17 -> -230 | BV39: =BP$25+BP$26*BU39 -> 0 | BW39: =BV39*Es -> 0 | BX39: =+IF(BW39>=0,IF(BV39<=eco,1-(1-BV39/eco)^n,1),0)*0.85*fck -> 0 | BY39: =MAX(MIN(BW39,fy),-fy)-IF(BW39>=0,BX39,0) -> 0 | BZ39: =IF(AND(ISNUMBER(Input!$D17),ISNUMBER(Input!$E17)),BY39*As,0) -> 0 | CA39: =BZ39*BU39 -> 0
A40: 9 | B40: =h/2-($A40-0.5)*G$24 -> 198 | C40: =D$25+D$26*B40 -> 0.0030883019 | D40: =+IF(C40>=0,IF(C40<=eco,1-(1-C40/eco)^n,1),0)*0.85*fck -> 25.5 | E40: =+D40*G$26 -> 122400 | F40: =+E40*B40 -> 24235200 | H40: 9 | I40: =Input!$E18 -> 130 | J40: =D$25+D$26*I40 -> 0.0029471698 | K40: =J40*Es -> 589.43396 | L40: =+IF(K40>=0,IF(J40<=eco,1-(1-J40/eco)^n,1),0)*0.85*fck -> 25.5 | M40: =MAX(MIN(K40,fy),-fy)-IF(K40>=0,L40,0) -> 374.5 | N40: =IF(AND(ISNUMBER(Input!$D18),ISNUMBER(Input!$E18)),M40*As,0) -> 301190.77 | O40: =N40*I40 -> 39154800 | Q40: 9 | R40: =h/2-($Q40-0.5)*W$24 -> 198 | S40: =T$25+T$26*R40 -> 0.0029824528 | T40: =+IF(S40>=0,IF(S40<=eco,1-(1-S40/eco)^n,1),0)*0.85*fck -> 25.5 | U40: =+T40*W$26 -> 122400 | V40: =+U40*R40 -> 24235200 | X40: 9 | Y40: =Input!$E18 -> 130 | Z40: =T$25+T$26*Y40 -> 0.0027707547 | AA40: =Z40*Es -> 554.15094 | AB40: =+IF(AA40>=0,IF(Z40<=eco,1-(1-Z40/eco)^n,1),0)*0.85*fck -> 25.5 | AC40: =MAX(MIN(AA40,fy),-fy)-IF(AA40>=0,AB40,0) -> 374.5 | AD40: =IF(AND(ISNUMBER(Input!$D18),ISNUMBER(Input!$E18)),AC40*As,0) -> 301190.77 | AE40: =AD40*Y40 -> 39154800 | AG40: 9 | AH40: =h/2-($AG40-0.5)*AM$24 -> 198 | AI40: =AJ$25+AJ$26*AH40 -> 0.0028766038 | AJ40: =+IF(AI40>=0,IF(AI40<=eco,1-(1-AI40/eco)^n,1),0)*0.85*fck -> 25.5 | AK40: =+AJ40*AM$26 -> 122400 | AL40: =+AK40*AH40 -> 24235200 | AN40: 9 | AO40: =Input!$E18 -> 130 | AP40: =AJ$25+AJ$26*AO40 -> 0.0025943396 | AQ40: =AP40*Es -> 518.86792 | AR40: =+IF(AQ40>=0,IF(AP40<=eco,1-(1-AP40/eco)^n,1),0)*0.85*fck -> 25.5 | AS40: =MAX(MIN(AQ40,fy),-fy)-IF(AQ40>=0,AR40,0) -> 374.5 | AT40: =IF(AND(ISNUMBER(Input!$D18),ISNUMBER(Input!$E18)),AS40*As,0) -> 301190.77 | AU40: =AT40*AO40 -> 39154800 | AW40: 9 | AX40: =h/2-($AW40-0.5)*BC$24 -> 198 | AY40: =AZ$25+AZ$26*AX40 -> 0.0027707547 | AZ40: =+IF(AY40>=0,IF(AY40<=eco,1-(1-AY40/eco)^n,1),0)*0.85*fck -> 25.5 | BA40: =+AZ40*BC$26 -> 122400 | BB40: =+BA40*AX40 -> 24235200 | BD40: 9 | BE40: =Input!$E18 -> 130 | BF40: =AZ$25+AZ$26*BE40 -> 0.0024179245 | BG40: =BF40*Es -> 483.58491 | BH40: =+IF(BG40>=0,IF(BF40<=eco,1-(1-BF40/eco)^n,1),0)*0.85*fck -> 25.5 | BI40: =MAX(MIN(BG40,fy),-fy)-IF(BG40>=0,BH40,0) -> 374.5 | BJ40: =IF(AND(ISNUMBER(Input!$D18),ISNUMBER(Input!$E18)),BI40*As,0) -> 301190.77 | BK40: =BJ40*BE40 -> 39154800 | BM40: 9 | BN40: =h/2-($BM40-0.5)*BS$24 -> 209.9 | BO40: =BP$25+BP$26*BN40 -> 0.002739 | BP40: =+IF(BO40>=0,IF(BO40<=eco,1-(1-BO40/eco)^n,1),0)*0.85*fck -> 25.5 | BQ40: =+BP40*BS$26 -> 108120 | BR40: =+BQ40*BN40 -> 22694388 | BT40: 9 | BU40: =Input!$E18 -> 130 | BV40: =BP$25+BP$26*BU40 -> 0.0022415094 | BW40: =BV40*Es -> 448.30189 | BX40: =+IF(BW40>=0,IF(BV40<=eco,1-(1-BV40/eco)^n,1),0)*0.85*fck -> 25.5 | BY40: =MAX(MIN(BW40,fy),-fy)-IF(BW40>=0,BX40,0) -> 374.5 | BZ40: =IF(AND(ISNUMBER(Input!$D18),ISNUMBER(Input!$E18)),BY40*As,0) -> 301190.77 | CA40: =BZ40*BU40 -> 39154800
A41: 10 | B41: =h/2-($A41-0.5)*G$24 -> 186 | C41: =D$25+D$26*B41 -> 0.0030633962 | D41: =+IF(C41>=0,IF(C41<=eco,1-(1-C41/eco)^n,1),0)*0.85*fck -> 25.5 | E41: =+D41*G$26 -> 122400 | F41: =+E41*B41 -> 22766400 | H41: 10 | I41: =Input!$E19 -> 130 | J41: =D$25+D$26*I41 -> 0.0029471698 | K41: =J41*Es -> 589.43396 | L41: =+IF(K41>=0,IF(J41<=eco,1-(1-J41/eco)^n,1),0)*0.85*fck -> 25.5 | M41: =MAX(MIN(K41,fy),-fy)-IF(K41>=0,L41,0) -> 374.5 | N41: =IF(AND(ISNUMBER(Input!$D19),ISNUMBER(Input!$E19)),M41*As,0) -> 301190.77 | O41: =N41*I41 -> 39154800 | Q41: 10 | R41: =h/2-($Q41-0.5)*W$24 -> 186 | S41: =T$25+T$26*R41 -> 0.0029450943 | T41: =+IF(S41>=0,IF(S41<=eco,1-(1-S41/eco)^n,1),0)*0.85*fck -> 25.5 | U41: =+T41*W$26 -> 122400 | V41: =+U41*R41 -> 22766400 | X41: 10 | Y41: =Input!$E19 -> 130 | Z41: =T$25+T$26*Y41 -> 0.0027707547 | AA41: =Z41*Es -> 554.15094 | AB41: =+IF(AA41>=0,IF(Z41<=eco,1-(1-Z41/eco)^n,1),0)*0.85*fck -> 25.5 | AC41: =MAX(MIN(AA41,fy),-fy)-IF(AA41>=0,AB41,0) -> 374.5 | AD41: =IF(AND(ISNUMBER(Input!$D19),ISNUMBER(Input!$E19)),AC41*As,0) -> 301190.77 | AE41: =AD41*Y41 -> 39154800 | AG41: 10 | AH41: =h/2-($AG41-0.5)*AM$24 -> 186 | AI41: =AJ$25+AJ$26*AH41 -> 0.0028267925 | AJ41: =+IF(AI41>=0,IF(AI41<=eco,1-(1-AI41/eco)^n,1),0)*0.85*fck -> 25.5 | AK41: =+AJ41*AM$26 -> 122400 | AL41: =+AK41*AH41 -> 22766400 | AN41: 10 | AO41: =Input!$E19 -> 130 | AP41: =AJ$25+AJ$26*AO41 -> 0.0025943396 | AQ41: =AP41*Es -> 518.86792 | AR41: =+IF(AQ41>=0,IF(AP41<=eco,1-(1-AP41/eco)^n,1),0)*0.85*fck -> 25.5 | AS41: =MAX(MIN(AQ41,fy),-fy)-IF(AQ41>=0,AR41,0) -> 374.5 | AT41: =IF(AND(ISNUMBER(Input!$D19),ISNUMBER(Input!$E19)),AS41*As,0) -> 301190.77 | AU41: =AT41*AO41 -> 39154800 | AW41: 10 | AX41: =h/2-($AW41-0.5)*BC$24 -> 186 | AY41: =AZ$25+AZ$26*AX41 -> 0.0027084906 | AZ41: =+IF(AY41>=0,IF(AY41<=eco,1-(1-AY41/eco)^n,1),0)*0.85*fck -> 25.5 | BA41: =+AZ41*BC$26 -> 122400 | BB41: =+BA41*AX41 -> 22766400 | BD41: 10 | BE41: =Input!$E19 -> 130 | BF41: =AZ$25+AZ$26*BE41 -> 0.0024179245 | BG41: =BF41*Es -> 483.58491 | BH41: =+IF(BG41>=0,IF(BF41<=eco,1-(1-BF41/eco)^n,1),0)*0.85*fck -> 25.5 | BI41: =MAX(MIN(BG41,fy),-fy)-IF(BG41>=0,BH41,0) -> 374.5 | BJ41: =IF(AND(ISNUMBER(Input!$D19),ISNUMBER(Input!$E19)),BI41*As,0) -> 301190.77 | BK41: =BJ41*BE41 -> 39154800 | BM41: 10 | BN41: =h/2-($BM41-0.5)*BS$24 -> 199.3 | BO41: =BP$25+BP$26*BN41 -> 0.002673 | BP41: =+IF(BO41>=0,IF(BO41<=eco,1-(1-BO41/eco)^n,1),0)*0.85*fck -> 25.5 | BQ41: =+BP41*BS$26 -> 108120 | BR41: =+BQ41*BN41 -> 21548316 | BT41: 10 | BU41: =Input!$E19 -> 130 | BV41: =BP$25+BP$26*BU41 -> 0.0022415094 | BW41: =BV41*Es -> 448.30189 | BX41: =+IF(BW41>=0,IF(BV41<=eco,1-(1-BV41/eco)^n,1),0)*0.85*fck -> 25.5 | BY41: =MAX(MIN(BW41,fy),-fy)-IF(BW41>=0,BX41,0) -> 374.5 | BZ41: =IF(AND(ISNUMBER(Input!$D19),ISNUMBER(Input!$E19)),BY41*As,0) -> 301190.77 | CA41: =BZ41*BU41 -> 39154800
