Workbook
Name eco: Input!$E$13
Name ecu: Input!$G$5
Name Es: Input!$E$24
Name fck: Input!$G$4
Name fy: Input!$E$25
Name n: Input!$E$12
Name p: '2D (15deg)'!$F$52
Name p: Summary!$F$58
Name pc: Input!$E$27
Name ps: Input!$E$26
Name xc: '2D (15deg)'!$H$47
Name yc: '2D (15deg)'!$H$48

Sheet Input
B3: Material
B4: ● | C4: Concrete | E4: fck | F4: = | G4: 30 | H4: Mpa
E5: εcu | F5: = | G5: =MIN(0.0033-(fck-40)/100000,0.0033) -> 0.0033
C7: Strain - Stress Relationship : Parabolic | M7: [KDS 24 14 21 3.1.2.5 (2)]
C9: 0 ≤ εc ≤ εco | E9: fc = (0.85fck) [ 1 - (1 - εc/εco)n] | P9: ε | Q9: fc
C10: else | E10: fc = 0.85fck | O10: 1 | P10: 0 | Q10: =+IF(P10>=0,IF(P10<=eco,1-(1-P10/eco)^$E$12,1),0)*0.85*fck -> 0
O11: 2 | P11: =+ecu/10*(O11-1) -> 0.00033 | Q11: =+IF(P11>=0,IF(P11<=eco,1-(1-P11/eco)^$E$12,1),0)*0.85*fck -> 7.7207625
C12: n | D12: = | E12: =MIN(1.2+1.5*((100-fck)/60)^4,2) -> 2 | O12: 3 | P12: =+ecu/10*(O12-1) -> 0.00066 | Q12: =+IF(P12>=0,IF(P12<=eco,1-(1-P12/eco)^$E$12,1),0)*0.85*fck -> 14.05305
C13: εco | D13: = | E13: =MAX(0.002+(fck-40)/100000,0.002) -> 0.002 | O13: 4 | P13: =+ecu/10*(O13-1) -> 0.00099 | Q13: =+IF(P13>=0,IF(P13<=eco,1-(1-P13/eco)^$E$12,1),0)*0.85*fck -> 18.996862
O14: 5 | P14: =+ecu/10*(O14-1) -> 0.00132 | Q14: =+IF(P14>=0,IF(P14<=eco,1-(1-P14/eco)^$E$12,1),0)*0.85*fck -> 22.5522
O15: 6 | P15: =+ecu/10*(O15-1) -> 0.00165 | Q15: =+IF(P15>=0,IF(P15<=eco,1-(1-P15/eco)^$E$12,1),0)*0.85*fck -> 24.719062
O16: 7 | P16: =+ecu/10*(O16-1) -> 0.00198 | Q16: =+IF(P16>=0,IF(P16<=eco,1-(1-P16/eco)^$E$12,1),0)*0.85*fck -> 25.49745
O17: 8 | P17: =+ecu/10*(O17-1) -> 0.00231 | Q17: =+IF(P17>=0,IF(P17<=eco,1-(1-P17/eco)^$E$12,1),0)*0.85*fck -> 25.5
O18: 9 | P18: =+ecu/10*(O18-1) -> 0.00264 | Q18: =+IF(P18>=0,IF(P18<=eco,1-(1-P18/eco)^$E$12,1),0)*0.85*fck -> 25.5
O19: 10 | P19: =+ecu/10*(O19-1) -> 0.00297 | Q19: =+IF(P19>=0,IF(P19<=eco,1-(1-P19/eco)^$E$12,1),0)*0.85*fck -> 25.5
B23: ● | C23: Steel
C24: Es | D24: = | E24: 200000 | F24: Mpa
C25: fy | D25: = | E25: 400 | F25: Mpa
C26: φs | D26: = | E26: 0.9
C27: φc | D27: = | E27: 0.65

Sheet Strain Equation
B2: Equation of strain
I4: Equation of Strain
J5: ε(x, y) = ε0 + κx*y + κy*x
I7: ε0 = | J7: strain at the reference axis
I8: κx, κy = | J8: curvature along x and y
I9: x, y = | J9: coordinate from reference axis

Sheet 2D (15deg)
B3: ● | C3: Original Geometry
C4: Boundary
C5: No. | D5: 1 | E5: 2 | F5: 3 | G5: 4 | H5: 5 | I5: 6 | J5: 7 | K5: 8 | L5: 9 | M5: 10 | N5: 11 | O5: 12 | P5: 13 | Q5: 14 | R5: 15 | S5: 16 | T5: 17 | U5: 18
C6: X | D6: -550 | E6: 550 | F6: 750 | G6: 750 | H6: 550 | I6: -550 | J6: -750 | K6: -750 | L6: =+D6 -> -550
C7: Y | D7: 600 | E7: 600 | F7: 400 | G7: -400 | H7: -600 | I7: -600 | J7: -400 | K7: 400 | L7: =+D7 -> 600
C9: Hole1
C10: No. | D10: 1 | E10: 2 | F10: 3 | G10: 4 | H10: 5 | I10: 6 | J10: 7 | K10: 8 | L10: 9 | M10: 10 | N10: 11 | O10: 12 | P10: 13 | Q10: 14 | R10: 15 | S10: 16 | T10: 17 | U10: 18
C11: X | D11: -450 | E11: -250 | F11: -150 | G11: -150 | H11: -250 | I11: -450 | J11: -550 | K11: -550 | L11: =+D11 -> -450
C12: Y | D12: 400 | E12: 400 | F12: 300 | G12: -300 | H12: -400 | I12: -400 | J12: -300 | K12: 300 | L12: =+D12 -> 400
C14: Hole2
C15: No. | D15: 1 | E15: 2 | F15: 3 | G15: 4 | H15: 5 | I15: 6 | J15: 7 | K15: 8 | L15: 9 | M15: 10 | N15: 11 | O15: 12 | P15: 13 | Q15: 14 | R15: 15 | S15: 16 | T15: 17 | U15: 18
C16: X | D16: 250 | E16: 450 | F16: 550 | G16: 550 | H16: 450 | I16: 250 | J16: 150 | K16: 150 | L16: =+D16 -> 250
C17: Y | D17: 400 | E17: 400 | F17: 300 | G17: -300 | H17: -400 | I17: -400 | J17: -300 | K17: 300 | L17: =+D17 -> 400
C19: Rebar
C20: No. | D20: 1 | E20: 2 | F20: 3 | G20: 4 | H20: 5 | I20: 6 | J20: 7 | K20: 8 | L20: 9 | M20: 10 | N20: 11 | O20: 12 | P20: 13 | Q20: 14 | R20: 15 | S20: 16 | T20: 17 | U20: 18
C21: X | D21: -400 | E21: -200 | F21: 0 | G21: 200 | H21: 400 | I21: -400 | J21: -200 | K21: 0 | L21: 200 | M21: 400 | N21: -680 | O21: -680 | P21: -680 | Q21: -680 | R21: 680 | S21: 680 | T21: 680 | U21: 680
C22: Y | D22: 530 | E22: 530 | F22: 530 | G22: 530 | H22: 530 | I22: -530 | J22: -530 | K22: -530 | L22: -530 | M22: -530 | N22: 300 | O22: 100 | P22: -100 | Q22: -300 | R22: 300 | S22: 100 | T22: -100 | U22: -300
C23: Dia | D23: 32 | E23: 32 | F23: 32 | G23: 32 | H23: 32 | I23: 32 | J23: 32 | K23: 32 | L23: 32 | M23: 32 | N23: 32 | O23: 32 | P23: 32 | Q23: 32 | R23: 32 | S23: 32 | T23: 32 | U23: 32
C26: Boundary
C27: No. | D27: 1 | E27: 2 | F27: 3 | G27: 4 | H27: 5 | I27: 6 | J27: 7 | K27: 8 | L27: 9 | M27: 10 | N27: 11 | O27: 12 | P27: 13 | Q27: 14 | R27: 15 | S27: 16 | T27: 17 | U27: 18
C28: X | D28: -550 | E28: 550 | F28: 750 | G28: 750 | H28: 550 | I28: -550 | J28: -750 | K28: -750 | L28: =+D28 -> -550
C29: Y | D29: 600 | E29: 600 | F29: 400 | G29: -400 | H29: -600 | I29: -600 | J29: -400 | K29: 400 | L29: =+D29 -> 600
C30: Hole1
C31: No. | D31: 1 | E31: 2 | F31: 3 | G31: 4 | H31: 5 | I31: 6 | J31: 7 | K31: 8 | L31: 9 | M31: 10 | N31: 11 | O31: 12 | P31: 13 | Q31: 14 | R31: 15 | S31: 16 | T31: 17 | U31: 18
C32: X | D32: -450 | E32: -250 | F32: -150 | G32: -150 | H32: -250 | I32: -450 | J32: -550 | K32: -550 | L32: =+D32 -> -450
C33: Y | D33: 400 | E33: 400 | F33: 300 | G33: -300 | H33: -400 | I33: -400 | J33: -300 | K33: 300 | L33: =+D33 -> 400
C34: Hole2
C35: No. | D35: 1 | E35: 2 | F35: 3 | G35: 4 | H35: 5 | I35: 6 | J35: 7 | K35: 8 | L35: 9 | M35: 10 | N35: 11 | O35: 12 | P35: 13 | Q35: 14 | R35: 15 | S35: 16 | T35: 17 | U35: 18
C36: X | D36: 250 | E36: 450 | F36: 550 | G36: 550 | H36: 450 | I36: 250 | J36: 150 | K36: 150 | L36: =+D36 -> 250
C37: Y | D37: 400 | E37: 400 | F37: 300 | G37: -300 | H37: -400 | I37: -400 | J37: -300 | K37: 300 | L37: =+D37 -> 400
C38: Rebar
C39: No. | D39: 1 | E39: 2 | F39: 3 | G39: 4 | H39: 5 | I39: 6 | J39: 7 | K39: 8 | L39: 9 | M39: 10 | N39: 11 | O39: 12 | P39: 13 | Q39: 14 | R39: 15 | S39: 16 | T39: 17 | U39: 18
C40: X | D40: -400 | E40: -200 | F40: 0 | G40: 200 | H40: 400 | I40: -400 | J40: -200 | K40: 0 | L40: 200 | M40: 400 | N40: -680 | O40: -680 | P40: -680 | Q40: -680 | R40: 680 | S40: 680 | T40: 680 | U40: 680
C41: Y | D41: 530 | E41: 530 | F41: 530 | G41: 530 | H41: 530 | I41: -530 | J41: -530 | K41: -530 | L41: -530 | M41: -530 | N41: 300 | O41: 100 | P41: -100 | Q41: -300 | R41: 300 | S41: 100 | T41: -100 | U41: -300
C42: Dia | D42: 32 | E42: 32 | F42: 32 | G42: 32 | H42: 32 | I42: 32 | J42: 32 | K42: 32 | L42: 32 | M42: 32 | N42: 32 | O42: 32 | P42: 32 | Q42: 32 | R42: 32 | S42: 32 | T42: 32 | U42: 32
D44: Area and Centroid
E45: Boundary | F45: Hole1 | G45: Hole2 | H45: SUM | J45: with i = 1 to n, and point n+1 = point 1
D46: Area | E46: =0.5*ABS(SUMPRODUCT(D6:K6,E7:L7)-SUMPRODUCT(D7:K7,E6:L6)) -> 1720000 | F46: =-0.5*ABS(SUMPRODUCT(D11:K11,E12:L12)-SUMPRODUCT(D12:K12,E11:L11)) -> -300000 | G46: =-0.5*ABS(SUMPRODUCT(D16:K16,E17:L17)-SUMPRODUCT(D17:K17,E16:L16)) -> -300000 | H46: =+E46+F46+G46 -> 1120000 | J46: D_i = x_i*y_(i+1) - x_(i+1)*y_i
D47: X | E47: {=SUMPRODUCT((D6:K6+E6:L6),(D6:K6*E7:L7-E6:L6*D7:K7))/(3*(SUMPRODUCT(D6:K6,E7:L7)-SUMPRODUCT(E6:L6,D7:K7)))} -> 0 | F47: {=SUMPRODUCT((D11:K11+E11:L11),(D11:K11*E12:L12-E11:L11*D12:K12))/(3*(SUMPRODUCT(D11:K11,E12:L12)-SUMPRODUCT(E11:L11,D12:K12)))} -> -350 | G47: {=SUMPRODUCT((D16:K16+E16:L16),(D16:K16*E17:L17-E16:L16*D17:K17))/(3*(SUMPRODUCT(D16:K16,E17:L17)-SUMPRODUCT(E16:L16,D17:K17)))} -> 350 | H47: =IFERROR(SUMPRODUCT(E46:G46,E47:G47)/H46,E47) -> 0 | J47: A = 1/2 * |Σ(D_i)|
D48: Y | E48: {=SUMPRODUCT((D7:K7+E7:L7),(D6:K6*E7:L7-E6:L6*D7:K7))/(3*(SUMPRODUCT(D6:K6,E7:L7)-SUMPRODUCT(E6:L6,D7:K7)))} -> 0 | F48: {=SUMPRODUCT((D12:K12+E12:L12),(D11:K11*E12:L12-E11:L11*D12:K12))/(3*(SUMPRODUCT(D11:K11,E12:L12)-SUMPRODUCT(E11:L11,D12:K12)))} -> 0 | G48: {=SUMPRODUCT((D17:K17+E17:L17),(D16:K16*E17:L17-E16:L16*D17:K17))/(3*(SUMPRODUCT(D16:K16,E17:L17)-SUMPRODUCT(E16:L16,D17:K17)))} -> 0 | H48: =IFERROR(SUMPRODUCT(E46:G46,E48:G48)/H46,E48) -> 0 | J48: Xc = Σ[(x_i + x_(i+1))*D_i] / [3*Σ(D_i)]
...

Sheet Newton
A1: NEWTON - RAPHSON INVERSE - Given (Pu, Mu) → strain state (ε0, κ), curvature, neutral axis
A3: 1) Demand Input | G3: 2) Initial Guess
A4: Pu (Axial) | C4: = | D4: 24942.922 | E4: kN | G4: ε0 | H4: = | I4: 0.001
A5: Mux (Moment) | C5: = | D5: 3714.1659 | E5: kNm | G5: κ x | H5: = | I5: 1.5e-07 | J5: 1/mm
A6: Muy (Moment) | C6: = | D6: 1431.7807 | E6: kNm | G6: κ y | H6: = | I6: 5e-08 | J6: 1/mm
A8: 3) Equilibrium result
B9: Newton-Raphson estimates the local sensitivity J, then computes how ε0 and κ should be corrected so that the calculated section response moves toward the target Pu and Mu.
B10: 뉴턴-랩슨 방법은 국부 민감도 J를 추정한 뒤, 계산된 단면 응답이 목표 Pu와 Mu에 가까워지도록 ε0와 κ의 수정량을 계산한다.
B12: Unknown vector: | D12: x = [ε0 ; κx ; κy]
B13: Residual vector: | D13: R(x) = [ P(ε0,κx,κy) − Pu ; Mx(ε0,κx,κy) − Mux ; My(ε0,κx,κy) − Muy ]
B14: Jacobian matrix: | D14: J =[ ∂P/∂ε0 ∂P/∂κx ∂P/∂κy ; ∂Mx/∂ε0 ∂Mx/∂κx ∂Mx/∂κy ; ∂My/∂ε0 ∂My/∂κx ∂My/∂κy ]
D15: J = [a b c ; b d e ; c e f]
D16: a = ∂P/∂ε0 = ∫T·dA ; b = ∂P/∂κx = ∂Mx/∂ε0 = ∫T·y·dA ; c = ∂P/∂κy = ∂My/∂ε0 = ∫T·x·dA
D17: d = ∂Mx/∂κx = ∫T·y²·dA ; e = ∂Mx/∂κy = ∂My/∂κx = ∫T·xy·dA ; f = ∂My/∂κy = ∫T·x²·dA
B18: Newton equation: | D18: Δx = [Δε0 ; Δκx ; Δκy] = −J⁻¹·R
B19: Update equation: | D19: x_new = x + Δx
D20: ε0,new = ε0 + Δε0
D21: κx,new = κx + Δκx | F21: κy,new = κy + Δκy
A24: ITERATION TABLE | E24: P(ε0,κx,κy) | F24: Mx(ε0,κx,κy) | G24: My(ε0,κx,κy) | H24: Residual Force & Moment | K24: Jacobian Matrix | T24: Δx = [Δε0 ; Δκx ; Δκy] = −J⁻¹·R
A25: No. | B25: e0 | C25: κ x | D25: κ y | E25: P | F25: Mx | G25: My | H25: rP | I25: rMx | J25: rMy | K25: J11 = a | L25: J12 = b | M25: J13 = c | N25: J22 = d | O25: J23 = e | P25: J33 = f | Q25: DET | R25: Δe0 | S25: Δκx | T25: Δκy | U25: rel
A26: 1 | B26: =+I4 -> 0.001 | C26: =+I5 -> 1.5e-07 | D26: =+I6 -> 5e-08 | E26: =+G54+Y54 -> 24011831 | F26: =+H54+Z54 -> 3.8633565e+08 | G26: =+I54+AA54 -> 1.7338596e+08 | H26: =+E26-$D$4*1000 -> -931090.93 | I26: =+F26-$D$5*10^6 -> -3.3278303e+09 | J26: =+G26-$D$6*10^6 -> -1.2583948e+09 | K26: =+K54+AC54 -> 1.6990717e+10 | L26: =L54+AD54 -> -3.0891073e+11 | M26: =+M54+AE54 -> -1.3720125e+11 | N26: =+N54+AF54 -> 2.575571e+15 | O26: =+O54+AG54 -> 0.024414062 | P26: =+P54+AH54 -> 3.4677193e+15 | Q26: =(K26*(N26*P26-O26*O26)-L26*(L26*P26-O26*M26)+M26*(L26*O26-N26*M26)) -> 1.5137077e+41 | R26: =((-H26)*(N26*P26-O26*O26)-L26*((-I26)*P26-O26*(-J26))+M26*((-I26)*O26-N26*(-J26)))/Q26 -> 8.1425302e-05 | S26: =(K26*((-I26)*P26-O26*(-J26))-(-H26)*(L26*P26-O26*M26)+M26*(L26*(-J26)-(-I26)*M26))/Q26 -> 1.3018408e-06 | T26: =(K26*(N26*(-J26)-O26*(-I26))-L26*(L26*(-J26)-(-I26)*M26)+(-H26)*(L26*O26-N26*M26))/Q26 -> 3.6610992e-07 | U26: =SQRT(H26^2+I26^2+J26^2)/MAX(SQRT(($D$4*1000)^2+($D$5*10^6)^2+($D$6*10^6)^2),1) -> 0.89377412
A27: 2 | B27: =+B26+R26 -> 0.0010814253 | C27: =+C26+S26 -> 1.4518408e-06 | D27: =+D26+T26 -> 4.1610992e-07 | E27: =+AP54+BH54 -> 22965602 | F27: =AQ54+BI54 -> 3.495071e+09 | G27: =AR54+BJ54 -> 1.3494764e+09 | H27: =+E27-$D$4*1000 -> -1977320.5 | I27: =+F27-$D$5*10^6 -> -2.1909493e+08 | J27: =+G27-$D$6*10^6 -> -82304318 | K27: =+AT54+BL54 -> 1.5710218e+10 | L27: =+AU54+BM54 -> -3.0596521e+12 | M27: =+AV54+BN54 -> -1.1924644e+12 | N27: =+AW54+BO54 -> 2.3713146e+15 | O27: =+AX54+BP54 -> -2.6581198e+13 | P27: =+AY54+BQ54 -> 3.2254854e+15 | Q27: =(K27*(N27*P27-O27*O27)-L27*(L27*P27-O27*M27)+M27*(L27*O27-N27*M27)) -> 8.6389517e+40 | R27: =((-H27)*(N27*P27-O27*O27)-L27*((-I27)*P27-O27*(-J27))+M27*((-I27)*O27-N27*(-J27)))/Q27 -> 0.00020292978 | S27: =(K27*((-I27)*P27-O27*(-J27))-(-H27)*(L27*P27-O27*M27)+M27*(L27*(-J27)-(-I27)*M27))/Q27 -> 3.5538928e-07 | T27: =(K27*(N27*(-J27)-O27*(-I27))-L27*(L27*(-J27)-(-I27)*M27)+(-H27)*(L27*O27-N27*M27))/Q27 -> 1.0346893e-07 | U27: =SQRT(H27^2+I27^2+J27^2)/MAX(SQRT(($D$4*1000)^2+($D$5*10^6)^2+($D$6*10^6)^2),1) -> 0.058797385
A28: 3 | B28: =+B27+R27 -> 0.0012843551 | C28: =+C27+S27 -> 1.8072301e-06 | D28: =+D27+T27 -> 5.1957885e-07 | E28: =+BY54+CQ54 -> 24479866 | F28: =+BZ54+CR54 -> 3.550761e+09 | G28: =+CA54+CS54 -> 1.3933131e+09 | H28: =+E28-$D$4*1000 -> -463056.34 | I28: =+F28-$D$5*10^6 -> -1.6340498e+08 | J28: =+G28-$D$6*10^6 -> -38467618 | K28: =+CC54+CU54 -> 1.263354e+10 | L28: =+CD54+CV54 -> -3.7218554e+12 | M28: =+CE54+CW54 -> -1.1957809e+12 | N28: =+CF54+CX54 -> 1.8896131e+15 | O28: =+CG54+CY54 -> 3.725874e+13 | P28: =+CH54+CZ54 -> 2.650214e+15 | Q28: =(K28*(N28*P28-O28*O28)-L28*(L28*P28-O28*M28)+M28*(L28*O28-N28*M28)) -> 2.4168089e+40 | R28: =((-H28)*(N28*P28-O28*O28)-L28*((-I28)*P28-O28*(-J28))+M28*((-I28)*O28-N28*(-J28)))/Q28 -> 0.00016568842 | S28: =(K28*((-I28)*P28-O28*(-J28))-(-H28)*(L28*P28-O28*M28)+M28*(L28*(-J28)-(-I28)*M28))/Q28 -> 4.1117542e-07 | T28: =(K28*(N28*(-J28)-O28*(-I28))-L28*(L28*(-J28)-(-I28)*M28)+(-H28)*(L28*O28-N28*M28))/Q28 -> 8.3493183e-08 | U28: =SQRT(H28^2+I28^2+J28^2)/MAX(SQRT(($D$4*1000)^2+($D$5*10^6)^2+($D$6*10^6)^2),1) -> 0.042172023
A29: 4 | B29: =+B28+R28 -> 0.0014500435 | C29: =+C28+S28 -> 2.2184055e-06 | D29: =+D28+T28 -> 6.0307203e-07 | E29: =+DH54+DZ54 -> 24829120 | F29: =+DI54+EA54 -> 3.6824704e+09 | G29: =+DJ54+EB54 -> 1.4257057e+09 | H29: =+E29-$D$4*1000 -> -113802.41 | I29: =+F29-$D$5*10^6 -> -31695496 | J29: =+G29-$D$6*10^6 -> -6075071.5 | K29: =+DL54+ED54 -> 1.1182905e+10 | L29: =+DM54+EE54 -> -3.6778321e+12 | M29: =+DN54+EF54 -> -1.0857347e+12 | N29: =+DO54+EG54 -> 1.7365542e+15 | O29: =+DP54+EH54 -> 3.0506174e+12 | P29: =+DQ54+EI54 -> 2.2703292e+15 | Q29: =(K29*(N29*P29-O29*O29)-L29*(L29*P29-O29*M29)+M29*(L29*O29-N29*M29)) -> 1.1356842e+40 | R29: =((-H29)*(N29*P29-O29*O29)-L29*((-I29)*P29-O29*(-J29))+M29*((-I29)*O29-N29*(-J29)))/Q29 -> 6.3803434e-05 | S29: =(K29*((-I29)*P29-O29*(-J29))-(-H29)*(L29*P29-O29*M29)+M29*(L29*(-J29)-(-I29)*M29))/Q29 -> 1.5332271e-07 | T29: =(K29*(N29*(-J29)-O29*(-I29))-L29*(L29*(-J29)-(-I29)*M29)+(-H29)*(L29*O29-N29*M29))/Q29 -> 3.2982416e-08 | U29: =SQRT(H29^2+I29^2+J29^2)/MAX(SQRT(($D$4*1000)^2+($D$5*10^6)^2+($D$6*10^6)^2),1) -> 0.0081073633 | W29: Original | X29: =+SQRT(D4^2+D5^2+D6^2) -> 25258.551
A30: 5 | B30: =+B29+R29 -> 0.0015138469 | C30: =+C29+S29 -> 2.3717282e-06 | D30: =+D29+T29 -> 6.3605445e-07 | E30: =+EQ54+FI54 -> 24935735 | F30: =+ER54+FJ54 -> 3.7119683e+09 | G30: =+ES54+FK54 -> 1.4312683e+09 | H30: =+E30-$D$4*1000 -> -7186.7435 | I30: =+F30-$D$5*10^6 -> -2197632.7 | J30: =+G30-$D$6*10^6 -> -512427.55 | K30: =+EU54+FM54 -> 1.071051e+10 | L30: =+EV54+FN54 -> -3.586447e+12 | M30: =+EW54+FO54 -> -9.7752768e+11 | N30: =+EX54+FP54 -> 1.6740543e+15 | O30: =+EY54+FQ54 -> -2.8227001e+13 | P30: =+EZ54+FR54 -> 2.1511954e+15 | Q30: =(K30*(N30*P30-O30*O30)-L30*(L30*P30-O30*M30)+M30*(L30*O30-N30*M30)) -> 9.0947949e+39 | R30: =((-H30)*(N30*P30-O30*O30)-L30*((-I30)*P30-O30*(-J30))+M30*((-I30)*O30-N30*(-J30)))/Q30 -> 4.8139e-06 | S30: =(K30*((-I30)*P30-O30*(-J30))-(-H30)*(L30*P30-O30*M30)+M30*(L30*(-J30)-(-I30)*M30))/Q30 -> 1.1669408e-08 | T30: =(K30*(N30*(-J30)-O30*(-I30))-L30*(L30*(-J30)-(-I30)*M30)+(-H30)*(L30*O30-N30*M30))/Q30 -> 2.5788176e-09 | U30: =SQRT(H30^2+I30^2+J30^2)/MAX(SQRT(($D$4*1000)^2+($D$5*10^6)^2+($D$6*10^6)^2),1) -> 0.0005668899 | W30: Target | X30: =+SQRT((E35/1000)^2+(G35/10^6)^2+(F35/10^6)^2) -> 25258.551
A31: 6 | B31: =+B30+R30 -> 0.0015186608 | C31: =+C30+S30 -> 2.3833976e-06 | D31: =+D30+T30 -> 6.3863326e-07 | E31: =+FZ54+GR54 -> 24942873 | F31: =+GA54+GS54 -> 3.7141641e+09 | G31: =+GB54+GT54 -> 1.4317841e+09 | H31: =+E31-$D$4*1000 -> -49.021026 | I31: =+F31-$D$5*10^6 -> -1889.7842 | J31: =+G31-$D$6*10^6 -> 3390.6575 | K31: =+GD54+GV54 -> 1.0693532e+10 | L31: =+GE54+GW54 -> -3.5878601e+12 | M31: =+GF54+GX54 -> -9.7743999e+11 | N31: =+GG54+GY54 -> 1.6739802e+15 | O31: =+GH54+GZ54 -> -2.6715331e+13 | P31: =+GI54+HA54 -> 2.1468194e+15 | Q31: =(K31*(N31*P31-O31*O31)-L31*(L31*P31-O31*M31)+M31*(L31*O31-N31*M31)) -> 8.9999409e+39 | R31: =((-H31)*(N31*P31-O31*O31)-L31*((-I31)*P31-O31*(-J31))+M31*((-I31)*O31-N31*(-J31)))/Q31 -> 2.0540807e-08 | S31: =(K31*((-I31)*P31-O31*(-J31))-(-H31)*(L31*P31-O31*M31)+M31*(L31*(-J31)-(-I31)*M31))/Q31 -> 4.5287294e-11 | T31: =(K31*(N31*(-J31)-O31*(-I31))-L31*(L31*(-J31)-(-I31)*M31)+(-H31)*(L31*O31-N31*M31))/Q31 -> 8.3363386e-12 | U31: =SQRT(H31^2+I31^2+J31^2)/MAX(SQRT(($D$4*1000)^2+($D$5*10^6)^2+($D$6*10^6)^2),1) -> 9.7522579e-07 | W31: Diff | X31: =(X30-X29)/X29 -> 8.6417756e-16
A32: 7 | B32: =+B31+R31 -> 0.0015186814 | C32: =+C31+S31 -> 2.3834429e-06 | D32: =+D31+T31 -> 6.386416e-07 | E32: =+HI54+IA54 -> 24942922 | F32: =+HJ54+IB54 -> 3.7141659e+09 | G32: =+HK54+IC54 -> 1.4317807e+09 | H32: =+E32-$D$4*1000 -> -0.0008787401 | I32: =+F32-$D$5*10^6 -> -0.045227051 | J32: =+G32-$D$6*10^6 -> 0.086322069 | K32: =+HM54+IE54 -> 1.0693449e+10 | L32: =+HN54+IF54 -> -3.5878623e+12 | M32: =+HO54+IG54 -> -9.7743605e+11 | N32: =+HP54+IH54 -> 1.6739782e+15 | O32: =+HQ54+II54 -> -2.6709532e+13 | P32: =+HR54+IJ54 -> 2.1467989e+15 | Q32: =(K32*(N32*P32-O32*O32)-L32*(L32*P32-O32*M32)+M32*(L32*O32-N32*M32)) -> 8.9995203e+39 | R32: =((-H32)*(N32*P32-O32*O32)-L32*((-I32)*P32-O32*(-J32))+M32*((-I32)*O32-N32*(-J32)))/Q32 -> 3.7305567e-13 | S32: =(K32*((-I32)*P32-O32*(-J32))-(-H32)*(L32*P32-O32*M32)+M32*(L32*(-J32)-(-I32)*M32))/Q32 -> 8.2882655e-16 | T32: =(K32*(N32*(-J32)-O32*(-I32))-L32*(L32*(-J32)-(-I32)*M32)+(-H32)*(L32*O32-N32*M32))/Q32 -> 1.3995422e-16 | U32: =SQRT(H32^2+I32^2+J32^2)/MAX(SQRT(($D$4*1000)^2+($D$5*10^6)^2+($D$6*10^6)^2),1) -> 2.4482489e-11
A33: 8 | B33: =+B32+R32 -> 0.0015186814 | C33: =+C32+S32 -> 2.3834429e-06 | D33: =+D32+T32 -> 6.386416e-07 | E33: =+IR54+JJ54 -> 24942922 | F33: =+IS54+JK54 -> 3.7141659e+09 | G33: =+IT54+JL54 -> 1.4317807e+09 | H33: =+E33-$D$4*1000 -> 0 | I33: =+F33-$D$5*10^6 -> 0 | J33: =+G33-$D$6*10^6 -> -4.7683716e-06 | K33: =+IV54+JN54 -> 1.0713958e+10 | L33: =+IW54+JO54 -> -3.5987317e+12 | M33: =+IX54+JP54 -> -9.8563938e+11 | N33: =+IY54+JQ54 -> 1.679739e+15 | O33: =+IZ54+JR54 -> -2.2361769e+13 | P33: =+JA54+JS54 -> 2.1500803e+15 | Q33: =(K33*(N33*P33-O33*O33)-L33*(L33*P33-O33*M33)+M33*(L33*O33-N33*M33)) -> 9.0530012e+39 | R33: =((-H33)*(N33*P33-O33*O33)-L33*((-I33)*P33-O33*(-J33))+M33*((-I33)*O33-N33*(-J33)))/Q33 -> 9.1442895e-19 | S33: =(K33*((-I33)*P33-O33*(-J33))-(-H33)*(L33*P33-O33*M33)+M33*(L33*(-J33)-(-I33)*M33))/Q33 -> 1.9944857e-21 | T33: =(K33*(N33*(-J33)-O33*(-I33))-L33*(L33*(-J33)-(-I33)*M33)+(-H33)*(L33*O33-N33*M33))/Q33 -> 2.6577003e-21 | U33: =SQRT(H33^2+I33^2+J33^2)/MAX(SQRT(($D$4*1000)^2+($D$5*10^6)^2+($D$6*10^6)^2),1) -> 1.1978849e-15 | W33: Converged Criteria | Y33: Diff % <= 10^-4 (0.01%)
A34: 9 | B34: =+B33+R33 -> 0.0015186814 | C34: =+C33+S33 -> 2.3834429e-06 | D34: =+D33+T33 -> 6.386416e-07 | E34: =+KA54+KS54 -> 24942922 | F34: =+KB54+KT54 -> 3.7141659e+09 | G34: =+KC54+KU54 -> 1.4317807e+09 | H34: =+E34-$D$4*1000 -> 0 | I34: =+F34-$D$5*10^6 -> 0 | J34: =+G34-$D$6*10^6 -> 0 | K34: =+KE54+KW54 -> 1.0713958e+10 | L34: =+KF54+KX54 -> -3.5987317e+12 | M34: =+KG54+KY54 -> -9.8563938e+11 | N34: =+KH54+KZ54 -> 1.679739e+15 | O34: =+KI54+LA54 -> -2.2361769e+13 | P34: =+KJ54+LB54 -> 2.1500803e+15 | Q34: =(K34*(N34*P34-O34*O34)-L34*(L34*P34-O34*M34)+M34*(L34*O34-N34*M34)) -> 9.0530012e+39 | R34: =((-H34)*(N34*P34-O34*O34)-L34*((-I34)*P34-O34*(-J34))+M34*((-I34)*O34-N34*(-J34)))/Q34 -> 0 | S34: =(K34*((-I34)*P34-O34*(-J34))-(-H34)*(L34*P34-O34*M34)+M34*(L34*(-J34)-(-I34)*M34))/Q34 -> 0 | T34: =(K34*(N34*(-J34)-O34*(-I34))-L34*(L34*(-J34)-(-I34)*M34)+(-H34)*(L34*O34-N34*M34))/Q34 -> 0 | U34: =SQRT(H34^2+I34^2+J34^2)/MAX(SQRT(($D$4*1000)^2+($D$5*10^6)^2+($D$6*10^6)^2),1) -> 0
A35: 10 | B35: =+B34+R34 -> 0.0015186814 | C35: =+C34+S34 -> 2.3834429e-06 | D35: =+D34+T34 -> 6.386416e-07 | E35: =+LJ54+MB54 -> 24942922 | F35: =+LK54+MC54 -> 3.7141659e+09 | G35: =+LL54+MD54 -> 1.4317807e+09 | H35: =+E35-$D$4*1000 -> 0 | I35: =+F35-$D$5*10^6 -> 0 | J35: =+G35-$D$6*10^6 -> 0 | K35: =+LN54+MF54 -> 1.0713958e+10 | L35: =+LO54+MG54 -> -3.5987317e+12 | M35: =+LP54+MH54 -> -9.8563938e+11 | N35: =+LQ54+MI54 -> 1.679739e+15 | O35: =+LR54+MJ54 -> -2.2361769e+13 | P35: =+LS54+MK54 -> 2.1500803e+15 | Q35: =(K35*(N35*P35-O35*O35)-L35*(L35*P35-O35*M35)+M35*(L35*O35-N35*M35)) -> 9.0530012e+39 | R35: =((-H35)*(N35*P35-O35*O35)-L35*((-I35)*P35-O35*(-J35))+M35*((-I35)*O35-N35*(-J35)))/Q35 -> 0 | S35: =(K35*((-I35)*P35-O35*(-J35))-(-H35)*(L35*P35-O35*M35)+M35*(L35*(-J35)-(-I35)*M35))/Q35 -> 0 | T35: =(K35*(N35*(-J35)-O35*(-I35))-L35*(L35*(-J35)-(-I35)*M35)+(-H35)*(L35*O35-N35*M35))/Q35 -> 0 | U35: =SQRT(H35^2+I35^2+J35^2)/MAX(SQRT(($D$4*1000)^2+($D$5*10^6)^2+($D$6*10^6)^2),1) -> 0
A38: Max 20 | W38: =(B35-'2D (15deg)'!L132)/B35 -> 3.2839871e-15
W39: =(C35-'2D (15deg)'!L134)/C35 -> 4.0868942e-15
A40: 4) SECTION RESPONSE (from converged ε0, κx, κy) | W40: =(D35-'2D (15deg)'!L135)/D35 -> 4.3104882e-15
A41: Curvature κ | D41: κx | E41: =+C35 -> 2.3834429e-06 | F41: 1/mm
D42: κy | E42: =+D35 -> 6.386416e-07 | F42: 1/mm
A43: ε0 (strain at centroid) | E43: =+B35 -> 0.0015186814
A46: ITERATION #1 | AJ46: ITERATION #2 | BS46: ITERATION #3 | DB46: ITERATION #4 | EK46: ITERATION #5 | FT46: ITERATION #6 | HC46: ITERATION #7 | IL46: ITERATION #8 | JU46: ITERATION #9 | LD46: ITERATION #10
A47: ε0 = | B47: =+B26 -> 0.001 | AJ47: ε0 = | AK47: =+B27 -> 0.0010814253 | BS47: ε0 = | BT47: =+B28 -> 0.0012843551 | DB47: ε0 = | DC47: =+B29 -> 0.0014500435 | EK47: ε0 = | EL47: =+B30 -> 0.0015138469 | FT47: ε0 = | FU47: =+B31 -> 0.0015186608 | HC47: ε0 = | HD47: =+B32 -> 0.0015186814 | IL47: ε0 = | IM47: =+B33 -> 0.0015186814 | JU47: ε0 = | JV47: =+B34 -> 0.0015186814 | LD47: ε0 = | LE47: =+B35 -> 0.0015186814
A48: κx = | B48: =+C26 -> 1.5e-07 | AJ48: κx = | AK48: =+C27 -> 1.4518408e-06 | BS48: κx = | BT48: =+C28 -> 1.8072301e-06 | DB48: κx = | DC48: =+C29 -> 2.2184055e-06 | EK48: κx = | EL48: =+C30 -> 2.3717282e-06 | FT48: κx = | FU48: =+C31 -> 2.3833976e-06 | HC48: κx = | HD48: =+C32 -> 2.3834429e-06 | IL48: κx = | IM48: =+C33 -> 2.3834429e-06 | JU48: κx = | JV48: =+C34 -> 2.3834429e-06 | LD48: κx = | LE48: =+C35 -> 2.3834429e-06
A49: κy = | B49: =+D26 -> 5e-08 | AJ49: κy = | AK49: =+D27 -> 4.1610992e-07 | BS49: κy = | BT49: =+D28 -> 5.1957885e-07 | DB49: κy = | DC49: =+D29 -> 6.0307203e-07 | EK49: κy = | EL49: =+D30 -> 6.3605445e-07 | FT49: κy = | FU49: =+D31 -> 6.3863326e-07 | HC49: κy = | HD49: =+D32 -> 6.386416e-07 | IL49: κy = | IM49: =+D33 -> 6.386416e-07 | JU49: κy = | JV49: =+D34 -> 6.386416e-07 | LD49: κy = | LE49: =+D35 -> 6.386416e-07
...

Sheet Summary
C6: Do for all from o degree to 360 degree, with step 15 degree
C8: Rotation | E8: =+'[1]0-degree'!p -> 0 | F8: degree
C9: Point | D9: C/C1 | E9: fs/fy | F9: εs | G9: ε0 | H9: κ | I9: P | K9: Mx | M9: My | O9: Normial | R9: Factored
H10: 1/mm | I10: Concrete | J10: Steel | K10: Concrete | L10: Steel | M10: Concrete | N10: Steel | O10: SumP | P10: SumMx | Q10: SumMy | R10: SumP | S10: SumMx | T10: SumMy
C11: P0 | D11: Pure Compression | G11: =+'[1]0-degree'!G86 -> 0.0033 | H11: =+'[1]0-degree'!H86 -> 0 | I11: =+'[1]0-degree'!I86 -> 28560 | J11: =+'[1]0-degree'!J86 -> 5421.4339 | K11: =+'[1]0-degree'!K86 -> 0 | L11: =+'[1]0-degree'!L86 -> 0 | M11: =+'[1]0-degree'!M86 -> 0 | N11: =+'[1]0-degree'!N86 -> 0 | ... T11: =+'[1]0-degree'!T86 -> 0
C12: P1 | D12: 1 | E12: 0 | G12: =+'[1]0-degree'!G87 -> 0.0024238938 | H12: =+'[1]0-degree'!H87 -> 2.920354e-06 | I12: =+'[1]0-degree'!I87 -> 25301.206 | J12: =+'[1]0-degree'!J87 -> 4406.5465 | K12: =+'[1]0-degree'!K87 -> 1729.7589 | L12: =+'[1]0-degree'!L87 -> 504.91306 | M12: =+'[1]0-degree'!M87 -> 0 | N12: =+'[1]0-degree'!N87 -> 0 | ... T12: =+'[1]0-degree'!T87 -> 0
C13: P2 | E13: 0.5 | G13: =+'[1]0-degree'!G88 -> 0.0021584071 | H13: =+'[1]0-degree'!H88 -> 3.8053097e-06 | I13: =+'[1]0-degree'!I88 -> 18889.428 | J13: =+'[1]0-degree'!J88 -> 3638.0217 | K13: =+'[1]0-degree'!K88 -> 4345.1975 | L13: =+'[1]0-degree'!L88 -> 844.23258 | M13: =+'[1]0-degree'!M88 -> 0 | N13: =+'[1]0-degree'!N88 -> 0 | ... T13: =+'[1]0-degree'!T88 -> 0
C14: P3 | E14: 1 | G14: =+'[1]0-degree'!G89 -> 0.0018929204 | H14: =+'[1]0-degree'!H89 -> 4.6902655e-06 | I14: =+'[1]0-degree'!I89 -> 16032.184 | J14: =+'[1]0-degree'!J89 -> 2793.1015 | K14: =+'[1]0-degree'!K89 -> 4792.6541 | L14: =+'[1]0-degree'!L89 -> 1208.1598 | M14: =+'[1]0-degree'!M89 -> 0 | N14: =+'[1]0-degree'!N89 -> -1.1175871e-13 | ... T14: =+'[1]0-degree'!T89 -> -1.0058284e-13
C15: P4 | F15: 0.05 | G15: =+'[1]0-degree'!G90 -> 0.0010964602 | H15: =+'[1]0-degree'!H90 -> 7.3451327e-06 | I15: =+'[1]0-degree'!I90 -> 11565.747 | J15: =+'[1]0-degree'!J90 -> 794.92776 | K15: =+'[1]0-degree'!K90 -> 4683.7408 | L15: =+'[1]0-degree'!L90 -> 1982.7529 | M15: =+'[1]0-degree'!M90 -> 0 | N15: =+'[1]0-degree'!N90 -> 0 | ... T15: =+'[1]0-degree'!T90 -> 0
C16: P5 | D16: Pure Tension | G16: =+'[1]0-degree'!G91 -> -0.05 | H16: =+'[1]0-degree'!H91 -> 0 | I16: =+'[1]0-degree'!I91 -> 0 | J16: =+'[1]0-degree'!J91 -> -5790.5836 | K16: =+'[1]0-degree'!K91 -> 0 | L16: =+'[1]0-degree'!L91 -> 0 | M16: =+'[1]0-degree'!M91 -> 0 | N16: =+'[1]0-degree'!N91 -> 0 | ... T16: =+'[1]0-degree'!T91 -> 0
C18: Rotation | E18: =+'[1]15-degree'!E84 -> 15 | F18: degree
C19: Point | D19: C/C1 | E19: fs/fy | F19: εs | G19: ε0 | H19: κ | I19: P | K19: Mx | M19: My | O19: Normial | R19: Factored
H20: 1/mm | I20: Concrete | J20: Steel | K20: Concrete | L20: Steel | M20: Concrete | N20: Steel | O20: SumP | P20: SumMx | Q20: SumMy | R20: SumP | S20: SumMx | T20: SumMy
C21: P0 | D21: Pure Compression | G21: =+'[1]15-degree'!G87 -> 0.0033 | H21: =+'[1]15-degree'!H87 -> 0 | I21: =+'[1]15-degree'!K87 -> 28560 | J21: =+'[1]15-degree'!L87 -> 5421.4339 | K21: =+'[1]15-degree'!M87 -> 0 | L21: =+'[1]15-degree'!N87 -> 0 | M21: =+'[1]15-degree'!O87 -> 0 | N21: =+'[1]15-degree'!P87 -> 0 | O21: =+'[1]15-degree'!Q87 -> 33981.434 | P21: =+'[1]15-degree'!R87 -> 0 | ... T21: =+'[1]15-degree'!V87 -> 0
C22: P1 | D22: 1 | E22: 0 | G22: =+'[1]15-degree'!G88 -> 0.0025597435 | H22: =+'[1]15-degree'!H88 -> 2.4675217e-06 | I22: =+'[1]15-degree'!K88 -> 27091.888 | J22: =+'[1]15-degree'!L88 -> 4758.0436 | K22: =+'[1]15-degree'!M88 -> 752.88191 | L22: =+'[1]15-degree'!N88 -> 322.41643 | M22: =+'[1]15-degree'!O88 -> 517.43444 | N22: =+'[1]15-degree'!P88 -> 114.82263 | O22: =+'[1]15-degree'!Q88 -> 31849.931 | P22: =+'[1]15-degree'!R88 -> 1075.2983 | ... T22: =+'[1]15-degree'!V88 -> 439.67275
C23: P2 | E23: 0.5 | G23: =+'[1]15-degree'!G89 -> 0.0023354233 | H23: =+'[1]15-degree'!H89 -> 3.2152555e-06 | I23: =+'[1]15-degree'!K89 -> 20002.941 | J23: =+'[1]15-degree'!L89 -> 4142.425 | K23: =+'[1]15-degree'!M89 -> 3815.759 | L23: =+'[1]15-degree'!N89 -> 598.57417 | M23: =+'[1]15-degree'!O89 -> 1241.3181 | N23: =+'[1]15-degree'!P89 -> 226.30605 | O23: =+'[1]15-degree'!Q89 -> 24145.366 | P23: =+'[1]15-degree'!R89 -> 4414.3332 | ... T23: =+'[1]15-degree'!V89 -> 1010.5322
C24: P3 | E24: 1 | G24: =+'[1]15-degree'!G90 -> 0.0021111032 | H24: =+'[1]15-degree'!H90 -> 3.9629893e-06 | I24: =+'[1]15-degree'!K90 -> 16312.512 | J24: =+'[1]15-degree'!L90 -> 3464.3997 | K24: =+'[1]15-degree'!M90 -> 4621.7466 | L24: =+'[1]15-degree'!N90 -> 878.70625 | M24: =+'[1]15-degree'!O90 -> 1180.8847 | N24: =+'[1]15-degree'!P90 -> 328.69523 | O24: =+'[1]15-degree'!Q90 -> 19776.912 | P24: =+'[1]15-degree'!R90 -> 5500.4528 | ... T24: =+'[1]15-degree'!V90 -> 1063.4008
C25: P4 | F25: 0.05 | G25: =+'[1]15-degree'!G91 -> 0.0014381427 | H25: =+'[1]15-degree'!H91 -> 6.2061909e-06 | I25: =+'[1]15-degree'!K91 -> 10746.221 | J25: =+'[1]15-degree'!L91 -> 1340.3732 | K25: =+'[1]15-degree'!M91 -> 4385.9375 | L25: =+'[1]15-degree'!N91 -> 1739.8373 | M25: =+'[1]15-degree'!O91 -> 1190.6582 | N25: =+'[1]15-degree'!P91 -> 643.94619 | O25: =+'[1]15-degree'!Q91 -> 12086.594 | P25: =+'[1]15-degree'!R91 -> 6125.7748 | ... T25: =+'[1]15-degree'!V91 -> 1353.4794
C26: P5 | D26: Pure Tension | G26: =+'[1]15-degree'!G92 -> -0.05 | H26: =+'[1]15-degree'!H92 -> 0 | I26: =+'[1]15-degree'!K92 -> 0 | J26: =+'[1]15-degree'!L92 -> -5790.5836 | K26: =+'[1]15-degree'!M92 -> 0 | L26: =+'[1]15-degree'!N92 -> 0 | M26: =+'[1]15-degree'!O92 -> 0 | N26: =+'[1]15-degree'!P92 -> 0 | O26: =+'[1]15-degree'!Q92 -> -5790.5836 | P26: =+'[1]15-degree'!R92 -> 0 | ... T26: =+'[1]15-degree'!V92 -> 0
C28: Rotation | E28: 30 | F28: degree
C29: Point | D29: C/C1 | E29: fs/fy | F29: εs | G29: ε0 | H29: κ | I29: P | K29: Mx | M29: My | O29: Normial | R29: Factored
H30: 1/mm | I30: Concrete | J30: Steel | K30: Concrete | L30: Steel | M30: Concrete | N30: Steel | O30: SumP | P30: SumMx | Q30: SumMy | R30: SumP | S30: SumMx | T30: SumMy
C31: P0 | D31: Pure Compression | G31: =+'[1]30-degree'!G86 -> 0.0033 | H31: =+'[1]30-degree'!H86 -> 0 | I31: =+'[1]30-degree'!I86 -> 28560 | J31: =+'[1]30-degree'!J86 -> 5421.4339 | K31: =+'[1]30-degree'!K86 -> 0 | L31: =+'[1]30-degree'!L86 -> 0 | M31: =+'[1]30-degree'!M86 -> 0 | N31: =+'[1]30-degree'!N86 -> 0 | ... T31: =+'[1]30-degree'!T86 -> 0
C32: P1 | D32: 1 | E32: 0 | G32: =+'[1]30-degree'!G87 -> 0.0026189364 | H32: =+'[1]30-degree'!H87 -> 2.270212e-06 | I32: =+'[1]30-degree'!I87 -> 27030.915 | J32: =+'[1]30-degree'!J87 -> 4911.1807 | K32: =+'[1]30-degree'!K87 -> 743.58608 | L32: =+'[1]30-degree'!L87 -> 219.69946 | M32: =+'[1]30-degree'!M87 -> 793.16144 | N32: =+'[1]30-degree'!N87 -> 186.19186 | ... T32: =+'[1]30-degree'!T87 -> 683.1276
C33: P2 | E33: 0.5 | G33: =+'[1]30-degree'!G88 -> 0.0024125535 | H33: =+'[1]30-degree'!H88 -> 2.9581551e-06 | I33: =+'[1]30-degree'!I88 -> 21387.303 | J33: =+'[1]30-degree'!J88 -> 4292.5438 | K33: =+'[1]30-degree'!K88 -> 2875.3688 | L33: =+'[1]30-degree'!L88 -> 459.17402 | M33: =+'[1]30-degree'!M88 -> 2402.9672 | N33: =+'[1]30-degree'!N88 -> 358.76975 | ... T33: =+'[1]30-degree'!T88 -> 1884.8214
C34: P3 | E34: 1 | G34: =+'[1]30-degree'!G89 -> 0.0022061706 | H34: =+'[1]30-degree'!H89 -> 3.6460981e-06 | I34: =+'[1]30-degree'!I89 -> 16518.158 | J34: =+'[1]30-degree'!J89 -> 3666.2681 | K34: =+'[1]30-degree'!K89 -> 4056.5145 | L34: =+'[1]30-degree'!L89 -> 689.72839 | M34: =+'[1]30-degree'!M89 -> 2479.7479 | N34: =+'[1]30-degree'!N89 -> 538.33485 | ... T34: =+'[1]30-degree'!T89 -> 2096.3375
C35: P4 | F35: 0.05 | G35: =+'[1]30-degree'!G90 -> 0.0015870218 | H35: =+'[1]30-degree'!H90 -> 5.7099273e-06 | I35: =+'[1]30-degree'!I90 -> 9674.867 | J35: =+'[1]30-degree'!J90 -> 1658.02 | K35: =+'[1]30-degree'!K90 -> 3620.4972 | L35: =+'[1]30-degree'!L90 -> 1378.7867 | M35: =+'[1]30-degree'!M90 -> 2447.942 | N35: =+'[1]30-degree'!N90 -> 1158.9742 | ... T35: =+'[1]30-degree'!T90 -> 2634.2391
C36: P5 | D36: Pure Tension | G36: =+'[1]30-degree'!G91 -> -0.05 | H36: =+'[1]30-degree'!H91 -> 0 | I36: =+'[1]30-degree'!I91 -> 0 | J36: =+'[1]30-degree'!J91 -> -5790.5836 | K36: =+'[1]30-degree'!K91 -> 0 | L36: =+'[1]30-degree'!L91 -> 0 | M36: =+'[1]30-degree'!M91 -> 0 | N36: =+'[1]30-degree'!N91 -> 0 | ... T36: =+'[1]30-degree'!T91 -> 0
C40: For each degree of rotation, do for all points (18 points)
C42: Point | D42: C/C1 | E42: fs/fy | F42: εs
C44: P0 | D44: Pure Compression
C45: P1 | D45: 3
C46: P2 | D46: 2
C47: P3 | D47: 1.5
C48: P4 | D48: 1.2
C49: P5 fs=0 | D49: 1 | E49: 0
C50: P6 | E50: 0.25
C51: P7 | E51: 0.5
C52: P8 | E52: 0.75
C53: P9 fs=fy | E53: 1 | F53: 0.002
...
