Workbook
Name fck: Input!$C$14
Name alpha: Input!$C$15
Name sig_blk: Input!$C$16
Name beta_1: Input!$C$17
Name ecu: Input!$C$18
Name Es: Input!$C$23
Name fy_char: Input!$C$24
Name gamma_s: Input!$C$25
Name fy: Input!$C$26
Name epsy: Input!$C$27
Name phi_c: Input!$C$33
Name phi_t: Input!$C$34
Name ept_lim: Input!$C$35
Name cap_r: Input!$C$36
Name theta: Input!$C$40
Name u_max: Input!$C$41
Name d_theta: Input!$C$42
Name blk_tol: Input!$C$43
Name xc: Input!$C$44
Name yc: Input!$C$45
Name Pu: Input!$C$53
Name Mux: Input!$C$54
Name Muy: Input!$C$55
Name theta_L: Input!$C$57
Name Mu: Input!$C$58
Name Geom_Area: Geometry!$G$35
Name Bar_No: Geometry!$B$39:$B$56
Name Bar_X: Geometry!$E$39:$E$56
Name Bar_Y: Geometry!$F$39:$F$56
Name Bar_As: Geometry!$G$39:$G$56
Name Bar_U: Geometry!$H$39:$H$56
Name Blk_St: Block!$B$6:$B$40
Name Blk_c: Block!$C$6:$C$40
Name Blk_Cc: Block!$J$6:$J$40
Name Blk_Mcx: Block!$K$6:$K$40
Name Blk_Mcy: Block!$L$6:$L$40
Name Stl_St: Steel!$B$6:$B$635
Name Stl_Ept: Steel!$H$6:$H$635
Name Stl_F: Steel!$M$6:$M$635
Name Stl_Mx: Steel!$N$6:$N$635
Name Stl_My: Steel!$O$6:$O$635

Sheet Input
B1: EQUIVALENT RECTANGULAR STRESS BLOCK — SECTION CALCULATION
B2: Project | C2: PM-advanced (7) 2D reference case | E2: Every shaded cell drives live formulas on the other sheets. Only the clipped-polygon geometry and the sampled surface grid are engine values; the ledger, φ, contour and residual are formulas.
B3: Section | C3: PM-advanced (7) 2D — 1500x1200 chamfered section, two voids
B4: Generated | C4: 2026-08-04 23:05:32
B6: Calculation profile
B7: profile | C7: KDS 14 20 20 — Equivalent rectangular block | E7: method equivalent-rectangular-block
B8: resistance profile | C8: KDS 2024 current set · resistance: KDS 14 20 10:2021 + KDS 14 20 20:2022 | E8: 2024 partial-revision framework (effective 2025-01-05)
B9: verification status | C9: draft | E9: not an engineering approval; see docs/00-README §4
B10: modified from defaults | C10: no
B12: Concrete — equivalent block
B13: standard | C13: KDS | E13: KDS C30 (workbook Input)
B14: fck | C14: 30 | D14: MPa | E14: characteristic/input strength
B15: α (σblock/fck) | C15: 0.85 | D15: - | E15: resolved by the code adapter; KDS writes it as η·0.85, ACI as 0.85
B16: σblock = α·fck | C16: =alpha*fck -> 25.5 | D16: MPa
B17: β1 | C17: 0.8 | D17: - | E17: block depth a = β1·c
B18: εcu | C18: 0.0033 | D18: - | E18: extreme compression fibre strain
B19: displaced concrete deducted | C19: yes | E19: bars inside the block carry σs − σblock
B21: Reinforcement
B22: standard | C22: KDS | E22: SD400 (workbook Input)
B23: Es | C23: 200000 | D23: MPa
B24: fy (characteristic) | C24: 400 | D24: MPa
B25: γs | C25: 1 | D25: - | E25: not applied by this material family
B26: fy (model) | C26: =fy_char -> 400 | D26: MPa
B27: εy = fy/Es | C27: =fy/Es -> 0.002 | D27: -
B28: εu (declared) | C28: not declared | D28: - | E28: rupture is not enforced
B29: law | C29: Elastic – perfectly plastic: fs = clamp(Es·ε, −fy, +fy)
B31: Strength reduction and axial cap
B32: transverse reinforcement | C32: other | E32: selects the compression-controlled φ and the cap ratio
B33: φ compression (active) | C33: 0.65 | D33: -
B34: φ tension | C34: 0.85 | D34: -
B35: εt,limit | C35: 0.005 | D35: - | E35: fixed 0.005 at or below fy = 400 MPa, else 2.5·εy
B36: axial cap ratio | C36: 0.8 | D36: -
B37: axial cap applied | C37: yes | E37: clips the design surface at cap ratio × the factored compression pole
B39: Analysis
B40: θ (block-normal direction) | C40: 15 | D40: deg | E40: audited direction; snapped from the requested 15.0000° to the nearest sampled direction
B41: u_max (compression edge) | C41: 827.97199 | D41: mm | E41: max of n·(x,y) over the outer boundary at θ; an engine value because it needs the polygon
B42: Dθ (projected depth) | C42: 1655.944 | D42: mm
B43: block-boundary tolerance | C43: 1.5e-07 | D43: mm | E43: the kernel's own 1e-10 · characteristic length; a bar within it counts as inside the block
B44: xc | C44: 0 | D44: mm | E44: analysis origin = net concrete centroid
B45: yc | C45: 0 | D45: mm | E45: all X, Y below are measured from it
...

Sheet Geometry
B1: SECTION GEOMETRY ABOUT THE ANALYSIS ORIGIN
B2: Ring vertices are input data. Area and first moments are recomputed here by the shoelace formula so the origin used by every other sheet is verifiable.
B4: # | C4: solid | D4: ring | E4: X (mm) | F4: Y (mm) | G4: X·Ynext − Xnext·Y | H4: (X+Xnext)·cross | I4: (Y+Ynext)·cross
B5: 1 | C5: 1 | D5: outer | E5: -550 | F5: 600 | G5: =E5*F6-E6*F5 | H5: =(E5+E6)*G5 | I5: =(F5+F6)*G5
B6: 2 | C6: 1 | D6: outer | E6: 550 | F6: 600 | G6: =E6*F7-E7*F6 | H6: =(E6+E7)*G6 | I6: =(F6+F7)*G6
B7: 3 | C7: 1 | D7: outer | E7: 750 | F7: 400 | G7: =E7*F8-E8*F7 | H7: =(E7+E8)*G7 | I7: =(F7+F8)*G7
B8: 4 | C8: 1 | D8: outer | E8: 750 | F8: -400 | G8: =E8*F9-E9*F8 | H8: =(E8+E9)*G8 | I8: =(F8+F9)*G8
B9: 5 | C9: 1 | D9: outer | E9: 550 | F9: -600 | G9: =E9*F10-E10*F9 | H9: =(E9+E10)*G9 | I9: =(F9+F10)*G9
B10: 6 | C10: 1 | D10: outer | E10: -550 | F10: -600 | G10: =E10*F11-E11*F10 | H10: =(E10+E11)*G10 | I10: =(F10+F11)*G10
B11: 7 | C11: 1 | D11: outer | E11: -750 | F11: -400 | G11: =E11*F12-E12*F11 | H11: =(E11+E12)*G11 | I11: =(F11+F12)*G11
B12: 8 | C12: 1 | D12: outer | E12: -750 | F12: 400 | G12: =E12*F5-E5*F12 | H12: =(E12+E5)*G12 | I12: =(F12+F5)*G12
D13: ring total | G13: =SUM(G5:G12)/2 | H13: =SUM(H5:H12)/6 | I13: =SUM(I5:I12)/6 | J13: signed area, Sx, Sy of this ring
B15: 1 | C15: 1 | D15: hole 1 | E15: -450 | F15: 400 | G15: =E15*F16-E16*F15 | H15: =(E15+E16)*G15 | I15: =(F15+F16)*G15
B16: 2 | C16: 1 | D16: hole 1 | E16: -250 | F16: 400 | G16: =E16*F17-E17*F16 | H16: =(E16+E17)*G16 | I16: =(F16+F17)*G16
B17: 3 | C17: 1 | D17: hole 1 | E17: -150 | F17: 300 | G17: =E17*F18-E18*F17 | H17: =(E17+E18)*G17 | I17: =(F17+F18)*G17
B18: 4 | C18: 1 | D18: hole 1 | E18: -150 | F18: -300 | G18: =E18*F19-E19*F18 | H18: =(E18+E19)*G18 | I18: =(F18+F19)*G18
B19: 5 | C19: 1 | D19: hole 1 | E19: -250 | F19: -400 | G19: =E19*F20-E20*F19 | H19: =(E19+E20)*G19 | I19: =(F19+F20)*G19
B20: 6 | C20: 1 | D20: hole 1 | E20: -450 | F20: -400 | G20: =E20*F21-E21*F20 | H20: =(E20+E21)*G20 | I20: =(F20+F21)*G20
B21: 7 | C21: 1 | D21: hole 1 | E21: -550 | F21: -300 | G21: =E21*F22-E22*F21 | H21: =(E21+E22)*G21 | I21: =(F21+F22)*G21
B22: 8 | C22: 1 | D22: hole 1 | E22: -550 | F22: 300 | G22: =E22*F15-E15*F22 | H22: =(E22+E15)*G22 | I22: =(F22+F15)*G22
D23: ring total | G23: =SUM(G15:G22)/2 | H23: =SUM(H15:H22)/6 | I23: =SUM(I15:I22)/6 | J23: subtracted as a hole
B25: 1 | C25: 1 | D25: hole 2 | E25: 250 | F25: 400 | G25: =E25*F26-E26*F25 | H25: =(E25+E26)*G25 | I25: =(F25+F26)*G25
B26: 2 | C26: 1 | D26: hole 2 | E26: 450 | F26: 400 | G26: =E26*F27-E27*F26 | H26: =(E26+E27)*G26 | I26: =(F26+F27)*G26
B27: 3 | C27: 1 | D27: hole 2 | E27: 550 | F27: 300 | G27: =E27*F28-E28*F27 | H27: =(E27+E28)*G27 | I27: =(F27+F28)*G27
B28: 4 | C28: 1 | D28: hole 2 | E28: 550 | F28: -300 | G28: =E28*F29-E29*F28 | H28: =(E28+E29)*G28 | I28: =(F28+F29)*G28
B29: 5 | C29: 1 | D29: hole 2 | E29: 450 | F29: -400 | G29: =E29*F30-E30*F29 | H29: =(E29+E30)*G29 | I29: =(F29+F30)*G29
B30: 6 | C30: 1 | D30: hole 2 | E30: 250 | F30: -400 | G30: =E30*F31-E31*F30 | H30: =(E30+E31)*G30 | I30: =(F30+F31)*G30
B31: 7 | C31: 1 | D31: hole 2 | E31: 150 | F31: -300 | G31: =E31*F32-E32*F31 | H31: =(E31+E32)*G31 | I31: =(F31+F32)*G31
B32: 8 | C32: 1 | D32: hole 2 | E32: 150 | F32: 300 | G32: =E32*F25-E25*F32 | H32: =(E32+E25)*G32 | I32: =(F32+F25)*G32
D33: ring total | G33: =SUM(G25:G32)/2 | H33: =SUM(H25:H32)/6 | I33: =SUM(I25:I32)/6 | J33: subtracted as a hole
D35: NET | G35: =ABS(G13)-ABS(G23)-ABS(G33) | H35: =SIGN(G13)*H13-SIGN(G23)*H23-SIGN(G33)*H33 | I35: =SIGN(G13)*I13-SIGN(G23)*I23-SIGN(G33)*I33 | J35: =IF(ABS(H35)+ABS(I35)<=0.000001*ABS(G35)*1500.000000,"OK - the origin is the net centroid","CHECK - first moments about the origin are not zero")
B37: Reinforcement schedule
B38: # | C38: id | D38: Ø (mm) | E38: X (mm) | F38: Y (mm) | G38: As (mm²) | H38: n·(X,Y) (mm)
B39: 1 | C39: 1 | D39: 32 | E39: -400 | F39: 530 | G39: =PI()*D39^2/4 | H39: =COS(RADIANS(theta))*(E39+xc)+SIN(RADIANS(theta))*(F39+yc)
B40: 2 | C40: 2 | D40: 32 | E40: -200 | F40: 530 | G40: =PI()*D40^2/4 | H40: =COS(RADIANS(theta))*(E40+xc)+SIN(RADIANS(theta))*(F40+yc)
B41: 3 | C41: 3 | D41: 32 | E41: 0 | F41: 530 | G41: =PI()*D41^2/4 | H41: =COS(RADIANS(theta))*(E41+xc)+SIN(RADIANS(theta))*(F41+yc)
B42: 4 | C42: 4 | D42: 32 | E42: 200 | F42: 530 | G42: =PI()*D42^2/4 | H42: =COS(RADIANS(theta))*(E42+xc)+SIN(RADIANS(theta))*(F42+yc)
B43: 5 | C43: 5 | D43: 32 | E43: 400 | F43: 530 | G43: =PI()*D43^2/4 | H43: =COS(RADIANS(theta))*(E43+xc)+SIN(RADIANS(theta))*(F43+yc)
B44: 6 | C44: 6 | D44: 32 | E44: -400 | F44: -530 | G44: =PI()*D44^2/4 | H44: =COS(RADIANS(theta))*(E44+xc)+SIN(RADIANS(theta))*(F44+yc)
B45: 7 | C45: 7 | D45: 32 | E45: -200 | F45: -530 | G45: =PI()*D45^2/4 | H45: =COS(RADIANS(theta))*(E45+xc)+SIN(RADIANS(theta))*(F45+yc)
...

Sheet Block_Clip
B1: CLIPPED COMPRESSION POLYGON, u ≥ u_max − β1·c
B2: The clipping itself is an engine value. Its area and first moments are recomputed here by shoelace so the numbers the Block ledger multiplies by σblock are independently verifiable.
B4: station | C4: ring | D4: sign | E4: X (mm) | F4: Y (mm) | G4: cross | H4: (X+Xn)·cross | I4: (Y+Yn)·cross
B5: 1 | C5: outer | D5: 1 | E5: -353.53829 | F5: -600 | G5: =E5*F6-E6*F5 | H5: =(E5+E6)*G5 | I5: =(F5+F6)*G5
B6: 1 | C6: outer | D6: 1 | E6: 550 | F6: -600 | G6: =E6*F7-E7*F6 | H6: =(E6+E7)*G6 | I6: =(F6+F7)*G6
B7: 1 | C7: outer | D7: 1 | E7: 750 | F7: -400 | G7: =E7*F8-E8*F7 | H7: =(E7+E8)*G7 | I7: =(F7+F8)*G7
B8: 1 | C8: outer | D8: 1 | E8: 750 | F8: 400 | G8: =E8*F9-E9*F8 | H8: =(E8+E9)*G8 | I8: =(F8+F9)*G8
B9: 1 | C9: outer | D9: 1 | E9: 550 | F9: 600 | G9: =E9*F10-E10*F9 | H9: =(E9+E10)*G9 | I9: =(F9+F10)*G9
B10: 1 | C10: outer | D10: 1 | E10: -550 | F10: 600 | G10: =E10*F11-E11*F10 | H10: =(E10+E11)*G10 | I10: =(F10+F11)*G10
B11: 1 | C11: outer | D11: 1 | E11: -648.64537 | F11: 501.35463 | G11: =E11*F5-E5*F11 | H11: =(E11+E5)*G11 | I11: =(F11+F5)*G11
B12: 1 | C12: ring Σ | G12: =D5*ABS(SUM(G5:G11)/2) | H12: =D5*SIGN(SUM(G5:G11))*SUM(H5:H11)/6 | I12: =D5*SIGN(SUM(G5:G11))*SUM(I5:I11)/6
B13: 1 | C13: hole 1 | D13: -1 | E13: -450 | F13: 400 | G13: =E13*F14-E14*F13 | H13: =(E13+E14)*G13 | I13: =(F13+F14)*G13
B14: 1 | C14: hole 1 | D14: -1 | E14: -250 | F14: 400 | G14: =E14*F15-E15*F14 | H14: =(E14+E15)*G14 | I14: =(F14+F15)*G14
B15: 1 | C15: hole 1 | D15: -1 | E15: -150 | F15: 300 | G15: =E15*F16-E16*F15 | H15: =(E15+E16)*G15 | I15: =(F15+F16)*G15
B16: 1 | C16: hole 1 | D16: -1 | E16: -150 | F16: -300 | G16: =E16*F17-E17*F16 | H16: =(E16+E17)*G16 | I16: =(F16+F17)*G16
B17: 1 | C17: hole 1 | D17: -1 | E17: -250 | F17: -400 | G17: =E17*F18-E18*F17 | H17: =(E17+E18)*G17 | I17: =(F17+F18)*G17
B18: 1 | C18: hole 1 | D18: -1 | E18: -407.12813 | F18: -400 | G18: =E18*F19-E19*F18 | H18: =(E18+E19)*G18 | I18: =(F18+F19)*G18
B19: 1 | C19: hole 1 | D19: -1 | E19: -550 | F19: 133.20508 | G19: =E19*F20-E20*F19 | H19: =(E19+E20)*G19 | I19: =(F19+F20)*G19
B20: 1 | C20: hole 1 | D20: -1 | E20: -550 | F20: 300 | G20: =E20*F13-E13*F20 | H20: =(E20+E13)*G20 | I20: =(F20+F13)*G20
B21: 1 | C21: ring Σ | G21: =D13*ABS(SUM(G13:G20)/2) | H21: =D13*SIGN(SUM(G13:G20))*SUM(H13:H20)/6 | I21: =D13*SIGN(SUM(G13:G20))*SUM(I13:I20)/6
B22: 1 | C22: hole 2 | D22: -1 | E22: 250 | F22: 400 | G22: =E22*F23-E23*F22 | H22: =(E22+E23)*G22 | I22: =(F22+F23)*G22
B23: 1 | C23: hole 2 | D23: -1 | E23: 450 | F23: 400 | G23: =E23*F24-E24*F23 | H23: =(E23+E24)*G23 | I23: =(F23+F24)*G23
B24: 1 | C24: hole 2 | D24: -1 | E24: 550 | F24: 300 | G24: =E24*F25-E25*F24 | H24: =(E24+E25)*G24 | I24: =(F24+F25)*G24
B25: 1 | C25: hole 2 | D25: -1 | E25: 550 | F25: -300 | G25: =E25*F26-E26*F25 | H25: =(E25+E26)*G25 | I25: =(F25+F26)*G25
B26: 1 | C26: hole 2 | D26: -1 | E26: 450 | F26: -400 | G26: =E26*F27-E27*F26 | H26: =(E26+E27)*G26 | I26: =(F26+F27)*G26
B27: 1 | C27: hole 2 | D27: -1 | E27: 250 | F27: -400 | G27: =E27*F28-E28*F27 | H27: =(E27+E28)*G27 | I27: =(F27+F28)*G27
B28: 1 | C28: hole 2 | D28: -1 | E28: 150 | F28: -300 | G28: =E28*F29-E29*F28 | H28: =(E28+E29)*G28 | I28: =(F28+F29)*G28
B29: 1 | C29: hole 2 | D29: -1 | E29: 150 | F29: 300 | G29: =E29*F22-E22*F29 | H29: =(E29+E22)*G29 | I29: =(F29+F22)*G29
B30: 1 | C30: ring Σ | G30: =D22*ABS(SUM(G22:G29)/2) | H30: =D22*SIGN(SUM(G22:G29))*SUM(H22:H29)/6 | I30: =D22*SIGN(SUM(G22:G29))*SUM(I22:I29)/6
B31: 1 | C31: station Σ | G31: =G12+G21+G30 | H31: =H12+H21+H30 | I31: =I12+I21+I30
B33: 2 | C33: outer | D33: 1 | E33: -260.12781 | F33: -600 | G33: =E33*F34-E34*F33 | H33: =(E33+E34)*G33 | I33: =(F33+F34)*G33
B34: 2 | C34: outer | D34: 1 | E34: 550 | F34: -600 | G34: =E34*F35-E35*F34 | H34: =(E34+E35)*G34 | I34: =(F34+F35)*G34
B35: 2 | C35: outer | D35: 1 | E35: 750 | F35: -400 | G35: =E35*F36-E36*F35 | H35: =(E35+E36)*G35 | I35: =(F35+F36)*G35
B36: 2 | C36: outer | D36: 1 | E36: 750 | F36: 400 | G36: =E36*F37-E37*F36 | H36: =(E36+E37)*G36 | I36: =(F36+F37)*G36
B37: 2 | C37: outer | D37: 1 | E37: 550 | F37: 600 | G37: =E37*F38-E38*F37 | H37: =(E37+E38)*G37 | I37: =(F37+F38)*G37
B38: 2 | C38: outer | D38: 1 | E38: -550 | F38: 600 | G38: =E38*F39-E39*F38 | H38: =(E38+E39)*G38 | I38: =(F38+F39)*G38
B39: 2 | C39: outer | D39: 1 | E39: -574.97485 | F39: 575.02515 | G39: =E39*F33-E33*F39 | H39: =(E39+E33)*G39 | I39: =(F39+F33)*G39
B40: 2 | C40: ring Σ | G40: =D33*ABS(SUM(G33:G39)/2) | H40: =D33*SIGN(SUM(G33:G39))*SUM(H33:H39)/6 | I40: =D33*SIGN(SUM(G33:G39))*SUM(I33:I39)/6
B41: 2 | C41: hole 1 | D41: -1 | E41: -450 | F41: 400 | G41: =E41*F42-E42*F41 | H41: =(E41+E42)*G41 | I41: =(F41+F42)*G41
B42: 2 | C42: hole 1 | D42: -1 | E42: -250 | F42: 400 | G42: =E42*F43-E43*F42 | H42: =(E42+E43)*G42 | I42: =(F42+F43)*G42
...

Sheet Block
B1: CONCRETE BLOCK LEDGER AT θ
B2: One row per neutral-axis state at the audited direction. Cc, Mcx and Mcy are formulas over σblock and the clipped moments recomputed on Block_Clip, so changing fck or α on Input propagates through the whole ledger.
B5: st | C5: c (mm) | D5: a = β1·c | E5: A_blk (mm²) | F5: Sx (mm³) | G5: Sy (mm³) | H5: x̄ (mm) | I5: ȳ (mm) | J5: Cc (kN) | K5: Mcx (kN·m) | L5: Mcy (kN·m) | M5: A engine (mm²)
B6: 1 | C6: 1655.944 | D6: =beta_1*C6 | E6: =Block_Clip!G31 | F6: =Block_Clip!H31 | G6: =Block_Clip!I31 | H6: =IF(E6=0,0,F6/E6) | I6: =IF(E6=0,0,G6/E6) | J6: =sig_blk*E6/1000 | K6: =sig_blk*(G6-yc*E6)/1000000 | L6: =sig_blk*(F6-xc*E6)/1000000 | M6: 904090.22
B7: 2 | C7: 1543.1595 | D7: =beta_1*C7 | E7: =Block_Clip!G58 | F7: =Block_Clip!H58 | G7: =Block_Clip!I58 | H7: =IF(E7=0,0,F7/E7) | I7: =IF(E7=0,0,G7/E7) | J7: =sig_blk*E7/1000 | K7: =sig_blk*(G7-yc*E7)/1000000 | L7: =sig_blk*(F7-xc*E7)/1000000 | M7: 860367.38
B8: 3 | C8: 1438.0566 | D8: =beta_1*C8 | E8: =Block_Clip!G82 | F8: =Block_Clip!H82 | G8: =Block_Clip!I82 | H8: =IF(E8=0,0,F8/E8) | I8: =IF(E8=0,0,G8/E8) | J8: =sig_blk*E8/1000 | K8: =sig_blk*(G8-yc*E8)/1000000 | L8: =sig_blk*(F8-xc*E8)/1000000 | M8: 823324.92
B9: 4 | C9: 1270.8407 | D9: =beta_1*C9 | E9: =Block_Clip!G105 | F9: =Block_Clip!H105 | G9: =Block_Clip!I105 | H9: =IF(E9=0,0,F9/E9) | I9: =IF(E9=0,0,G9/E9) | J9: =sig_blk*E9/1000 | K9: =sig_blk*(G9-yc*E9)/1000000 | L9: =sig_blk*(F9-xc*E9)/1000000 | M9: 756010.91
B10: 5 | C10: 1138.4615 | D10: =beta_1*C10 | E10: =Block_Clip!G127 | F10: =Block_Clip!H127 | G10: =Block_Clip!I127 | H10: =IF(E10=0,0,F10/E10) | I10: =IF(E10=0,0,G10/E10) | J10: =sig_blk*E10/1000 | K10: =sig_blk*(G10-yc*E10)/1000000 | L10: =sig_blk*(F10-xc*E10)/1000000 | M10: 662200.6
B11: 6 | C11: 1031.0595 | D11: =beta_1*C11 | E11: =Block_Clip!G145 | F11: =Block_Clip!H145 | G11: =Block_Clip!I145 | H11: =IF(E11=0,0,F11/E11) | I11: =IF(E11=0,0,G11/E11) | J11: =sig_blk*E11/1000 | K11: =sig_blk*(G11-yc*E11)/1000000 | L11: =sig_blk*(F11-xc*E11)/1000000 | M11: 556118.43
B12: 7 | C12: 972.84452 | D12: =beta_1*C12 | E12: =Block_Clip!G163 | F12: =Block_Clip!H163 | G12: =Block_Clip!I163 | H12: =IF(E12=0,0,F12/E12) | I12: =IF(E12=0,0,G12/E12) | J12: =sig_blk*E12/1000 | K12: =sig_blk*(G12-yc*E12)/1000000 | L12: =sig_blk*(F12-xc*E12)/1000000 | M12: 498260.64
B13: 8 | C13: 942.17502 | D13: =beta_1*C13 | E13: =Block_Clip!G182 | F13: =Block_Clip!H182 | G13: =Block_Clip!I182 | H13: =IF(E13=0,0,F13/E13) | I13: =IF(E13=0,0,G13/E13) | J13: =sig_blk*E13/1000 | K13: =sig_blk*(G13-yc*E13)/1000000 | L13: =sig_blk*(F13-xc*E13)/1000000 | M13: 467912.73
B14: 9 | C14: 908.55964 | D14: =beta_1*C14 | E14: =Block_Clip!G201 | F14: =Block_Clip!H201 | G14: =Block_Clip!I201 | H14: =IF(E14=0,0,F14/E14) | I14: =IF(E14=0,0,G14/E14) | J14: =sig_blk*E14/1000 | K14: =sig_blk*(G14-yc*E14)/1000000 | L14: =sig_blk*(F14-xc*E14)/1000000 | M14: 437506.34
B15: 10 | C15: 867.39923 | D15: =beta_1*C15 | E15: =Block_Clip!G220 | F15: =Block_Clip!H220 | G15: =Block_Clip!I220 | H15: =IF(E15=0,0,F15/E15) | I15: =IF(E15=0,0,G15/E15) | J15: =sig_blk*E15/1000 | K15: =sig_blk*(G15-yc*E15)/1000000 | L15: =sig_blk*(F15-xc*E15)/1000000 | M15: 405656.75
B16: 11 | C16: 852.24396 | D16: =beta_1*C16 | E16: =Block_Clip!G238 | F16: =Block_Clip!H238 | G16: =Block_Clip!I238 | H16: =IF(E16=0,0,F16/E16) | I16: =IF(E16=0,0,G16/E16) | J16: =sig_blk*E16/1000 | K16: =sig_blk*(G16-yc*E16)/1000000 | L16: =sig_blk*(F16-xc*E16)/1000000 | M16: 395372.55
B17: 12 | C17: 805.80113 | D17: =beta_1*C17 | E17: =Block_Clip!G256 | F17: =Block_Clip!H256 | G17: =Block_Clip!I256 | H17: =IF(E17=0,0,F17/E17) | I17: =IF(E17=0,0,G17/E17) | J17: =sig_blk*E17/1000 | K17: =sig_blk*(G17-yc*E17)/1000000 | L17: =sig_blk*(F17-xc*E17)/1000000 | M17: 367552.9
B18: 13 | C18: 802.5021 | D18: =beta_1*C18 | E18: =Block_Clip!G274 | F18: =Block_Clip!H274 | G18: =Block_Clip!I274 | H18: =IF(E18=0,0,F18/E18) | I18: =IF(E18=0,0,G18/E18) | J18: =sig_blk*E18/1000 | K18: =sig_blk*(G18-yc*E18)/1000000 | L18: =sig_blk*(F18-xc*E18)/1000000 | M18: 365786.8
B19: 14 | C19: 758.24647 | D19: =beta_1*C19 | E19: =Block_Clip!G292 | F19: =Block_Clip!H292 | G19: =Block_Clip!I292 | H19: =IF(E19=0,0,F19/E19) | I19: =IF(E19=0,0,G19/E19) | J19: =sig_blk*E19/1000 | K19: =sig_blk*(G19-yc*E19)/1000000 | L19: =sig_blk*(F19-xc*E19)/1000000 | M19: 344788.88
B20: 15 | C20: 748.57741 | D20: =beta_1*C20 | E20: =Block_Clip!G309 | F20: =Block_Clip!H309 | G20: =Block_Clip!I309 | H20: =IF(E20=0,0,F20/E20) | I20: =IF(E20=0,0,G20/E20) | J20: =sig_blk*E20/1000 | K20: =sig_blk*(G20-yc*E20)/1000000 | L20: =sig_blk*(F20-xc*E20)/1000000 | M20: 340800.4
B21: 16 | C21: 718.61686 | D21: =beta_1*C21 | E21: =Block_Clip!G326 | F21: =Block_Clip!H326 | G21: =Block_Clip!I326 | H21: =IF(E21=0,0,F21/E21) | I21: =IF(E21=0,0,G21/E21) | J21: =sig_blk*E21/1000 | K21: =sig_blk*(G21-yc*E21)/1000000 | L21: =sig_blk*(F21-xc*E21)/1000000 | M21: 328769.45
B22: 17 | C22: 682.92397 | D22: =beta_1*C22 | E22: =Block_Clip!G343 | F22: =Block_Clip!H343 | G22: =Block_Clip!I343 | H22: =IF(E22=0,0,F22/E22) | I22: =IF(E22=0,0,G22/E22) | J22: =sig_blk*E22/1000 | K22: =sig_blk*(G22-yc*E22)/1000000 | L22: =sig_blk*(F22-xc*E22)/1000000 | M22: 315070.5
B23: 18 | C23: 658.38736 | D23: =beta_1*C23 | E23: =Block_Clip!G360 | F23: =Block_Clip!H360 | G23: =Block_Clip!I360 | H23: =IF(E23=0,0,F23/E23) | I23: =IF(E23=0,0,G23/E23) | J23: =sig_blk*E23/1000 | K23: =sig_blk*(G23-yc*E23)/1000000 | L23: =sig_blk*(F23-xc*E23)/1000000 | M23: 306053.08
B24: 19 | C24: 650.60896 | D24: =beta_1*C24 | E24: =Block_Clip!G377 | F24: =Block_Clip!H377 | G24: =Block_Clip!I377 | H24: =IF(E24=0,0,F24/E24) | I24: =IF(E24=0,0,G24/E24) | J24: =sig_blk*E24/1000 | K24: =sig_blk*(G24-yc*E24)/1000000 | L24: =sig_blk*(F24-xc*E24)/1000000 | M24: 303262.43
B25: 20 | C25: 621.21397 | D25: =beta_1*C25 | E25: =Block_Clip!G394 | F25: =Block_Clip!H394 | G25: =Block_Clip!I394 | H25: =IF(E25=0,0,F25/E25) | I25: =IF(E25=0,0,G25/E25) | J25: =sig_blk*E25/1000 | K25: =sig_blk*(G25-yc*E25)/1000000 | L25: =sig_blk*(F25-xc*E25)/1000000 | M25: 293012.04
B26: 21 | C26: 613.78864 | D26: =beta_1*C26 | E26: =Block_Clip!G410 | F26: =Block_Clip!H410 | G26: =Block_Clip!I410 | H26: =IF(E26=0,0,F26/E26) | I26: =IF(E26=0,0,G26/E26) | J26: =sig_blk*E26/1000 | K26: =sig_blk*(G26-yc*E26)/1000000 | L26: =sig_blk*(F26-xc*E26)/1000000 | M26: 290482.46
B27: 22 | C27: 572.21101 | D27: =beta_1*C27 | E27: =Block_Clip!G425 | F27: =Block_Clip!H425 | G27: =Block_Clip!I425 | H27: =IF(E27=0,0,F27/E27) | I27: =IF(E27=0,0,G27/E27) | J27: =sig_blk*E27/1000 | K27: =sig_blk*(G27-yc*E27)/1000000 | L27: =sig_blk*(F27-xc*E27)/1000000 | M27: 276050.02
B28: 23 | C28: 505.98288 | D28: =beta_1*C28 | E28: =Block_Clip!G439 | F28: =Block_Clip!H439 | G28: =Block_Clip!I439 | H28: =IF(E28=0,0,F28/E28) | I28: =IF(E28=0,0,G28/E28) | J28: =sig_blk*E28/1000 | K28: =sig_blk*(G28-yc*E28)/1000000 | L28: =sig_blk*(F28-xc*E28)/1000000 | M28: 252115.75
B29: 24 | C29: 453.49503 | D29: =beta_1*C29 | E29: =Block_Clip!G452 | F29: =Block_Clip!H452 | G29: =Block_Clip!I452 | H29: =IF(E29=0,0,F29/E29) | I29: =IF(E29=0,0,G29/E29) | J29: =sig_blk*E29/1000 | K29: =sig_blk*(G29-yc*E29)/1000000 | L29: =sig_blk*(F29-xc*E29)/1000000 | M29: 232925.09
B30: 25 | C30: 410.87332 | D30: =beta_1*C30 | E30: =Block_Clip!G465 | F30: =Block_Clip!H465 | G30: =Block_Clip!I465 | H30: =IF(E30=0,0,F30/E30) | I30: =IF(E30=0,0,G30/E30) | J30: =sig_blk*E30/1000 | K30: =sig_blk*(G30-yc*E30)/1000000 | L30: =sig_blk*(F30-xc*E30)/1000000 | M30: 214435.32
B31: 26 | C31: 345.86172 | D31: =beta_1*C31 | E31: =Block_Clip!G477 | F31: =Block_Clip!H477 | G31: =Block_Clip!I477 | H31: =IF(E31=0,0,F31/E31) | I31: =IF(E31=0,0,G31/E31) | J31: =sig_blk*E31/1000 | K31: =sig_blk*(G31-yc*E31)/1000000 | L31: =sig_blk*(F31-xc*E31)/1000000 | M31: 179043.24
B32: 27 | C32: 298.61285 | D32: =beta_1*C32 | E32: =Block_Clip!G489 | F32: =Block_Clip!H489 | G32: =Block_Clip!I489 | H32: =IF(E32=0,0,F32/E32) | I32: =IF(E32=0,0,G32/E32) | J32: =sig_blk*E32/1000 | K32: =sig_blk*(G32-yc*E32)/1000000 | L32: =sig_blk*(F32-xc*E32)/1000000 | M32: 146287.41
B33: 28 | C33: 262.72188 | D33: =beta_1*C33 | E33: =Block_Clip!G497 | F33: =Block_Clip!H497 | G33: =Block_Clip!I497 | H33: =IF(E33=0,0,F33/E33) | I33: =IF(E33=0,0,G33/E33) | J33: =sig_blk*E33/1000 | K33: =sig_blk*(G33-yc*E33)/1000000 | L33: =sig_blk*(F33-xc*E33)/1000000 | M33: 117211.13
B34: 29 | C34: 234.53284 | D34: =beta_1*C34 | E34: =Block_Clip!G504 | F34: =Block_Clip!H504 | G34: =Block_Clip!I504 | H34: =IF(E34=0,0,F34/E34) | I34: =IF(E34=0,0,G34/E34) | J34: =sig_blk*E34/1000 | K34: =sig_blk*(G34-yc*E34)/1000000 | L34: =sig_blk*(F34-xc*E34)/1000000 | M34: 94615.22
B35: 30 | C35: 193.09594 | D35: =beta_1*C35 | E35: =Block_Clip!G511 | F35: =Block_Clip!H511 | G35: =Block_Clip!I511 | H35: =IF(E35=0,0,F35/E35) | I35: =IF(E35=0,0,G35/E35) | J35: =sig_blk*E35/1000 | K35: =sig_blk*(G35-yc*E35)/1000000 | L35: =sig_blk*(F35-xc*E35)/1000000 | M35: 65070.338
B36: 31 | C36: 164.10256 | D36: =beta_1*C36 | E36: =Block_Clip!G517 | F36: =Block_Clip!H517 | G36: =Block_Clip!I517 | H36: =IF(E36=0,0,F36/E36) | I36: =IF(E36=0,0,G36/E36) | J36: =sig_blk*E36/1000 | K36: =sig_blk*(G36-yc*E36)/1000000 | L36: =sig_blk*(F36-xc*E36)/1000000 | M36: 47086.828
B37: 32 | C37: 126.20358 | D37: =beta_1*C37 | E37: =Block_Clip!G523 | F37: =Block_Clip!H523 | G37: =Block_Clip!I523 | H37: =IF(E37=0,0,F37/E37) | I37: =IF(E37=0,0,G37/E37) | J37: =sig_blk*E37/1000 | K37: =sig_blk*(G37-yc*E37)/1000000 | L37: =sig_blk*(F37-xc*E37)/1000000 | M37: 27849.161
B38: 33 | C38: 102.52561 | D38: =beta_1*C38 | E38: =Block_Clip!G529 | F38: =Block_Clip!H529 | G38: =Block_Clip!I529 | H38: =IF(E38=0,0,F38/E38) | I38: =IF(E38=0,0,G38/E38) | J38: =sig_blk*E38/1000 | K38: =sig_blk*(G38-yc*E38)/1000000 | L38: =sig_blk*(F38-xc*E38)/1000000 | M38: 18379.491
B39: 34 | C39: 69.790742 | D39: =beta_1*C39 | E39: =Block_Clip!G535 | F39: =Block_Clip!H535 | G39: =Block_Clip!I535 | H39: =IF(E39=0,0,F39/E39) | I39: =IF(E39=0,0,G39/E39) | J39: =sig_blk*E39/1000 | K39: =sig_blk*(G39-yc*E39)/1000000 | L39: =sig_blk*(F39-xc*E39)/1000000 | M39: 8516.5633
B40: 35 | C40: 52.900437 | D40: =beta_1*C40 | E40: =Block_Clip!G541 | F40: =Block_Clip!H541 | G40: =Block_Clip!I541 | H40: =IF(E40=0,0,F40/E40) | I40: =IF(E40=0,0,G40/E40) | J40: =sig_blk*E40/1000 | K40: =sig_blk*(G40-yc*E40)/1000000 | L40: =sig_blk*(F40-xc*E40)/1000000 | M40: 4893.1357
B42: shoelace vs engine | E42: =MAX(ABS(E6:E40-M6:M40)) | F42: =IF(E42<=0.000001*MAX(M6:M40),"OK - the clipped polygon reproduces the area used by the kernel","CHECK - clipped area disagrees") | H42: Array comparison; on older Excel builds confirm with Ctrl+Shift+Enter.

Sheet Steel
B1: REINFORCEMENT LEDGER — EVERY BAR AT EVERY STATION
B2: ε = εcu·(1 − depth/c) with depth measured from the compression edge along the block normal. A bar inside the block carries σs − σblock, because the block already counted the concrete it displaces.
B5: st | C5: bar | D5: c (mm) | E5: u (mm) | F5: depth (mm) | G5: ε | H5: εt | I5: σs (MPa) | J5: in block | K5: σdisp | L5: σnet | M5: F (kN) | N5: Mx (kN·m) | O5: My (kN·m)
B6: 1 | C6: 1 | D6: =INDEX(Blk_c,MATCH(B6,Blk_St,0)) | E6: =INDEX(Bar_U,MATCH(C6,Bar_No,0)) | F6: =u_max-E6 | G6: =ecu*(1-F6/D6) | H6: =MAX(0,-G6) | I6: =MAX(MIN(Es*G6,fy),-fy) | J6: =IF(E6>=u_max-beta_1*D6-blk_tol,1,0) | K6: =J6*sig_blk | L6: =I6-K6 | M6: =INDEX(Bar_As,MATCH(C6,Bar_No,0))*L6/1000 | N6: =M6*INDEX(Bar_Y,MATCH(C6,Bar_No,0))/1000 | O6: =M6*INDEX(Bar_X,MATCH(C6,Bar_No,0))/1000
B7: 1 | C7: 2 | D7: =INDEX(Blk_c,MATCH(B7,Blk_St,0)) | E7: =INDEX(Bar_U,MATCH(C7,Bar_No,0)) | F7: =u_max-E7 | G7: =ecu*(1-F7/D7) | H7: =MAX(0,-G7) | I7: =MAX(MIN(Es*G7,fy),-fy) | J7: =IF(E7>=u_max-beta_1*D7-blk_tol,1,0) | K7: =J7*sig_blk | L7: =I7-K7 | M7: =INDEX(Bar_As,MATCH(C7,Bar_No,0))*L7/1000 | N7: =M7*INDEX(Bar_Y,MATCH(C7,Bar_No,0))/1000 | O7: =M7*INDEX(Bar_X,MATCH(C7,Bar_No,0))/1000
B8: 1 | C8: 3 | D8: =INDEX(Blk_c,MATCH(B8,Blk_St,0)) | E8: =INDEX(Bar_U,MATCH(C8,Bar_No,0)) | F8: =u_max-E8 | G8: =ecu*(1-F8/D8) | H8: =MAX(0,-G8) | I8: =MAX(MIN(Es*G8,fy),-fy) | J8: =IF(E8>=u_max-beta_1*D8-blk_tol,1,0) | K8: =J8*sig_blk | L8: =I8-K8 | M8: =INDEX(Bar_As,MATCH(C8,Bar_No,0))*L8/1000 | N8: =M8*INDEX(Bar_Y,MATCH(C8,Bar_No,0))/1000 | O8: =M8*INDEX(Bar_X,MATCH(C8,Bar_No,0))/1000
B9: 1 | C9: 4 | D9: =INDEX(Blk_c,MATCH(B9,Blk_St,0)) | E9: =INDEX(Bar_U,MATCH(C9,Bar_No,0)) | F9: =u_max-E9 | G9: =ecu*(1-F9/D9) | H9: =MAX(0,-G9) | I9: =MAX(MIN(Es*G9,fy),-fy) | J9: =IF(E9>=u_max-beta_1*D9-blk_tol,1,0) | K9: =J9*sig_blk | L9: =I9-K9 | M9: =INDEX(Bar_As,MATCH(C9,Bar_No,0))*L9/1000 | N9: =M9*INDEX(Bar_Y,MATCH(C9,Bar_No,0))/1000 | O9: =M9*INDEX(Bar_X,MATCH(C9,Bar_No,0))/1000
B10: 1 | C10: 5 | D10: =INDEX(Blk_c,MATCH(B10,Blk_St,0)) | E10: =INDEX(Bar_U,MATCH(C10,Bar_No,0)) | F10: =u_max-E10 | G10: =ecu*(1-F10/D10) | H10: =MAX(0,-G10) | I10: =MAX(MIN(Es*G10,fy),-fy) | J10: =IF(E10>=u_max-beta_1*D10-blk_tol,1,0) | K10: =J10*sig_blk | L10: =I10-K10 | M10: =INDEX(Bar_As,MATCH(C10,Bar_No,0))*L10/1000 | N10: =M10*INDEX(Bar_Y,MATCH(C10,Bar_No,0))/1000 | O10: =M10*INDEX(Bar_X,MATCH(C10,Bar_No,0))/1000
B11: 1 | C11: 6 | D11: =INDEX(Blk_c,MATCH(B11,Blk_St,0)) | E11: =INDEX(Bar_U,MATCH(C11,Bar_No,0)) | F11: =u_max-E11 | G11: =ecu*(1-F11/D11) | H11: =MAX(0,-G11) | I11: =MAX(MIN(Es*G11,fy),-fy) | J11: =IF(E11>=u_max-beta_1*D11-blk_tol,1,0) | K11: =J11*sig_blk | L11: =I11-K11 | M11: =INDEX(Bar_As,MATCH(C11,Bar_No,0))*L11/1000 | N11: =M11*INDEX(Bar_Y,MATCH(C11,Bar_No,0))/1000 | O11: =M11*INDEX(Bar_X,MATCH(C11,Bar_No,0))/1000
B12: 1 | C12: 7 | D12: =INDEX(Blk_c,MATCH(B12,Blk_St,0)) | E12: =INDEX(Bar_U,MATCH(C12,Bar_No,0)) | F12: =u_max-E12 | G12: =ecu*(1-F12/D12) | H12: =MAX(0,-G12) | I12: =MAX(MIN(Es*G12,fy),-fy) | J12: =IF(E12>=u_max-beta_1*D12-blk_tol,1,0) | K12: =J12*sig_blk | L12: =I12-K12 | M12: =INDEX(Bar_As,MATCH(C12,Bar_No,0))*L12/1000 | N12: =M12*INDEX(Bar_Y,MATCH(C12,Bar_No,0))/1000 | O12: =M12*INDEX(Bar_X,MATCH(C12,Bar_No,0))/1000
B13: 1 | C13: 8 | D13: =INDEX(Blk_c,MATCH(B13,Blk_St,0)) | E13: =INDEX(Bar_U,MATCH(C13,Bar_No,0)) | F13: =u_max-E13 | G13: =ecu*(1-F13/D13) | H13: =MAX(0,-G13) | I13: =MAX(MIN(Es*G13,fy),-fy) | J13: =IF(E13>=u_max-beta_1*D13-blk_tol,1,0) | K13: =J13*sig_blk | L13: =I13-K13 | M13: =INDEX(Bar_As,MATCH(C13,Bar_No,0))*L13/1000 | N13: =M13*INDEX(Bar_Y,MATCH(C13,Bar_No,0))/1000 | O13: =M13*INDEX(Bar_X,MATCH(C13,Bar_No,0))/1000
B14: 1 | C14: 9 | D14: =INDEX(Blk_c,MATCH(B14,Blk_St,0)) | E14: =INDEX(Bar_U,MATCH(C14,Bar_No,0)) | F14: =u_max-E14 | G14: =ecu*(1-F14/D14) | H14: =MAX(0,-G14) | I14: =MAX(MIN(Es*G14,fy),-fy) | J14: =IF(E14>=u_max-beta_1*D14-blk_tol,1,0) | K14: =J14*sig_blk | L14: =I14-K14 | M14: =INDEX(Bar_As,MATCH(C14,Bar_No,0))*L14/1000 | N14: =M14*INDEX(Bar_Y,MATCH(C14,Bar_No,0))/1000 | O14: =M14*INDEX(Bar_X,MATCH(C14,Bar_No,0))/1000
B15: 1 | C15: 10 | D15: =INDEX(Blk_c,MATCH(B15,Blk_St,0)) | E15: =INDEX(Bar_U,MATCH(C15,Bar_No,0)) | F15: =u_max-E15 | G15: =ecu*(1-F15/D15) | H15: =MAX(0,-G15) | I15: =MAX(MIN(Es*G15,fy),-fy) | J15: =IF(E15>=u_max-beta_1*D15-blk_tol,1,0) | K15: =J15*sig_blk | L15: =I15-K15 | M15: =INDEX(Bar_As,MATCH(C15,Bar_No,0))*L15/1000 | N15: =M15*INDEX(Bar_Y,MATCH(C15,Bar_No,0))/1000 | O15: =M15*INDEX(Bar_X,MATCH(C15,Bar_No,0))/1000
B16: 1 | C16: 11 | D16: =INDEX(Blk_c,MATCH(B16,Blk_St,0)) | E16: =INDEX(Bar_U,MATCH(C16,Bar_No,0)) | F16: =u_max-E16 | G16: =ecu*(1-F16/D16) | H16: =MAX(0,-G16) | I16: =MAX(MIN(Es*G16,fy),-fy) | J16: =IF(E16>=u_max-beta_1*D16-blk_tol,1,0) | K16: =J16*sig_blk | L16: =I16-K16 | M16: =INDEX(Bar_As,MATCH(C16,Bar_No,0))*L16/1000 | N16: =M16*INDEX(Bar_Y,MATCH(C16,Bar_No,0))/1000 | O16: =M16*INDEX(Bar_X,MATCH(C16,Bar_No,0))/1000
B17: 1 | C17: 12 | D17: =INDEX(Blk_c,MATCH(B17,Blk_St,0)) | E17: =INDEX(Bar_U,MATCH(C17,Bar_No,0)) | F17: =u_max-E17 | G17: =ecu*(1-F17/D17) | H17: =MAX(0,-G17) | I17: =MAX(MIN(Es*G17,fy),-fy) | J17: =IF(E17>=u_max-beta_1*D17-blk_tol,1,0) | K17: =J17*sig_blk | L17: =I17-K17 | M17: =INDEX(Bar_As,MATCH(C17,Bar_No,0))*L17/1000 | N17: =M17*INDEX(Bar_Y,MATCH(C17,Bar_No,0))/1000 | O17: =M17*INDEX(Bar_X,MATCH(C17,Bar_No,0))/1000
... B635: 35 | C635: 18 | D635: =INDEX(Blk_c,MATCH(B635,Blk_St,0)) | E635: =INDEX(Bar_U,MATCH(C635,Bar_No,0)) | F635: =u_max-E635 | G635: =ecu*(1-F635/D635) | H635: =MAX(0,-G635) | I635: =MAX(MIN(Es*G635,fy),-fy) | J635: =IF(E635>=u_max-beta_1*D635-blk_tol,1,0) | K635: =J635*sig_blk | L635: =I635-K635 | M635: =INDEX(Bar_As,MATCH(C635,Bar_No,0))*L635/1000 | N635: =M635*INDEX(Bar_Y,MATCH(C635,Bar_No,0))/1000 | O635: =M635*INDEX(Bar_X,MATCH(C635,Bar_No,0))/1000

Sheet PM_Angle
B1: NOMINAL AND DESIGN RESULTANTS AT θ
B2: P = Cc + ΣFs. φ interpolates linearly between φc at εy and φt at εt,limit on the controlling (most tensile) bar — the same rule the adapter applies, written out. The engine columns are the solver's own design resultants; the Δ column is the reconciliation.
B6: st | C6: c (mm) | D6: Cc (kN) | E6: ΣFs (kN) | F6: Pn (kN) | G6: Mnx (kN·m) | H6: Mny (kN·m) | I6: εt,ctrl | J6: φ | K6: class | L6: φPn (kN) | M6: φMnx (kN·m) | N6: φMny (kN·m) | O6: engine φPn | P6: Δ (kN)
B7: 1 | C7: =Block!C6 | D7: =Block!J6 | E7: =SUM(Steel!M6:M23) | F7: =D7+E7 | G7: =Block!K6+SUM(Steel!N6:N23) | H7: =Block!L6+SUM(Steel!O6:O23) | I7: =MAX(Steel!H6:H23) | J7: =IF(I7<=epsy,phi_c,IF(I7>=ept_lim,phi_t,phi_c+(phi_t-phi_c)*(I7-epsy)/(ept_lim-epsy))) | K7: =IF(I7<=epsy,"compression",IF(I7>=ept_lim,"tension","transition")) | L7: =J7*F7 | M7: =J7*G7 | N7: =J7*H7 | O7: 17396.107 | P7: =L7-O7
B8: 2 | C8: =Block!C7 | D8: =Block!J7 | E8: =SUM(Steel!M24:M41) | F8: =D8+E8 | G8: =Block!K7+SUM(Steel!N24:N41) | H8: =Block!L7+SUM(Steel!O24:O41) | I8: =MAX(Steel!H24:H41) | J8: =IF(I8<=epsy,phi_c,IF(I8>=ept_lim,phi_t,phi_c+(phi_t-phi_c)*(I8-epsy)/(ept_lim-epsy))) | K8: =IF(I8<=epsy,"compression",IF(I8>=ept_lim,"tension","transition")) | L8: =J8*F8 | M8: =J8*G8 | N8: =J8*H8 | O8: 16475.903 | P8: =L8-O8
B9: 3 | C9: =Block!C8 | D9: =Block!J8 | E9: =SUM(Steel!M42:M59) | F9: =D9+E9 | G9: =Block!K8+SUM(Steel!N42:N59) | H9: =Block!L8+SUM(Steel!O42:O59) | I9: =MAX(Steel!H42:H59) | J9: =IF(I9<=epsy,phi_c,IF(I9>=ept_lim,phi_t,phi_c+(phi_t-phi_c)*(I9-epsy)/(ept_lim-epsy))) | K9: =IF(I9<=epsy,"compression",IF(I9>=ept_lim,"tension","transition")) | L9: =J9*F9 | M9: =J9*G9 | N9: =J9*H9 | O9: 15662.525 | P9: =L9-O9
B10: 4 | C10: =Block!C9 | D10: =Block!J9 | E10: =SUM(Steel!M60:M77) | F10: =D10+E10 | G10: =Block!K9+SUM(Steel!N60:N77) | H10: =Block!L9+SUM(Steel!O60:O77) | I10: =MAX(Steel!H60:H77) | J10: =IF(I10<=epsy,phi_c,IF(I10>=ept_lim,phi_t,phi_c+(phi_t-phi_c)*(I10-epsy)/(ept_lim-epsy))) | K10: =IF(I10<=epsy,"compression",IF(I10>=ept_lim,"tension","transition")) | L10: =J10*F10 | M10: =J10*G10 | N10: =J10*H10 | O10: 14136.572 | P10: =L10-O10
B11: 5 | C11: =Block!C10 | D11: =Block!J10 | E11: =SUM(Steel!M78:M95) | F11: =D11+E11 | G11: =Block!K10+SUM(Steel!N78:N95) | H11: =Block!L10+SUM(Steel!O78:O95) | I11: =MAX(Steel!H78:H95) | J11: =IF(I11<=epsy,phi_c,IF(I11>=ept_lim,phi_t,phi_c+(phi_t-phi_c)*(I11-epsy)/(ept_lim-epsy))) | K11: =IF(I11<=epsy,"compression",IF(I11>=ept_lim,"tension","transition")) | L11: =J11*F11 | M11: =J11*G11 | N11: =J11*H11 | O11: 12156.553 | P11: =L11-O11
B12: 6 | C12: =Block!C11 | D12: =Block!J11 | E12: =SUM(Steel!M96:M113) | F12: =D12+E12 | G12: =Block!K11+SUM(Steel!N96:N113) | H12: =Block!L11+SUM(Steel!O96:O113) | I12: =MAX(Steel!H96:H113) | J12: =IF(I12<=epsy,phi_c,IF(I12>=ept_lim,phi_t,phi_c+(phi_t-phi_c)*(I12-epsy)/(ept_lim-epsy))) | K12: =IF(I12<=epsy,"compression",IF(I12>=ept_lim,"tension","transition")) | L12: =J12*F12 | M12: =J12*G12 | N12: =J12*H12 | O12: 9972.3079 | P12: =L12-O12
B13: 7 | C13: =Block!C12 | D13: =Block!J12 | E13: =SUM(Steel!M114:M131) | F13: =D13+E13 | G13: =Block!K12+SUM(Steel!N114:N131) | H13: =Block!L12+SUM(Steel!O114:O131) | I13: =MAX(Steel!H114:H131) | J13: =IF(I13<=epsy,phi_c,IF(I13>=ept_lim,phi_t,phi_c+(phi_t-phi_c)*(I13-epsy)/(ept_lim-epsy))) | K13: =IF(I13<=epsy,"compression",IF(I13>=ept_lim,"tension","transition")) | L13: =J13*F13 | M13: =J13*G13 | N13: =J13*H13 | O13: 8734.6887 | P13: =L13-O13
B14: 8 | C14: =Block!C13 | D14: =Block!J13 | E14: =SUM(Steel!M132:M149) | F14: =D14+E14 | G14: =Block!K13+SUM(Steel!N132:N149) | H14: =Block!L13+SUM(Steel!O132:O149) | I14: =MAX(Steel!H132:H149) | J14: =IF(I14<=epsy,phi_c,IF(I14>=ept_lim,phi_t,phi_c+(phi_t-phi_c)*(I14-epsy)/(ept_lim-epsy))) | K14: =IF(I14<=epsy,"compression",IF(I14>=ept_lim,"tension","transition")) | L14: =J14*F14 | M14: =J14*G14 | N14: =J14*H14 | O14: 8245.7738 | P14: =L14-O14
B15: 9 | C15: =Block!C14 | D15: =Block!J14 | E15: =SUM(Steel!M150:M167) | F15: =D15+E15 | G15: =Block!K14+SUM(Steel!N150:N167) | H15: =Block!L14+SUM(Steel!O150:O167) | I15: =MAX(Steel!H150:H167) | J15: =IF(I15<=epsy,phi_c,IF(I15>=ept_lim,phi_t,phi_c+(phi_t-phi_c)*(I15-epsy)/(ept_lim-epsy))) | K15: =IF(I15<=epsy,"compression",IF(I15>=ept_lim,"tension","transition")) | L15: =J15*F15 | M15: =J15*G15 | N15: =J15*H15 | O15: 7737.1739 | P15: =L15-O15
B16: 10 | C16: =Block!C15 | D16: =Block!J15 | E16: =SUM(Steel!M168:M185) | F16: =D16+E16 | G16: =Block!K15+SUM(Steel!N168:N185) | H16: =Block!L15+SUM(Steel!O168:O185) | I16: =MAX(Steel!H168:H185) | J16: =IF(I16<=epsy,phi_c,IF(I16>=ept_lim,phi_t,phi_c+(phi_t-phi_c)*(I16-epsy)/(ept_lim-epsy))) | K16: =IF(I16<=epsy,"compression",IF(I16>=ept_lim,"tension","transition")) | L16: =J16*F16 | M16: =J16*G16 | N16: =J16*H16 | O16: 7205.7711 | P16: =L16-O16
B17: 11 | C17: =Block!C16 | D17: =Block!J16 | E17: =SUM(Steel!M186:M203) | F17: =D17+E17 | G17: =Block!K16+SUM(Steel!N186:N203) | H17: =Block!L16+SUM(Steel!O186:O203) | I17: =MAX(Steel!H186:H203) | J17: =IF(I17<=epsy,phi_c,IF(I17>=ept_lim,phi_t,phi_c+(phi_t-phi_c)*(I17-epsy)/(ept_lim-epsy))) | K17: =IF(I17<=epsy,"compression",IF(I17>=ept_lim,"tension","transition")) | L17: =J17*F17 | M17: =J17*G17 | N17: =J17*H17 | O17: 7049.0822 | P17: =L17-O17
B18: 12 | C18: =Block!C17 | D18: =Block!J17 | E18: =SUM(Steel!M204:M221) | F18: =D18+E18 | G18: =Block!K17+SUM(Steel!N204:N221) | H18: =Block!L17+SUM(Steel!O204:O221) | I18: =MAX(Steel!H204:H221) | J18: =IF(I18<=epsy,phi_c,IF(I18>=ept_lim,phi_t,phi_c+(phi_t-phi_c)*(I18-epsy)/(ept_lim-epsy))) | K18: =IF(I18<=epsy,"compression",IF(I18>=ept_lim,"tension","transition")) | L18: =J18*F18 | M18: =J18*G18 | N18: =J18*H18 | O18: 6590.3686 | P18: =L18-O18
B19: 13 | C19: =Block!C18 | D19: =Block!J18 | E19: =SUM(Steel!M222:M239) | F19: =D19+E19 | G19: =Block!K18+SUM(Steel!N222:N239) | H19: =Block!L18+SUM(Steel!O222:O239) | I19: =MAX(Steel!H222:H239) | J19: =IF(I19<=epsy,phi_c,IF(I19>=ept_lim,phi_t,phi_c+(phi_t-phi_c)*(I19-epsy)/(ept_lim-epsy))) | K19: =IF(I19<=epsy,"compression",IF(I19>=ept_lim,"tension","transition")) | L19: =J19*F19 | M19: =J19*G19 | N19: =J19*H19 | O19: 6560.6929 | P19: =L19-O19
B20: 14 | C20: =Block!C19 | D20: =Block!J19 | E20: =SUM(Steel!M240:M257) | F20: =D20+E20 | G20: =Block!K19+SUM(Steel!N240:N257) | H20: =Block!L19+SUM(Steel!O240:O257) | I20: =MAX(Steel!H240:H257) | J20: =IF(I20<=epsy,phi_c,IF(I20>=ept_lim,phi_t,phi_c+(phi_t-phi_c)*(I20-epsy)/(ept_lim-epsy))) | K20: =IF(I20<=epsy,"compression",IF(I20>=ept_lim,"tension","transition")) | L20: =J20*F20 | M20: =J20*G20 | N20: =J20*H20 | O20: 6190.5488 | P20: =L20-O20
B21: 15 | C21: =Block!C20 | D21: =Block!J20 | E21: =SUM(Steel!M258:M275) | F21: =D21+E21 | G21: =Block!K20+SUM(Steel!N258:N275) | H21: =Block!L20+SUM(Steel!O258:O275) | I21: =MAX(Steel!H258:H275) | J21: =IF(I21<=epsy,phi_c,IF(I21>=ept_lim,phi_t,phi_c+(phi_t-phi_c)*(I21-epsy)/(ept_lim-epsy))) | K21: =IF(I21<=epsy,"compression",IF(I21>=ept_lim,"tension","transition")) | L21: =J21*F21 | M21: =J21*G21 | N21: =J21*H21 | O21: 6114.6544 | P21: =L21-O21
B22: 16 | C22: =Block!C21 | D22: =Block!J21 | E22: =SUM(Steel!M276:M293) | F22: =D22+E22 | G22: =Block!K21+SUM(Steel!N276:N293) | H22: =Block!L21+SUM(Steel!O276:O293) | I22: =MAX(Steel!H276:H293) | J22: =IF(I22<=epsy,phi_c,IF(I22>=ept_lim,phi_t,phi_c+(phi_t-phi_c)*(I22-epsy)/(ept_lim-epsy))) | K22: =IF(I22<=epsy,"compression",IF(I22>=ept_lim,"tension","transition")) | L22: =J22*F22 | M22: =J22*G22 | N22: =J22*H22 | O22: 5891.3235 | P22: =L22-O22
B23: 17 | C23: =Block!C22 | D23: =Block!J22 | E23: =SUM(Steel!M294:M311) | F23: =D23+E23 | G23: =Block!K22+SUM(Steel!N294:N311) | H23: =Block!L22+SUM(Steel!O294:O311) | I23: =MAX(Steel!H294:H311) | J23: =IF(I23<=epsy,phi_c,IF(I23>=ept_lim,phi_t,phi_c+(phi_t-phi_c)*(I23-epsy)/(ept_lim-epsy))) | K23: =IF(I23<=epsy,"compression",IF(I23>=ept_lim,"tension","transition")) | L23: =J23*F23 | M23: =J23*G23 | N23: =J23*H23 | O23: 5623.7098 | P23: =L23-O23
B24: 18 | C24: =Block!C23 | D24: =Block!J23 | E24: =SUM(Steel!M312:M329) | F24: =D24+E24 | G24: =Block!K23+SUM(Steel!N312:N329) | H24: =Block!L23+SUM(Steel!O312:O329) | I24: =MAX(Steel!H312:H329) | J24: =IF(I24<=epsy,phi_c,IF(I24>=ept_lim,phi_t,phi_c+(phi_t-phi_c)*(I24-epsy)/(ept_lim-epsy))) | K24: =IF(I24<=epsy,"compression",IF(I24>=ept_lim,"tension","transition")) | L24: =J24*F24 | M24: =J24*G24 | N24: =J24*H24 | O24: 5443.5051 | P24: =L24-O24
B25: 19 | C25: =Block!C24 | D25: =Block!J24 | E25: =SUM(Steel!M330:M347) | F25: =D25+E25 | G25: =Block!K24+SUM(Steel!N330:N347) | H25: =Block!L24+SUM(Steel!O330:O347) | I25: =MAX(Steel!H330:H347) | J25: =IF(I25<=epsy,phi_c,IF(I25>=ept_lim,phi_t,phi_c+(phi_t-phi_c)*(I25-epsy)/(ept_lim-epsy))) | K25: =IF(I25<=epsy,"compression",IF(I25>=ept_lim,"tension","transition")) | L25: =J25*F25 | M25: =J25*G25 | N25: =J25*H25 | O25: 5388.9798 | P25: =L25-O25
B26: 20 | C26: =Block!C25 | D26: =Block!J25 | E26: =SUM(Steel!M348:M365) | F26: =D26+E26 | G26: =Block!K25+SUM(Steel!N348:N365) | H26: =Block!L25+SUM(Steel!O348:O365) | I26: =MAX(Steel!H348:H365) | J26: =IF(I26<=epsy,phi_c,IF(I26>=ept_lim,phi_t,phi_c+(phi_t-phi_c)*(I26-epsy)/(ept_lim-epsy))) | K26: =IF(I26<=epsy,"compression",IF(I26>=ept_lim,"tension","transition")) | L26: =J26*F26 | M26: =J26*G26 | N26: =J26*H26 | O26: 5190.5943 | P26: =L26-O26
B27: 21 | C27: =Block!C26 | D27: =Block!J26 | E27: =SUM(Steel!M366:M383) | F27: =D27+E27 | G27: =Block!K26+SUM(Steel!N366:N383) | H27: =Block!L26+SUM(Steel!O366:O383) | I27: =MAX(Steel!H366:H383) | J27: =IF(I27<=epsy,phi_c,IF(I27>=ept_lim,phi_t,phi_c+(phi_t-phi_c)*(I27-epsy)/(ept_lim-epsy))) | K27: =IF(I27<=epsy,"compression",IF(I27>=ept_lim,"tension","transition")) | L27: =J27*F27 | M27: =J27*G27 | N27: =J27*H27 | O27: 5092.348 | P27: =L27-O27
B28: 22 | C28: =Block!C27 | D28: =Block!J27 | E28: =SUM(Steel!M384:M401) | F28: =D28+E28 | G28: =Block!K27+SUM(Steel!N384:N401) | H28: =Block!L27+SUM(Steel!O384:O401) | I28: =MAX(Steel!H384:H401) | J28: =IF(I28<=epsy,phi_c,IF(I28>=ept_lim,phi_t,phi_c+(phi_t-phi_c)*(I28-epsy)/(ept_lim-epsy))) | K28: =IF(I28<=epsy,"compression",IF(I28>=ept_lim,"tension","transition")) | L28: =J28*F28 | M28: =J28*G28 | N28: =J28*H28 | O28: 4551.9722 | P28: =L28-O28
B29: 23 | C29: =Block!C28 | D29: =Block!J28 | E29: =SUM(Steel!M402:M419) | F29: =D29+E29 | G29: =Block!K28+SUM(Steel!N402:N419) | H29: =Block!L28+SUM(Steel!O402:O419) | I29: =MAX(Steel!H402:H419) | J29: =IF(I29<=epsy,phi_c,IF(I29>=ept_lim,phi_t,phi_c+(phi_t-phi_c)*(I29-epsy)/(ept_lim-epsy))) | K29: =IF(I29<=epsy,"compression",IF(I29>=ept_lim,"tension","transition")) | L29: =J29*F29 | M29: =J29*G29 | N29: =J29*H29 | O29: 3686.4329 | P29: =L29-O29
B30: 24 | C30: =Block!C29 | D30: =Block!J29 | E30: =SUM(Steel!M420:M437) | F30: =D30+E30 | G30: =Block!K29+SUM(Steel!N420:N437) | H30: =Block!L29+SUM(Steel!O420:O437) | I30: =MAX(Steel!H420:H437) | J30: =IF(I30<=epsy,phi_c,IF(I30>=ept_lim,phi_t,phi_c+(phi_t-phi_c)*(I30-epsy)/(ept_lim-epsy))) | K30: =IF(I30<=epsy,"compression",IF(I30>=ept_lim,"tension","transition")) | L30: =J30*F30 | M30: =J30*G30 | N30: =J30*H30 | O30: 2976.4432 | P30: =L30-O30
B31: 25 | C31: =Block!C30 | D31: =Block!J30 | E31: =SUM(Steel!M438:M455) | F31: =D31+E31 | G31: =Block!K30+SUM(Steel!N438:N455) | H31: =Block!L30+SUM(Steel!O438:O455) | I31: =MAX(Steel!H438:H455) | J31: =IF(I31<=epsy,phi_c,IF(I31>=ept_lim,phi_t,phi_c+(phi_t-phi_c)*(I31-epsy)/(ept_lim-epsy))) | K31: =IF(I31<=epsy,"compression",IF(I31>=ept_lim,"tension","transition")) | L31: =J31*F31 | M31: =J31*G31 | N31: =J31*H31 | O31: 2349.808 | P31: =L31-O31
B32: 26 | C32: =Block!C31 | D32: =Block!J31 | E32: =SUM(Steel!M456:M473) | F32: =D32+E32 | G32: =Block!K31+SUM(Steel!N456:N473) | H32: =Block!L31+SUM(Steel!O456:O473) | I32: =MAX(Steel!H456:H473) | J32: =IF(I32<=epsy,phi_c,IF(I32>=ept_lim,phi_t,phi_c+(phi_t-phi_c)*(I32-epsy)/(ept_lim-epsy))) | K32: =IF(I32<=epsy,"compression",IF(I32>=ept_lim,"tension","transition")) | L32: =J32*F32 | M32: =J32*G32 | N32: =J32*H32 | O32: 1241.7205 | P32: =L32-O32
B33: 27 | C33: =Block!C32 | D33: =Block!J32 | E33: =SUM(Steel!M474:M491) | F33: =D33+E33 | G33: =Block!K32+SUM(Steel!N474:N491) | H33: =Block!L32+SUM(Steel!O474:O491) | I33: =MAX(Steel!H474:H491) | J33: =IF(I33<=epsy,phi_c,IF(I33>=ept_lim,phi_t,phi_c+(phi_t-phi_c)*(I33-epsy)/(ept_lim-epsy))) | K33: =IF(I33<=epsy,"compression",IF(I33>=ept_lim,"tension","transition")) | L33: =J33*F33 | M33: =J33*G33 | N33: =J33*H33 | O33: 288.84645 | P33: =L33-O33
B34: 28 | C34: =Block!C33 | D34: =Block!J33 | E34: =SUM(Steel!M492:M509) | F34: =D34+E34 | G34: =Block!K33+SUM(Steel!N492:N509) | H34: =Block!L33+SUM(Steel!O492:O509) | I34: =MAX(Steel!H492:H509) | J34: =IF(I34<=epsy,phi_c,IF(I34>=ept_lim,phi_t,phi_c+(phi_t-phi_c)*(I34-epsy)/(ept_lim-epsy))) | K34: =IF(I34<=epsy,"compression",IF(I34>=ept_lim,"tension","transition")) | L34: =J34*F34 | M34: =J34*G34 | N34: =J34*H34 | O34: -526.22337 | P34: =L34-O34
B35: 29 | C35: =Block!C34 | D35: =Block!J34 | E35: =SUM(Steel!M510:M527) | F35: =D35+E35 | G35: =Block!K34+SUM(Steel!N510:N527) | H35: =Block!L34+SUM(Steel!O510:O527) | I35: =MAX(Steel!H510:H527) | J35: =IF(I35<=epsy,phi_c,IF(I35>=ept_lim,phi_t,phi_c+(phi_t-phi_c)*(I35-epsy)/(ept_lim-epsy))) | K35: =IF(I35<=epsy,"compression",IF(I35>=ept_lim,"tension","transition")) | L35: =J35*F35 | M35: =J35*G35 | N35: =J35*H35 | O35: -1185.5246 | P35: =L35-O35
B36: 30 | C36: =Block!C35 | D36: =Block!J35 | E36: =SUM(Steel!M528:M545) | F36: =D36+E36 | G36: =Block!K35+SUM(Steel!N528:N545) | H36: =Block!L35+SUM(Steel!O528:O545) | I36: =MAX(Steel!H528:H545) | J36: =IF(I36<=epsy,phi_c,IF(I36>=ept_lim,phi_t,phi_c+(phi_t-phi_c)*(I36-epsy)/(ept_lim-epsy))) | K36: =IF(I36<=epsy,"compression",IF(I36>=ept_lim,"tension","transition")) | L36: =J36*F36 | M36: =J36*G36 | N36: =J36*H36 | O36: -2234.19 | P36: =L36-O36
B37: 31 | C37: =Block!C36 | D37: =Block!J36 | E37: =SUM(Steel!M546:M563) | F37: =D37+E37 | G37: =Block!K36+SUM(Steel!N546:N563) | H37: =Block!L36+SUM(Steel!O546:O563) | I37: =MAX(Steel!H546:H563) | J37: =IF(I37<=epsy,phi_c,IF(I37>=ept_lim,phi_t,phi_c+(phi_t-phi_c)*(I37-epsy)/(ept_lim-epsy))) | K37: =IF(I37<=epsy,"compression",IF(I37>=ept_lim,"tension","transition")) | L37: =J37*F37 | M37: =J37*G37 | N37: =J37*H37 | O37: -2902.4658 | P37: =L37-O37
B38: 32 | C38: =Block!C37 | D38: =Block!J37 | E38: =SUM(Steel!M564:M581) | F38: =D38+E38 | G38: =Block!K37+SUM(Steel!N564:N581) | H38: =Block!L37+SUM(Steel!O564:O581) | I38: =MAX(Steel!H564:H581) | J38: =IF(I38<=epsy,phi_c,IF(I38>=ept_lim,phi_t,phi_c+(phi_t-phi_c)*(I38-epsy)/(ept_lim-epsy))) | K38: =IF(I38<=epsy,"compression",IF(I38>=ept_lim,"tension","transition")) | L38: =J38*F38 | M38: =J38*G38 | N38: =J38*H38 | O38: -3719.8529 | P38: =L38-O38
B39: 33 | C39: =Block!C38 | D39: =Block!J38 | E39: =SUM(Steel!M582:M599) | F39: =D39+E39 | G39: =Block!K38+SUM(Steel!N582:N599) | H39: =Block!L38+SUM(Steel!O582:O599) | I39: =MAX(Steel!H582:H599) | J39: =IF(I39<=epsy,phi_c,IF(I39>=ept_lim,phi_t,phi_c+(phi_t-phi_c)*(I39-epsy)/(ept_lim-epsy))) | K39: =IF(I39<=epsy,"compression",IF(I39>=ept_lim,"tension","transition")) | L39: =J39*F39 | M39: =J39*G39 | N39: =J39*H39 | O39: -4125.0617 | P39: =L39-O39
B40: 34 | C40: =Block!C39 | D40: =Block!J39 | E40: =SUM(Steel!M600:M617) | F40: =D40+E40 | G40: =Block!K39+SUM(Steel!N600:N617) | H40: =Block!L39+SUM(Steel!O600:O617) | I40: =MAX(Steel!H600:H617) | J40: =IF(I40<=epsy,phi_c,IF(I40>=ept_lim,phi_t,phi_c+(phi_t-phi_c)*(I40-epsy)/(ept_lim-epsy))) | K40: =IF(I40<=epsy,"compression",IF(I40>=ept_lim,"tension","transition")) | L40: =J40*F40 | M40: =J40*G40 | N40: =J40*H40 | O40: -4617.2096 | P40: =L40-O40
B41: 35 | C41: =Block!C40 | D41: =Block!J40 | E41: =SUM(Steel!M618:M635) | F41: =D41+E41 | G41: =Block!K40+SUM(Steel!N618:N635) | H41: =Block!L40+SUM(Steel!O618:O635) | I41: =MAX(Steel!H618:H635) | J41: =IF(I41<=epsy,phi_c,IF(I41>=ept_lim,phi_t,phi_c+(phi_t-phi_c)*(I41-epsy)/(ept_lim-epsy))) | K41: =IF(I41<=epsy,"compression",IF(I41>=ept_lim,"tension","transition")) | L41: =J41*F41 | M41: =J41*G41 | N41: =J41*H41 | O41: -4815.9373 | P41: =L41-O41
B43: worst |Δ| | L43: =IF(P43<=0.000001*MAX(ABS(O7:O41)),"OK - the sheet reproduces the design resultants","CHECK - the sheet and the solver disagree") | P43: =MAX(ABS(P7:P41))

Sheet MxMy_FixedP
B1: DESIGN SURFACE AT P = Pu, AND THE DEMAND-RAY QUERY
B2: The grid is the solver's design surface, sampled direction by direction. Everything after it — the P-interval bracket, the linear interpolation to Pu, and the ray query at θ_L — is a formula, because that logic is what a reviewer needs to see.
B7: dir | C7: θ (deg) | D7: row | E7: P (kN) | F7: Mx (kN·m) | G7: My (kN·m) | H7: P next | I7: Mx next | J7: My next | K7: brackets Pu | L7: t | M7: Mx @ Pu | N7: My @ Pu
B8: 1 | C8: 0 | D8: 1 | E8: 17297.34 | F8: -2.9057264e-14 | G8: 2904.9396 | H8: =E9 | I8: =F9 | J8: =G9 | K8: =IF(AND(Pu>=MIN(E8,H8),Pu<=MAX(E8,H8),E8<>H8),1,0) | L8: =IF(K8=1,(Pu-E8)/(H8-E8),"") | M8: =IF(K8=1,F8+L8*(I8-F8),"") | N8: =IF(K8=1,G8+L8*(J8-G8),"")
B9: 1 | C9: 0 | D9: 2 | E9: 16729.913 | F9: 4.8428774e-14 | G9: 3174.4158 | H9: =E10 | I9: =F10 | J9: =G10 | K9: =IF(AND(Pu>=MIN(E9,H9),Pu<=MAX(E9,H9),E9<>H9),1,0) | L9: =IF(K9=1,(Pu-E9)/(H9-E9),"") | M9: =IF(K9=1,F9+L9*(I9-F9),"") | N9: =IF(K9=1,G9+L9*(J9-G9),"")
B10: 1 | C10: 0 | D10: 3 | E10: 16022.717 | F10: 4.8428774e-14 | G10: 3472.6936 | H10: =E11 | I10: =F11 | J10: =G11 | K10: =IF(AND(Pu>=MIN(E10,H10),Pu<=MAX(E10,H10),E10<>H10),1,0) | L10: =IF(K10=1,(Pu-E10)/(H10-E10),"") | M10: =IF(K10=1,F10+L10*(I10-F10),"") | N10: =IF(K10=1,G10+L10*(J10-G10),"")
B11: 1 | C11: 0 | D11: 4 | E11: 15292.22 | F11: 3.5322737e-13 | G11: 3729.1431 | H11: =E12 | I11: =F12 | J11: =G12 | K11: =IF(AND(Pu>=MIN(E11,H11),Pu<=MAX(E11,H11),E11<>H11),1,0) | L11: =IF(K11=1,(Pu-E11)/(H11-E11),"") | M11: =IF(K11=1,F11+L11*(I11-F11),"") | N11: =IF(K11=1,G11+L11*(J11-G11),"")
B12: 1 | C12: 0 | D12: 5 | E12: 13975.531 | F12: 1.7434359e-13 | G12: 4103.4486 | H12: =E13 | I12: =F13 | J12: =G13 | K12: =IF(AND(Pu>=MIN(E12,H12),Pu<=MAX(E12,H12),E12<>H12),1,0) | L12: =IF(K12=1,(Pu-E12)/(H12-E12),"") | M12: =IF(K12=1,F12+L12*(I12-F12),"") | N12: =IF(K12=1,G12+L12*(J12-G12),"")
B13: 1 | C13: 0 | D13: 6 | E13: 11846.56 | F13: 9.6857548e-15 | G13: 4476.6752 | H13: =E14 | I13: =F14 | J13: =G14 | K13: =IF(AND(Pu>=MIN(E13,H13),Pu<=MAX(E13,H13),E13<>H13),1,0) | L13: =IF(K13=1,(Pu-E13)/(H13-E13),"") | M13: =IF(K13=1,F13+L13*(I13-F13),"") | N13: =IF(K13=1,G13+L13*(J13-G13),"")
B14: 1 | C14: 0 | D14: 7 | E14: 9888.8473 | F14: 9.6857548e-15 | G14: 4705.7304 | H14: =E15 | I14: =F15 | J14: =G15 | K14: =IF(AND(Pu>=MIN(E14,H14),Pu<=MAX(E14,H14),E14<>H14),1,0) | L14: =IF(K14=1,(Pu-E14)/(H14-E14),"") | M14: =IF(K14=1,F14+L14*(I14-F14),"") | N14: =IF(K14=1,G14+L14*(J14-G14),"")
B15: 1 | C15: 0 | D15: 8 | E15: 8968.9203 | F15: 1.7434359e-13 | G15: 4781.5439 | H15: =E16 | I15: =F16 | J15: =G16 | K15: =IF(AND(Pu>=MIN(E15,H15),Pu<=MAX(E15,H15),E15<>H15),1,0) | L15: =IF(K15=1,(Pu-E15)/(H15-E15),"") | M15: =IF(K15=1,F15+L15*(I15-F15),"") | N15: =IF(K15=1,G15+L15*(J15-G15),"")
B16: 1 | C16: 0 | D16: 9 | E16: 8450.3301 | F16: -1.3879008e-13 | G16: 4876.424 | H16: =E17 | I16: =F17 | J16: =G17 | K16: =IF(AND(Pu>=MIN(E16,H16),Pu<=MAX(E16,H16),E16<>H16),1,0) | L16: =IF(K16=1,(Pu-E16)/(H16-E16),"") | M16: =IF(K16=1,F16+L16*(I16-F16),"") | N16: =IF(K16=1,G16+L16*(J16-G16),"")
B17: 1 | C17: 0 | D17: 10 | E17: 8128.7478 | F17: 1.0058284e-14 | G17: 4928.9402 | H17: =E18 | I17: =F18 | J17: =G18 | K17: =IF(AND(Pu>=MIN(E17,H17),Pu<=MAX(E17,H17),E17<>H17),1,0) | L17: =IF(K17=1,(Pu-E17)/(H17-E17),"") | M17: =IF(K17=1,F17+L17*(I17-F17),"") | N17: =IF(K17=1,G17+L17*(J17-G17),"")
B18: 1 | C18: 0 | D18: 11 | E18: 7417.8304 | F18: 1.0387103e-14 | G18: 5030.2129 | H18: =E19 | I18: =F19 | J18: =G19 | K18: =IF(AND(Pu>=MIN(E18,H18),Pu<=MAX(E18,H18),E18<>H18),1,0) | L18: =IF(K18=1,(Pu-E18)/(H18-E18),"") | M18: =IF(K18=1,F18+L18*(I18-F18),"") | N18: =IF(K18=1,G18+L18*(J18-G18),"")
B19: 1 | C19: 0 | D19: 12 | E19: 7325.1421 | F19: 1.0430813e-14 | G19: 5042.038 | H19: =E20 | I19: =F20 | J19: =G20 | K19: =IF(AND(Pu>=MIN(E19,H19),Pu<=MAX(E19,H19),E19<>H19),1,0) | L19: =IF(K19=1,(Pu-E19)/(H19-E19),"") | M19: =IF(K19=1,F19+L19*(I19-F19),"") | N19: =IF(K19=1,G19+L19*(J19-G19),"")
... B42: 1 | C42: 0 | D42: 35 | E42: -3089.4118 | F42: 0 | G42: 1287.3803 | H42: =E43 | I42: =F43 | J42: =G43 | K42: =IF(AND(Pu>=MIN(E42,H42),Pu<=MAX(E42,H42),E42<>H42),1,0) | L42: =IF(K42=1,(Pu-E42)/(H42-E42),"") | M42: =IF(K42=1,F42+L42*(I42-F42),"") | N42: =IF(K42=1,G42+L42*(J42-G42),"")
B43: 1 | C43: 0 | D43: 36 | E43: -3963.2733 | F43: 0 | G43: 687.13691
B45: 2 | C45: 0.9375 | D45: 1 | E45: 17343.654 | F45: 38.84148 | G45: 2880.5494 | H45: =E46 | I45: =F46 | J45: =G46 | K45: =IF(AND(Pu>=MIN(E45,H45),Pu<=MAX(E45,H45),E45<>H45),1,0) | L45: =IF(K45=1,(Pu-E45)/(H45-E45),"") | M45: =IF(K45=1,F45+L45*(I45-F45),"") | N45: =IF(K45=1,G45+L45*(J45-G45),"")
B46: 2 | C46: 0.9375 | D46: 2 | E46: 16764.646 | F46: 34.874656 | G46: 3157.5371 | H46: =E47 | I46: =F47 | J46: =G47 | K46: =IF(AND(Pu>=MIN(E46,H46),Pu<=MAX(E46,H46),E46<>H46),1,0) | L46: =IF(K46=1,(Pu-E46)/(H46-E46),"") | M46: =IF(K46=1,F46+L46*(I46-F46),"") | N46: =IF(K46=1,G46+L46*(J46-G46),"")
B47: 2 | C47: 0.9375 | D47: 3 | E47: 16050.012 | F47: 36.298554 | G47: 3459.3058 | H47: =E48 | I47: =F48 | J47: =G48 | K47: =IF(AND(Pu>=MIN(E47,H47),Pu<=MAX(E47,H47),E47<>H47),1,0) | L47: =IF(K47=1,(Pu-E47)/(H47-E47),"") | M47: =IF(K47=1,F47+L47*(I47-F47),"") | N47: =IF(K47=1,G47+L47*(J47-G47),"")
B48: 2 | C48: 0.9375 | D48: 4 | E48: 15317.188 | F48: 37.999826 | G48: 3718.621 | H48: =E49 | I48: =F49 | J48: =G49 | K48: =IF(AND(Pu>=MIN(E48,H48),Pu<=MAX(E48,H48),E48<>H48),1,0) | L48: =IF(K48=1,(Pu-E48)/(H48-E48),"") | M48: =IF(K48=1,F48+L48*(I48-F48),"") | N48: =IF(K48=1,G48+L48*(J48-G48),"")
B49: 2 | C49: 0.9375 | D49: 5 | E49: 13997.962 | F49: 44.891982 | G49: 4094.8544 | H49: =E50 | I49: =F50 | J49: =G50 | K49: =IF(AND(Pu>=MIN(E49,H49),Pu<=MAX(E49,H49),E49<>H49),1,0) | L49: =IF(K49=1,(Pu-E49)/(H49-E49),"") | M49: =IF(K49=1,F49+L49*(I49-F49),"") | N49: =IF(K49=1,G49+L49*(J49-G49),"")
B50: 2 | C50: 0.9375 | D50: 6 | E50: 11869.768 | F50: 52.339493 | G50: 4468.6316 | H50: =E51 | I50: =F51 | J50: =G51 | K50: =IF(AND(Pu>=MIN(E50,H50),Pu<=MAX(E50,H50),E50<>H50),1,0) | L50: =IF(K50=1,(Pu-E50)/(H50-E50),"") | M50: =IF(K50=1,F50+L50*(I50-F50),"") | N50: =IF(K50=1,G50+L50*(J50-G50),"")
B51: 2 | C51: 0.9375 | D51: 7 | E51: 9886.2762 | F51: 46.657928 | G51: 4697.9636 | H51: =E52 | I51: =F52 | J51: =G52 | K51: =IF(AND(Pu>=MIN(E51,H51),Pu<=MAX(E51,H51),E51<>H51),1,0) | L51: =IF(K51=1,(Pu-E51)/(H51-E51),"") | M51: =IF(K51=1,F51+L51*(I51-F51),"") | N51: =IF(K51=1,G51+L51*(J51-G51),"")
B52: 2 | C52: 0.9375 | D52: 8 | E52: 8956.0946 | F52: 56.826329 | G52: 4772.3498 | H52: =E53 | I52: =F53 | J52: =G53 | K52: =IF(AND(Pu>=MIN(E52,H52),Pu<=MAX(E52,H52),E52<>H52),1,0) | L52: =IF(K52=1,(Pu-E52)/(H52-E52),"") | M52: =IF(K52=1,F52+L52*(I52-F52),"") | N52: =IF(K52=1,G52+L52*(J52-G52),"")
B53: 2 | C53: 0.9375 | D53: 9 | E53: 8435.0594 | F53: 58.808163 | G53: 4870.5069 | H53: =E54 | I53: =F54 | J53: =G54 | K53: =IF(AND(Pu>=MIN(E53,H53),Pu<=MAX(E53,H53),E53<>H53),1,0) | L53: =IF(K53=1,(Pu-E53)/(H53-E53),"") | M53: =IF(K53=1,F53+L53*(I53-F53),"") | N53: =IF(K53=1,G53+L53*(J53-G53),"")
B54: 2 | C54: 0.9375 | D54: 10 | E54: 8101.3149 | F54: 60.208036 | G54: 4923.7233 | H54: =E55 | I54: =F55 | J54: =G55 | K54: =IF(AND(Pu>=MIN(E54,H54),Pu<=MAX(E54,H54),E54<>H54),1,0) | L54: =IF(K54=1,(Pu-E54)/(H54-E54),"") | M54: =IF(K54=1,F54+L54*(I54-F54),"") | N54: =IF(K54=1,G54+L54*(J54-G54),"")
B55: 2 | C55: 0.9375 | D55: 11 | E55: 7392.2056 | F55: 63.318664 | G55: 5021.8024 | H55: =E56 | I55: =F56 | J55: =G56 | K55: =IF(AND(Pu>=MIN(E55,H55),Pu<=MAX(E55,H55),E55<>H55),1,0) | L55: =IF(K55=1,(Pu-E55)/(H55-E55),"") | M55: =IF(K55=1,F55+L55*(I55-F55),"") | N55: =IF(K55=1,G55+L55*(J55-G55),"")
B56: 2 | C56: 0.9375 | D56: 12 | E56: 7289.4608 | F56: 63.784404 | G56: 5034.4643 | H56: =E57 | I56: =F57 | J56: =G57 | K56: =IF(AND(Pu>=MIN(E56,H56),Pu<=MAX(E56,H56),E56<>H56),1,0) | L56: =IF(K56=1,(Pu-E56)/(H56-E56),"") | M56: =IF(K56=1,F56+L56*(I56-F56),"") | N56: =IF(K56=1,G56+L56*(J56-G56),"")
... B79: 2 | C79: 0.9375 | D79: 35 | E79: -3374.6407 | F79: 43.929269 | G79: 1090.6229 | H79: =E80 | I79: =F80 | J79: =G80 | K79: =IF(AND(Pu>=MIN(E79,H79),Pu<=MAX(E79,H79),E79<>H79),1,0) | L79: =IF(K79=1,(Pu-E79)/(H79-E79),"") | M79: =IF(K79=1,F79+L79*(I79-F79),"") | N79: =IF(K79=1,G79+L79*(J79-G79),"")
B80: 2 | C80: 0.9375 | D80: 36 | E80: -4260.1368 | F80: 38.420872 | G80: 481.08088
B82: 3 | C82: 1.875 | D82: 1 | E82: 17391.476 | F82: 78.107574 | G82: 2854.6775 | H82: =E83 | I82: =F83 | J82: =G83 | K82: =IF(AND(Pu>=MIN(E82,H82),Pu<=MAX(E82,H82),E82<>H82),1,0) | L82: =IF(K82=1,(Pu-E82)/(H82-E82),"") | M82: =IF(K82=1,F82+L82*(I82-F82),"") | N82: =IF(K82=1,G82+L82*(J82-G82),"")
B83: 3 | C83: 1.875 | D83: 2 | E83: 16800.998 | F83: 70.322891 | G83: 3139.3576 | H83: =E84 | I83: =F84 | J83: =G84 | K83: =IF(AND(Pu>=MIN(E83,H83),Pu<=MAX(E83,H83),E83<>H83),1,0) | L83: =IF(K83=1,(Pu-E83)/(H83-E83),"") | M83: =IF(K83=1,F83+L83*(I83-F83),"") | N83: =IF(K83=1,G83+L83*(J83-G83),"")
B84: 3 | C84: 1.875 | D84: 3 | E84: 16077.058 | F84: 72.550511 | G84: 3445.4507 | H84: =E85 | I84: =F85 | J84: =G85 | K84: =IF(AND(Pu>=MIN(E84,H84),Pu<=MAX(E84,H84),E84<>H84),1,0) | L84: =IF(K84=1,(Pu-E84)/(H84-E84),"") | M84: =IF(K84=1,F84+L84*(I84-F84),"") | N84: =IF(K84=1,G84+L84*(J84-G84),"")
B85: 3 | C85: 1.875 | D85: 4 | E85: 15342.031 | F85: 75.839476 | G85: 3707.6917 | H85: =E86 | I85: =F86 | J85: =G86 | K85: =IF(AND(Pu>=MIN(E85,H85),Pu<=MAX(E85,H85),E85<>H85),1,0) | L85: =IF(K85=1,(Pu-E85)/(H85-E85),"") | M85: =IF(K85=1,F85+L85*(I85-F85),"") | N85: =IF(K85=1,G85+L85*(J85-G85),"")
B86: 3 | C86: 1.875 | D86: 5 | E86: 14019.231 | F86: 89.414663 | G86: 4085.9798 | H86: =E87 | I86: =F87 | J86: =G87 | K86: =IF(AND(Pu>=MIN(E86,H86),Pu<=MAX(E86,H86),E86<>H86),1,0) | L86: =IF(K86=1,(Pu-E86)/(H86-E86),"") | M86: =IF(K86=1,F86+L86*(I86-F86),"") | N86: =IF(K86=1,G86+L86*(J86-G86),"")
B87: 3 | C87: 1.875 | D87: 6 | E87: 11892.814 | F87: 104.47898 | G87: 4460.0513 | H87: =E88 | I87: =F88 | J87: =G88 | K87: =IF(AND(Pu>=MIN(E87,H87),Pu<=MAX(E87,H87),E87<>H87),1,0) | L87: =IF(K87=1,(Pu-E87)/(H87-E87),"") | M87: =IF(K87=1,F87+L87*(I87-F87),"") | N87: =IF(K87=1,G87+L87*(J87-G87),"")
B88: 3 | C88: 1.875 | D88: 7 | E88: 9894.6344 | F88: 101.33116 | G88: 4688.7954 | H88: =E89 | I88: =F89 | J88: =G89 | K88: =IF(AND(Pu>=MIN(E88,H88),Pu<=MAX(E88,H88),E88<>H88),1,0) | L88: =IF(K88=1,(Pu-E88)/(H88-E88),"") | M88: =IF(K88=1,F88+L88*(I88-F88),"") | N88: =IF(K88=1,G88+L88*(J88-G88),"")
B89: 3 | C89: 1.875 | D89: 8 | E89: 8942.9129 | F89: 113.55533 | G89: 4762.5118 | H89: =E90 | I89: =F90 | J89: =G90 | K89: =IF(AND(Pu>=MIN(E89,H89),Pu<=MAX(E89,H89),E89<>H89),1,0) | L89: =IF(K89=1,(Pu-E89)/(H89-E89),"") | M89: =IF(K89=1,F89+L89*(I89-F89),"") | N89: =IF(K89=1,G89+L89*(J89-G89),"")
B90: 3 | C90: 1.875 | D90: 9 | E90: 8419.8468 | F90: 117.27877 | G90: 4864.0106 | H90: =E91 | I90: =F91 | J90: =G91 | K90: =IF(AND(Pu>=MIN(E90,H90),Pu<=MAX(E90,H90),E90<>H90),1,0) | L90: =IF(K90=1,(Pu-E90)/(H90-E90),"") | M90: =IF(K90=1,F90+L90*(I90-F90),"") | N90: =IF(K90=1,G90+L90*(J90-G90),"")
...

Sheet PM_Theta
B1: VERTICAL P–Mθ SECTION THROUGH THE DEMAND DIRECTION
B2: A true plane cut of the design surface at θ_L, produced by the same slicer the Results plot uses. Mθ is the signed projection of (Mx, My) onto the demand direction, so a pole sits at Mθ = 0.
B6: # | C6: path | D6: P (kN) | E6: Mθ (kN·m) | F6: Mx (kN·m) | G6: My (kN·m)
B7: 1 | C7: 1 | D7: 17670.346 | E7: -2258.0598 | F7: -2106.9308 | G7: -812.20468
B8: 2 | C8: 1 | D8: 17598.2 | E8: -2291.0781 | F8: -2137.7393 | G8: -824.0811
B9: 3 | C9: 1 | D9: 17435.267 | E9: -2361.639 | F9: -2203.5777 | G9: -849.46125
B10: 4 | C10: 1 | D10: 17322.672 | E10: -2413.0168 | F10: -2251.5168 | G10: -867.94138
B11: 5 | C11: 1 | D11: 16798.22 | E11: -2601.8167 | F11: -2427.6806 | G11: -935.85109
B12: 6 | C12: 1 | D12: 16109.625 | E12: -2878.5703 | F12: -2685.9114 | G12: -1035.397
B13: 7 | C13: 1 | D13: 16048.526 | E13: -2897.3307 | F13: -2703.4162 | G13: -1042.1449
B14: 8 | C14: 1 | D14: 15946.326 | E14: -2931.4158 | F14: -2735.22 | G14: -1054.405
B15: 9 | C15: 1 | D15: 14930.133 | E15: -3262.0372 | F15: -3043.7134 | G15: -1173.3267
B16: 10 | C16: 1 | D16: 14476.063 | E16: -3373.3971 | F16: -3147.6201 | G16: -1213.3819
B17: 11 | C17: 1 | D17: 13522.345 | E17: -3624.3034 | F17: -3381.7336 | G17: -1303.6308
B18: 12 | C18: 1 | D18: 13216.134 | E18: -3701.5444 | F18: -3453.8049 | G18: -1331.4137
... B261: 255 | C261: 1 | D261: 17670.346 | E261: -2258.0598 | F261: -2106.9308 | G261: -812.20468

Sheet Equilibrium
B1: CONVERGED EQUIVALENT-BLOCK CAPACITY STATE ON THE DEMAND RAY
B3: θ* (block normal) | C3: 76.709207 | D3: deg | E3: solved direction; not the demand moment direction
B4: c* | C4: 1369.944 | D4: mm | E4: solved neutral-axis depth
B5: a* = β1·c* | C5: 1095.9552 | D5: mm
B6: A_blk* | C6: 868224.22 | D6: mm² | E6: exact clipping at the solved state
B7: Cc* | C7: 22139.718 | D7: kN
B8: ΣFs* | C8: 3545.7065 | D8: kN
B9: Pn* | C9: 25685.424 | D9: kN
B10: Mnx* | C10: 3824.7294 | D10: kN·m
B11: Mny* | C11: 1474.402 | D11: kN·m
B12: εt,ctrl | C12: 0 | D12: - | E12: controlling bar 1
B13: φ* | C13: 0.65 | D13: - | E13: compression-controlled
B14: utilization (governing ray) | C14: 1.4939884 | D14: - | E14: factored demand against the design surface
