Workbook
Name fck: Input!$C$7
Name alpha: Input!$C$8
Name eco: Input!$C$9
Name ecu: Input!$C$10
Name n: Input!$C$11
Name Es: Input!$C$15
Name fy: Input!$C$16
Name theta: Input!$C$21
Name etu: Input!$C$22
Name xc: Input!$C$23
Name yc: Input!$C$24
Name Pu: Input!$C$29
Name Mux: Input!$C$30
Name Muy: Input!$C$31
Name Geom_Area: Geometry!$D$62
Name u_max: Geometry!$D$63
Name u_min: Geometry!$D$64
Name u_bar: Geometry!$D$65
Name C1_len: Geometry!$D$66
Name As_tot: Geometry!$D$68
Name Mesh_X: Mesh!$B$5:$B$1261
Name Mesh_Y: Mesh!$C$5:$C$1261
Name Mesh_A: Mesh!$D$5:$D$1261
Name St_e0: 'PM_Angle'!$J$7:$J$25
Name St_kx: 'PM_Angle'!$K$7:$K$25
Name St_ky: 'PM_Angle'!$L$7:$L$25
Name Det: Concrete!$C$4
Name St_P: 'PM_Angle'!$S$7:$S$25
Name St_Mx: 'PM_Angle'!$T$7:$T$25
Name St_My: 'PM_Angle'!$U$7:$U$25

Sheet Input
B1: P–M SECTION CALCULATION — NOMINAL RESISTANCE
B2: Project | C2: PM-advanced (7) 2D reference case | E2: Every value on a shaded input cell drives live formulas on the other sheets. Only the Mesh, Geometry and bar tables hold engine-computed constants.
B3: Section | C3: PM-advanced (7) 2D — 1500x1200 chamfered section, two voids
B4: Generated | C4: 2026-07-23 07:28:14
B6: Concrete
B7: fck | C7: 30 | D7: MPa | E7: KDS C30 (workbook Input)
B8: alpha | C8: 0.85 | D8: - | E8: stress-block factor
B9: eps_co | C9: 0.002 | D9: -
B10: eps_cu | C10: 0.0033 | D10: -
B11: n | C11: 2 | D11: -
B12: law | C12: KDS parabola-rectangle, fc = alpha*fck*(1-(1-eps/eco)^n) up to eco, then alpha*fck
B14: Reinforcement
B15: Es | C15: 200000 | D15: MPa | E15: SD400 (workbook Input)
B16: fy | C16: 400 | D16: MPa
B17: eps_y = fy/Es | C17: 0.002 | D17: - | E17: used by the fs/fy stations
B18: law | C18: Elastic - perfectly plastic, fs = clamp(Es*eps, -fy, +fy)
B20: Analysis
B21: theta | C21: 15 | D21: deg | E21: direction of the vertical slice
B22: eps_tu | C22: -0.05 | D22: - | E22: uniform strain used for station P18
B23: xc | C23: 0 | D23: mm | E23: analysis origin = net concrete centroid
B24: yc | C24: 0 | D24: mm | E24: all X, Y below are measured from it
B25: mesh cell size | C25: 87.242926 | D25: mm | E25: clipped-cell grid, docs/02 §5
B26: mesh points | C26: 1257 | D26: - | E26: 3-point degree-2 rule per clipped triangle
B28: Demand
B29: Pu | C29: 24942.922 | D29: kN | E29: ULS-1 workbook Newton demand (on the 15 deg surface)
B30: Mux | C30: 3714.1659 | D30: kN·m
B31: Muy | C31: 1431.7807 | D31: kN·m
B33: Net concrete area (from mesh) | C33: =SUM(Mesh_A) | D33: mm² | E33: =IF(ABS(C33-Geom_Area)<=0.000001*Geom_Area,"OK — matches the exact polygon area","CHECK — mesh and polygon areas differ")

Sheet Geometry
B1: GEOMETRY ABOUT THE ANALYSIS ORIGIN
B2: Coordinates are engine constants, already translated by (xc, yc). Everything else on this sheet is a formula.
B4: Solid 1 outer
B5: No. | C5: Ring | D5: X (mm) | E5: Y (mm) | F5: D_i | G5: u = Y·cosθ + X·sinθ
B6: 1 | C6: Solid 1 outer | D6: -550 | E6: 600 | F6: =D6*E7-D7*E6 | G6: =E6*COS(RADIANS(theta))+D6*SIN(RADIANS(theta))
B7: 2 | C7: Solid 1 outer | D7: 550 | E7: 600 | F7: =D7*E8-D8*E7 | G7: =E7*COS(RADIANS(theta))+D7*SIN(RADIANS(theta))
B8: 3 | C8: Solid 1 outer | D8: 750 | E8: 400 | F8: =D8*E9-D9*E8 | G8: =E8*COS(RADIANS(theta))+D8*SIN(RADIANS(theta))
B9: 4 | C9: Solid 1 outer | D9: 750 | E9: -400 | F9: =D9*E10-D10*E9 | G9: =E9*COS(RADIANS(theta))+D9*SIN(RADIANS(theta))
B10: 5 | C10: Solid 1 outer | D10: 550 | E10: -600 | F10: =D10*E11-D11*E10 | G10: =E10*COS(RADIANS(theta))+D10*SIN(RADIANS(theta))
B11: 6 | C11: Solid 1 outer | D11: -550 | E11: -600 | F11: =D11*E12-D12*E11 | G11: =E11*COS(RADIANS(theta))+D11*SIN(RADIANS(theta))
B12: 7 | C12: Solid 1 outer | D12: -750 | E12: -400 | F12: =D12*E13-D13*E12 | G12: =E12*COS(RADIANS(theta))+D12*SIN(RADIANS(theta))
B13: 8 | C13: Solid 1 outer | D13: -750 | E13: 400 | F13: =D13*E6-D6*E13 | G13: =E13*COS(RADIANS(theta))+D13*SIN(RADIANS(theta))
C14: Area = ½·Σ D_i | F14: =SUM(F6:F13)/2
B16: Solid 1 hole 1
B17: No. | C17: Ring | D17: X (mm) | E17: Y (mm) | F17: D_i | G17: u = Y·cosθ + X·sinθ
B18: 1 | C18: Solid 1 hole 1 | D18: -450 | E18: 400 | F18: =D18*E19-D19*E18 | G18: =E18*COS(RADIANS(theta))+D18*SIN(RADIANS(theta))
B19: 2 | C19: Solid 1 hole 1 | D19: -250 | E19: 400 | F19: =D19*E20-D20*E19 | G19: =E19*COS(RADIANS(theta))+D19*SIN(RADIANS(theta))
B20: 3 | C20: Solid 1 hole 1 | D20: -150 | E20: 300 | F20: =D20*E21-D21*E20 | G20: =E20*COS(RADIANS(theta))+D20*SIN(RADIANS(theta))
B21: 4 | C21: Solid 1 hole 1 | D21: -150 | E21: -300 | F21: =D21*E22-D22*E21 | G21: =E21*COS(RADIANS(theta))+D21*SIN(RADIANS(theta))
B22: 5 | C22: Solid 1 hole 1 | D22: -250 | E22: -400 | F22: =D22*E23-D23*E22 | G22: =E22*COS(RADIANS(theta))+D22*SIN(RADIANS(theta))
B23: 6 | C23: Solid 1 hole 1 | D23: -450 | E23: -400 | F23: =D23*E24-D24*E23 | G23: =E23*COS(RADIANS(theta))+D23*SIN(RADIANS(theta))
B24: 7 | C24: Solid 1 hole 1 | D24: -550 | E24: -300 | F24: =D24*E25-D25*E24 | G24: =E24*COS(RADIANS(theta))+D24*SIN(RADIANS(theta))
B25: 8 | C25: Solid 1 hole 1 | D25: -550 | E25: 300 | F25: =D25*E18-D18*E25 | G25: =E25*COS(RADIANS(theta))+D25*SIN(RADIANS(theta))
C26: Area = ½·Σ D_i | F26: =SUM(F18:F25)/2
B28: Solid 1 hole 2
B29: No. | C29: Ring | D29: X (mm) | E29: Y (mm) | F29: D_i | G29: u = Y·cosθ + X·sinθ
B30: 1 | C30: Solid 1 hole 2 | D30: 250 | E30: 400 | F30: =D30*E31-D31*E30 | G30: =E30*COS(RADIANS(theta))+D30*SIN(RADIANS(theta))
B31: 2 | C31: Solid 1 hole 2 | D31: 450 | E31: 400 | F31: =D31*E32-D32*E31 | G31: =E31*COS(RADIANS(theta))+D31*SIN(RADIANS(theta))
B32: 3 | C32: Solid 1 hole 2 | D32: 550 | E32: 300 | F32: =D32*E33-D33*E32 | G32: =E32*COS(RADIANS(theta))+D32*SIN(RADIANS(theta))
B33: 4 | C33: Solid 1 hole 2 | D33: 550 | E33: -300 | F33: =D33*E34-D34*E33 | G33: =E33*COS(RADIANS(theta))+D33*SIN(RADIANS(theta))
B34: 5 | C34: Solid 1 hole 2 | D34: 450 | E34: -400 | F34: =D34*E35-D35*E34 | G34: =E34*COS(RADIANS(theta))+D34*SIN(RADIANS(theta))
B35: 6 | C35: Solid 1 hole 2 | D35: 250 | E35: -400 | F35: =D35*E36-D36*E35 | G35: =E35*COS(RADIANS(theta))+D35*SIN(RADIANS(theta))
B36: 7 | C36: Solid 1 hole 2 | D36: 150 | E36: -300 | F36: =D36*E37-D37*E36 | G36: =E36*COS(RADIANS(theta))+D36*SIN(RADIANS(theta))
B37: 8 | C37: Solid 1 hole 2 | D37: 150 | E37: 300 | F37: =D37*E30-D30*E37 | G37: =E37*COS(RADIANS(theta))+D37*SIN(RADIANS(theta))
C38: Area = ½·Σ D_i | F38: =SUM(F30:F37)/2
B40: Reinforcement
B41: No. | C41: Dia (mm) | D41: X (mm) | E41: Y (mm) | F41: As (mm²) | G41: u = Y·cosθ + X·sinθ
B42: 1 | C42: 32 | D42: -400 | E42: 530 | F42: =PI()*C42^2/4 | G42: =E42*COS(RADIANS(theta))+D42*SIN(RADIANS(theta))
B43: 2 | C43: 32 | D43: -200 | E43: 530 | F43: =PI()*C43^2/4 | G43: =E43*COS(RADIANS(theta))+D43*SIN(RADIANS(theta))
B44: 3 | C44: 32 | D44: 0 | E44: 530 | F44: =PI()*C44^2/4 | G44: =E44*COS(RADIANS(theta))+D44*SIN(RADIANS(theta))
...

Sheet Mesh
A1: CONCRETE INTEGRATION MESH — ENGINE CONSTANTS
A2: Quadrature points of the clipped-cell mesh (docs/02 §5). X, Y are measured from the analysis origin; A is the tributary area. These four columns are the only geometric constants the workbook needs.
A4: No. | B4: X (mm) | C4: Y (mm) | D4: A (mm²)
A5: 1 | B5: -703.90959 | C5: -435.80228 | D5: 635.07367
A6: 2 | B6: -673.0452 | C6: -466.66667 | D6: 635.07367
A7: 3 | B7: -673.0452 | C7: -435.80228 | D7: 635.07367
A8: 4 | B8: -745.74764 | C8: -363.09984 | D8: 262.49286
A9: 5 | B9: -745.74764 | C9: -393.96423 | D9: 262.49286
A10: 6 | B10: -732.99057 | C10: -406.7213 | D10: 262.49286
A11: 7 | B11: -731.20715 | C11: -367.3522 | D11: 897.56653
A12: 8 | B12: -718.45008 | C12: -410.97366 | D12: 897.56653
A13: 9 | B13: -687.58569 | C13: -410.97366 | D13: 897.56653
A14: 10 | B14: -677.29756 | C14: -396.43317 | D14: 1268.5547
A15: 11 | B15: -677.29756 | C15: -352.81171 | D15: 1268.5547
A16: 12 | B16: -720.91902 | C16: -352.81171 | D16: 1268.5547
... A1261: 1257 | B1261: 738.75316 | C1261: 404.52554 | D1261: 113.39011

Sheet PM_Angle
B1: P–M ENVELOPE AT THETA — 19 STATIONS, NOMINAL
B2: Direction theta = 15.0 deg. Shaded cells are the station schedule; everything else is a formula driven by Input, Geometry, Concrete and Steel.
B4: Station definition | F4: Strain plane (formula) | M4: Concrete | P4: Steel | S4: Total (nominal) | W4: Engine check
B5: Point | C5: C/C1 | D5: fs/fy | E5: eps_s | F5: u_ctrl (mm) | G5: eps_ctrl | H5: c (mm) | I5: kappa (1/mm) | J5: eps_0 | K5: kx (1/mm) | L5: ky (1/mm) | M5: P (kN) | N5: Mx (kN·m) | O5: My (kN·m) | P5: P (kN) | Q5: Mx (kN·m) | R5: My (kN·m) | S5: P (kN) | T5: Mx (kN·m) | U5: My (kN·m) | V5: |M| (kN·m) | W5: P engine (kN) | X5: Δ P (%)
B7: P0 | F7: — | G7: =ecu | H7: n/a | I7: 0 | J7: =ecu | K7: =I7*COS(RADIANS(theta)) | L7: =I7*SIN(RADIANS(theta)) | M7: =SUMPRODUCT(Concrete!$K$8:$K$1264,Mesh_A)/1000 | N7: =SUMPRODUCT(Concrete!$K$8:$K$1264,Mesh_A,Mesh_Y)/1000000 | O7: =SUMPRODUCT(Concrete!$K$8:$K$1264,Mesh_A,Mesh_X)/1000000 | P7: =Steel!J6/1000 | Q7: =Steel!K6/1000000 | R7: =Steel!L6/1000000 | S7: =M7+P7 | T7: =N7+Q7 | U7: =O7+R7 | V7: =SQRT(T7^2+U7^2) | W7: 33981.434 | X7: =IF(ABS(W7)<0.000000001,0,(S7-W7)/W7*100)
B8: P1 | C8: 3 | F8: =u_max-C8*C1_len | G8: =0 | H8: =ecu/I8 | I8: =(ecu-G8)/(u_max-F8) | J8: =ecu-I8*u_max | K8: =I8*COS(RADIANS(theta)) | L8: =I8*SIN(RADIANS(theta)) | M8: =SUMPRODUCT(Concrete!$M$8:$M$1264,Mesh_A)/1000 | N8: =SUMPRODUCT(Concrete!$M$8:$M$1264,Mesh_A,Mesh_Y)/1000000 | O8: =SUMPRODUCT(Concrete!$M$8:$M$1264,Mesh_A,Mesh_X)/1000000 | P8: =Steel!Q6/1000 | Q8: =Steel!R6/1000000 | R8: =Steel!S6/1000000 | S8: =M8+P8 | T8: =N8+Q8 | U8: =O8+R8 | V8: =SQRT(T8^2+U8^2) | W8: 33981.434 | X8: =IF(ABS(W8)<0.000000001,0,(S8-W8)/W8*100)
B9: P2 | C9: 2 | F9: =u_max-C9*C1_len | G9: =0 | H9: =ecu/I9 | I9: =(ecu-G9)/(u_max-F9) | J9: =ecu-I9*u_max | K9: =I9*COS(RADIANS(theta)) | L9: =I9*SIN(RADIANS(theta)) | M9: =SUMPRODUCT(Concrete!$O$8:$O$1264,Mesh_A)/1000 | N9: =SUMPRODUCT(Concrete!$O$8:$O$1264,Mesh_A,Mesh_Y)/1000000 | O9: =SUMPRODUCT(Concrete!$O$8:$O$1264,Mesh_A,Mesh_X)/1000000 | P9: =Steel!X6/1000 | Q9: =Steel!Y6/1000000 | R9: =Steel!Z6/1000000 | S9: =M9+P9 | T9: =N9+Q9 | U9: =O9+R9 | V9: =SQRT(T9^2+U9^2) | W9: 33683.338 | X9: =IF(ABS(W9)<0.000000001,0,(S9-W9)/W9*100)
B10: P3 | C10: 1.5 | F10: =u_max-C10*C1_len | G10: =0 | H10: =ecu/I10 | I10: =(ecu-G10)/(u_max-F10) | J10: =ecu-I10*u_max | K10: =I10*COS(RADIANS(theta)) | L10: =I10*SIN(RADIANS(theta)) | M10: =SUMPRODUCT(Concrete!$Q$8:$Q$1264,Mesh_A)/1000 | N10: =SUMPRODUCT(Concrete!$Q$8:$Q$1264,Mesh_A,Mesh_Y)/1000000 | O10: =SUMPRODUCT(Concrete!$Q$8:$Q$1264,Mesh_A,Mesh_X)/1000000 | P10: =Steel!AE6/1000 | Q10: =Steel!AF6/1000000 | R10: =Steel!AG6/1000000 | S10: =M10+P10 | T10: =N10+Q10 | U10: =O10+R10 | V10: =SQRT(T10^2+U10^2) | W10: 32195.888 | X10: =IF(ABS(W10)<0.000000001,0,(S10-W10)/W10*100)
B11: P4 | C11: 1.2 | F11: =u_max-C11*C1_len | G11: =0 | H11: =ecu/I11 | I11: =(ecu-G11)/(u_max-F11) | J11: =ecu-I11*u_max | K11: =I11*COS(RADIANS(theta)) | L11: =I11*SIN(RADIANS(theta)) | M11: =SUMPRODUCT(Concrete!$S$8:$S$1264,Mesh_A)/1000 | N11: =SUMPRODUCT(Concrete!$S$8:$S$1264,Mesh_A,Mesh_Y)/1000000 | O11: =SUMPRODUCT(Concrete!$S$8:$S$1264,Mesh_A,Mesh_X)/1000000 | P11: =Steel!AL6/1000 | Q11: =Steel!AM6/1000000 | R11: =Steel!AN6/1000000 | S11: =M11+P11 | T11: =N11+Q11 | U11: =O11+R11 | V11: =SQRT(T11^2+U11^2) | W11: 29291.136 | X11: =IF(ABS(W11)<0.000000001,0,(S11-W11)/W11*100)
B12: P5 | D12: 0 | F12: =u_bar | G12: =-E12 | H12: =ecu/I12 | I12: =(ecu-G12)/(u_max-F12) | J12: =ecu-I12*u_max | K12: =I12*COS(RADIANS(theta)) | L12: =I12*SIN(RADIANS(theta)) | M12: =SUMPRODUCT(Concrete!$U$8:$U$1264,Mesh_A)/1000 | N12: =SUMPRODUCT(Concrete!$U$8:$U$1264,Mesh_A,Mesh_Y)/1000000 | O12: =SUMPRODUCT(Concrete!$U$8:$U$1264,Mesh_A,Mesh_X)/1000000 | P12: =Steel!AS6/1000 | Q12: =Steel!AT6/1000000 | R12: =Steel!AU6/1000000 | S12: =M12+P12 | T12: =N12+Q12 | U12: =O12+R12 | V12: =SQRT(T12^2+U12^2) | W12: 24941.454 | X12: =IF(ABS(W12)<0.000000001,0,(S12-W12)/W12*100)
B13: P6 | D13: 0.25 | F13: =u_bar | G13: =-D13*fy/Es | H13: =ecu/I13 | I13: =(ecu-G13)/(u_max-F13) | J13: =ecu-I13*u_max | K13: =I13*COS(RADIANS(theta)) | L13: =I13*SIN(RADIANS(theta)) | M13: =SUMPRODUCT(Concrete!$W$8:$W$1264,Mesh_A)/1000 | N13: =SUMPRODUCT(Concrete!$W$8:$W$1264,Mesh_A,Mesh_Y)/1000000 | O13: =SUMPRODUCT(Concrete!$W$8:$W$1264,Mesh_A,Mesh_X)/1000000 | P13: =Steel!AZ6/1000 | Q13: =Steel!BA6/1000000 | R13: =Steel!BB6/1000000 | S13: =M13+P13 | T13: =N13+Q13 | U13: =O13+R13 | V13: =SQRT(T13^2+U13^2) | W13: 21079.019 | X13: =IF(ABS(W13)<0.000000001,0,(S13-W13)/W13*100)
B14: P7 | D14: 0.5 | F14: =u_bar | G14: =-D14*fy/Es | H14: =ecu/I14 | I14: =(ecu-G14)/(u_max-F14) | J14: =ecu-I14*u_max | K14: =I14*COS(RADIANS(theta)) | L14: =I14*SIN(RADIANS(theta)) | M14: =SUMPRODUCT(Concrete!$Y$8:$Y$1264,Mesh_A)/1000 | N14: =SUMPRODUCT(Concrete!$Y$8:$Y$1264,Mesh_A,Mesh_Y)/1000000 | O14: =SUMPRODUCT(Concrete!$Y$8:$Y$1264,Mesh_A,Mesh_X)/1000000 | P14: =Steel!BG6/1000 | Q14: =Steel!BH6/1000000 | R14: =Steel!BI6/1000000 | S14: =M14+P14 | T14: =N14+Q14 | U14: =O14+R14 | V14: =SQRT(T14^2+U14^2) | W14: 18153.31 | X14: =IF(ABS(W14)<0.000000001,0,(S14-W14)/W14*100)
B15: P8 | D15: 0.75 | F15: =u_bar | G15: =-D15*fy/Es | H15: =ecu/I15 | I15: =(ecu-G15)/(u_max-F15) | J15: =ecu-I15*u_max | K15: =I15*COS(RADIANS(theta)) | L15: =I15*SIN(RADIANS(theta)) | M15: =SUMPRODUCT(Concrete!$AA$8:$AA$1264,Mesh_A)/1000 | N15: =SUMPRODUCT(Concrete!$AA$8:$AA$1264,Mesh_A,Mesh_Y)/1000000 | O15: =SUMPRODUCT(Concrete!$AA$8:$AA$1264,Mesh_A,Mesh_X)/1000000 | P15: =Steel!BN6/1000 | Q15: =Steel!BO6/1000000 | R15: =Steel!BP6/1000000 | S15: =M15+P15 | T15: =N15+Q15 | U15: =O15+R15 | V15: =SQRT(T15^2+U15^2) | W15: 15853.978 | X15: =IF(ABS(W15)<0.000000001,0,(S15-W15)/W15*100)
B16: P9 | D16: 1 | F16: =u_bar | G16: =-D16*fy/Es | H16: =ecu/I16 | I16: =(ecu-G16)/(u_max-F16) | J16: =ecu-I16*u_max | K16: =I16*COS(RADIANS(theta)) | L16: =I16*SIN(RADIANS(theta)) | M16: =SUMPRODUCT(Concrete!$AC$8:$AC$1264,Mesh_A)/1000 | N16: =SUMPRODUCT(Concrete!$AC$8:$AC$1264,Mesh_A,Mesh_Y)/1000000 | O16: =SUMPRODUCT(Concrete!$AC$8:$AC$1264,Mesh_A,Mesh_X)/1000000 | P16: =Steel!BU6/1000 | Q16: =Steel!BV6/1000000 | R16: =Steel!BW6/1000000 | S16: =M16+P16 | T16: =N16+Q16 | U16: =O16+R16 | V16: =SQRT(T16^2+U16^2) | W16: 13872.543 | X16: =IF(ABS(W16)<0.000000001,0,(S16-W16)/W16*100)
B17: P10 | E17: 0.003 | F17: =u_bar | G17: =-E17 | H17: =ecu/I17 | I17: =(ecu-G17)/(u_max-F17) | J17: =ecu-I17*u_max | K17: =I17*COS(RADIANS(theta)) | L17: =I17*SIN(RADIANS(theta)) | M17: =SUMPRODUCT(Concrete!$AE$8:$AE$1264,Mesh_A)/1000 | N17: =SUMPRODUCT(Concrete!$AE$8:$AE$1264,Mesh_A,Mesh_Y)/1000000 | O17: =SUMPRODUCT(Concrete!$AE$8:$AE$1264,Mesh_A,Mesh_X)/1000000 | P17: =Steel!CB6/1000 | Q17: =Steel!CC6/1000000 | R17: =Steel!CD6/1000000 | S17: =M17+P17 | T17: =N17+Q17 | U17: =O17+R17 | V17: =SQRT(T17^2+U17^2) | W17: 10905.321 | X17: =IF(ABS(W17)<0.000000001,0,(S17-W17)/W17*100)
B18: P11 | E18: 0.005 | F18: =u_bar | G18: =-E18 | H18: =ecu/I18 | I18: =(ecu-G18)/(u_max-F18) | J18: =ecu-I18*u_max | K18: =I18*COS(RADIANS(theta)) | L18: =I18*SIN(RADIANS(theta)) | M18: =SUMPRODUCT(Concrete!$AG$8:$AG$1264,Mesh_A)/1000 | N18: =SUMPRODUCT(Concrete!$AG$8:$AG$1264,Mesh_A,Mesh_Y)/1000000 | O18: =SUMPRODUCT(Concrete!$AG$8:$AG$1264,Mesh_A,Mesh_X)/1000000 | P18: =Steel!CI6/1000 | Q18: =Steel!CJ6/1000000 | R18: =Steel!CK6/1000000 | S18: =M18+P18 | T18: =N18+Q18 | U18: =O18+R18 | V18: =SQRT(T18^2+U18^2) | W18: 7089.75 | X18: =IF(ABS(W18)<0.000000001,0,(S18-W18)/W18*100)
B19: P12 | E19: 0.0075 | F19: =u_bar | G19: =-E19 | H19: =ecu/I19 | I19: =(ecu-G19)/(u_max-F19) | J19: =ecu-I19*u_max | K19: =I19*COS(RADIANS(theta)) | L19: =I19*SIN(RADIANS(theta)) | M19: =SUMPRODUCT(Concrete!$AI$8:$AI$1264,Mesh_A)/1000 | N19: =SUMPRODUCT(Concrete!$AI$8:$AI$1264,Mesh_A,Mesh_Y)/1000000 | O19: =SUMPRODUCT(Concrete!$AI$8:$AI$1264,Mesh_A,Mesh_X)/1000000 | P19: =Steel!CP6/1000 | Q19: =Steel!CQ6/1000000 | R19: =Steel!CR6/1000000 | S19: =M19+P19 | T19: =N19+Q19 | U19: =O19+R19 | V19: =SQRT(T19^2+U19^2) | W19: 3844.8513 | X19: =IF(ABS(W19)<0.000000001,0,(S19-W19)/W19*100)
B20: P13 | E20: 0.01 | F20: =u_bar | G20: =-E20 | H20: =ecu/I20 | I20: =(ecu-G20)/(u_max-F20) | J20: =ecu-I20*u_max | K20: =I20*COS(RADIANS(theta)) | L20: =I20*SIN(RADIANS(theta)) | M20: =SUMPRODUCT(Concrete!$AK$8:$AK$1264,Mesh_A)/1000 | N20: =SUMPRODUCT(Concrete!$AK$8:$AK$1264,Mesh_A,Mesh_Y)/1000000 | O20: =SUMPRODUCT(Concrete!$AK$8:$AK$1264,Mesh_A,Mesh_X)/1000000 | P20: =Steel!CW6/1000 | Q20: =Steel!CX6/1000000 | R20: =Steel!CY6/1000000 | S20: =M20+P20 | T20: =N20+Q20 | U20: =O20+R20 | V20: =SQRT(T20^2+U20^2) | W20: 1694.8502 | X20: =IF(ABS(W20)<0.000000001,0,(S20-W20)/W20*100)
B21: P14 | E21: 0.015 | F21: =u_bar | G21: =-E21 | H21: =ecu/I21 | I21: =(ecu-G21)/(u_max-F21) | J21: =ecu-I21*u_max | K21: =I21*COS(RADIANS(theta)) | L21: =I21*SIN(RADIANS(theta)) | M21: =SUMPRODUCT(Concrete!$AM$8:$AM$1264,Mesh_A)/1000 | N21: =SUMPRODUCT(Concrete!$AM$8:$AM$1264,Mesh_A,Mesh_Y)/1000000 | O21: =SUMPRODUCT(Concrete!$AM$8:$AM$1264,Mesh_A,Mesh_X)/1000000 | P21: =Steel!DD6/1000 | Q21: =Steel!DE6/1000000 | R21: =Steel!DF6/1000000 | S21: =M21+P21 | T21: =N21+Q21 | U21: =O21+R21 | V21: =SQRT(T21^2+U21^2) | W21: -1005.049 | X21: =IF(ABS(W21)<0.000000001,0,(S21-W21)/W21*100)
B22: P15 | E22: 0.025 | F22: =u_bar | G22: =-E22 | H22: =ecu/I22 | I22: =(ecu-G22)/(u_max-F22) | J22: =ecu-I22*u_max | K22: =I22*COS(RADIANS(theta)) | L22: =I22*SIN(RADIANS(theta)) | M22: =SUMPRODUCT(Concrete!$AO$8:$AO$1264,Mesh_A)/1000 | N22: =SUMPRODUCT(Concrete!$AO$8:$AO$1264,Mesh_A,Mesh_Y)/1000000 | O22: =SUMPRODUCT(Concrete!$AO$8:$AO$1264,Mesh_A,Mesh_X)/1000000 | P22: =Steel!DK6/1000 | Q22: =Steel!DL6/1000000 | R22: =Steel!DM6/1000000 | S22: =M22+P22 | T22: =N22+Q22 | U22: =O22+R22 | V22: =SQRT(T22^2+U22^2) | W22: -3748.284 | X22: =IF(ABS(W22)<0.000000001,0,(S22-W22)/W22*100)
B23: P16 | E23: 0.03 | F23: =u_bar | G23: =-E23 | H23: =ecu/I23 | I23: =(ecu-G23)/(u_max-F23) | J23: =ecu-I23*u_max | K23: =I23*COS(RADIANS(theta)) | L23: =I23*SIN(RADIANS(theta)) | M23: =SUMPRODUCT(Concrete!$AQ$8:$AQ$1264,Mesh_A)/1000 | N23: =SUMPRODUCT(Concrete!$AQ$8:$AQ$1264,Mesh_A,Mesh_Y)/1000000 | O23: =SUMPRODUCT(Concrete!$AQ$8:$AQ$1264,Mesh_A,Mesh_X)/1000000 | P23: =Steel!DR6/1000 | Q23: =Steel!DS6/1000000 | R23: =Steel!DT6/1000000 | S23: =M23+P23 | T23: =N23+Q23 | U23: =O23+R23 | V23: =SQRT(T23^2+U23^2) | W23: -4342.2974 | X23: =IF(ABS(W23)<0.000000001,0,(S23-W23)/W23*100)
B24: P17 | E24: 0.05 | F24: =u_bar | G24: =-E24 | H24: =ecu/I24 | I24: =(ecu-G24)/(u_max-F24) | J24: =ecu-I24*u_max | K24: =I24*COS(RADIANS(theta)) | L24: =I24*SIN(RADIANS(theta)) | M24: =SUMPRODUCT(Concrete!$AS$8:$AS$1264,Mesh_A)/1000 | N24: =SUMPRODUCT(Concrete!$AS$8:$AS$1264,Mesh_A,Mesh_Y)/1000000 | O24: =SUMPRODUCT(Concrete!$AS$8:$AS$1264,Mesh_A,Mesh_X)/1000000 | P24: =Steel!DY6/1000 | Q24: =Steel!DZ6/1000000 | R24: =Steel!EA6/1000000 | S24: =M24+P24 | T24: =N24+Q24 | U24: =O24+R24 | V24: =SQRT(T24^2+U24^2) | W24: -5310.7751 | X24: =IF(ABS(W24)<0.000000001,0,(S24-W24)/W24*100)
B25: P18 | F25: — | G25: =etu | H25: n/a | I25: 0 | J25: =etu | K25: =I25*COS(RADIANS(theta)) | L25: =I25*SIN(RADIANS(theta)) | M25: =SUMPRODUCT(Concrete!$AU$8:$AU$1264,Mesh_A)/1000 | N25: =SUMPRODUCT(Concrete!$AU$8:$AU$1264,Mesh_A,Mesh_Y)/1000000 | O25: =SUMPRODUCT(Concrete!$AU$8:$AU$1264,Mesh_A,Mesh_X)/1000000 | P25: =Steel!EF6/1000 | Q25: =Steel!EG6/1000000 | R25: =Steel!EH6/1000000 | S25: =M25+P25 | T25: =N25+Q25 | U25: =O25+R25 | V25: =SQRT(T25^2+U25^2) | W25: -5790.5836 | X25: =IF(ABS(W25)<0.000000001,0,(S25-W25)/W25*100)
B27: Demand point and utilisation along the theta slice
B28: =Pu | C28: Pu
B29: =Mux | C29: Mux
B30: =Muy | C30: Muy
B31: =SQRT(Mux^2+Muy^2) | C31: Mu resultant
B32: =MAX(1,MIN(18,SUMPRODUCT(--(St_P>=Pu)))) | C32: Bracketing station k
B33: =(Pu-INDEX(St_P,B32,1))/(INDEX(St_P,B32+1,1)-INDEX(St_P,B32,1)) | C33: t (interpolation)
B34: =INDEX(St_Mx,B32,1)+B33*(INDEX(St_Mx,B32+1,1)-INDEX(St_Mx,B32,1)) | C34: Mx capacity at Pu
B35: =INDEX(St_My,B32,1)+B33*(INDEX(St_My,B32+1,1)-INDEX(St_My,B32,1)) | C35: My capacity at Pu
B36: =SQRT(B34^2+B35^2) | C36: M capacity resultant
B37: =IF(B36<=0,"n/a",B31/B36) | C37: Utilisation Mu / Mn

Sheet Concrete
A1: CONCRETE — FIBRE STRAIN AND STRESS PER STATION
A2: eps = eps_0 + kx·Y + ky·X | fc = KDS parabola-rectangle, fc = alpha*fck*(1-(1-eps/eco)^n) up to eco, then alpha*fck
A3: Columns A–D mirror the Mesh sheet. Columns E–I expand the full force/moment ledger for the station chosen in cell C4. Columns J onward hold eps and fc for all 19 stations, which the PM_Angle totals integrate.
A4: Detail station (0…18) | C4: 5 | D4: ="detail shown for station P"&C4
J5: P0 | L5: P1 | N5: P2 | P5: P3 | R5: P4 | T5: P5 | V5: P6 | X5: P7 | Z5: P8 | AB5: P9 | AD5: P10 | AF5: P11 | AH5: P12 | AJ5: P13 | AL5: P14 | AN5: P15 | AP5: P16 | AR5: P17 | AT5: P18
A6: No. | B6: X (mm) | C6: Y (mm) | D6: A (mm²) | E6: eps | F6: fc (MPa) | G6: Fc (N) | H6: Mcx (N·mm) | I6: Mcy (N·mm) | J6: eps | K6: fc (MPa) | L6: eps | M6: fc (MPa) | N6: eps | O6: fc (MPa) | P6: eps | Q6: fc (MPa) | R6: eps | S6: fc (MPa) | T6: eps | U6: fc (MPa) | V6: eps | W6: fc (MPa) | X6: eps | Y6: fc (MPa) | Z6: eps | AA6: fc (MPa) | AB6: eps | AC6: fc (MPa) | AD6: eps | AE6: fc (MPa) | AF6: eps | AG6: fc (MPa) | AH6: eps | AI6: fc (MPa) | AJ6: eps | AK6: fc (MPa) | AL6: eps | AM6: fc (MPa) | AN6: eps | AO6: fc (MPa) | AP6: eps | AQ6: fc (MPa) | AR6: eps | AS6: fc (MPa) | AT6: eps | AU6: fc (MPa)
A7: SUM | D7: =SUM(D8:D1264) | G7: =SUM(G8:G1264) | H7: =SUM(H8:H1264) | I7: =SUM(I8:I1264)
A8: =Mesh!A5 | B8: =Mesh!B5 | C8: =Mesh!C5 | D8: =Mesh!D5 | E8: =INDEX(St_e0,Det+1)+INDEX(St_kx,Det+1)*C8+INDEX(St_ky,Det+1)*B8 | F8: =IF(E8>0,IF(E8<=eco,alpha*fck*(1-(1-E8/eco)^n),alpha*fck),0) | G8: =F8*D8 | H8: =G8*C8 | I8: =G8*B8 | J8: =PM_Angle!$J$7+PM_Angle!$K$7*$C8+PM_Angle!$L$7*$B8 | K8: =IF(J8>0,IF(J8<=eco,alpha*fck*(1-(1-J8/eco)^n),alpha*fck),0) | L8: =PM_Angle!$J$8+PM_Angle!$K$8*$C8+PM_Angle!$L$8*$B8 | M8: =IF(L8>0,IF(L8<=eco,alpha*fck*(1-(1-L8/eco)^n),alpha*fck),0) | N8: =PM_Angle!$J$9+PM_Angle!$K$9*$C8+PM_Angle!$L$9*$B8 | O8: =IF(N8>0,IF(N8<=eco,alpha*fck*(1-(1-N8/eco)^n),alpha*fck),0) | P8: =PM_Angle!$J$10+PM_Angle!$K$10*$C8+PM_Angle!$L$10*$B8 | Q8: =IF(P8>0,IF(P8<=eco,alpha*fck*(1-(1-P8/eco)^n),alpha*fck),0) | R8: =PM_Angle!$J$11+PM_Angle!$K$11*$C8+PM_Angle!$L$11*$B8 | S8: =IF(R8>0,IF(R8<=eco,alpha*fck*(1-(1-R8/eco)^n),alpha*fck),0) | T8: =PM_Angle!$J$12+PM_Angle!$K$12*$C8+PM_Angle!$L$12*$B8 | U8: =IF(T8>0,IF(T8<=eco,alpha*fck*(1-(1-T8/eco)^n),alpha*fck),0) | V8: =PM_Angle!$J$13+PM_Angle!$K$13*$C8+PM_Angle!$L$13*$B8 | W8: =IF(V8>0,IF(V8<=eco,alpha*fck*(1-(1-V8/eco)^n),alpha*fck),0) | X8: =PM_Angle!$J$14+PM_Angle!$K$14*$C8+PM_Angle!$L$14*$B8 | Y8: =IF(X8>0,IF(X8<=eco,alpha*fck*(1-(1-X8/eco)^n),alpha*fck),0) | Z8: =PM_Angle!$J$15+PM_Angle!$K$15*$C8+PM_Angle!$L$15*$B8 | AA8: =IF(Z8>0,IF(Z8<=eco,alpha*fck*(1-(1-Z8/eco)^n),alpha*fck),0) | AB8: =PM_Angle!$J$16+PM_Angle!$K$16*$C8+PM_Angle!$L$16*$B8 | AC8: =IF(AB8>0,IF(AB8<=eco,alpha*fck*(1-(1-AB8/eco)^n),alpha*fck),0) | AD8: =PM_Angle!$J$17+PM_Angle!$K$17*$C8+PM_Angle!$L$17*$B8 | AE8: =IF(AD8>0,IF(AD8<=eco,alpha*fck*(1-(1-AD8/eco)^n),alpha*fck),0) | AF8: =PM_Angle!$J$18+PM_Angle!$K$18*$C8+PM_Angle!$L$18*$B8 | AG8: =IF(AF8>0,IF(AF8<=eco,alpha*fck*(1-(1-AF8/eco)^n),alpha*fck),0) | AH8: =PM_Angle!$J$19+PM_Angle!$K$19*$C8+PM_Angle!$L$19*$B8 | AI8: =IF(AH8>0,IF(AH8<=eco,alpha*fck*(1-(1-AH8/eco)^n),alpha*fck),0) | AJ8: =PM_Angle!$J$20+PM_Angle!$K$20*$C8+PM_Angle!$L$20*$B8 | AK8: =IF(AJ8>0,IF(AJ8<=eco,alpha*fck*(1-(1-AJ8/eco)^n),alpha*fck),0) | AL8: =PM_Angle!$J$21+PM_Angle!$K$21*$C8+PM_Angle!$L$21*$B8 | AM8: =IF(AL8>0,IF(AL8<=eco,alpha*fck*(1-(1-AL8/eco)^n),alpha*fck),0) | AN8: =PM_Angle!$J$22+PM_Angle!$K$22*$C8+PM_Angle!$L$22*$B8 | AO8: =IF(AN8>0,IF(AN8<=eco,alpha*fck*(1-(1-AN8/eco)^n),alpha*fck),0) | AP8: =PM_Angle!$J$23+PM_Angle!$K$23*$C8+PM_Angle!$L$23*$B8 | AQ8: =IF(AP8>0,IF(AP8<=eco,alpha*fck*(1-(1-AP8/eco)^n),alpha*fck),0) | AR8: =PM_Angle!$J$24+PM_Angle!$K$24*$C8+PM_Angle!$L$24*$B8 | AS8: =IF(AR8>0,IF(AR8<=eco,alpha*fck*(1-(1-AR8/eco)^n),alpha*fck),0) | AT8: =PM_Angle!$J$25+PM_Angle!$K$25*$C8+PM_Angle!$L$25*$B8 | AU8: =IF(AT8>0,IF(AT8<=eco,alpha*fck*(1-(1-AT8/eco)^n),alpha*fck),0)
A9: =Mesh!A6 | B9: =Mesh!B6 | C9: =Mesh!C6 | D9: =Mesh!D6 | E9: =INDEX(St_e0,Det+1)+INDEX(St_kx,Det+1)*C9+INDEX(St_ky,Det+1)*B9 | F9: =IF(E9>0,IF(E9<=eco,alpha*fck*(1-(1-E9/eco)^n),alpha*fck),0) | G9: =F9*D9 | H9: =G9*C9 | I9: =G9*B9 | J9: =PM_Angle!$J$7+PM_Angle!$K$7*$C9+PM_Angle!$L$7*$B9 | K9: =IF(J9>0,IF(J9<=eco,alpha*fck*(1-(1-J9/eco)^n),alpha*fck),0) | L9: =PM_Angle!$J$8+PM_Angle!$K$8*$C9+PM_Angle!$L$8*$B9 | M9: =IF(L9>0,IF(L9<=eco,alpha*fck*(1-(1-L9/eco)^n),alpha*fck),0) | N9: =PM_Angle!$J$9+PM_Angle!$K$9*$C9+PM_Angle!$L$9*$B9 | O9: =IF(N9>0,IF(N9<=eco,alpha*fck*(1-(1-N9/eco)^n),alpha*fck),0) | P9: =PM_Angle!$J$10+PM_Angle!$K$10*$C9+PM_Angle!$L$10*$B9 | Q9: =IF(P9>0,IF(P9<=eco,alpha*fck*(1-(1-P9/eco)^n),alpha*fck),0) | R9: =PM_Angle!$J$11+PM_Angle!$K$11*$C9+PM_Angle!$L$11*$B9 | S9: =IF(R9>0,IF(R9<=eco,alpha*fck*(1-(1-R9/eco)^n),alpha*fck),0) | T9: =PM_Angle!$J$12+PM_Angle!$K$12*$C9+PM_Angle!$L$12*$B9 | U9: =IF(T9>0,IF(T9<=eco,alpha*fck*(1-(1-T9/eco)^n),alpha*fck),0) | V9: =PM_Angle!$J$13+PM_Angle!$K$13*$C9+PM_Angle!$L$13*$B9 | W9: =IF(V9>0,IF(V9<=eco,alpha*fck*(1-(1-V9/eco)^n),alpha*fck),0) | X9: =PM_Angle!$J$14+PM_Angle!$K$14*$C9+PM_Angle!$L$14*$B9 | Y9: =IF(X9>0,IF(X9<=eco,alpha*fck*(1-(1-X9/eco)^n),alpha*fck),0) | Z9: =PM_Angle!$J$15+PM_Angle!$K$15*$C9+PM_Angle!$L$15*$B9 | AA9: =IF(Z9>0,IF(Z9<=eco,alpha*fck*(1-(1-Z9/eco)^n),alpha*fck),0) | AB9: =PM_Angle!$J$16+PM_Angle!$K$16*$C9+PM_Angle!$L$16*$B9 | AC9: =IF(AB9>0,IF(AB9<=eco,alpha*fck*(1-(1-AB9/eco)^n),alpha*fck),0) | AD9: =PM_Angle!$J$17+PM_Angle!$K$17*$C9+PM_Angle!$L$17*$B9 | AE9: =IF(AD9>0,IF(AD9<=eco,alpha*fck*(1-(1-AD9/eco)^n),alpha*fck),0) | AF9: =PM_Angle!$J$18+PM_Angle!$K$18*$C9+PM_Angle!$L$18*$B9 | AG9: =IF(AF9>0,IF(AF9<=eco,alpha*fck*(1-(1-AF9/eco)^n),alpha*fck),0) | AH9: =PM_Angle!$J$19+PM_Angle!$K$19*$C9+PM_Angle!$L$19*$B9 | AI9: =IF(AH9>0,IF(AH9<=eco,alpha*fck*(1-(1-AH9/eco)^n),alpha*fck),0) | AJ9: =PM_Angle!$J$20+PM_Angle!$K$20*$C9+PM_Angle!$L$20*$B9 | AK9: =IF(AJ9>0,IF(AJ9<=eco,alpha*fck*(1-(1-AJ9/eco)^n),alpha*fck),0) | AL9: =PM_Angle!$J$21+PM_Angle!$K$21*$C9+PM_Angle!$L$21*$B9 | AM9: =IF(AL9>0,IF(AL9<=eco,alpha*fck*(1-(1-AL9/eco)^n),alpha*fck),0) | AN9: =PM_Angle!$J$22+PM_Angle!$K$22*$C9+PM_Angle!$L$22*$B9 | AO9: =IF(AN9>0,IF(AN9<=eco,alpha*fck*(1-(1-AN9/eco)^n),alpha*fck),0) | AP9: =PM_Angle!$J$23+PM_Angle!$K$23*$C9+PM_Angle!$L$23*$B9 | AQ9: =IF(AP9>0,IF(AP9<=eco,alpha*fck*(1-(1-AP9/eco)^n),alpha*fck),0) | AR9: =PM_Angle!$J$24+PM_Angle!$K$24*$C9+PM_Angle!$L$24*$B9 | AS9: =IF(AR9>0,IF(AR9<=eco,alpha*fck*(1-(1-AR9/eco)^n),alpha*fck),0) | AT9: =PM_Angle!$J$25+PM_Angle!$K$25*$C9+PM_Angle!$L$25*$B9 | AU9: =IF(AT9>0,IF(AT9<=eco,alpha*fck*(1-(1-AT9/eco)^n),alpha*fck),0)
A10: =Mesh!A7 | B10: =Mesh!B7 | C10: =Mesh!C7 | D10: =Mesh!D7 | E10: =INDEX(St_e0,Det+1)+INDEX(St_kx,Det+1)*C10+INDEX(St_ky,Det+1)*B10 | F10: =IF(E10>0,IF(E10<=eco,alpha*fck*(1-(1-E10/eco)^n),alpha*fck),0) | G10: =F10*D10 | H10: =G10*C10 | I10: =G10*B10 | J10: =PM_Angle!$J$7+PM_Angle!$K$7*$C10+PM_Angle!$L$7*$B10 | K10: =IF(J10>0,IF(J10<=eco,alpha*fck*(1-(1-J10/eco)^n),alpha*fck),0) | L10: =PM_Angle!$J$8+PM_Angle!$K$8*$C10+PM_Angle!$L$8*$B10 | M10: =IF(L10>0,IF(L10<=eco,alpha*fck*(1-(1-L10/eco)^n),alpha*fck),0) | N10: =PM_Angle!$J$9+PM_Angle!$K$9*$C10+PM_Angle!$L$9*$B10 | O10: =IF(N10>0,IF(N10<=eco,alpha*fck*(1-(1-N10/eco)^n),alpha*fck),0) | P10: =PM_Angle!$J$10+PM_Angle!$K$10*$C10+PM_Angle!$L$10*$B10 | Q10: =IF(P10>0,IF(P10<=eco,alpha*fck*(1-(1-P10/eco)^n),alpha*fck),0) | R10: =PM_Angle!$J$11+PM_Angle!$K$11*$C10+PM_Angle!$L$11*$B10 | S10: =IF(R10>0,IF(R10<=eco,alpha*fck*(1-(1-R10/eco)^n),alpha*fck),0) | T10: =PM_Angle!$J$12+PM_Angle!$K$12*$C10+PM_Angle!$L$12*$B10 | U10: =IF(T10>0,IF(T10<=eco,alpha*fck*(1-(1-T10/eco)^n),alpha*fck),0) | V10: =PM_Angle!$J$13+PM_Angle!$K$13*$C10+PM_Angle!$L$13*$B10 | W10: =IF(V10>0,IF(V10<=eco,alpha*fck*(1-(1-V10/eco)^n),alpha*fck),0) | X10: =PM_Angle!$J$14+PM_Angle!$K$14*$C10+PM_Angle!$L$14*$B10 | Y10: =IF(X10>0,IF(X10<=eco,alpha*fck*(1-(1-X10/eco)^n),alpha*fck),0) | Z10: =PM_Angle!$J$15+PM_Angle!$K$15*$C10+PM_Angle!$L$15*$B10 | AA10: =IF(Z10>0,IF(Z10<=eco,alpha*fck*(1-(1-Z10/eco)^n),alpha*fck),0) | AB10: =PM_Angle!$J$16+PM_Angle!$K$16*$C10+PM_Angle!$L$16*$B10 | AC10: =IF(AB10>0,IF(AB10<=eco,alpha*fck*(1-(1-AB10/eco)^n),alpha*fck),0) | AD10: =PM_Angle!$J$17+PM_Angle!$K$17*$C10+PM_Angle!$L$17*$B10 | AE10: =IF(AD10>0,IF(AD10<=eco,alpha*fck*(1-(1-AD10/eco)^n),alpha*fck),0) | AF10: =PM_Angle!$J$18+PM_Angle!$K$18*$C10+PM_Angle!$L$18*$B10 | AG10: =IF(AF10>0,IF(AF10<=eco,alpha*fck*(1-(1-AF10/eco)^n),alpha*fck),0) | AH10: =PM_Angle!$J$19+PM_Angle!$K$19*$C10+PM_Angle!$L$19*$B10 | AI10: =IF(AH10>0,IF(AH10<=eco,alpha*fck*(1-(1-AH10/eco)^n),alpha*fck),0) | AJ10: =PM_Angle!$J$20+PM_Angle!$K$20*$C10+PM_Angle!$L$20*$B10 | AK10: =IF(AJ10>0,IF(AJ10<=eco,alpha*fck*(1-(1-AJ10/eco)^n),alpha*fck),0) | AL10: =PM_Angle!$J$21+PM_Angle!$K$21*$C10+PM_Angle!$L$21*$B10 | AM10: =IF(AL10>0,IF(AL10<=eco,alpha*fck*(1-(1-AL10/eco)^n),alpha*fck),0) | AN10: =PM_Angle!$J$22+PM_Angle!$K$22*$C10+PM_Angle!$L$22*$B10 | AO10: =IF(AN10>0,IF(AN10<=eco,alpha*fck*(1-(1-AN10/eco)^n),alpha*fck),0) | AP10: =PM_Angle!$J$23+PM_Angle!$K$23*$C10+PM_Angle!$L$23*$B10 | AQ10: =IF(AP10>0,IF(AP10<=eco,alpha*fck*(1-(1-AP10/eco)^n),alpha*fck),0) | AR10: =PM_Angle!$J$24+PM_Angle!$K$24*$C10+PM_Angle!$L$24*$B10 | AS10: =IF(AR10>0,IF(AR10<=eco,alpha*fck*(1-(1-AR10/eco)^n),alpha*fck),0) | AT10: =PM_Angle!$J$25+PM_Angle!$K$25*$C10+PM_Angle!$L$25*$B10 | AU10: =IF(AT10>0,IF(AT10<=eco,alpha*fck*(1-(1-AT10/eco)^n),alpha*fck),0)
A11: =Mesh!A8 | B11: =Mesh!B8 | C11: =Mesh!C8 | D11: =Mesh!D8 | E11: =INDEX(St_e0,Det+1)+INDEX(St_kx,Det+1)*C11+INDEX(St_ky,Det+1)*B11 | F11: =IF(E11>0,IF(E11<=eco,alpha*fck*(1-(1-E11/eco)^n),alpha*fck),0) | G11: =F11*D11 | H11: =G11*C11 | I11: =G11*B11 | J11: =PM_Angle!$J$7+PM_Angle!$K$7*$C11+PM_Angle!$L$7*$B11 | K11: =IF(J11>0,IF(J11<=eco,alpha*fck*(1-(1-J11/eco)^n),alpha*fck),0) | L11: =PM_Angle!$J$8+PM_Angle!$K$8*$C11+PM_Angle!$L$8*$B11 | M11: =IF(L11>0,IF(L11<=eco,alpha*fck*(1-(1-L11/eco)^n),alpha*fck),0) | N11: =PM_Angle!$J$9+PM_Angle!$K$9*$C11+PM_Angle!$L$9*$B11 | O11: =IF(N11>0,IF(N11<=eco,alpha*fck*(1-(1-N11/eco)^n),alpha*fck),0) | P11: =PM_Angle!$J$10+PM_Angle!$K$10*$C11+PM_Angle!$L$10*$B11 | Q11: =IF(P11>0,IF(P11<=eco,alpha*fck*(1-(1-P11/eco)^n),alpha*fck),0) | R11: =PM_Angle!$J$11+PM_Angle!$K$11*$C11+PM_Angle!$L$11*$B11 | S11: =IF(R11>0,IF(R11<=eco,alpha*fck*(1-(1-R11/eco)^n),alpha*fck),0) | T11: =PM_Angle!$J$12+PM_Angle!$K$12*$C11+PM_Angle!$L$12*$B11 | U11: =IF(T11>0,IF(T11<=eco,alpha*fck*(1-(1-T11/eco)^n),alpha*fck),0) | V11: =PM_Angle!$J$13+PM_Angle!$K$13*$C11+PM_Angle!$L$13*$B11 | W11: =IF(V11>0,IF(V11<=eco,alpha*fck*(1-(1-V11/eco)^n),alpha*fck),0) | X11: =PM_Angle!$J$14+PM_Angle!$K$14*$C11+PM_Angle!$L$14*$B11 | Y11: =IF(X11>0,IF(X11<=eco,alpha*fck*(1-(1-X11/eco)^n),alpha*fck),0) | Z11: =PM_Angle!$J$15+PM_Angle!$K$15*$C11+PM_Angle!$L$15*$B11 | AA11: =IF(Z11>0,IF(Z11<=eco,alpha*fck*(1-(1-Z11/eco)^n),alpha*fck),0) | AB11: =PM_Angle!$J$16+PM_Angle!$K$16*$C11+PM_Angle!$L$16*$B11 | AC11: =IF(AB11>0,IF(AB11<=eco,alpha*fck*(1-(1-AB11/eco)^n),alpha*fck),0) | AD11: =PM_Angle!$J$17+PM_Angle!$K$17*$C11+PM_Angle!$L$17*$B11 | AE11: =IF(AD11>0,IF(AD11<=eco,alpha*fck*(1-(1-AD11/eco)^n),alpha*fck),0) | AF11: =PM_Angle!$J$18+PM_Angle!$K$18*$C11+PM_Angle!$L$18*$B11 | AG11: =IF(AF11>0,IF(AF11<=eco,alpha*fck*(1-(1-AF11/eco)^n),alpha*fck),0) | AH11: =PM_Angle!$J$19+PM_Angle!$K$19*$C11+PM_Angle!$L$19*$B11 | AI11: =IF(AH11>0,IF(AH11<=eco,alpha*fck*(1-(1-AH11/eco)^n),alpha*fck),0) | AJ11: =PM_Angle!$J$20+PM_Angle!$K$20*$C11+PM_Angle!$L$20*$B11 | AK11: =IF(AJ11>0,IF(AJ11<=eco,alpha*fck*(1-(1-AJ11/eco)^n),alpha*fck),0) | AL11: =PM_Angle!$J$21+PM_Angle!$K$21*$C11+PM_Angle!$L$21*$B11 | AM11: =IF(AL11>0,IF(AL11<=eco,alpha*fck*(1-(1-AL11/eco)^n),alpha*fck),0) | AN11: =PM_Angle!$J$22+PM_Angle!$K$22*$C11+PM_Angle!$L$22*$B11 | AO11: =IF(AN11>0,IF(AN11<=eco,alpha*fck*(1-(1-AN11/eco)^n),alpha*fck),0) | AP11: =PM_Angle!$J$23+PM_Angle!$K$23*$C11+PM_Angle!$L$23*$B11 | AQ11: =IF(AP11>0,IF(AP11<=eco,alpha*fck*(1-(1-AP11/eco)^n),alpha*fck),0) | AR11: =PM_Angle!$J$24+PM_Angle!$K$24*$C11+PM_Angle!$L$24*$B11 | AS11: =IF(AR11>0,IF(AR11<=eco,alpha*fck*(1-(1-AR11/eco)^n),alpha*fck),0) | AT11: =PM_Angle!$J$25+PM_Angle!$K$25*$C11+PM_Angle!$L$25*$B11 | AU11: =IF(AT11>0,IF(AT11<=eco,alpha*fck*(1-(1-AT11/eco)^n),alpha*fck),0)
A12: =Mesh!A9 | B12: =Mesh!B9 | C12: =Mesh!C9 | D12: =Mesh!D9 | E12: =INDEX(St_e0,Det+1)+INDEX(St_kx,Det+1)*C12+INDEX(St_ky,Det+1)*B12 | F12: =IF(E12>0,IF(E12<=eco,alpha*fck*(1-(1-E12/eco)^n),alpha*fck),0) | G12: =F12*D12 | H12: =G12*C12 | I12: =G12*B12 | J12: =PM_Angle!$J$7+PM_Angle!$K$7*$C12+PM_Angle!$L$7*$B12 | K12: =IF(J12>0,IF(J12<=eco,alpha*fck*(1-(1-J12/eco)^n),alpha*fck),0) | L12: =PM_Angle!$J$8+PM_Angle!$K$8*$C12+PM_Angle!$L$8*$B12 | M12: =IF(L12>0,IF(L12<=eco,alpha*fck*(1-(1-L12/eco)^n),alpha*fck),0) | N12: =PM_Angle!$J$9+PM_Angle!$K$9*$C12+PM_Angle!$L$9*$B12 | O12: =IF(N12>0,IF(N12<=eco,alpha*fck*(1-(1-N12/eco)^n),alpha*fck),0) | P12: =PM_Angle!$J$10+PM_Angle!$K$10*$C12+PM_Angle!$L$10*$B12 | Q12: =IF(P12>0,IF(P12<=eco,alpha*fck*(1-(1-P12/eco)^n),alpha*fck),0) | R12: =PM_Angle!$J$11+PM_Angle!$K$11*$C12+PM_Angle!$L$11*$B12 | S12: =IF(R12>0,IF(R12<=eco,alpha*fck*(1-(1-R12/eco)^n),alpha*fck),0) | T12: =PM_Angle!$J$12+PM_Angle!$K$12*$C12+PM_Angle!$L$12*$B12 | U12: =IF(T12>0,IF(T12<=eco,alpha*fck*(1-(1-T12/eco)^n),alpha*fck),0) | V12: =PM_Angle!$J$13+PM_Angle!$K$13*$C12+PM_Angle!$L$13*$B12 | W12: =IF(V12>0,IF(V12<=eco,alpha*fck*(1-(1-V12/eco)^n),alpha*fck),0) | X12: =PM_Angle!$J$14+PM_Angle!$K$14*$C12+PM_Angle!$L$14*$B12 | Y12: =IF(X12>0,IF(X12<=eco,alpha*fck*(1-(1-X12/eco)^n),alpha*fck),0) | Z12: =PM_Angle!$J$15+PM_Angle!$K$15*$C12+PM_Angle!$L$15*$B12 | AA12: =IF(Z12>0,IF(Z12<=eco,alpha*fck*(1-(1-Z12/eco)^n),alpha*fck),0) | AB12: =PM_Angle!$J$16+PM_Angle!$K$16*$C12+PM_Angle!$L$16*$B12 | AC12: =IF(AB12>0,IF(AB12<=eco,alpha*fck*(1-(1-AB12/eco)^n),alpha*fck),0) | AD12: =PM_Angle!$J$17+PM_Angle!$K$17*$C12+PM_Angle!$L$17*$B12 | AE12: =IF(AD12>0,IF(AD12<=eco,alpha*fck*(1-(1-AD12/eco)^n),alpha*fck),0) | AF12: =PM_Angle!$J$18+PM_Angle!$K$18*$C12+PM_Angle!$L$18*$B12 | AG12: =IF(AF12>0,IF(AF12<=eco,alpha*fck*(1-(1-AF12/eco)^n),alpha*fck),0) | AH12: =PM_Angle!$J$19+PM_Angle!$K$19*$C12+PM_Angle!$L$19*$B12 | AI12: =IF(AH12>0,IF(AH12<=eco,alpha*fck*(1-(1-AH12/eco)^n),alpha*fck),0) | AJ12: =PM_Angle!$J$20+PM_Angle!$K$20*$C12+PM_Angle!$L$20*$B12 | AK12: =IF(AJ12>0,IF(AJ12<=eco,alpha*fck*(1-(1-AJ12/eco)^n),alpha*fck),0) | AL12: =PM_Angle!$J$21+PM_Angle!$K$21*$C12+PM_Angle!$L$21*$B12 | AM12: =IF(AL12>0,IF(AL12<=eco,alpha*fck*(1-(1-AL12/eco)^n),alpha*fck),0) | AN12: =PM_Angle!$J$22+PM_Angle!$K$22*$C12+PM_Angle!$L$22*$B12 | AO12: =IF(AN12>0,IF(AN12<=eco,alpha*fck*(1-(1-AN12/eco)^n),alpha*fck),0) | AP12: =PM_Angle!$J$23+PM_Angle!$K$23*$C12+PM_Angle!$L$23*$B12 | AQ12: =IF(AP12>0,IF(AP12<=eco,alpha*fck*(1-(1-AP12/eco)^n),alpha*fck),0) | AR12: =PM_Angle!$J$24+PM_Angle!$K$24*$C12+PM_Angle!$L$24*$B12 | AS12: =IF(AR12>0,IF(AR12<=eco,alpha*fck*(1-(1-AR12/eco)^n),alpha*fck),0) | AT12: =PM_Angle!$J$25+PM_Angle!$K$25*$C12+PM_Angle!$L$25*$B12 | AU12: =IF(AT12>0,IF(AT12<=eco,alpha*fck*(1-(1-AT12/eco)^n),alpha*fck),0)
A13: =Mesh!A10 | B13: =Mesh!B10 | C13: =Mesh!C10 | D13: =Mesh!D10 | E13: =INDEX(St_e0,Det+1)+INDEX(St_kx,Det+1)*C13+INDEX(St_ky,Det+1)*B13 | F13: =IF(E13>0,IF(E13<=eco,alpha*fck*(1-(1-E13/eco)^n),alpha*fck),0) | G13: =F13*D13 | H13: =G13*C13 | I13: =G13*B13 | J13: =PM_Angle!$J$7+PM_Angle!$K$7*$C13+PM_Angle!$L$7*$B13 | K13: =IF(J13>0,IF(J13<=eco,alpha*fck*(1-(1-J13/eco)^n),alpha*fck),0) | L13: =PM_Angle!$J$8+PM_Angle!$K$8*$C13+PM_Angle!$L$8*$B13 | M13: =IF(L13>0,IF(L13<=eco,alpha*fck*(1-(1-L13/eco)^n),alpha*fck),0) | N13: =PM_Angle!$J$9+PM_Angle!$K$9*$C13+PM_Angle!$L$9*$B13 | O13: =IF(N13>0,IF(N13<=eco,alpha*fck*(1-(1-N13/eco)^n),alpha*fck),0) | P13: =PM_Angle!$J$10+PM_Angle!$K$10*$C13+PM_Angle!$L$10*$B13 | Q13: =IF(P13>0,IF(P13<=eco,alpha*fck*(1-(1-P13/eco)^n),alpha*fck),0) | R13: =PM_Angle!$J$11+PM_Angle!$K$11*$C13+PM_Angle!$L$11*$B13 | S13: =IF(R13>0,IF(R13<=eco,alpha*fck*(1-(1-R13/eco)^n),alpha*fck),0) | T13: =PM_Angle!$J$12+PM_Angle!$K$12*$C13+PM_Angle!$L$12*$B13 | U13: =IF(T13>0,IF(T13<=eco,alpha*fck*(1-(1-T13/eco)^n),alpha*fck),0) | V13: =PM_Angle!$J$13+PM_Angle!$K$13*$C13+PM_Angle!$L$13*$B13 | W13: =IF(V13>0,IF(V13<=eco,alpha*fck*(1-(1-V13/eco)^n),alpha*fck),0) | X13: =PM_Angle!$J$14+PM_Angle!$K$14*$C13+PM_Angle!$L$14*$B13 | Y13: =IF(X13>0,IF(X13<=eco,alpha*fck*(1-(1-X13/eco)^n),alpha*fck),0) | Z13: =PM_Angle!$J$15+PM_Angle!$K$15*$C13+PM_Angle!$L$15*$B13 | AA13: =IF(Z13>0,IF(Z13<=eco,alpha*fck*(1-(1-Z13/eco)^n),alpha*fck),0) | AB13: =PM_Angle!$J$16+PM_Angle!$K$16*$C13+PM_Angle!$L$16*$B13 | AC13: =IF(AB13>0,IF(AB13<=eco,alpha*fck*(1-(1-AB13/eco)^n),alpha*fck),0) | AD13: =PM_Angle!$J$17+PM_Angle!$K$17*$C13+PM_Angle!$L$17*$B13 | AE13: =IF(AD13>0,IF(AD13<=eco,alpha*fck*(1-(1-AD13/eco)^n),alpha*fck),0) | AF13: =PM_Angle!$J$18+PM_Angle!$K$18*$C13+PM_Angle!$L$18*$B13 | AG13: =IF(AF13>0,IF(AF13<=eco,alpha*fck*(1-(1-AF13/eco)^n),alpha*fck),0) | AH13: =PM_Angle!$J$19+PM_Angle!$K$19*$C13+PM_Angle!$L$19*$B13 | AI13: =IF(AH13>0,IF(AH13<=eco,alpha*fck*(1-(1-AH13/eco)^n),alpha*fck),0) | AJ13: =PM_Angle!$J$20+PM_Angle!$K$20*$C13+PM_Angle!$L$20*$B13 | AK13: =IF(AJ13>0,IF(AJ13<=eco,alpha*fck*(1-(1-AJ13/eco)^n),alpha*fck),0) | AL13: =PM_Angle!$J$21+PM_Angle!$K$21*$C13+PM_Angle!$L$21*$B13 | AM13: =IF(AL13>0,IF(AL13<=eco,alpha*fck*(1-(1-AL13/eco)^n),alpha*fck),0) | AN13: =PM_Angle!$J$22+PM_Angle!$K$22*$C13+PM_Angle!$L$22*$B13 | AO13: =IF(AN13>0,IF(AN13<=eco,alpha*fck*(1-(1-AN13/eco)^n),alpha*fck),0) | AP13: =PM_Angle!$J$23+PM_Angle!$K$23*$C13+PM_Angle!$L$23*$B13 | AQ13: =IF(AP13>0,IF(AP13<=eco,alpha*fck*(1-(1-AP13/eco)^n),alpha*fck),0) | AR13: =PM_Angle!$J$24+PM_Angle!$K$24*$C13+PM_Angle!$L$24*$B13 | AS13: =IF(AR13>0,IF(AR13<=eco,alpha*fck*(1-(1-AR13/eco)^n),alpha*fck),0) | AT13: =PM_Angle!$J$25+PM_Angle!$K$25*$C13+PM_Angle!$L$25*$B13 | AU13: =IF(AT13>0,IF(AT13<=eco,alpha*fck*(1-(1-AT13/eco)^n),alpha*fck),0)
A14: =Mesh!A11 | B14: =Mesh!B11 | C14: =Mesh!C11 | D14: =Mesh!D11 | E14: =INDEX(St_e0,Det+1)+INDEX(St_kx,Det+1)*C14+INDEX(St_ky,Det+1)*B14 | F14: =IF(E14>0,IF(E14<=eco,alpha*fck*(1-(1-E14/eco)^n),alpha*fck),0) | G14: =F14*D14 | H14: =G14*C14 | I14: =G14*B14 | J14: =PM_Angle!$J$7+PM_Angle!$K$7*$C14+PM_Angle!$L$7*$B14 | K14: =IF(J14>0,IF(J14<=eco,alpha*fck*(1-(1-J14/eco)^n),alpha*fck),0) | L14: =PM_Angle!$J$8+PM_Angle!$K$8*$C14+PM_Angle!$L$8*$B14 | M14: =IF(L14>0,IF(L14<=eco,alpha*fck*(1-(1-L14/eco)^n),alpha*fck),0) | N14: =PM_Angle!$J$9+PM_Angle!$K$9*$C14+PM_Angle!$L$9*$B14 | O14: =IF(N14>0,IF(N14<=eco,alpha*fck*(1-(1-N14/eco)^n),alpha*fck),0) | P14: =PM_Angle!$J$10+PM_Angle!$K$10*$C14+PM_Angle!$L$10*$B14 | Q14: =IF(P14>0,IF(P14<=eco,alpha*fck*(1-(1-P14/eco)^n),alpha*fck),0) | R14: =PM_Angle!$J$11+PM_Angle!$K$11*$C14+PM_Angle!$L$11*$B14 | S14: =IF(R14>0,IF(R14<=eco,alpha*fck*(1-(1-R14/eco)^n),alpha*fck),0) | T14: =PM_Angle!$J$12+PM_Angle!$K$12*$C14+PM_Angle!$L$12*$B14 | U14: =IF(T14>0,IF(T14<=eco,alpha*fck*(1-(1-T14/eco)^n),alpha*fck),0) | V14: =PM_Angle!$J$13+PM_Angle!$K$13*$C14+PM_Angle!$L$13*$B14 | W14: =IF(V14>0,IF(V14<=eco,alpha*fck*(1-(1-V14/eco)^n),alpha*fck),0) | X14: =PM_Angle!$J$14+PM_Angle!$K$14*$C14+PM_Angle!$L$14*$B14 | Y14: =IF(X14>0,IF(X14<=eco,alpha*fck*(1-(1-X14/eco)^n),alpha*fck),0) | Z14: =PM_Angle!$J$15+PM_Angle!$K$15*$C14+PM_Angle!$L$15*$B14 | AA14: =IF(Z14>0,IF(Z14<=eco,alpha*fck*(1-(1-Z14/eco)^n),alpha*fck),0) | AB14: =PM_Angle!$J$16+PM_Angle!$K$16*$C14+PM_Angle!$L$16*$B14 | AC14: =IF(AB14>0,IF(AB14<=eco,alpha*fck*(1-(1-AB14/eco)^n),alpha*fck),0) | AD14: =PM_Angle!$J$17+PM_Angle!$K$17*$C14+PM_Angle!$L$17*$B14 | AE14: =IF(AD14>0,IF(AD14<=eco,alpha*fck*(1-(1-AD14/eco)^n),alpha*fck),0) | AF14: =PM_Angle!$J$18+PM_Angle!$K$18*$C14+PM_Angle!$L$18*$B14 | AG14: =IF(AF14>0,IF(AF14<=eco,alpha*fck*(1-(1-AF14/eco)^n),alpha*fck),0) | AH14: =PM_Angle!$J$19+PM_Angle!$K$19*$C14+PM_Angle!$L$19*$B14 | AI14: =IF(AH14>0,IF(AH14<=eco,alpha*fck*(1-(1-AH14/eco)^n),alpha*fck),0) | AJ14: =PM_Angle!$J$20+PM_Angle!$K$20*$C14+PM_Angle!$L$20*$B14 | AK14: =IF(AJ14>0,IF(AJ14<=eco,alpha*fck*(1-(1-AJ14/eco)^n),alpha*fck),0) | AL14: =PM_Angle!$J$21+PM_Angle!$K$21*$C14+PM_Angle!$L$21*$B14 | AM14: =IF(AL14>0,IF(AL14<=eco,alpha*fck*(1-(1-AL14/eco)^n),alpha*fck),0) | AN14: =PM_Angle!$J$22+PM_Angle!$K$22*$C14+PM_Angle!$L$22*$B14 | AO14: =IF(AN14>0,IF(AN14<=eco,alpha*fck*(1-(1-AN14/eco)^n),alpha*fck),0) | AP14: =PM_Angle!$J$23+PM_Angle!$K$23*$C14+PM_Angle!$L$23*$B14 | AQ14: =IF(AP14>0,IF(AP14<=eco,alpha*fck*(1-(1-AP14/eco)^n),alpha*fck),0) | AR14: =PM_Angle!$J$24+PM_Angle!$K$24*$C14+PM_Angle!$L$24*$B14 | AS14: =IF(AR14>0,IF(AR14<=eco,alpha*fck*(1-(1-AR14/eco)^n),alpha*fck),0) | AT14: =PM_Angle!$J$25+PM_Angle!$K$25*$C14+PM_Angle!$L$25*$B14 | AU14: =IF(AT14>0,IF(AT14<=eco,alpha*fck*(1-(1-AT14/eco)^n),alpha*fck),0)
A15: =Mesh!A12 | B15: =Mesh!B12 | C15: =Mesh!C12 | D15: =Mesh!D12 | E15: =INDEX(St_e0,Det+1)+INDEX(St_kx,Det+1)*C15+INDEX(St_ky,Det+1)*B15 | F15: =IF(E15>0,IF(E15<=eco,alpha*fck*(1-(1-E15/eco)^n),alpha*fck),0) | G15: =F15*D15 | H15: =G15*C15 | I15: =G15*B15 | J15: =PM_Angle!$J$7+PM_Angle!$K$7*$C15+PM_Angle!$L$7*$B15 | K15: =IF(J15>0,IF(J15<=eco,alpha*fck*(1-(1-J15/eco)^n),alpha*fck),0) | L15: =PM_Angle!$J$8+PM_Angle!$K$8*$C15+PM_Angle!$L$8*$B15 | M15: =IF(L15>0,IF(L15<=eco,alpha*fck*(1-(1-L15/eco)^n),alpha*fck),0) | N15: =PM_Angle!$J$9+PM_Angle!$K$9*$C15+PM_Angle!$L$9*$B15 | O15: =IF(N15>0,IF(N15<=eco,alpha*fck*(1-(1-N15/eco)^n),alpha*fck),0) | P15: =PM_Angle!$J$10+PM_Angle!$K$10*$C15+PM_Angle!$L$10*$B15 | Q15: =IF(P15>0,IF(P15<=eco,alpha*fck*(1-(1-P15/eco)^n),alpha*fck),0) | R15: =PM_Angle!$J$11+PM_Angle!$K$11*$C15+PM_Angle!$L$11*$B15 | S15: =IF(R15>0,IF(R15<=eco,alpha*fck*(1-(1-R15/eco)^n),alpha*fck),0) | T15: =PM_Angle!$J$12+PM_Angle!$K$12*$C15+PM_Angle!$L$12*$B15 | U15: =IF(T15>0,IF(T15<=eco,alpha*fck*(1-(1-T15/eco)^n),alpha*fck),0) | V15: =PM_Angle!$J$13+PM_Angle!$K$13*$C15+PM_Angle!$L$13*$B15 | W15: =IF(V15>0,IF(V15<=eco,alpha*fck*(1-(1-V15/eco)^n),alpha*fck),0) | X15: =PM_Angle!$J$14+PM_Angle!$K$14*$C15+PM_Angle!$L$14*$B15 | Y15: =IF(X15>0,IF(X15<=eco,alpha*fck*(1-(1-X15/eco)^n),alpha*fck),0) | Z15: =PM_Angle!$J$15+PM_Angle!$K$15*$C15+PM_Angle!$L$15*$B15 | AA15: =IF(Z15>0,IF(Z15<=eco,alpha*fck*(1-(1-Z15/eco)^n),alpha*fck),0) | AB15: =PM_Angle!$J$16+PM_Angle!$K$16*$C15+PM_Angle!$L$16*$B15 | AC15: =IF(AB15>0,IF(AB15<=eco,alpha*fck*(1-(1-AB15/eco)^n),alpha*fck),0) | AD15: =PM_Angle!$J$17+PM_Angle!$K$17*$C15+PM_Angle!$L$17*$B15 | AE15: =IF(AD15>0,IF(AD15<=eco,alpha*fck*(1-(1-AD15/eco)^n),alpha*fck),0) | AF15: =PM_Angle!$J$18+PM_Angle!$K$18*$C15+PM_Angle!$L$18*$B15 | AG15: =IF(AF15>0,IF(AF15<=eco,alpha*fck*(1-(1-AF15/eco)^n),alpha*fck),0) | AH15: =PM_Angle!$J$19+PM_Angle!$K$19*$C15+PM_Angle!$L$19*$B15 | AI15: =IF(AH15>0,IF(AH15<=eco,alpha*fck*(1-(1-AH15/eco)^n),alpha*fck),0) | AJ15: =PM_Angle!$J$20+PM_Angle!$K$20*$C15+PM_Angle!$L$20*$B15 | AK15: =IF(AJ15>0,IF(AJ15<=eco,alpha*fck*(1-(1-AJ15/eco)^n),alpha*fck),0) | AL15: =PM_Angle!$J$21+PM_Angle!$K$21*$C15+PM_Angle!$L$21*$B15 | AM15: =IF(AL15>0,IF(AL15<=eco,alpha*fck*(1-(1-AL15/eco)^n),alpha*fck),0) | AN15: =PM_Angle!$J$22+PM_Angle!$K$22*$C15+PM_Angle!$L$22*$B15 | AO15: =IF(AN15>0,IF(AN15<=eco,alpha*fck*(1-(1-AN15/eco)^n),alpha*fck),0) | AP15: =PM_Angle!$J$23+PM_Angle!$K$23*$C15+PM_Angle!$L$23*$B15 | AQ15: =IF(AP15>0,IF(AP15<=eco,alpha*fck*(1-(1-AP15/eco)^n),alpha*fck),0) | AR15: =PM_Angle!$J$24+PM_Angle!$K$24*$C15+PM_Angle!$L$24*$B15 | AS15: =IF(AR15>0,IF(AR15<=eco,alpha*fck*(1-(1-AR15/eco)^n),alpha*fck),0) | AT15: =PM_Angle!$J$25+PM_Angle!$K$25*$C15+PM_Angle!$L$25*$B15 | AU15: =IF(AT15>0,IF(AT15<=eco,alpha*fck*(1-(1-AT15/eco)^n),alpha*fck),0)
A16: =Mesh!A13 | B16: =Mesh!B13 | C16: =Mesh!C13 | D16: =Mesh!D13 | E16: =INDEX(St_e0,Det+1)+INDEX(St_kx,Det+1)*C16+INDEX(St_ky,Det+1)*B16 | F16: =IF(E16>0,IF(E16<=eco,alpha*fck*(1-(1-E16/eco)^n),alpha*fck),0) | G16: =F16*D16 | H16: =G16*C16 | I16: =G16*B16 | J16: =PM_Angle!$J$7+PM_Angle!$K$7*$C16+PM_Angle!$L$7*$B16 | K16: =IF(J16>0,IF(J16<=eco,alpha*fck*(1-(1-J16/eco)^n),alpha*fck),0) | L16: =PM_Angle!$J$8+PM_Angle!$K$8*$C16+PM_Angle!$L$8*$B16 | M16: =IF(L16>0,IF(L16<=eco,alpha*fck*(1-(1-L16/eco)^n),alpha*fck),0) | N16: =PM_Angle!$J$9+PM_Angle!$K$9*$C16+PM_Angle!$L$9*$B16 | O16: =IF(N16>0,IF(N16<=eco,alpha*fck*(1-(1-N16/eco)^n),alpha*fck),0) | P16: =PM_Angle!$J$10+PM_Angle!$K$10*$C16+PM_Angle!$L$10*$B16 | Q16: =IF(P16>0,IF(P16<=eco,alpha*fck*(1-(1-P16/eco)^n),alpha*fck),0) | R16: =PM_Angle!$J$11+PM_Angle!$K$11*$C16+PM_Angle!$L$11*$B16 | S16: =IF(R16>0,IF(R16<=eco,alpha*fck*(1-(1-R16/eco)^n),alpha*fck),0) | T16: =PM_Angle!$J$12+PM_Angle!$K$12*$C16+PM_Angle!$L$12*$B16 | U16: =IF(T16>0,IF(T16<=eco,alpha*fck*(1-(1-T16/eco)^n),alpha*fck),0) | V16: =PM_Angle!$J$13+PM_Angle!$K$13*$C16+PM_Angle!$L$13*$B16 | W16: =IF(V16>0,IF(V16<=eco,alpha*fck*(1-(1-V16/eco)^n),alpha*fck),0) | X16: =PM_Angle!$J$14+PM_Angle!$K$14*$C16+PM_Angle!$L$14*$B16 | Y16: =IF(X16>0,IF(X16<=eco,alpha*fck*(1-(1-X16/eco)^n),alpha*fck),0) | Z16: =PM_Angle!$J$15+PM_Angle!$K$15*$C16+PM_Angle!$L$15*$B16 | AA16: =IF(Z16>0,IF(Z16<=eco,alpha*fck*(1-(1-Z16/eco)^n),alpha*fck),0) | AB16: =PM_Angle!$J$16+PM_Angle!$K$16*$C16+PM_Angle!$L$16*$B16 | AC16: =IF(AB16>0,IF(AB16<=eco,alpha*fck*(1-(1-AB16/eco)^n),alpha*fck),0) | AD16: =PM_Angle!$J$17+PM_Angle!$K$17*$C16+PM_Angle!$L$17*$B16 | AE16: =IF(AD16>0,IF(AD16<=eco,alpha*fck*(1-(1-AD16/eco)^n),alpha*fck),0) | AF16: =PM_Angle!$J$18+PM_Angle!$K$18*$C16+PM_Angle!$L$18*$B16 | AG16: =IF(AF16>0,IF(AF16<=eco,alpha*fck*(1-(1-AF16/eco)^n),alpha*fck),0) | AH16: =PM_Angle!$J$19+PM_Angle!$K$19*$C16+PM_Angle!$L$19*$B16 | AI16: =IF(AH16>0,IF(AH16<=eco,alpha*fck*(1-(1-AH16/eco)^n),alpha*fck),0) | AJ16: =PM_Angle!$J$20+PM_Angle!$K$20*$C16+PM_Angle!$L$20*$B16 | AK16: =IF(AJ16>0,IF(AJ16<=eco,alpha*fck*(1-(1-AJ16/eco)^n),alpha*fck),0) | AL16: =PM_Angle!$J$21+PM_Angle!$K$21*$C16+PM_Angle!$L$21*$B16 | AM16: =IF(AL16>0,IF(AL16<=eco,alpha*fck*(1-(1-AL16/eco)^n),alpha*fck),0) | AN16: =PM_Angle!$J$22+PM_Angle!$K$22*$C16+PM_Angle!$L$22*$B16 | AO16: =IF(AN16>0,IF(AN16<=eco,alpha*fck*(1-(1-AN16/eco)^n),alpha*fck),0) | AP16: =PM_Angle!$J$23+PM_Angle!$K$23*$C16+PM_Angle!$L$23*$B16 | AQ16: =IF(AP16>0,IF(AP16<=eco,alpha*fck*(1-(1-AP16/eco)^n),alpha*fck),0) | AR16: =PM_Angle!$J$24+PM_Angle!$K$24*$C16+PM_Angle!$L$24*$B16 | AS16: =IF(AR16>0,IF(AR16<=eco,alpha*fck*(1-(1-AR16/eco)^n),alpha*fck),0) | AT16: =PM_Angle!$J$25+PM_Angle!$K$25*$C16+PM_Angle!$L$25*$B16 | AU16: =IF(AT16>0,IF(AT16<=eco,alpha*fck*(1-(1-AT16/eco)^n),alpha*fck),0)
A17: =Mesh!A14 | B17: =Mesh!B14 | C17: =Mesh!C14 | D17: =Mesh!D14 | E17: =INDEX(St_e0,Det+1)+INDEX(St_kx,Det+1)*C17+INDEX(St_ky,Det+1)*B17 | F17: =IF(E17>0,IF(E17<=eco,alpha*fck*(1-(1-E17/eco)^n),alpha*fck),0) | G17: =F17*D17 | H17: =G17*C17 | I17: =G17*B17 | J17: =PM_Angle!$J$7+PM_Angle!$K$7*$C17+PM_Angle!$L$7*$B17 | K17: =IF(J17>0,IF(J17<=eco,alpha*fck*(1-(1-J17/eco)^n),alpha*fck),0) | L17: =PM_Angle!$J$8+PM_Angle!$K$8*$C17+PM_Angle!$L$8*$B17 | M17: =IF(L17>0,IF(L17<=eco,alpha*fck*(1-(1-L17/eco)^n),alpha*fck),0) | N17: =PM_Angle!$J$9+PM_Angle!$K$9*$C17+PM_Angle!$L$9*$B17 | O17: =IF(N17>0,IF(N17<=eco,alpha*fck*(1-(1-N17/eco)^n),alpha*fck),0) | P17: =PM_Angle!$J$10+PM_Angle!$K$10*$C17+PM_Angle!$L$10*$B17 | Q17: =IF(P17>0,IF(P17<=eco,alpha*fck*(1-(1-P17/eco)^n),alpha*fck),0) | R17: =PM_Angle!$J$11+PM_Angle!$K$11*$C17+PM_Angle!$L$11*$B17 | S17: =IF(R17>0,IF(R17<=eco,alpha*fck*(1-(1-R17/eco)^n),alpha*fck),0) | T17: =PM_Angle!$J$12+PM_Angle!$K$12*$C17+PM_Angle!$L$12*$B17 | U17: =IF(T17>0,IF(T17<=eco,alpha*fck*(1-(1-T17/eco)^n),alpha*fck),0) | V17: =PM_Angle!$J$13+PM_Angle!$K$13*$C17+PM_Angle!$L$13*$B17 | W17: =IF(V17>0,IF(V17<=eco,alpha*fck*(1-(1-V17/eco)^n),alpha*fck),0) | X17: =PM_Angle!$J$14+PM_Angle!$K$14*$C17+PM_Angle!$L$14*$B17 | Y17: =IF(X17>0,IF(X17<=eco,alpha*fck*(1-(1-X17/eco)^n),alpha*fck),0) | Z17: =PM_Angle!$J$15+PM_Angle!$K$15*$C17+PM_Angle!$L$15*$B17 | AA17: =IF(Z17>0,IF(Z17<=eco,alpha*fck*(1-(1-Z17/eco)^n),alpha*fck),0) | AB17: =PM_Angle!$J$16+PM_Angle!$K$16*$C17+PM_Angle!$L$16*$B17 | AC17: =IF(AB17>0,IF(AB17<=eco,alpha*fck*(1-(1-AB17/eco)^n),alpha*fck),0) | AD17: =PM_Angle!$J$17+PM_Angle!$K$17*$C17+PM_Angle!$L$17*$B17 | AE17: =IF(AD17>0,IF(AD17<=eco,alpha*fck*(1-(1-AD17/eco)^n),alpha*fck),0) | AF17: =PM_Angle!$J$18+PM_Angle!$K$18*$C17+PM_Angle!$L$18*$B17 | AG17: =IF(AF17>0,IF(AF17<=eco,alpha*fck*(1-(1-AF17/eco)^n),alpha*fck),0) | AH17: =PM_Angle!$J$19+PM_Angle!$K$19*$C17+PM_Angle!$L$19*$B17 | AI17: =IF(AH17>0,IF(AH17<=eco,alpha*fck*(1-(1-AH17/eco)^n),alpha*fck),0) | AJ17: =PM_Angle!$J$20+PM_Angle!$K$20*$C17+PM_Angle!$L$20*$B17 | AK17: =IF(AJ17>0,IF(AJ17<=eco,alpha*fck*(1-(1-AJ17/eco)^n),alpha*fck),0) | AL17: =PM_Angle!$J$21+PM_Angle!$K$21*$C17+PM_Angle!$L$21*$B17 | AM17: =IF(AL17>0,IF(AL17<=eco,alpha*fck*(1-(1-AL17/eco)^n),alpha*fck),0) | AN17: =PM_Angle!$J$22+PM_Angle!$K$22*$C17+PM_Angle!$L$22*$B17 | AO17: =IF(AN17>0,IF(AN17<=eco,alpha*fck*(1-(1-AN17/eco)^n),alpha*fck),0) | AP17: =PM_Angle!$J$23+PM_Angle!$K$23*$C17+PM_Angle!$L$23*$B17 | AQ17: =IF(AP17>0,IF(AP17<=eco,alpha*fck*(1-(1-AP17/eco)^n),alpha*fck),0) | AR17: =PM_Angle!$J$24+PM_Angle!$K$24*$C17+PM_Angle!$L$24*$B17 | AS17: =IF(AR17>0,IF(AR17<=eco,alpha*fck*(1-(1-AR17/eco)^n),alpha*fck),0) | AT17: =PM_Angle!$J$25+PM_Angle!$K$25*$C17+PM_Angle!$L$25*$B17 | AU17: =IF(AT17>0,IF(AT17<=eco,alpha*fck*(1-(1-AT17/eco)^n),alpha*fck),0)
A18: =Mesh!A15 | B18: =Mesh!B15 | C18: =Mesh!C15 | D18: =Mesh!D15 | E18: =INDEX(St_e0,Det+1)+INDEX(St_kx,Det+1)*C18+INDEX(St_ky,Det+1)*B18 | F18: =IF(E18>0,IF(E18<=eco,alpha*fck*(1-(1-E18/eco)^n),alpha*fck),0) | G18: =F18*D18 | H18: =G18*C18 | I18: =G18*B18 | J18: =PM_Angle!$J$7+PM_Angle!$K$7*$C18+PM_Angle!$L$7*$B18 | K18: =IF(J18>0,IF(J18<=eco,alpha*fck*(1-(1-J18/eco)^n),alpha*fck),0) | L18: =PM_Angle!$J$8+PM_Angle!$K$8*$C18+PM_Angle!$L$8*$B18 | M18: =IF(L18>0,IF(L18<=eco,alpha*fck*(1-(1-L18/eco)^n),alpha*fck),0) | N18: =PM_Angle!$J$9+PM_Angle!$K$9*$C18+PM_Angle!$L$9*$B18 | O18: =IF(N18>0,IF(N18<=eco,alpha*fck*(1-(1-N18/eco)^n),alpha*fck),0) | P18: =PM_Angle!$J$10+PM_Angle!$K$10*$C18+PM_Angle!$L$10*$B18 | Q18: =IF(P18>0,IF(P18<=eco,alpha*fck*(1-(1-P18/eco)^n),alpha*fck),0) | R18: =PM_Angle!$J$11+PM_Angle!$K$11*$C18+PM_Angle!$L$11*$B18 | S18: =IF(R18>0,IF(R18<=eco,alpha*fck*(1-(1-R18/eco)^n),alpha*fck),0) | T18: =PM_Angle!$J$12+PM_Angle!$K$12*$C18+PM_Angle!$L$12*$B18 | U18: =IF(T18>0,IF(T18<=eco,alpha*fck*(1-(1-T18/eco)^n),alpha*fck),0) | V18: =PM_Angle!$J$13+PM_Angle!$K$13*$C18+PM_Angle!$L$13*$B18 | W18: =IF(V18>0,IF(V18<=eco,alpha*fck*(1-(1-V18/eco)^n),alpha*fck),0) | X18: =PM_Angle!$J$14+PM_Angle!$K$14*$C18+PM_Angle!$L$14*$B18 | Y18: =IF(X18>0,IF(X18<=eco,alpha*fck*(1-(1-X18/eco)^n),alpha*fck),0) | Z18: =PM_Angle!$J$15+PM_Angle!$K$15*$C18+PM_Angle!$L$15*$B18 | AA18: =IF(Z18>0,IF(Z18<=eco,alpha*fck*(1-(1-Z18/eco)^n),alpha*fck),0) | AB18: =PM_Angle!$J$16+PM_Angle!$K$16*$C18+PM_Angle!$L$16*$B18 | AC18: =IF(AB18>0,IF(AB18<=eco,alpha*fck*(1-(1-AB18/eco)^n),alpha*fck),0) | AD18: =PM_Angle!$J$17+PM_Angle!$K$17*$C18+PM_Angle!$L$17*$B18 | AE18: =IF(AD18>0,IF(AD18<=eco,alpha*fck*(1-(1-AD18/eco)^n),alpha*fck),0) | AF18: =PM_Angle!$J$18+PM_Angle!$K$18*$C18+PM_Angle!$L$18*$B18 | AG18: =IF(AF18>0,IF(AF18<=eco,alpha*fck*(1-(1-AF18/eco)^n),alpha*fck),0) | AH18: =PM_Angle!$J$19+PM_Angle!$K$19*$C18+PM_Angle!$L$19*$B18 | AI18: =IF(AH18>0,IF(AH18<=eco,alpha*fck*(1-(1-AH18/eco)^n),alpha*fck),0) | AJ18: =PM_Angle!$J$20+PM_Angle!$K$20*$C18+PM_Angle!$L$20*$B18 | AK18: =IF(AJ18>0,IF(AJ18<=eco,alpha*fck*(1-(1-AJ18/eco)^n),alpha*fck),0) | AL18: =PM_Angle!$J$21+PM_Angle!$K$21*$C18+PM_Angle!$L$21*$B18 | AM18: =IF(AL18>0,IF(AL18<=eco,alpha*fck*(1-(1-AL18/eco)^n),alpha*fck),0) | AN18: =PM_Angle!$J$22+PM_Angle!$K$22*$C18+PM_Angle!$L$22*$B18 | AO18: =IF(AN18>0,IF(AN18<=eco,alpha*fck*(1-(1-AN18/eco)^n),alpha*fck),0) | AP18: =PM_Angle!$J$23+PM_Angle!$K$23*$C18+PM_Angle!$L$23*$B18 | AQ18: =IF(AP18>0,IF(AP18<=eco,alpha*fck*(1-(1-AP18/eco)^n),alpha*fck),0) | AR18: =PM_Angle!$J$24+PM_Angle!$K$24*$C18+PM_Angle!$L$24*$B18 | AS18: =IF(AR18>0,IF(AR18<=eco,alpha*fck*(1-(1-AR18/eco)^n),alpha*fck),0) | AT18: =PM_Angle!$J$25+PM_Angle!$K$25*$C18+PM_Angle!$L$25*$B18 | AU18: =IF(AT18>0,IF(AT18<=eco,alpha*fck*(1-(1-AT18/eco)^n),alpha*fck),0)
A19: =Mesh!A16 | B19: =Mesh!B16 | C19: =Mesh!C16 | D19: =Mesh!D16 | E19: =INDEX(St_e0,Det+1)+INDEX(St_kx,Det+1)*C19+INDEX(St_ky,Det+1)*B19 | F19: =IF(E19>0,IF(E19<=eco,alpha*fck*(1-(1-E19/eco)^n),alpha*fck),0) | G19: =F19*D19 | H19: =G19*C19 | I19: =G19*B19 | J19: =PM_Angle!$J$7+PM_Angle!$K$7*$C19+PM_Angle!$L$7*$B19 | K19: =IF(J19>0,IF(J19<=eco,alpha*fck*(1-(1-J19/eco)^n),alpha*fck),0) | L19: =PM_Angle!$J$8+PM_Angle!$K$8*$C19+PM_Angle!$L$8*$B19 | M19: =IF(L19>0,IF(L19<=eco,alpha*fck*(1-(1-L19/eco)^n),alpha*fck),0) | N19: =PM_Angle!$J$9+PM_Angle!$K$9*$C19+PM_Angle!$L$9*$B19 | O19: =IF(N19>0,IF(N19<=eco,alpha*fck*(1-(1-N19/eco)^n),alpha*fck),0) | P19: =PM_Angle!$J$10+PM_Angle!$K$10*$C19+PM_Angle!$L$10*$B19 | Q19: =IF(P19>0,IF(P19<=eco,alpha*fck*(1-(1-P19/eco)^n),alpha*fck),0) | R19: =PM_Angle!$J$11+PM_Angle!$K$11*$C19+PM_Angle!$L$11*$B19 | S19: =IF(R19>0,IF(R19<=eco,alpha*fck*(1-(1-R19/eco)^n),alpha*fck),0) | T19: =PM_Angle!$J$12+PM_Angle!$K$12*$C19+PM_Angle!$L$12*$B19 | U19: =IF(T19>0,IF(T19<=eco,alpha*fck*(1-(1-T19/eco)^n),alpha*fck),0) | V19: =PM_Angle!$J$13+PM_Angle!$K$13*$C19+PM_Angle!$L$13*$B19 | W19: =IF(V19>0,IF(V19<=eco,alpha*fck*(1-(1-V19/eco)^n),alpha*fck),0) | X19: =PM_Angle!$J$14+PM_Angle!$K$14*$C19+PM_Angle!$L$14*$B19 | Y19: =IF(X19>0,IF(X19<=eco,alpha*fck*(1-(1-X19/eco)^n),alpha*fck),0) | Z19: =PM_Angle!$J$15+PM_Angle!$K$15*$C19+PM_Angle!$L$15*$B19 | AA19: =IF(Z19>0,IF(Z19<=eco,alpha*fck*(1-(1-Z19/eco)^n),alpha*fck),0) | AB19: =PM_Angle!$J$16+PM_Angle!$K$16*$C19+PM_Angle!$L$16*$B19 | AC19: =IF(AB19>0,IF(AB19<=eco,alpha*fck*(1-(1-AB19/eco)^n),alpha*fck),0) | AD19: =PM_Angle!$J$17+PM_Angle!$K$17*$C19+PM_Angle!$L$17*$B19 | AE19: =IF(AD19>0,IF(AD19<=eco,alpha*fck*(1-(1-AD19/eco)^n),alpha*fck),0) | AF19: =PM_Angle!$J$18+PM_Angle!$K$18*$C19+PM_Angle!$L$18*$B19 | AG19: =IF(AF19>0,IF(AF19<=eco,alpha*fck*(1-(1-AF19/eco)^n),alpha*fck),0) | AH19: =PM_Angle!$J$19+PM_Angle!$K$19*$C19+PM_Angle!$L$19*$B19 | AI19: =IF(AH19>0,IF(AH19<=eco,alpha*fck*(1-(1-AH19/eco)^n),alpha*fck),0) | AJ19: =PM_Angle!$J$20+PM_Angle!$K$20*$C19+PM_Angle!$L$20*$B19 | AK19: =IF(AJ19>0,IF(AJ19<=eco,alpha*fck*(1-(1-AJ19/eco)^n),alpha*fck),0) | AL19: =PM_Angle!$J$21+PM_Angle!$K$21*$C19+PM_Angle!$L$21*$B19 | AM19: =IF(AL19>0,IF(AL19<=eco,alpha*fck*(1-(1-AL19/eco)^n),alpha*fck),0) | AN19: =PM_Angle!$J$22+PM_Angle!$K$22*$C19+PM_Angle!$L$22*$B19 | AO19: =IF(AN19>0,IF(AN19<=eco,alpha*fck*(1-(1-AN19/eco)^n),alpha*fck),0) | AP19: =PM_Angle!$J$23+PM_Angle!$K$23*$C19+PM_Angle!$L$23*$B19 | AQ19: =IF(AP19>0,IF(AP19<=eco,alpha*fck*(1-(1-AP19/eco)^n),alpha*fck),0) | AR19: =PM_Angle!$J$24+PM_Angle!$K$24*$C19+PM_Angle!$L$24*$B19 | AS19: =IF(AR19>0,IF(AR19<=eco,alpha*fck*(1-(1-AR19/eco)^n),alpha*fck),0) | AT19: =PM_Angle!$J$25+PM_Angle!$K$25*$C19+PM_Angle!$L$25*$B19 | AU19: =IF(AT19>0,IF(AT19<=eco,alpha*fck*(1-(1-AT19/eco)^n),alpha*fck),0)
... A1264: =Mesh!A1261 | B1264: =Mesh!B1261 | C1264: =Mesh!C1261 | D1264: =Mesh!D1261 | E1264: =INDEX(St_e0,Det+1)+INDEX(St_kx,Det+1)*C1264+INDEX(St_ky,Det+1)*B1264 | F1264: =IF(E1264>0,IF(E1264<=eco,alpha*fck*(1-(1-E1264/eco)^n),alpha*fck),0) | G1264: =F1264*D1264 | H1264: =G1264*C1264 | I1264: =G1264*B1264 | J1264: =PM_Angle!$J$7+PM_Angle!$K$7*$C1264+PM_Angle!$L$7*$B1264 | K1264: =IF(J1264>0,IF(J1264<=eco,alpha*fck*(1-(1-J1264/eco)^n),alpha*fck),0) | L1264: =PM_Angle!$J$8+PM_Angle!$K$8*$C1264+PM_Angle!$L$8*$B1264 | M1264: =IF(L1264>0,IF(L1264<=eco,alpha*fck*(1-(1-L1264/eco)^n),alpha*fck),0) | N1264: =PM_Angle!$J$9+PM_Angle!$K$9*$C1264+PM_Angle!$L$9*$B1264 | O1264: =IF(N1264>0,IF(N1264<=eco,alpha*fck*(1-(1-N1264/eco)^n),alpha*fck),0) | P1264: =PM_Angle!$J$10+PM_Angle!$K$10*$C1264+PM_Angle!$L$10*$B1264 | Q1264: =IF(P1264>0,IF(P1264<=eco,alpha*fck*(1-(1-P1264/eco)^n),alpha*fck),0) | R1264: =PM_Angle!$J$11+PM_Angle!$K$11*$C1264+PM_Angle!$L$11*$B1264 | S1264: =IF(R1264>0,IF(R1264<=eco,alpha*fck*(1-(1-R1264/eco)^n),alpha*fck),0) | T1264: =PM_Angle!$J$12+PM_Angle!$K$12*$C1264+PM_Angle!$L$12*$B1264 | U1264: =IF(T1264>0,IF(T1264<=eco,alpha*fck*(1-(1-T1264/eco)^n),alpha*fck),0) | V1264: =PM_Angle!$J$13+PM_Angle!$K$13*$C1264+PM_Angle!$L$13*$B1264 | W1264: =IF(V1264>0,IF(V1264<=eco,alpha*fck*(1-(1-V1264/eco)^n),alpha*fck),0) | X1264: =PM_Angle!$J$14+PM_Angle!$K$14*$C1264+PM_Angle!$L$14*$B1264 | Y1264: =IF(X1264>0,IF(X1264<=eco,alpha*fck*(1-(1-X1264/eco)^n),alpha*fck),0) | Z1264: =PM_Angle!$J$15+PM_Angle!$K$15*$C1264+PM_Angle!$L$15*$B1264 | AA1264: =IF(Z1264>0,IF(Z1264<=eco,alpha*fck*(1-(1-Z1264/eco)^n),alpha*fck),0) | AB1264: =PM_Angle!$J$16+PM_Angle!$K$16*$C1264+PM_Angle!$L$16*$B1264 | AC1264: =IF(AB1264>0,IF(AB1264<=eco,alpha*fck*(1-(1-AB1264/eco)^n),alpha*fck),0) | AD1264: =PM_Angle!$J$17+PM_Angle!$K$17*$C1264+PM_Angle!$L$17*$B1264 | AE1264: =IF(AD1264>0,IF(AD1264<=eco,alpha*fck*(1-(1-AD1264/eco)^n),alpha*fck),0) | AF1264: =PM_Angle!$J$18+PM_Angle!$K$18*$C1264+PM_Angle!$L$18*$B1264 | AG1264: =IF(AF1264>0,IF(AF1264<=eco,alpha*fck*(1-(1-AF1264/eco)^n),alpha*fck),0) | AH1264: =PM_Angle!$J$19+PM_Angle!$K$19*$C1264+PM_Angle!$L$19*$B1264 | AI1264: =IF(AH1264>0,IF(AH1264<=eco,alpha*fck*(1-(1-AH1264/eco)^n),alpha*fck),0) | AJ1264: =PM_Angle!$J$20+PM_Angle!$K$20*$C1264+PM_Angle!$L$20*$B1264 | AK1264: =IF(AJ1264>0,IF(AJ1264<=eco,alpha*fck*(1-(1-AJ1264/eco)^n),alpha*fck),0) | AL1264: =PM_Angle!$J$21+PM_Angle!$K$21*$C1264+PM_Angle!$L$21*$B1264 | AM1264: =IF(AL1264>0,IF(AL1264<=eco,alpha*fck*(1-(1-AL1264/eco)^n),alpha*fck),0) | AN1264: =PM_Angle!$J$22+PM_Angle!$K$22*$C1264+PM_Angle!$L$22*$B1264 | AO1264: =IF(AN1264>0,IF(AN1264<=eco,alpha*fck*(1-(1-AN1264/eco)^n),alpha*fck),0) | AP1264: =PM_Angle!$J$23+PM_Angle!$K$23*$C1264+PM_Angle!$L$23*$B1264 | AQ1264: =IF(AP1264>0,IF(AP1264<=eco,alpha*fck*(1-(1-AP1264/eco)^n),alpha*fck),0) | AR1264: =PM_Angle!$J$24+PM_Angle!$K$24*$C1264+PM_Angle!$L$24*$B1264 | AS1264: =IF(AR1264>0,IF(AR1264<=eco,alpha*fck*(1-(1-AR1264/eco)^n),alpha*fck),0) | AT1264: =PM_Angle!$J$25+PM_Angle!$K$25*$C1264+PM_Angle!$L$25*$B1264 | AU1264: =IF(AT1264>0,IF(AT1264<=eco,alpha*fck*(1-(1-AT1264/eco)^n),alpha*fck),0)

Sheet Steel
A1: REINFORCEMENT — PER BAR, ALL 19 STATIONS
A2: fs = Elastic - perfectly plastic, fs = clamp(Es*eps, -fy, +fy). The bar force uses fs,eff = fs − fc so the concrete displaced by the bar is not counted twice (docs/11 §3.3).
F4: P0 | M4: P1 | T4: P2 | AA4: P3 | AH4: P4 | AO4: P5 | AV4: P6 | BC4: P7 | BJ4: P8 | BQ4: P9 | BX4: P10 | CE4: P11 | CL4: P12 | CS4: P13 | CZ4: P14 | DG4: P15 | DN4: P16 | DU4: P17 | EB4: P18
